2019-06-13 06:43:51,223 INFO org.apache.hadoop.yarn.server.resourcemanager.ResourceManager: STARTUP_MSG: 
/************************************************************
STARTUP_MSG: Starting ResourceManager
STARTUP_MSG:   host = dea0525850a6/172.24.0.2
STARTUP_MSG:   args = []
STARTUP_MSG:   version = 2.7.0
STARTUP_MSG:   build = https://git-wip-us.apache.org/repos/asf/hadoop.git -r d4c8d4d4d203c934e8074b31289a28724c0842cf; compiled by 'jenkins' on 2015-04-10T18:40Z
STARTUP_MSG:   java = 1.7.0_71
************************************************************/
2019-06-13 06:43:51,238 INFO org.apache.hadoop.yarn.server.resourcemanager.ResourceManager: registered UNIX signal handlers for [TERM, HUP, INT]
2019-06-13 06:43:51,662 INFO org.apache.hadoop.conf.Configuration: found resource core-site.xml at file:/usr/local/hadoop-2.7.0/etc/hadoop/core-site.xml
2019-06-13 06:43:51,876 INFO org.apache.hadoop.security.Groups: clearing userToGroupsMap cache
2019-06-13 06:43:52,175 INFO org.apache.hadoop.conf.Configuration: found resource yarn-site.xml at file:/usr/local/hadoop-2.7.0/etc/hadoop/yarn-site.xml
2019-06-13 06:43:53,255 INFO org.apache.hadoop.yarn.event.AsyncDispatcher: Registering class org.apache.hadoop.yarn.server.resourcemanager.RMFatalEventType for class org.apache.hadoop.yarn.server.resourcemanager.ResourceManager$RMFatalEventDispatcher
2019-06-13 06:43:54,463 INFO org.apache.hadoop.yarn.server.resourcemanager.security.NMTokenSecretManagerInRM: NMTokenKeyRollingInterval: 86400000ms and NMTokenKeyActivationDelay: 900000ms
2019-06-13 06:43:54,468 INFO org.apache.hadoop.yarn.server.resourcemanager.security.RMContainerTokenSecretManager: ContainerTokenKeyRollingInterval: 86400000ms and ContainerTokenKeyActivationDelay: 900000ms
2019-06-13 06:43:54,475 INFO org.apache.hadoop.yarn.server.resourcemanager.security.AMRMTokenSecretManager: AMRMTokenKeyRollingInterval: 86400000ms and AMRMTokenKeyActivationDelay: 900000 ms
2019-06-13 06:43:54,664 INFO org.apache.hadoop.yarn.event.AsyncDispatcher: Registering class org.apache.hadoop.yarn.server.resourcemanager.recovery.RMStateStoreEventType for class org.apache.hadoop.yarn.server.resourcemanager.recovery.RMStateStore$ForwardingEventHandler
2019-06-13 06:43:54,762 INFO org.apache.hadoop.yarn.event.AsyncDispatcher: Registering class org.apache.hadoop.yarn.server.resourcemanager.NodesListManagerEventType for class org.apache.hadoop.yarn.server.resourcemanager.NodesListManager
2019-06-13 06:43:54,762 INFO org.apache.hadoop.yarn.server.resourcemanager.ResourceManager: Using Scheduler: org.apache.hadoop.yarn.server.resourcemanager.scheduler.capacity.CapacityScheduler
2019-06-13 06:43:54,894 INFO org.apache.hadoop.yarn.event.AsyncDispatcher: Registering class org.apache.hadoop.yarn.server.resourcemanager.scheduler.event.SchedulerEventType for class org.apache.hadoop.yarn.server.resourcemanager.ResourceManager$SchedulerEventDispatcher
2019-06-13 06:43:54,895 INFO org.apache.hadoop.yarn.event.AsyncDispatcher: Registering class org.apache.hadoop.yarn.server.resourcemanager.rmapp.RMAppEventType for class org.apache.hadoop.yarn.server.resourcemanager.ResourceManager$ApplicationEventDispatcher
2019-06-13 06:43:54,897 INFO org.apache.hadoop.yarn.event.AsyncDispatcher: Registering class org.apache.hadoop.yarn.server.resourcemanager.rmapp.attempt.RMAppAttemptEventType for class org.apache.hadoop.yarn.server.resourcemanager.ResourceManager$ApplicationAttemptEventDispatcher
2019-06-13 06:43:54,898 INFO org.apache.hadoop.yarn.event.AsyncDispatcher: Registering class org.apache.hadoop.yarn.server.resourcemanager.rmnode.RMNodeEventType for class org.apache.hadoop.yarn.server.resourcemanager.ResourceManager$NodeEventDispatcher
2019-06-13 06:43:55,118 INFO org.apache.hadoop.metrics2.impl.MetricsConfig: loaded properties from hadoop-metrics2.properties
2019-06-13 06:43:55,371 INFO org.apache.hadoop.metrics2.impl.MetricsSystemImpl: Scheduled snapshot period at 10 second(s).
2019-06-13 06:43:55,371 INFO org.apache.hadoop.metrics2.impl.MetricsSystemImpl: ResourceManager metrics system started
2019-06-13 06:43:55,743 INFO org.apache.hadoop.yarn.event.AsyncDispatcher: Registering class org.apache.hadoop.yarn.server.resourcemanager.RMAppManagerEventType for class org.apache.hadoop.yarn.server.resourcemanager.RMAppManager
2019-06-13 06:43:55,874 INFO org.apache.hadoop.yarn.event.AsyncDispatcher: Registering class org.apache.hadoop.yarn.server.resourcemanager.amlauncher.AMLauncherEventType for class org.apache.hadoop.yarn.server.resourcemanager.amlauncher.ApplicationMasterLauncher
2019-06-13 06:43:55,876 INFO org.apache.hadoop.yarn.server.resourcemanager.RMNMInfo: Registered RMNMInfo MBean
2019-06-13 06:43:55,878 INFO org.apache.hadoop.yarn.security.YarnAuthorizationProvider: org.apache.hadoop.yarn.security.ConfiguredYarnAuthorizer is instiantiated.
2019-06-13 06:43:55,878 INFO org.apache.hadoop.yarn.server.resourcemanager.metrics.SystemMetricsPublisher: YARN system metrics publishing service is not enabled
2019-06-13 06:43:55,879 INFO org.apache.hadoop.util.HostsFileReader: Refreshing hosts (include/exclude) list
2019-06-13 06:43:55,908 INFO org.apache.hadoop.conf.Configuration: found resource capacity-scheduler.xml at file:/usr/local/hadoop-2.7.0/etc/hadoop/capacity-scheduler.xml
2019-06-13 06:43:56,189 INFO org.apache.hadoop.yarn.server.resourcemanager.scheduler.capacity.CapacitySchedulerConfiguration: max alloc mb per queue for root is undefined
2019-06-13 06:43:56,253 INFO org.apache.hadoop.yarn.server.resourcemanager.scheduler.capacity.CapacitySchedulerConfiguration: max alloc vcore per queue for root is undefined
2019-06-13 06:43:56,266 INFO org.apache.hadoop.yarn.server.resourcemanager.scheduler.capacity.ParentQueue: root, capacity=1.0, asboluteCapacity=1.0, maxCapacity=1.0, asboluteMaxCapacity=1.0, state=RUNNING, acls=ADMINISTER_QUEUE:*SUBMIT_APP:*, labels=*,
, reservationsContinueLooking=true
2019-06-13 06:43:56,266 INFO org.apache.hadoop.yarn.server.resourcemanager.scheduler.capacity.ParentQueue: Initialized parent-queue root name=root, fullname=root
2019-06-13 06:43:56,296 INFO org.apache.hadoop.yarn.server.resourcemanager.scheduler.capacity.CapacitySchedulerConfiguration: max alloc mb per queue for root.default is undefined
2019-06-13 06:43:56,296 INFO org.apache.hadoop.yarn.server.resourcemanager.scheduler.capacity.CapacitySchedulerConfiguration: max alloc vcore per queue for root.default is undefined
2019-06-13 06:43:56,301 INFO org.apache.hadoop.yarn.server.resourcemanager.scheduler.capacity.LeafQueue: Initializing default
capacity = 1.0 [= (float) configuredCapacity / 100 ]
asboluteCapacity = 1.0 [= parentAbsoluteCapacity * capacity ]
maxCapacity = 1.0 [= configuredMaxCapacity ]
absoluteMaxCapacity = 1.0 [= 1.0 maximumCapacity undefined, (parentAbsoluteMaxCapacity * maximumCapacity) / 100 otherwise ]
userLimit = 100 [= configuredUserLimit ]
userLimitFactor = 1.0 [= configuredUserLimitFactor ]
maxApplications = 10000 [= configuredMaximumSystemApplicationsPerQueue or (int)(configuredMaximumSystemApplications * absoluteCapacity)]
maxApplicationsPerUser = 10000 [= (int)(maxApplications * (userLimit / 100.0f) * userLimitFactor) ]
usedCapacity = 0.0 [= usedResourcesMemory / (clusterResourceMemory * absoluteCapacity)]
absoluteUsedCapacity = 0.0 [= usedResourcesMemory / clusterResourceMemory]
maxAMResourcePerQueuePercent = 0.1 [= configuredMaximumAMResourcePercent ]
minimumAllocationFactor = 0.875 [= (float)(maximumAllocationMemory - minimumAllocationMemory) / maximumAllocationMemory ]
maximumAllocation = <memory:8192, vCores:32> [= configuredMaxAllocation ]
numContainers = 0 [= currentNumContainers ]
state = RUNNING [= configuredState ]
acls = ADMINISTER_QUEUE:*SUBMIT_APP:* [= configuredAcls ]
nodeLocalityDelay = 40
labels=*,
nodeLocalityDelay = 40
reservationsContinueLooking = true
preemptionDisabled = true

2019-06-13 06:43:56,301 INFO org.apache.hadoop.yarn.server.resourcemanager.scheduler.capacity.CapacityScheduler: Initialized queue: default: capacity=1.0, absoluteCapacity=1.0, usedResources=<memory:0, vCores:0>, usedCapacity=0.0, absoluteUsedCapacity=0.0, numApps=0, numContainers=0
2019-06-13 06:43:56,307 INFO org.apache.hadoop.yarn.server.resourcemanager.scheduler.capacity.CapacityScheduler: Initialized queue: root: numChildQueue= 1, capacity=1.0, absoluteCapacity=1.0, usedResources=<memory:0, vCores:0>usedCapacity=0.0, numApps=0, numContainers=0
2019-06-13 06:43:56,308 INFO org.apache.hadoop.yarn.server.resourcemanager.scheduler.capacity.CapacityScheduler: Initialized root queue root: numChildQueue= 1, capacity=1.0, absoluteCapacity=1.0, usedResources=<memory:0, vCores:0>usedCapacity=0.0, numApps=0, numContainers=0
2019-06-13 06:43:56,308 INFO org.apache.hadoop.yarn.server.resourcemanager.scheduler.capacity.CapacityScheduler: Initialized queue mappings, override: false
2019-06-13 06:43:56,308 INFO org.apache.hadoop.yarn.server.resourcemanager.scheduler.capacity.CapacityScheduler: Initialized CapacityScheduler with calculator=class org.apache.hadoop.yarn.util.resource.DefaultResourceCalculator, minimumAllocation=<<memory:1024, vCores:1>>, maximumAllocation=<<memory:8192, vCores:32>>, asynchronousScheduling=false, asyncScheduleInterval=5ms
2019-06-13 06:43:56,354 INFO org.apache.hadoop.yarn.server.resourcemanager.ResourceManager: Transitioning to active state
2019-06-13 06:43:57,224 INFO org.apache.hadoop.yarn.server.resourcemanager.recovery.RMStateStore: Updating AMRMToken
2019-06-13 06:43:57,227 INFO org.apache.hadoop.yarn.server.resourcemanager.security.RMContainerTokenSecretManager: Rolling master-key for container-tokens
2019-06-13 06:43:57,227 INFO org.apache.hadoop.yarn.server.resourcemanager.security.NMTokenSecretManagerInRM: Rolling master-key for nm-tokens
2019-06-13 06:43:57,228 INFO org.apache.hadoop.security.token.delegation.AbstractDelegationTokenSecretManager: Updating the current master key for generating delegation tokens
2019-06-13 06:43:57,230 INFO org.apache.hadoop.yarn.server.resourcemanager.security.RMDelegationTokenSecretManager: storing master key with keyID 1
2019-06-13 06:43:57,230 INFO org.apache.hadoop.yarn.server.resourcemanager.recovery.RMStateStore: Storing RMDTMasterKey.
2019-06-13 06:43:57,231 INFO org.apache.hadoop.security.token.delegation.AbstractDelegationTokenSecretManager: Starting expired delegation token remover thread, tokenRemoverScanInterval=60 min(s)
2019-06-13 06:43:57,232 INFO org.apache.hadoop.security.token.delegation.AbstractDelegationTokenSecretManager: Updating the current master key for generating delegation tokens
2019-06-13 06:43:57,232 INFO org.apache.hadoop.yarn.server.resourcemanager.security.RMDelegationTokenSecretManager: storing master key with keyID 2
2019-06-13 06:43:57,232 INFO org.apache.hadoop.yarn.server.resourcemanager.recovery.RMStateStore: Storing RMDTMasterKey.
2019-06-13 06:43:57,234 INFO org.apache.hadoop.yarn.event.AsyncDispatcher: Registering class org.apache.hadoop.yarn.nodelabels.event.NodeLabelsStoreEventType for class org.apache.hadoop.yarn.nodelabels.CommonNodeLabelsManager$ForwardingEventHandler
2019-06-13 06:43:57,482 INFO org.apache.hadoop.ipc.CallQueueManager: Using callQueue class java.util.concurrent.LinkedBlockingQueue
2019-06-13 06:43:57,498 INFO org.apache.hadoop.ipc.Server: Starting Socket Reader #1 for port 8031
2019-06-13 06:43:57,552 INFO org.apache.hadoop.yarn.factories.impl.pb.RpcServerFactoryPBImpl: Adding protocol org.apache.hadoop.yarn.server.api.ResourceTrackerPB to the server
2019-06-13 06:43:57,552 INFO org.apache.hadoop.ipc.Server: IPC Server Responder: starting
2019-06-13 06:43:57,552 INFO org.apache.hadoop.ipc.Server: IPC Server listener on 8031: starting
2019-06-13 06:43:58,549 INFO org.apache.hadoop.ipc.CallQueueManager: Using callQueue class java.util.concurrent.LinkedBlockingQueue
2019-06-13 06:43:58,558 INFO org.apache.hadoop.ipc.Server: Starting Socket Reader #1 for port 8030
2019-06-13 06:43:58,577 INFO org.apache.hadoop.yarn.factories.impl.pb.RpcServerFactoryPBImpl: Adding protocol org.apache.hadoop.yarn.api.ApplicationMasterProtocolPB to the server
2019-06-13 06:43:58,578 INFO org.apache.hadoop.ipc.Server: IPC Server Responder: starting
2019-06-13 06:43:58,578 INFO org.apache.hadoop.ipc.Server: IPC Server listener on 8030: starting
2019-06-13 06:43:58,873 INFO org.apache.hadoop.ipc.CallQueueManager: Using callQueue class java.util.concurrent.LinkedBlockingQueue
2019-06-13 06:43:58,874 INFO org.apache.hadoop.ipc.Server: Starting Socket Reader #1 for port 8032
2019-06-13 06:43:58,878 INFO org.apache.hadoop.yarn.factories.impl.pb.RpcServerFactoryPBImpl: Adding protocol org.apache.hadoop.yarn.api.ApplicationClientProtocolPB to the server
2019-06-13 06:43:58,878 INFO org.apache.hadoop.ipc.Server: IPC Server Responder: starting
2019-06-13 06:43:58,883 INFO org.apache.hadoop.ipc.Server: IPC Server listener on 8032: starting
2019-06-13 06:43:58,888 INFO org.apache.hadoop.yarn.server.resourcemanager.ResourceManager: Transitioned to active state
2019-06-13 06:43:59,292 INFO org.mortbay.log: Logging to org.slf4j.impl.Log4jLoggerAdapter(org.mortbay.log) via org.mortbay.log.Slf4jLog
2019-06-13 06:43:59,345 INFO org.apache.hadoop.security.authentication.server.AuthenticationFilter: Unable to initialize FileSignerSecretProvider, falling back to use random secrets.
2019-06-13 06:43:59,351 INFO org.apache.hadoop.http.HttpRequestLog: Http request log for http.requests.resourcemanager is not defined
2019-06-13 06:43:59,428 INFO org.apache.hadoop.http.HttpServer2: Added global filter 'safety' (class=org.apache.hadoop.http.HttpServer2$QuotingInputFilter)
2019-06-13 06:43:59,434 INFO org.apache.hadoop.http.HttpServer2: Added filter RMAuthenticationFilter (class=org.apache.hadoop.yarn.server.security.http.RMAuthenticationFilter) to context cluster
2019-06-13 06:43:59,435 INFO org.apache.hadoop.http.HttpServer2: Added filter RMAuthenticationFilter (class=org.apache.hadoop.yarn.server.security.http.RMAuthenticationFilter) to context logs
2019-06-13 06:43:59,435 INFO org.apache.hadoop.http.HttpServer2: Added filter RMAuthenticationFilter (class=org.apache.hadoop.yarn.server.security.http.RMAuthenticationFilter) to context static
2019-06-13 06:43:59,435 INFO org.apache.hadoop.http.HttpServer2: Added filter static_user_filter (class=org.apache.hadoop.http.lib.StaticUserWebFilter$StaticUserFilter) to context cluster
2019-06-13 06:43:59,435 INFO org.apache.hadoop.http.HttpServer2: Added filter static_user_filter (class=org.apache.hadoop.http.lib.StaticUserWebFilter$StaticUserFilter) to context logs
2019-06-13 06:43:59,435 INFO org.apache.hadoop.http.HttpServer2: Added filter static_user_filter (class=org.apache.hadoop.http.lib.StaticUserWebFilter$StaticUserFilter) to context static
2019-06-13 06:43:59,439 INFO org.apache.hadoop.http.HttpServer2: adding path spec: /cluster/*
2019-06-13 06:43:59,439 INFO org.apache.hadoop.http.HttpServer2: adding path spec: /ws/*
2019-06-13 06:43:59,447 INFO org.apache.hadoop.http.HttpServer2: Jetty bound to port 8088
2019-06-13 06:43:59,447 INFO org.mortbay.log: jetty-6.1.26
2019-06-13 06:43:59,904 INFO org.mortbay.log: Extract jar:file:/usr/local/hadoop-2.7.0/share/hadoop/yarn/hadoop-yarn-common-2.7.0.jar!/webapps/cluster to /tmp/Jetty_0_0_0_0_8088_cluster____u0rgz3/webapp
2019-06-13 06:44:00,799 INFO org.apache.hadoop.security.token.delegation.AbstractDelegationTokenSecretManager: Updating the current master key for generating delegation tokens
2019-06-13 06:44:00,800 INFO org.apache.hadoop.security.token.delegation.AbstractDelegationTokenSecretManager: Starting expired delegation token remover thread, tokenRemoverScanInterval=60 min(s)
2019-06-13 06:44:00,800 INFO org.apache.hadoop.security.token.delegation.AbstractDelegationTokenSecretManager: Updating the current master key for generating delegation tokens
2019-06-13 06:44:00,808 INFO org.mortbay.log: Started HttpServer2$SelectChannelConnectorWithSafeStartup@0.0.0.0:8088
2019-06-13 06:44:00,808 INFO org.apache.hadoop.yarn.webapp.WebApps: Web app /cluster started at 8088
2019-06-13 06:44:01,968 INFO org.apache.hadoop.yarn.webapp.WebApps: Registered webapp guice modules
2019-06-13 06:44:02,238 INFO org.apache.hadoop.ipc.CallQueueManager: Using callQueue class java.util.concurrent.LinkedBlockingQueue
2019-06-13 06:44:02,239 INFO org.apache.hadoop.ipc.Server: Starting Socket Reader #1 for port 8033
2019-06-13 06:44:02,244 INFO org.apache.hadoop.yarn.factories.impl.pb.RpcServerFactoryPBImpl: Adding protocol org.apache.hadoop.yarn.server.api.ResourceManagerAdministrationProtocolPB to the server
2019-06-13 06:44:02,244 INFO org.apache.hadoop.ipc.Server: IPC Server Responder: starting
2019-06-13 06:44:02,244 INFO org.apache.hadoop.ipc.Server: IPC Server listener on 8033: starting
2019-06-13 06:44:02,594 INFO org.apache.hadoop.yarn.util.RackResolver: Resolved dea0525850a6 to /default-rack
2019-06-13 06:44:02,596 INFO org.apache.hadoop.yarn.server.resourcemanager.ResourceTrackerService: NodeManager from node dea0525850a6(cmPort: 44943 httpPort: 8042) registered with capability: <memory:8192, vCores:8>, assigned nodeId dea0525850a6:44943
2019-06-13 06:44:02,628 INFO org.apache.hadoop.yarn.server.resourcemanager.rmnode.RMNodeImpl: dea0525850a6:44943 Node Transitioned from NEW to RUNNING
2019-06-13 06:44:02,631 INFO org.apache.hadoop.yarn.server.resourcemanager.scheduler.capacity.CapacityScheduler: Added node dea0525850a6:44943 clusterResource: <memory:8192, vCores:8>
2019-06-13 06:44:02,686 INFO org.apache.hadoop.yarn.server.resourcemanager.rmnode.RMNodeImpl: Node dea0525850a6:44943 reported UNHEALTHY with details: 1/1 local-dirs are bad: /tmp/hadoop-root/nm-local-dir; 1/1 log-dirs are bad: /usr/local/hadoop/logs/userlogs
2019-06-13 06:44:02,687 INFO org.apache.hadoop.yarn.server.resourcemanager.rmnode.RMNodeImpl: dea0525850a6:44943 Node Transitioned from RUNNING to UNHEALTHY
2019-06-13 06:44:02,688 INFO org.apache.hadoop.yarn.server.resourcemanager.scheduler.capacity.CapacityScheduler: Removed node dea0525850a6:44943 clusterResource: <memory:0, vCores:0>
2019-06-13 06:53:55,909 INFO org.apache.hadoop.yarn.server.resourcemanager.scheduler.AbstractYarnScheduler: Release request cache is cleaned up
2019-06-13 07:03:43,752 INFO org.apache.hadoop.yarn.server.resourcemanager.ClientRMService: Allocated new applicationId: 1
2019-06-13 07:03:45,674 INFO org.apache.hadoop.yarn.server.resourcemanager.ClientRMService: Application with id 1 submitted by user root
2019-06-13 07:03:45,674 INFO org.apache.hadoop.yarn.server.resourcemanager.rmapp.RMAppImpl: Storing application with id application_1560422636355_0001
2019-06-13 07:03:45,675 INFO org.apache.hadoop.yarn.server.resourcemanager.RMAuditLogger: USER=root	IP=172.24.0.2	OPERATION=Submit Application Request	TARGET=ClientRMService	RESULT=SUCCESS	APPID=application_1560422636355_0001
2019-06-13 07:03:45,685 INFO org.apache.hadoop.yarn.server.resourcemanager.rmapp.RMAppImpl: application_1560422636355_0001 State change from NEW to NEW_SAVING
2019-06-13 07:03:45,685 INFO org.apache.hadoop.yarn.server.resourcemanager.recovery.RMStateStore: Storing info for app: application_1560422636355_0001
2019-06-13 07:03:45,687 INFO org.apache.hadoop.yarn.server.resourcemanager.rmapp.RMAppImpl: application_1560422636355_0001 State change from NEW_SAVING to SUBMITTED
2019-06-13 07:03:45,690 INFO org.apache.hadoop.yarn.server.resourcemanager.scheduler.capacity.ParentQueue: Application added - appId: application_1560422636355_0001 user: root leaf-queue of parent: root #applications: 1
2019-06-13 07:03:45,691 INFO org.apache.hadoop.yarn.server.resourcemanager.scheduler.capacity.CapacityScheduler: Accepted application application_1560422636355_0001 from user: root, in queue: default
2019-06-13 07:03:45,709 INFO org.apache.hadoop.yarn.server.resourcemanager.rmapp.RMAppImpl: application_1560422636355_0001 State change from SUBMITTED to ACCEPTED
2019-06-13 07:03:45,741 INFO org.apache.hadoop.yarn.server.resourcemanager.ApplicationMasterService: Registering app attempt : appattempt_1560422636355_0001_000001
2019-06-13 07:03:45,742 INFO org.apache.hadoop.yarn.server.resourcemanager.rmapp.attempt.RMAppAttemptImpl: appattempt_1560422636355_0001_000001 State change from NEW to SUBMITTED
2019-06-13 07:03:45,752 WARN org.apache.hadoop.yarn.server.resourcemanager.scheduler.capacity.LeafQueue: maximum-am-resource-percent is insufficient to start a single application in queue, it is likely set too low. skipping enforcement to allow at least one application to start
2019-06-13 07:03:45,752 WARN org.apache.hadoop.yarn.server.resourcemanager.scheduler.capacity.LeafQueue: maximum-am-resource-percent is insufficient to start a single application in queue for user, it is likely set too low. skipping enforcement to allow at least one application to start
2019-06-13 07:03:45,752 INFO org.apache.hadoop.yarn.server.resourcemanager.scheduler.capacity.LeafQueue: Application application_1560422636355_0001 from user: root activated in queue: default
2019-06-13 07:03:45,752 INFO org.apache.hadoop.yarn.server.resourcemanager.scheduler.capacity.LeafQueue: Application added - appId: application_1560422636355_0001 user: org.apache.hadoop.yarn.server.resourcemanager.scheduler.capacity.LeafQueue$User@ec93b84, leaf-queue: default #user-pending-applications: 0 #user-active-applications: 1 #queue-pending-applications: 0 #queue-active-applications: 1
2019-06-13 07:03:45,752 INFO org.apache.hadoop.yarn.server.resourcemanager.scheduler.capacity.CapacityScheduler: Added Application Attempt appattempt_1560422636355_0001_000001 to scheduler from user root in queue default
2019-06-13 07:03:45,754 INFO org.apache.hadoop.yarn.server.resourcemanager.rmapp.attempt.RMAppAttemptImpl: appattempt_1560422636355_0001_000001 State change from SUBMITTED to SCHEDULED
2019-06-13 07:04:12,405 WARN org.apache.hadoop.yarn.server.webapp.AppBlock: Container with id 'container_1560422636355_0001_01_000001' doesn't exist in RM.
2019-06-13 07:08:01,977 INFO org.apache.hadoop.yarn.server.resourcemanager.ClientRMService: Allocated new applicationId: 2
2019-06-13 07:08:02,823 INFO org.apache.hadoop.yarn.server.resourcemanager.ClientRMService: Application with id 2 submitted by user root
2019-06-13 07:08:02,823 INFO org.apache.hadoop.yarn.server.resourcemanager.rmapp.RMAppImpl: Storing application with id application_1560422636355_0002
2019-06-13 07:08:02,823 INFO org.apache.hadoop.yarn.server.resourcemanager.RMAuditLogger: USER=root	IP=172.24.0.2	OPERATION=Submit Application Request	TARGET=ClientRMService	RESULT=SUCCESS	APPID=application_1560422636355_0002
2019-06-13 07:08:02,824 INFO org.apache.hadoop.yarn.server.resourcemanager.rmapp.RMAppImpl: application_1560422636355_0002 State change from NEW to NEW_SAVING
2019-06-13 07:08:02,824 INFO org.apache.hadoop.yarn.server.resourcemanager.recovery.RMStateStore: Storing info for app: application_1560422636355_0002
2019-06-13 07:08:02,824 INFO org.apache.hadoop.yarn.server.resourcemanager.rmapp.RMAppImpl: application_1560422636355_0002 State change from NEW_SAVING to SUBMITTED
2019-06-13 07:08:02,824 INFO org.apache.hadoop.yarn.server.resourcemanager.scheduler.capacity.ParentQueue: Application added - appId: application_1560422636355_0002 user: root leaf-queue of parent: root #applications: 2
2019-06-13 07:08:02,824 INFO org.apache.hadoop.yarn.server.resourcemanager.scheduler.capacity.CapacityScheduler: Accepted application application_1560422636355_0002 from user: root, in queue: default
2019-06-13 07:08:02,825 INFO org.apache.hadoop.yarn.server.resourcemanager.rmapp.RMAppImpl: application_1560422636355_0002 State change from SUBMITTED to ACCEPTED
2019-06-13 07:08:02,825 INFO org.apache.hadoop.yarn.server.resourcemanager.ApplicationMasterService: Registering app attempt : appattempt_1560422636355_0002_000001
2019-06-13 07:08:02,825 INFO org.apache.hadoop.yarn.server.resourcemanager.rmapp.attempt.RMAppAttemptImpl: appattempt_1560422636355_0002_000001 State change from NEW to SUBMITTED
2019-06-13 07:08:02,825 INFO org.apache.hadoop.yarn.server.resourcemanager.scheduler.capacity.LeafQueue: not starting application as amIfStarted exceeds amLimit
2019-06-13 07:08:02,825 INFO org.apache.hadoop.yarn.server.resourcemanager.scheduler.capacity.LeafQueue: Application added - appId: application_1560422636355_0002 user: org.apache.hadoop.yarn.server.resourcemanager.scheduler.capacity.LeafQueue$User@ec93b84, leaf-queue: default #user-pending-applications: 1 #user-active-applications: 1 #queue-pending-applications: 1 #queue-active-applications: 1
2019-06-13 07:08:02,825 INFO org.apache.hadoop.yarn.server.resourcemanager.scheduler.capacity.CapacityScheduler: Added Application Attempt appattempt_1560422636355_0002_000001 to scheduler from user root in queue default
2019-06-13 07:08:02,825 INFO org.apache.hadoop.yarn.server.resourcemanager.rmapp.attempt.RMAppAttemptImpl: appattempt_1560422636355_0002_000001 State change from SUBMITTED to SCHEDULED
2019-06-13 07:08:36,870 WARN org.apache.hadoop.yarn.server.webapp.AppBlock: Container with id 'container_1560422636355_0001_01_000001' doesn't exist in RM.
2019-06-13 07:09:53,462 WARN org.apache.hadoop.yarn.server.webapp.AppBlock: Container with id 'container_1560422636355_0002_01_000001' doesn't exist in RM.
2019-06-13 07:10:00,273 INFO org.apache.hadoop.yarn.server.resourcemanager.rmapp.RMAppImpl: application_1560422636355_0002 State change from ACCEPTED to KILLING
2019-06-13 07:10:00,291 INFO org.apache.hadoop.yarn.server.resourcemanager.rmapp.attempt.RMAppAttemptImpl: Updating application attempt appattempt_1560422636355_0002_000001 with final state: KILLED, and exit status: -1000
2019-06-13 07:10:00,292 INFO org.apache.hadoop.yarn.server.resourcemanager.rmapp.attempt.RMAppAttemptImpl: appattempt_1560422636355_0002_000001 State change from SCHEDULED to FINAL_SAVING
2019-06-13 07:10:00,292 INFO org.apache.hadoop.yarn.server.resourcemanager.ApplicationMasterService: Unregistering app attempt : appattempt_1560422636355_0002_000001
2019-06-13 07:10:00,293 INFO org.apache.hadoop.yarn.server.resourcemanager.security.AMRMTokenSecretManager: Application finished, removing password for appattempt_1560422636355_0002_000001
2019-06-13 07:10:00,293 INFO org.apache.hadoop.yarn.server.resourcemanager.rmapp.attempt.RMAppAttemptImpl: appattempt_1560422636355_0002_000001 State change from FINAL_SAVING to KILLED
2019-06-13 07:10:00,293 INFO org.apache.hadoop.yarn.server.resourcemanager.rmapp.RMAppImpl: Updating application application_1560422636355_0002 with final state: KILLED
2019-06-13 07:10:00,294 INFO org.apache.hadoop.yarn.server.resourcemanager.rmapp.RMAppImpl: application_1560422636355_0002 State change from KILLING to FINAL_SAVING
2019-06-13 07:10:00,294 INFO org.apache.hadoop.yarn.server.resourcemanager.recovery.RMStateStore: Updating info for app: application_1560422636355_0002
2019-06-13 07:10:00,294 INFO org.apache.hadoop.yarn.server.resourcemanager.scheduler.capacity.CapacityScheduler: Application Attempt appattempt_1560422636355_0002_000001 is done. finalState=KILLED
2019-06-13 07:10:00,294 INFO org.apache.hadoop.yarn.server.resourcemanager.scheduler.AppSchedulingInfo: Application application_1560422636355_0002 requests cleared
2019-06-13 07:10:00,294 INFO org.apache.hadoop.yarn.server.resourcemanager.scheduler.capacity.LeafQueue: Application removed - appId: application_1560422636355_0002 user: root queue: default #user-pending-applications: 0 #user-active-applications: 1 #queue-pending-applications: 0 #queue-active-applications: 1
2019-06-13 07:10:00,296 INFO org.apache.hadoop.yarn.server.resourcemanager.rmapp.RMAppImpl: application_1560422636355_0002 State change from FINAL_SAVING to KILLED
2019-06-13 07:10:00,296 INFO org.apache.hadoop.yarn.server.resourcemanager.scheduler.capacity.ParentQueue: Application removed - appId: application_1560422636355_0002 user: root leaf-queue of parent: root #applications: 1
2019-06-13 07:10:00,297 INFO org.apache.hadoop.yarn.server.resourcemanager.RMAuditLogger: USER=root	OPERATION=Application Finished - Killed	TARGET=RMAppManager	RESULT=SUCCESS	APPID=application_1560422636355_0002
2019-06-13 07:10:00,299 INFO org.apache.hadoop.yarn.server.resourcemanager.RMAppManager$ApplicationSummary: appId=application_1560422636355_0002,name=grep-search,user=root,queue=default,state=KILLED,trackingUrl=http://dea0525850a6:8088/cluster/app/application_1560422636355_0002,appMasterHost=N/A,startTime=1560424082823,finishTime=1560424200293,finalStatus=KILLED,memorySeconds=0,vcoreSeconds=0,preemptedAMContainers=0,preemptedNonAMContainers=0,preemptedResources=<memory:0\, vCores:0>,applicationType=MAPREDUCE
2019-06-13 07:10:01,315 WARN org.apache.hadoop.yarn.server.webapp.AppBlock: Container with id 'container_1560422636355_0002_01_000001' doesn't exist in RM.
2019-06-13 07:10:18,731 WARN org.apache.hadoop.yarn.server.webapp.AppBlock: Container with id 'container_1560422636355_0002_01_000001' doesn't exist in RM.
2019-06-13 07:10:21,826 WARN org.apache.hadoop.yarn.server.webapp.AppBlock: Container with id 'container_1560422636355_0002_01_000001' doesn't exist in RM.
2019-06-13 07:11:22,387 INFO org.apache.hadoop.yarn.server.resourcemanager.ClientRMService: Allocated new applicationId: 3
2019-06-13 07:11:23,185 INFO org.apache.hadoop.yarn.server.resourcemanager.ClientRMService: Application with id 3 submitted by user root
2019-06-13 07:11:23,185 INFO org.apache.hadoop.yarn.server.resourcemanager.rmapp.RMAppImpl: Storing application with id application_1560422636355_0003
2019-06-13 07:11:23,185 INFO org.apache.hadoop.yarn.server.resourcemanager.RMAuditLogger: USER=root	IP=172.24.0.2	OPERATION=Submit Application Request	TARGET=ClientRMService	RESULT=SUCCESS	APPID=application_1560422636355_0003
2019-06-13 07:11:23,185 INFO org.apache.hadoop.yarn.server.resourcemanager.rmapp.RMAppImpl: application_1560422636355_0003 State change from NEW to NEW_SAVING
2019-06-13 07:11:23,185 INFO org.apache.hadoop.yarn.server.resourcemanager.recovery.RMStateStore: Storing info for app: application_1560422636355_0003
2019-06-13 07:11:23,185 INFO org.apache.hadoop.yarn.server.resourcemanager.rmapp.RMAppImpl: application_1560422636355_0003 State change from NEW_SAVING to SUBMITTED
2019-06-13 07:11:23,186 INFO org.apache.hadoop.yarn.server.resourcemanager.scheduler.capacity.ParentQueue: Application added - appId: application_1560422636355_0003 user: root leaf-queue of parent: root #applications: 2
2019-06-13 07:11:23,186 INFO org.apache.hadoop.yarn.server.resourcemanager.scheduler.capacity.CapacityScheduler: Accepted application application_1560422636355_0003 from user: root, in queue: default
2019-06-13 07:11:23,187 INFO org.apache.hadoop.yarn.server.resourcemanager.rmapp.RMAppImpl: application_1560422636355_0003 State change from SUBMITTED to ACCEPTED
2019-06-13 07:11:23,187 INFO org.apache.hadoop.yarn.server.resourcemanager.ApplicationMasterService: Registering app attempt : appattempt_1560422636355_0003_000001
2019-06-13 07:11:23,187 INFO org.apache.hadoop.yarn.server.resourcemanager.rmapp.attempt.RMAppAttemptImpl: appattempt_1560422636355_0003_000001 State change from NEW to SUBMITTED
2019-06-13 07:11:23,188 INFO org.apache.hadoop.yarn.server.resourcemanager.scheduler.capacity.LeafQueue: not starting application as amIfStarted exceeds amLimit
2019-06-13 07:11:23,188 INFO org.apache.hadoop.yarn.server.resourcemanager.scheduler.capacity.LeafQueue: Application added - appId: application_1560422636355_0003 user: org.apache.hadoop.yarn.server.resourcemanager.scheduler.capacity.LeafQueue$User@ec93b84, leaf-queue: default #user-pending-applications: 1 #user-active-applications: 1 #queue-pending-applications: 1 #queue-active-applications: 1
2019-06-13 07:11:23,188 INFO org.apache.hadoop.yarn.server.resourcemanager.scheduler.capacity.CapacityScheduler: Added Application Attempt appattempt_1560422636355_0003_000001 to scheduler from user root in queue default
2019-06-13 07:11:23,189 INFO org.apache.hadoop.yarn.server.resourcemanager.rmapp.attempt.RMAppAttemptImpl: appattempt_1560422636355_0003_000001 State change from SUBMITTED to SCHEDULED
