2019-06-26 06:16:54,455 INFO org.apache.hadoop.yarn.server.resourcemanager.ResourceManager: STARTUP_MSG: 
/************************************************************
STARTUP_MSG: Starting ResourceManager
STARTUP_MSG:   host = e9a6a0455f0d/172.24.0.2
STARTUP_MSG:   args = []
STARTUP_MSG:   version = 2.7.1
STARTUP_MSG:   build = https://git-wip-us.apache.org/repos/asf/hadoop.git -r 15ecc87ccf4a0228f35af08fc56de536e6ce657a; compiled by 'jenkins' on 2015-06-29T06:04Z
STARTUP_MSG:   java = 1.7.0_71
************************************************************/
2019-06-26 06:16:54,463 INFO org.apache.hadoop.yarn.server.resourcemanager.ResourceManager: registered UNIX signal handlers for [TERM, HUP, INT]
2019-06-26 06:16:54,798 INFO org.apache.hadoop.conf.Configuration: found resource core-site.xml at file:/usr/local/hadoop-2.7.1/etc/hadoop/core-site.xml
2019-06-26 06:16:54,940 WARN org.apache.hadoop.util.NativeCodeLoader: Unable to load native-hadoop library for your platform... using builtin-java classes where applicable
2019-06-26 06:16:54,979 INFO org.apache.hadoop.security.Groups: clearing userToGroupsMap cache
2019-06-26 06:16:55,093 INFO org.apache.hadoop.conf.Configuration: found resource yarn-site.xml at file:/usr/local/hadoop-2.7.1/etc/hadoop/yarn-site.xml
2019-06-26 06:16:55,353 INFO org.apache.hadoop.yarn.event.AsyncDispatcher: Registering class org.apache.hadoop.yarn.server.resourcemanager.RMFatalEventType for class org.apache.hadoop.yarn.server.resourcemanager.ResourceManager$RMFatalEventDispatcher
2019-06-26 06:16:55,593 INFO org.apache.hadoop.yarn.server.resourcemanager.security.NMTokenSecretManagerInRM: NMTokenKeyRollingInterval: 86400000ms and NMTokenKeyActivationDelay: 900000ms
2019-06-26 06:16:55,597 INFO org.apache.hadoop.yarn.server.resourcemanager.security.RMContainerTokenSecretManager: ContainerTokenKeyRollingInterval: 86400000ms and ContainerTokenKeyActivationDelay: 900000ms
2019-06-26 06:16:55,602 INFO org.apache.hadoop.yarn.server.resourcemanager.security.AMRMTokenSecretManager: AMRMTokenKeyRollingInterval: 86400000ms and AMRMTokenKeyActivationDelay: 900000 ms
2019-06-26 06:16:55,636 INFO org.apache.hadoop.yarn.event.AsyncDispatcher: Registering class org.apache.hadoop.yarn.server.resourcemanager.recovery.RMStateStoreEventType for class org.apache.hadoop.yarn.server.resourcemanager.recovery.RMStateStore$ForwardingEventHandler
2019-06-26 06:16:55,640 INFO org.apache.hadoop.yarn.event.AsyncDispatcher: Registering class org.apache.hadoop.yarn.server.resourcemanager.NodesListManagerEventType for class org.apache.hadoop.yarn.server.resourcemanager.NodesListManager
2019-06-26 06:16:55,641 INFO org.apache.hadoop.yarn.server.resourcemanager.ResourceManager: Using Scheduler: org.apache.hadoop.yarn.server.resourcemanager.scheduler.capacity.CapacityScheduler
2019-06-26 06:16:55,654 INFO org.apache.hadoop.yarn.event.AsyncDispatcher: Registering class org.apache.hadoop.yarn.server.resourcemanager.scheduler.event.SchedulerEventType for class org.apache.hadoop.yarn.server.resourcemanager.ResourceManager$SchedulerEventDispatcher
2019-06-26 06:16:55,655 INFO org.apache.hadoop.yarn.event.AsyncDispatcher: Registering class org.apache.hadoop.yarn.server.resourcemanager.rmapp.RMAppEventType for class org.apache.hadoop.yarn.server.resourcemanager.ResourceManager$ApplicationEventDispatcher
2019-06-26 06:16:55,655 INFO org.apache.hadoop.yarn.event.AsyncDispatcher: Registering class org.apache.hadoop.yarn.server.resourcemanager.rmapp.attempt.RMAppAttemptEventType for class org.apache.hadoop.yarn.server.resourcemanager.ResourceManager$ApplicationAttemptEventDispatcher
2019-06-26 06:16:55,656 INFO org.apache.hadoop.yarn.event.AsyncDispatcher: Registering class org.apache.hadoop.yarn.server.resourcemanager.rmnode.RMNodeEventType for class org.apache.hadoop.yarn.server.resourcemanager.ResourceManager$NodeEventDispatcher
2019-06-26 06:16:55,715 INFO org.apache.hadoop.metrics2.impl.MetricsConfig: loaded properties from hadoop-metrics2.properties
2019-06-26 06:16:55,788 INFO org.apache.hadoop.metrics2.impl.MetricsSystemImpl: Scheduled snapshot period at 10 second(s).
2019-06-26 06:16:55,788 INFO org.apache.hadoop.metrics2.impl.MetricsSystemImpl: ResourceManager metrics system started
2019-06-26 06:16:55,816 INFO org.apache.hadoop.yarn.event.AsyncDispatcher: Registering class org.apache.hadoop.yarn.server.resourcemanager.RMAppManagerEventType for class org.apache.hadoop.yarn.server.resourcemanager.RMAppManager
2019-06-26 06:16:55,823 INFO org.apache.hadoop.yarn.event.AsyncDispatcher: Registering class org.apache.hadoop.yarn.server.resourcemanager.amlauncher.AMLauncherEventType for class org.apache.hadoop.yarn.server.resourcemanager.amlauncher.ApplicationMasterLauncher
2019-06-26 06:16:55,826 INFO org.apache.hadoop.yarn.server.resourcemanager.RMNMInfo: Registered RMNMInfo MBean
2019-06-26 06:16:55,828 INFO org.apache.hadoop.yarn.security.YarnAuthorizationProvider: org.apache.hadoop.yarn.security.ConfiguredYarnAuthorizer is instiantiated.
2019-06-26 06:16:55,829 INFO org.apache.hadoop.yarn.server.resourcemanager.metrics.SystemMetricsPublisher: YARN system metrics publishing service is not enabled
2019-06-26 06:16:55,830 INFO org.apache.hadoop.util.HostsFileReader: Refreshing hosts (include/exclude) list
2019-06-26 06:16:55,837 INFO org.apache.hadoop.conf.Configuration: found resource capacity-scheduler.xml at file:/usr/local/hadoop-2.7.1/etc/hadoop/capacity-scheduler.xml
2019-06-26 06:16:55,918 INFO org.apache.hadoop.yarn.server.resourcemanager.scheduler.capacity.CapacitySchedulerConfiguration: max alloc mb per queue for root is undefined
2019-06-26 06:16:55,918 INFO org.apache.hadoop.yarn.server.resourcemanager.scheduler.capacity.CapacitySchedulerConfiguration: max alloc vcore per queue for root is undefined
2019-06-26 06:16:55,922 INFO org.apache.hadoop.yarn.server.resourcemanager.scheduler.capacity.ParentQueue: root, capacity=1.0, asboluteCapacity=1.0, maxCapacity=1.0, asboluteMaxCapacity=1.0, state=RUNNING, acls=SUBMIT_APP:*ADMINISTER_QUEUE:*, labels=*,
, reservationsContinueLooking=true
2019-06-26 06:16:55,923 INFO org.apache.hadoop.yarn.server.resourcemanager.scheduler.capacity.ParentQueue: Initialized parent-queue root name=root, fullname=root
2019-06-26 06:16:55,937 INFO org.apache.hadoop.yarn.server.resourcemanager.scheduler.capacity.CapacitySchedulerConfiguration: max alloc mb per queue for root.default is undefined
2019-06-26 06:16:55,938 INFO org.apache.hadoop.yarn.server.resourcemanager.scheduler.capacity.CapacitySchedulerConfiguration: max alloc vcore per queue for root.default is undefined
2019-06-26 06:16:55,939 INFO org.apache.hadoop.yarn.server.resourcemanager.scheduler.capacity.LeafQueue: Initializing default
capacity = 1.0 [= (float) configuredCapacity / 100 ]
asboluteCapacity = 1.0 [= parentAbsoluteCapacity * capacity ]
maxCapacity = 1.0 [= configuredMaxCapacity ]
absoluteMaxCapacity = 1.0 [= 1.0 maximumCapacity undefined, (parentAbsoluteMaxCapacity * maximumCapacity) / 100 otherwise ]
userLimit = 100 [= configuredUserLimit ]
userLimitFactor = 1.0 [= configuredUserLimitFactor ]
maxApplications = 10000 [= configuredMaximumSystemApplicationsPerQueue or (int)(configuredMaximumSystemApplications * absoluteCapacity)]
maxApplicationsPerUser = 10000 [= (int)(maxApplications * (userLimit / 100.0f) * userLimitFactor) ]
usedCapacity = 0.0 [= usedResourcesMemory / (clusterResourceMemory * absoluteCapacity)]
absoluteUsedCapacity = 0.0 [= usedResourcesMemory / clusterResourceMemory]
maxAMResourcePerQueuePercent = 0.1 [= configuredMaximumAMResourcePercent ]
minimumAllocationFactor = 0.875 [= (float)(maximumAllocationMemory - minimumAllocationMemory) / maximumAllocationMemory ]
maximumAllocation = <memory:8192, vCores:32> [= configuredMaxAllocation ]
numContainers = 0 [= currentNumContainers ]
state = RUNNING [= configuredState ]
acls = SUBMIT_APP:*ADMINISTER_QUEUE:* [= configuredAcls ]
nodeLocalityDelay = 40
labels=*,
nodeLocalityDelay = 40
reservationsContinueLooking = true
preemptionDisabled = true

2019-06-26 06:16:55,939 INFO org.apache.hadoop.yarn.server.resourcemanager.scheduler.capacity.CapacityScheduler: Initialized queue: default: capacity=1.0, absoluteCapacity=1.0, usedResources=<memory:0, vCores:0>, usedCapacity=0.0, absoluteUsedCapacity=0.0, numApps=0, numContainers=0
2019-06-26 06:16:55,940 INFO org.apache.hadoop.yarn.server.resourcemanager.scheduler.capacity.CapacityScheduler: Initialized queue: root: numChildQueue= 1, capacity=1.0, absoluteCapacity=1.0, usedResources=<memory:0, vCores:0>usedCapacity=0.0, numApps=0, numContainers=0
2019-06-26 06:16:55,941 INFO org.apache.hadoop.yarn.server.resourcemanager.scheduler.capacity.CapacityScheduler: Initialized root queue root: numChildQueue= 1, capacity=1.0, absoluteCapacity=1.0, usedResources=<memory:0, vCores:0>usedCapacity=0.0, numApps=0, numContainers=0
2019-06-26 06:16:55,941 INFO org.apache.hadoop.yarn.server.resourcemanager.scheduler.capacity.CapacityScheduler: Initialized queue mappings, override: false
2019-06-26 06:16:55,941 INFO org.apache.hadoop.yarn.server.resourcemanager.scheduler.capacity.CapacityScheduler: Initialized CapacityScheduler with calculator=class org.apache.hadoop.yarn.util.resource.DefaultResourceCalculator, minimumAllocation=<<memory:1024, vCores:1>>, maximumAllocation=<<memory:8192, vCores:32>>, asynchronousScheduling=false, asyncScheduleInterval=5ms
2019-06-26 06:16:55,952 INFO org.apache.hadoop.yarn.server.resourcemanager.ResourceManager: Transitioning to active state
2019-06-26 06:16:55,967 INFO org.apache.hadoop.yarn.server.resourcemanager.recovery.RMStateStore: Updating AMRMToken
2019-06-26 06:16:55,967 INFO org.apache.hadoop.yarn.server.resourcemanager.security.RMContainerTokenSecretManager: Rolling master-key for container-tokens
2019-06-26 06:16:55,967 INFO org.apache.hadoop.yarn.server.resourcemanager.security.NMTokenSecretManagerInRM: Rolling master-key for nm-tokens
2019-06-26 06:16:55,967 INFO org.apache.hadoop.security.token.delegation.AbstractDelegationTokenSecretManager: Updating the current master key for generating delegation tokens
2019-06-26 06:16:55,968 INFO org.apache.hadoop.yarn.server.resourcemanager.security.RMDelegationTokenSecretManager: storing master key with keyID 1
2019-06-26 06:16:55,968 INFO org.apache.hadoop.yarn.server.resourcemanager.recovery.RMStateStore: Storing RMDTMasterKey.
2019-06-26 06:16:55,969 INFO org.apache.hadoop.security.token.delegation.AbstractDelegationTokenSecretManager: Starting expired delegation token remover thread, tokenRemoverScanInterval=60 min(s)
2019-06-26 06:16:55,969 INFO org.apache.hadoop.security.token.delegation.AbstractDelegationTokenSecretManager: Updating the current master key for generating delegation tokens
2019-06-26 06:16:55,969 INFO org.apache.hadoop.yarn.server.resourcemanager.security.RMDelegationTokenSecretManager: storing master key with keyID 2
2019-06-26 06:16:55,969 INFO org.apache.hadoop.yarn.server.resourcemanager.recovery.RMStateStore: Storing RMDTMasterKey.
2019-06-26 06:16:55,976 INFO org.apache.hadoop.yarn.event.AsyncDispatcher: Registering class org.apache.hadoop.yarn.nodelabels.event.NodeLabelsStoreEventType for class org.apache.hadoop.yarn.nodelabels.CommonNodeLabelsManager$ForwardingEventHandler
2019-06-26 06:16:56,019 INFO org.apache.hadoop.ipc.CallQueueManager: Using callQueue class java.util.concurrent.LinkedBlockingQueue
2019-06-26 06:16:56,030 INFO org.apache.hadoop.ipc.Server: Starting Socket Reader #1 for port 8031
2019-06-26 06:16:56,045 INFO org.apache.hadoop.yarn.factories.impl.pb.RpcServerFactoryPBImpl: Adding protocol org.apache.hadoop.yarn.server.api.ResourceTrackerPB to the server
2019-06-26 06:16:56,046 INFO org.apache.hadoop.ipc.Server: IPC Server Responder: starting
2019-06-26 06:16:56,046 INFO org.apache.hadoop.ipc.Server: IPC Server listener on 8031: starting
2019-06-26 06:16:56,153 INFO org.apache.hadoop.ipc.CallQueueManager: Using callQueue class java.util.concurrent.LinkedBlockingQueue
2019-06-26 06:16:56,168 INFO org.apache.hadoop.ipc.Server: Starting Socket Reader #1 for port 8030
2019-06-26 06:16:56,180 INFO org.apache.hadoop.yarn.factories.impl.pb.RpcServerFactoryPBImpl: Adding protocol org.apache.hadoop.yarn.api.ApplicationMasterProtocolPB to the server
2019-06-26 06:16:56,180 INFO org.apache.hadoop.ipc.Server: IPC Server Responder: starting
2019-06-26 06:16:56,180 INFO org.apache.hadoop.ipc.Server: IPC Server listener on 8030: starting
2019-06-26 06:16:56,245 INFO org.apache.hadoop.ipc.CallQueueManager: Using callQueue class java.util.concurrent.LinkedBlockingQueue
2019-06-26 06:16:56,247 INFO org.apache.hadoop.ipc.Server: Starting Socket Reader #1 for port 8032
2019-06-26 06:16:56,258 INFO org.apache.hadoop.yarn.factories.impl.pb.RpcServerFactoryPBImpl: Adding protocol org.apache.hadoop.yarn.api.ApplicationClientProtocolPB to the server
2019-06-26 06:16:56,258 INFO org.apache.hadoop.ipc.Server: IPC Server Responder: starting
2019-06-26 06:16:56,261 INFO org.apache.hadoop.ipc.Server: IPC Server listener on 8032: starting
2019-06-26 06:16:56,320 INFO org.apache.hadoop.yarn.server.resourcemanager.ResourceManager: Transitioned to active state
2019-06-26 06:16:56,444 INFO org.mortbay.log: Logging to org.slf4j.impl.Log4jLoggerAdapter(org.mortbay.log) via org.mortbay.log.Slf4jLog
2019-06-26 06:16:56,456 INFO org.apache.hadoop.security.authentication.server.AuthenticationFilter: Unable to initialize FileSignerSecretProvider, falling back to use random secrets.
2019-06-26 06:16:56,463 INFO org.apache.hadoop.http.HttpRequestLog: Http request log for http.requests.resourcemanager is not defined
2019-06-26 06:16:56,472 INFO org.apache.hadoop.http.HttpServer2: Added global filter 'safety' (class=org.apache.hadoop.http.HttpServer2$QuotingInputFilter)
2019-06-26 06:16:56,479 INFO org.apache.hadoop.http.HttpServer2: Added filter RMAuthenticationFilter (class=org.apache.hadoop.yarn.server.security.http.RMAuthenticationFilter) to context cluster
2019-06-26 06:16:56,479 INFO org.apache.hadoop.http.HttpServer2: Added filter RMAuthenticationFilter (class=org.apache.hadoop.yarn.server.security.http.RMAuthenticationFilter) to context logs
2019-06-26 06:16:56,479 INFO org.apache.hadoop.http.HttpServer2: Added filter RMAuthenticationFilter (class=org.apache.hadoop.yarn.server.security.http.RMAuthenticationFilter) to context static
2019-06-26 06:16:56,481 INFO org.apache.hadoop.http.HttpServer2: Added filter static_user_filter (class=org.apache.hadoop.http.lib.StaticUserWebFilter$StaticUserFilter) to context cluster
2019-06-26 06:16:56,481 INFO org.apache.hadoop.http.HttpServer2: Added filter static_user_filter (class=org.apache.hadoop.http.lib.StaticUserWebFilter$StaticUserFilter) to context logs
2019-06-26 06:16:56,481 INFO org.apache.hadoop.http.HttpServer2: Added filter static_user_filter (class=org.apache.hadoop.http.lib.StaticUserWebFilter$StaticUserFilter) to context static
2019-06-26 06:16:56,485 INFO org.apache.hadoop.http.HttpServer2: adding path spec: /cluster/*
2019-06-26 06:16:56,486 INFO org.apache.hadoop.http.HttpServer2: adding path spec: /ws/*
2019-06-26 06:16:56,497 INFO org.apache.hadoop.http.HttpServer2: Jetty bound to port 8088
2019-06-26 06:16:56,498 INFO org.mortbay.log: jetty-6.1.26
2019-06-26 06:16:56,553 INFO org.mortbay.log: Extract jar:file:/usr/local/hadoop-2.7.1/share/hadoop/yarn/hadoop-yarn-common-2.7.1.jar!/webapps/cluster to /tmp/Jetty_0_0_0_0_8088_cluster____u0rgz3/webapp
2019-06-26 06:16:57,007 INFO org.apache.hadoop.security.token.delegation.AbstractDelegationTokenSecretManager: Updating the current master key for generating delegation tokens
2019-06-26 06:16:57,022 INFO org.apache.hadoop.security.token.delegation.AbstractDelegationTokenSecretManager: Starting expired delegation token remover thread, tokenRemoverScanInterval=60 min(s)
2019-06-26 06:16:57,023 INFO org.apache.hadoop.security.token.delegation.AbstractDelegationTokenSecretManager: Updating the current master key for generating delegation tokens
2019-06-26 06:16:57,027 INFO org.mortbay.log: Started HttpServer2$SelectChannelConnectorWithSafeStartup@0.0.0.0:8088
2019-06-26 06:16:57,031 INFO org.apache.hadoop.yarn.webapp.WebApps: Web app /cluster started at 8088
2019-06-26 06:16:57,742 INFO org.apache.hadoop.yarn.webapp.WebApps: Registered webapp guice modules
2019-06-26 06:17:02,786 INFO org.apache.hadoop.ipc.CallQueueManager: Using callQueue class java.util.concurrent.LinkedBlockingQueue
2019-06-26 06:17:02,787 INFO org.apache.hadoop.ipc.Server: Starting Socket Reader #1 for port 8033
2019-06-26 06:17:02,794 INFO org.apache.hadoop.yarn.factories.impl.pb.RpcServerFactoryPBImpl: Adding protocol org.apache.hadoop.yarn.server.api.ResourceManagerAdministrationProtocolPB to the server
2019-06-26 06:17:02,795 INFO org.apache.hadoop.ipc.Server: IPC Server Responder: starting
2019-06-26 06:17:02,795 INFO org.apache.hadoop.ipc.Server: IPC Server listener on 8033: starting
2019-06-26 06:17:03,778 INFO org.apache.hadoop.yarn.util.RackResolver: Resolved e9a6a0455f0d to /default-rack
2019-06-26 06:17:03,779 INFO org.apache.hadoop.yarn.server.resourcemanager.ResourceTrackerService: NodeManager from node e9a6a0455f0d(cmPort: 42135 httpPort: 8042) registered with capability: <memory:8192, vCores:8>, assigned nodeId e9a6a0455f0d:42135
2019-06-26 06:17:03,780 INFO org.apache.hadoop.yarn.server.resourcemanager.rmnode.RMNodeImpl: e9a6a0455f0d:42135 Node Transitioned from NEW to RUNNING
2019-06-26 06:17:03,783 INFO org.apache.hadoop.yarn.server.resourcemanager.scheduler.capacity.CapacityScheduler: Added node e9a6a0455f0d:42135 clusterResource: <memory:8192, vCores:8>
2019-06-26 06:17:03,818 INFO org.apache.hadoop.yarn.server.resourcemanager.rmnode.RMNodeImpl: Node e9a6a0455f0d:42135 reported UNHEALTHY with details: 1/1 local-dirs are bad: /tmp/hadoop-root/nm-local-dir; 1/1 log-dirs are bad: /usr/local/hadoop/logs/userlogs
2019-06-26 06:17:03,819 INFO org.apache.hadoop.yarn.server.resourcemanager.rmnode.RMNodeImpl: e9a6a0455f0d:42135 Node Transitioned from RUNNING to UNHEALTHY
2019-06-26 06:17:03,820 INFO org.apache.hadoop.yarn.server.resourcemanager.scheduler.capacity.CapacityScheduler: Removed node e9a6a0455f0d:42135 clusterResource: <memory:0, vCores:0>
2019-06-26 06:26:55,837 INFO org.apache.hadoop.yarn.server.resourcemanager.scheduler.AbstractYarnScheduler: Release request cache is cleaned up
2019-06-27 06:16:55,979 INFO org.apache.hadoop.yarn.server.resourcemanager.security.NMTokenSecretManagerInRM: Rolling master-key for nm-tokens
2019-06-27 06:16:55,980 INFO org.apache.hadoop.yarn.server.resourcemanager.security.RMContainerTokenSecretManager: Rolling master-key for container-tokens
2019-06-27 06:16:55,980 INFO org.apache.hadoop.yarn.server.resourcemanager.security.AMRMTokenSecretManager: Rolling master-key for amrm-tokens
2019-06-27 06:16:56,021 INFO org.apache.hadoop.yarn.server.resourcemanager.security.NMTokenSecretManagerInRM: Going to activate master-key with key-id 1464471450 in 900000ms
2019-06-27 06:16:56,021 INFO org.apache.hadoop.yarn.server.resourcemanager.security.RMContainerTokenSecretManager: Going to activate master-key with key-id 969913143 in 900000ms
2019-06-27 06:16:56,034 INFO org.apache.hadoop.yarn.server.resourcemanager.recovery.RMStateStore: Updating AMRMToken
2019-06-27 06:16:58,418 INFO org.apache.hadoop.security.token.delegation.AbstractDelegationTokenSecretManager: Updating the current master key for generating delegation tokens
2019-06-27 06:16:58,419 INFO org.apache.hadoop.yarn.server.resourcemanager.security.RMDelegationTokenSecretManager: storing master key with keyID 3
2019-06-27 06:16:58,420 INFO org.apache.hadoop.yarn.server.resourcemanager.recovery.RMStateStore: Storing RMDTMasterKey.
2019-06-27 06:16:59,486 INFO org.apache.hadoop.security.token.delegation.AbstractDelegationTokenSecretManager: Updating the current master key for generating delegation tokens
2019-06-27 06:31:56,030 INFO org.apache.hadoop.yarn.server.resourcemanager.security.RMContainerTokenSecretManager: Activating next master key with id: 969913143
2019-06-27 06:31:56,030 INFO org.apache.hadoop.yarn.server.resourcemanager.security.NMTokenSecretManagerInRM: Activating next master key with id: 1464471450
2019-06-27 06:31:56,037 INFO org.apache.hadoop.yarn.server.resourcemanager.security.AMRMTokenSecretManager: Activating next master key with id: 643769857
2019-06-27 06:31:56,037 INFO org.apache.hadoop.yarn.server.resourcemanager.recovery.RMStateStore: Updating AMRMToken
2019-06-28 06:16:55,976 INFO org.apache.hadoop.yarn.server.resourcemanager.security.NMTokenSecretManagerInRM: Rolling master-key for nm-tokens
2019-06-28 06:16:55,976 INFO org.apache.hadoop.yarn.server.resourcemanager.security.RMContainerTokenSecretManager: Rolling master-key for container-tokens
2019-06-28 06:16:55,976 INFO org.apache.hadoop.yarn.server.resourcemanager.security.AMRMTokenSecretManager: Rolling master-key for amrm-tokens
2019-06-28 06:16:56,003 INFO org.apache.hadoop.yarn.server.resourcemanager.security.RMContainerTokenSecretManager: Going to activate master-key with key-id 969913144 in 900000ms
2019-06-28 06:16:56,003 INFO org.apache.hadoop.yarn.server.resourcemanager.security.NMTokenSecretManagerInRM: Going to activate master-key with key-id 1464471451 in 900000ms
2019-06-28 06:16:56,015 INFO org.apache.hadoop.yarn.server.resourcemanager.recovery.RMStateStore: Updating AMRMToken
2019-06-28 06:17:00,839 INFO org.apache.hadoop.security.token.delegation.AbstractDelegationTokenSecretManager: Updating the current master key for generating delegation tokens
2019-06-28 06:17:00,840 INFO org.apache.hadoop.yarn.server.resourcemanager.security.RMDelegationTokenSecretManager: storing master key with keyID 4
2019-06-28 06:17:00,840 INFO org.apache.hadoop.yarn.server.resourcemanager.recovery.RMStateStore: Storing RMDTMasterKey.
2019-06-28 06:17:01,893 INFO org.apache.hadoop.security.token.delegation.AbstractDelegationTokenSecretManager: Updating the current master key for generating delegation tokens
2019-06-28 06:31:56,004 INFO org.apache.hadoop.yarn.server.resourcemanager.security.NMTokenSecretManagerInRM: Activating next master key with id: 1464471451
2019-06-28 06:31:56,004 INFO org.apache.hadoop.yarn.server.resourcemanager.security.RMContainerTokenSecretManager: Activating next master key with id: 969913144
2019-06-28 06:31:56,015 INFO org.apache.hadoop.yarn.server.resourcemanager.security.AMRMTokenSecretManager: Activating next master key with id: 643769858
2019-06-28 06:31:56,016 INFO org.apache.hadoop.yarn.server.resourcemanager.recovery.RMStateStore: Updating AMRMToken
2019-09-16 04:37:53,165 INFO org.apache.hadoop.yarn.server.resourcemanager.ResourceManager: STARTUP_MSG: 
/************************************************************
STARTUP_MSG: Starting ResourceManager
STARTUP_MSG:   host = e9a6a0455f0d/172.24.0.2
STARTUP_MSG:   args = []
STARTUP_MSG:   version = 2.7.1
STARTUP_MSG:   build = https://git-wip-us.apache.org/repos/asf/hadoop.git -r 15ecc87ccf4a0228f35af08fc56de536e6ce657a; compiled by 'jenkins' on 2015-06-29T06:04Z
STARTUP_MSG:   java = 1.7.0_71
************************************************************/
2019-09-16 04:37:53,175 INFO org.apache.hadoop.yarn.server.resourcemanager.ResourceManager: registered UNIX signal handlers for [TERM, HUP, INT]
2019-09-16 04:37:53,636 INFO org.apache.hadoop.conf.Configuration: found resource core-site.xml at file:/usr/local/hadoop-2.7.1/etc/hadoop/core-site.xml
2019-09-16 04:37:53,819 WARN org.apache.hadoop.util.NativeCodeLoader: Unable to load native-hadoop library for your platform... using builtin-java classes where applicable
2019-09-16 04:37:53,853 INFO org.apache.hadoop.security.Groups: clearing userToGroupsMap cache
2019-09-16 04:37:54,166 INFO org.apache.hadoop.conf.Configuration: found resource yarn-site.xml at file:/usr/local/hadoop-2.7.1/etc/hadoop/yarn-site.xml
2019-09-16 04:37:54,609 INFO org.apache.hadoop.yarn.event.AsyncDispatcher: Registering class org.apache.hadoop.yarn.server.resourcemanager.RMFatalEventType for class org.apache.hadoop.yarn.server.resourcemanager.ResourceManager$RMFatalEventDispatcher
2019-09-16 04:37:55,247 INFO org.apache.hadoop.yarn.server.resourcemanager.security.NMTokenSecretManagerInRM: NMTokenKeyRollingInterval: 86400000ms and NMTokenKeyActivationDelay: 900000ms
2019-09-16 04:37:55,251 INFO org.apache.hadoop.yarn.server.resourcemanager.security.RMContainerTokenSecretManager: ContainerTokenKeyRollingInterval: 86400000ms and ContainerTokenKeyActivationDelay: 900000ms
2019-09-16 04:37:55,257 INFO org.apache.hadoop.yarn.server.resourcemanager.security.AMRMTokenSecretManager: AMRMTokenKeyRollingInterval: 86400000ms and AMRMTokenKeyActivationDelay: 900000 ms
2019-09-16 04:37:55,288 INFO org.apache.hadoop.yarn.event.AsyncDispatcher: Registering class org.apache.hadoop.yarn.server.resourcemanager.recovery.RMStateStoreEventType for class org.apache.hadoop.yarn.server.resourcemanager.recovery.RMStateStore$ForwardingEventHandler
2019-09-16 04:37:55,292 INFO org.apache.hadoop.yarn.event.AsyncDispatcher: Registering class org.apache.hadoop.yarn.server.resourcemanager.NodesListManagerEventType for class org.apache.hadoop.yarn.server.resourcemanager.NodesListManager
2019-09-16 04:37:55,292 INFO org.apache.hadoop.yarn.server.resourcemanager.ResourceManager: Using Scheduler: org.apache.hadoop.yarn.server.resourcemanager.scheduler.capacity.CapacityScheduler
2019-09-16 04:37:55,354 INFO org.apache.hadoop.yarn.event.AsyncDispatcher: Registering class org.apache.hadoop.yarn.server.resourcemanager.scheduler.event.SchedulerEventType for class org.apache.hadoop.yarn.server.resourcemanager.ResourceManager$SchedulerEventDispatcher
2019-09-16 04:37:55,355 INFO org.apache.hadoop.yarn.event.AsyncDispatcher: Registering class org.apache.hadoop.yarn.server.resourcemanager.rmapp.RMAppEventType for class org.apache.hadoop.yarn.server.resourcemanager.ResourceManager$ApplicationEventDispatcher
2019-09-16 04:37:55,356 INFO org.apache.hadoop.yarn.event.AsyncDispatcher: Registering class org.apache.hadoop.yarn.server.resourcemanager.rmapp.attempt.RMAppAttemptEventType for class org.apache.hadoop.yarn.server.resourcemanager.ResourceManager$ApplicationAttemptEventDispatcher
2019-09-16 04:37:55,357 INFO org.apache.hadoop.yarn.event.AsyncDispatcher: Registering class org.apache.hadoop.yarn.server.resourcemanager.rmnode.RMNodeEventType for class org.apache.hadoop.yarn.server.resourcemanager.ResourceManager$NodeEventDispatcher
2019-09-16 04:37:55,630 INFO org.apache.hadoop.metrics2.impl.MetricsConfig: loaded properties from hadoop-metrics2.properties
2019-09-16 04:37:56,076 INFO org.apache.hadoop.metrics2.impl.MetricsSystemImpl: Scheduled snapshot period at 10 second(s).
2019-09-16 04:37:56,076 INFO org.apache.hadoop.metrics2.impl.MetricsSystemImpl: ResourceManager metrics system started
2019-09-16 04:37:56,177 INFO org.apache.hadoop.yarn.event.AsyncDispatcher: Registering class org.apache.hadoop.yarn.server.resourcemanager.RMAppManagerEventType for class org.apache.hadoop.yarn.server.resourcemanager.RMAppManager
2019-09-16 04:37:56,241 INFO org.apache.hadoop.yarn.event.AsyncDispatcher: Registering class org.apache.hadoop.yarn.server.resourcemanager.amlauncher.AMLauncherEventType for class org.apache.hadoop.yarn.server.resourcemanager.amlauncher.ApplicationMasterLauncher
2019-09-16 04:37:56,245 INFO org.apache.hadoop.yarn.server.resourcemanager.RMNMInfo: Registered RMNMInfo MBean
2019-09-16 04:37:56,249 INFO org.apache.hadoop.yarn.security.YarnAuthorizationProvider: org.apache.hadoop.yarn.security.ConfiguredYarnAuthorizer is instiantiated.
2019-09-16 04:37:56,249 INFO org.apache.hadoop.yarn.server.resourcemanager.metrics.SystemMetricsPublisher: YARN system metrics publishing service is not enabled
2019-09-16 04:37:56,251 INFO org.apache.hadoop.util.HostsFileReader: Refreshing hosts (include/exclude) list
2019-09-16 04:37:56,261 INFO org.apache.hadoop.conf.Configuration: found resource capacity-scheduler.xml at file:/usr/local/hadoop-2.7.1/etc/hadoop/capacity-scheduler.xml
2019-09-16 04:37:56,498 INFO org.apache.hadoop.yarn.server.resourcemanager.scheduler.capacity.CapacitySchedulerConfiguration: max alloc mb per queue for root is undefined
2019-09-16 04:37:56,500 INFO org.apache.hadoop.yarn.server.resourcemanager.scheduler.capacity.CapacitySchedulerConfiguration: max alloc vcore per queue for root is undefined
2019-09-16 04:37:56,560 INFO org.apache.hadoop.yarn.server.resourcemanager.scheduler.capacity.ParentQueue: root, capacity=1.0, asboluteCapacity=1.0, maxCapacity=1.0, asboluteMaxCapacity=1.0, state=RUNNING, acls=SUBMIT_APP:*ADMINISTER_QUEUE:*, labels=*,
, reservationsContinueLooking=true
2019-09-16 04:37:56,560 INFO org.apache.hadoop.yarn.server.resourcemanager.scheduler.capacity.ParentQueue: Initialized parent-queue root name=root, fullname=root
2019-09-16 04:37:56,658 INFO org.apache.hadoop.yarn.server.resourcemanager.scheduler.capacity.CapacitySchedulerConfiguration: max alloc mb per queue for root.default is undefined
2019-09-16 04:37:56,662 INFO org.apache.hadoop.yarn.server.resourcemanager.scheduler.capacity.CapacitySchedulerConfiguration: max alloc vcore per queue for root.default is undefined
2019-09-16 04:37:56,684 INFO org.apache.hadoop.yarn.server.resourcemanager.scheduler.capacity.LeafQueue: Initializing default
capacity = 1.0 [= (float) configuredCapacity / 100 ]
asboluteCapacity = 1.0 [= parentAbsoluteCapacity * capacity ]
maxCapacity = 1.0 [= configuredMaxCapacity ]
absoluteMaxCapacity = 1.0 [= 1.0 maximumCapacity undefined, (parentAbsoluteMaxCapacity * maximumCapacity) / 100 otherwise ]
userLimit = 100 [= configuredUserLimit ]
userLimitFactor = 1.0 [= configuredUserLimitFactor ]
maxApplications = 10000 [= configuredMaximumSystemApplicationsPerQueue or (int)(configuredMaximumSystemApplications * absoluteCapacity)]
maxApplicationsPerUser = 10000 [= (int)(maxApplications * (userLimit / 100.0f) * userLimitFactor) ]
usedCapacity = 0.0 [= usedResourcesMemory / (clusterResourceMemory * absoluteCapacity)]
absoluteUsedCapacity = 0.0 [= usedResourcesMemory / clusterResourceMemory]
maxAMResourcePerQueuePercent = 0.1 [= configuredMaximumAMResourcePercent ]
minimumAllocationFactor = 0.875 [= (float)(maximumAllocationMemory - minimumAllocationMemory) / maximumAllocationMemory ]
maximumAllocation = <memory:8192, vCores:32> [= configuredMaxAllocation ]
numContainers = 0 [= currentNumContainers ]
state = RUNNING [= configuredState ]
acls = SUBMIT_APP:*ADMINISTER_QUEUE:* [= configuredAcls ]
nodeLocalityDelay = 40
labels=*,
nodeLocalityDelay = 40
reservationsContinueLooking = true
preemptionDisabled = true

2019-09-16 04:37:56,684 INFO org.apache.hadoop.yarn.server.resourcemanager.scheduler.capacity.CapacityScheduler: Initialized queue: default: capacity=1.0, absoluteCapacity=1.0, usedResources=<memory:0, vCores:0>, usedCapacity=0.0, absoluteUsedCapacity=0.0, numApps=0, numContainers=0
2019-09-16 04:37:56,684 INFO org.apache.hadoop.yarn.server.resourcemanager.scheduler.capacity.CapacityScheduler: Initialized queue: root: numChildQueue= 1, capacity=1.0, absoluteCapacity=1.0, usedResources=<memory:0, vCores:0>usedCapacity=0.0, numApps=0, numContainers=0
2019-09-16 04:37:56,685 INFO org.apache.hadoop.yarn.server.resourcemanager.scheduler.capacity.CapacityScheduler: Initialized root queue root: numChildQueue= 1, capacity=1.0, absoluteCapacity=1.0, usedResources=<memory:0, vCores:0>usedCapacity=0.0, numApps=0, numContainers=0
2019-09-16 04:37:56,686 INFO org.apache.hadoop.yarn.server.resourcemanager.scheduler.capacity.CapacityScheduler: Initialized queue mappings, override: false
2019-09-16 04:37:56,686 INFO org.apache.hadoop.yarn.server.resourcemanager.scheduler.capacity.CapacityScheduler: Initialized CapacityScheduler with calculator=class org.apache.hadoop.yarn.util.resource.DefaultResourceCalculator, minimumAllocation=<<memory:1024, vCores:1>>, maximumAllocation=<<memory:8192, vCores:32>>, asynchronousScheduling=false, asyncScheduleInterval=5ms
2019-09-16 04:37:56,949 INFO org.apache.hadoop.yarn.server.resourcemanager.ResourceManager: Transitioning to active state
2019-09-16 04:37:57,214 INFO org.apache.hadoop.yarn.server.resourcemanager.recovery.RMStateStore: Updating AMRMToken
2019-09-16 04:37:57,214 INFO org.apache.hadoop.yarn.server.resourcemanager.security.RMContainerTokenSecretManager: Rolling master-key for container-tokens
2019-09-16 04:37:57,215 INFO org.apache.hadoop.yarn.server.resourcemanager.security.NMTokenSecretManagerInRM: Rolling master-key for nm-tokens
2019-09-16 04:37:57,216 INFO org.apache.hadoop.security.token.delegation.AbstractDelegationTokenSecretManager: Updating the current master key for generating delegation tokens
2019-09-16 04:37:57,219 INFO org.apache.hadoop.yarn.server.resourcemanager.security.RMDelegationTokenSecretManager: storing master key with keyID 1
2019-09-16 04:37:57,219 INFO org.apache.hadoop.yarn.server.resourcemanager.recovery.RMStateStore: Storing RMDTMasterKey.
2019-09-16 04:37:57,230 INFO org.apache.hadoop.security.token.delegation.AbstractDelegationTokenSecretManager: Starting expired delegation token remover thread, tokenRemoverScanInterval=60 min(s)
2019-09-16 04:37:57,230 INFO org.apache.hadoop.security.token.delegation.AbstractDelegationTokenSecretManager: Updating the current master key for generating delegation tokens
2019-09-16 04:37:57,230 INFO org.apache.hadoop.yarn.server.resourcemanager.security.RMDelegationTokenSecretManager: storing master key with keyID 2
2019-09-16 04:37:57,230 INFO org.apache.hadoop.yarn.server.resourcemanager.recovery.RMStateStore: Storing RMDTMasterKey.
2019-09-16 04:37:57,232 INFO org.apache.hadoop.yarn.event.AsyncDispatcher: Registering class org.apache.hadoop.yarn.nodelabels.event.NodeLabelsStoreEventType for class org.apache.hadoop.yarn.nodelabels.CommonNodeLabelsManager$ForwardingEventHandler
2019-09-16 04:37:57,326 INFO org.apache.hadoop.ipc.CallQueueManager: Using callQueue class java.util.concurrent.LinkedBlockingQueue
2019-09-16 04:37:57,376 INFO org.apache.hadoop.ipc.Server: Starting Socket Reader #1 for port 8031
2019-09-16 04:37:57,429 INFO org.apache.hadoop.yarn.factories.impl.pb.RpcServerFactoryPBImpl: Adding protocol org.apache.hadoop.yarn.server.api.ResourceTrackerPB to the server
2019-09-16 04:37:57,430 INFO org.apache.hadoop.ipc.Server: IPC Server Responder: starting
2019-09-16 04:37:57,430 INFO org.apache.hadoop.ipc.Server: IPC Server listener on 8031: starting
2019-09-16 04:37:57,537 INFO org.apache.hadoop.ipc.CallQueueManager: Using callQueue class java.util.concurrent.LinkedBlockingQueue
2019-09-16 04:37:57,555 INFO org.apache.hadoop.ipc.Server: Starting Socket Reader #1 for port 8030
2019-09-16 04:37:57,583 INFO org.apache.hadoop.yarn.factories.impl.pb.RpcServerFactoryPBImpl: Adding protocol org.apache.hadoop.yarn.api.ApplicationMasterProtocolPB to the server
2019-09-16 04:37:57,583 INFO org.apache.hadoop.ipc.Server: IPC Server Responder: starting
2019-09-16 04:37:57,583 INFO org.apache.hadoop.ipc.Server: IPC Server listener on 8030: starting
2019-09-16 04:37:59,813 INFO org.apache.hadoop.yarn.util.RackResolver: Resolved e9a6a0455f0d to /default-rack
2019-09-16 04:37:59,815 INFO org.apache.hadoop.yarn.server.resourcemanager.ResourceTrackerService: NodeManager from node e9a6a0455f0d(cmPort: 38503 httpPort: 8042) registered with capability: <memory:8192, vCores:8>, assigned nodeId e9a6a0455f0d:38503
2019-09-16 04:38:07,926 INFO org.apache.hadoop.ipc.CallQueueManager: Using callQueue class java.util.concurrent.LinkedBlockingQueue
2019-09-16 04:38:07,928 INFO org.apache.hadoop.ipc.Server: Starting Socket Reader #1 for port 8032
2019-09-16 04:38:07,934 INFO org.apache.hadoop.yarn.factories.impl.pb.RpcServerFactoryPBImpl: Adding protocol org.apache.hadoop.yarn.api.ApplicationClientProtocolPB to the server
2019-09-16 04:38:07,934 INFO org.apache.hadoop.ipc.Server: IPC Server Responder: starting
2019-09-16 04:38:07,934 INFO org.apache.hadoop.ipc.Server: IPC Server listener on 8032: starting
2019-09-16 04:38:07,950 INFO org.apache.hadoop.yarn.server.resourcemanager.ResourceManager: Transitioned to active state
2019-09-16 04:38:08,103 INFO org.mortbay.log: Logging to org.slf4j.impl.Log4jLoggerAdapter(org.mortbay.log) via org.mortbay.log.Slf4jLog
2019-09-16 04:38:08,117 INFO org.apache.hadoop.security.authentication.server.AuthenticationFilter: Unable to initialize FileSignerSecretProvider, falling back to use random secrets.
2019-09-16 04:38:08,124 INFO org.apache.hadoop.http.HttpRequestLog: Http request log for http.requests.resourcemanager is not defined
2019-09-16 04:38:08,136 INFO org.apache.hadoop.http.HttpServer2: Added global filter 'safety' (class=org.apache.hadoop.http.HttpServer2$QuotingInputFilter)
2019-09-16 04:38:08,144 INFO org.apache.hadoop.http.HttpServer2: Added filter RMAuthenticationFilter (class=org.apache.hadoop.yarn.server.security.http.RMAuthenticationFilter) to context cluster
2019-09-16 04:38:08,144 INFO org.apache.hadoop.http.HttpServer2: Added filter RMAuthenticationFilter (class=org.apache.hadoop.yarn.server.security.http.RMAuthenticationFilter) to context static
2019-09-16 04:38:08,144 INFO org.apache.hadoop.http.HttpServer2: Added filter RMAuthenticationFilter (class=org.apache.hadoop.yarn.server.security.http.RMAuthenticationFilter) to context logs
2019-09-16 04:38:08,145 INFO org.apache.hadoop.http.HttpServer2: Added filter static_user_filter (class=org.apache.hadoop.http.lib.StaticUserWebFilter$StaticUserFilter) to context cluster
2019-09-16 04:38:08,145 INFO org.apache.hadoop.http.HttpServer2: Added filter static_user_filter (class=org.apache.hadoop.http.lib.StaticUserWebFilter$StaticUserFilter) to context static
2019-09-16 04:38:08,145 INFO org.apache.hadoop.http.HttpServer2: Added filter static_user_filter (class=org.apache.hadoop.http.lib.StaticUserWebFilter$StaticUserFilter) to context logs
2019-09-16 04:38:08,150 INFO org.apache.hadoop.http.HttpServer2: adding path spec: /cluster/*
2019-09-16 04:38:08,150 INFO org.apache.hadoop.http.HttpServer2: adding path spec: /ws/*
2019-09-16 04:38:08,162 INFO org.apache.hadoop.http.HttpServer2: Jetty bound to port 8088
2019-09-16 04:38:08,162 INFO org.mortbay.log: jetty-6.1.26
2019-09-16 04:38:08,200 INFO org.mortbay.log: Extract jar:file:/usr/local/hadoop-2.7.1/share/hadoop/yarn/hadoop-yarn-common-2.7.1.jar!/webapps/cluster to /tmp/Jetty_0_0_0_0_8088_cluster____u0rgz3/webapp
2019-09-16 04:38:08,526 INFO org.apache.hadoop.security.token.delegation.AbstractDelegationTokenSecretManager: Updating the current master key for generating delegation tokens
2019-09-16 04:38:08,530 INFO org.apache.hadoop.security.token.delegation.AbstractDelegationTokenSecretManager: Starting expired delegation token remover thread, tokenRemoverScanInterval=60 min(s)
2019-09-16 04:38:08,530 INFO org.apache.hadoop.security.token.delegation.AbstractDelegationTokenSecretManager: Updating the current master key for generating delegation tokens
2019-09-16 04:38:08,546 INFO org.mortbay.log: Started HttpServer2$SelectChannelConnectorWithSafeStartup@0.0.0.0:8088
2019-09-16 04:38:08,546 INFO org.apache.hadoop.yarn.webapp.WebApps: Web app /cluster started at 8088
2019-09-16 04:38:08,948 INFO org.apache.hadoop.yarn.webapp.WebApps: Registered webapp guice modules
2019-09-16 04:38:08,952 INFO org.apache.hadoop.yarn.server.resourcemanager.rmnode.RMNodeImpl: e9a6a0455f0d:38503 Node Transitioned from NEW to RUNNING
2019-09-16 04:38:08,957 INFO org.apache.hadoop.yarn.server.resourcemanager.scheduler.capacity.CapacityScheduler: Added node e9a6a0455f0d:38503 clusterResource: <memory:8192, vCores:8>
2019-09-16 04:38:09,030 INFO org.apache.hadoop.ipc.CallQueueManager: Using callQueue class java.util.concurrent.LinkedBlockingQueue
2019-09-16 04:38:09,031 INFO org.apache.hadoop.ipc.Server: Starting Socket Reader #1 for port 8033
2019-09-16 04:38:09,038 INFO org.apache.hadoop.yarn.factories.impl.pb.RpcServerFactoryPBImpl: Adding protocol org.apache.hadoop.yarn.server.api.ResourceManagerAdministrationProtocolPB to the server
2019-09-16 04:38:09,041 INFO org.apache.hadoop.ipc.Server: IPC Server Responder: starting
2019-09-16 04:38:09,042 INFO org.apache.hadoop.ipc.Server: IPC Server listener on 8033: starting
2019-09-16 04:47:56,262 INFO org.apache.hadoop.yarn.server.resourcemanager.scheduler.AbstractYarnScheduler: Release request cache is cleaned up
2019-09-16 06:05:50,533 INFO org.apache.hadoop.yarn.server.resourcemanager.ClientRMService: Allocated new applicationId: 1
2019-09-16 06:05:53,556 INFO org.apache.hadoop.yarn.server.resourcemanager.ClientRMService: Application with id 1 submitted by user root
2019-09-16 06:05:53,559 INFO org.apache.hadoop.yarn.server.resourcemanager.RMAuditLogger: USER=root	IP=172.24.0.2	OPERATION=Submit Application Request	TARGET=ClientRMService	RESULT=SUCCESS	APPID=application_1568623076950_0001
2019-09-16 06:05:53,560 INFO org.apache.hadoop.yarn.server.resourcemanager.rmapp.RMAppImpl: Storing application with id application_1568623076950_0001
2019-09-16 06:05:53,584 INFO org.apache.hadoop.yarn.server.resourcemanager.rmapp.RMAppImpl: application_1568623076950_0001 State change from NEW to NEW_SAVING
2019-09-16 06:05:53,585 INFO org.apache.hadoop.yarn.server.resourcemanager.recovery.RMStateStore: Storing info for app: application_1568623076950_0001
2019-09-16 06:05:53,636 INFO org.apache.hadoop.yarn.server.resourcemanager.rmapp.RMAppImpl: application_1568623076950_0001 State change from NEW_SAVING to SUBMITTED
2019-09-16 06:05:53,646 INFO org.apache.hadoop.yarn.server.resourcemanager.scheduler.capacity.ParentQueue: Application added - appId: application_1568623076950_0001 user: root leaf-queue of parent: root #applications: 1
2019-09-16 06:05:53,651 INFO org.apache.hadoop.yarn.server.resourcemanager.scheduler.capacity.CapacityScheduler: Accepted application application_1568623076950_0001 from user: root, in queue: default
2019-09-16 06:05:53,657 INFO org.apache.hadoop.yarn.server.resourcemanager.rmapp.RMAppImpl: application_1568623076950_0001 State change from SUBMITTED to ACCEPTED
2019-09-16 06:05:53,751 INFO org.apache.hadoop.yarn.server.resourcemanager.ApplicationMasterService: Registering app attempt : appattempt_1568623076950_0001_000001
2019-09-16 06:05:53,755 INFO org.apache.hadoop.yarn.server.resourcemanager.rmapp.attempt.RMAppAttemptImpl: appattempt_1568623076950_0001_000001 State change from NEW to SUBMITTED
2019-09-16 06:05:53,791 WARN org.apache.hadoop.yarn.server.resourcemanager.scheduler.capacity.LeafQueue: maximum-am-resource-percent is insufficient to start a single application in queue, it is likely set too low. skipping enforcement to allow at least one application to start
2019-09-16 06:05:53,791 WARN org.apache.hadoop.yarn.server.resourcemanager.scheduler.capacity.LeafQueue: maximum-am-resource-percent is insufficient to start a single application in queue for user, it is likely set too low. skipping enforcement to allow at least one application to start
2019-09-16 06:05:53,791 INFO org.apache.hadoop.yarn.server.resourcemanager.scheduler.capacity.LeafQueue: Application application_1568623076950_0001 from user: root activated in queue: default
2019-09-16 06:05:53,791 INFO org.apache.hadoop.yarn.server.resourcemanager.scheduler.capacity.LeafQueue: Application added - appId: application_1568623076950_0001 user: org.apache.hadoop.yarn.server.resourcemanager.scheduler.capacity.LeafQueue$User@1619372c, leaf-queue: default #user-pending-applications: 0 #user-active-applications: 1 #queue-pending-applications: 0 #queue-active-applications: 1
2019-09-16 06:05:53,792 INFO org.apache.hadoop.yarn.server.resourcemanager.scheduler.capacity.CapacityScheduler: Added Application Attempt appattempt_1568623076950_0001_000001 to scheduler from user root in queue default
2019-09-16 06:05:53,797 INFO org.apache.hadoop.yarn.server.resourcemanager.rmapp.attempt.RMAppAttemptImpl: appattempt_1568623076950_0001_000001 State change from SUBMITTED to SCHEDULED
2019-09-16 06:05:53,943 INFO org.apache.hadoop.yarn.server.resourcemanager.rmcontainer.RMContainerImpl: container_1568623076950_0001_01_000001 Container Transitioned from NEW to ALLOCATED
2019-09-16 06:05:53,944 INFO org.apache.hadoop.yarn.server.resourcemanager.RMAuditLogger: USER=root	OPERATION=AM Allocated Container	TARGET=SchedulerApp	RESULT=SUCCESS	APPID=application_1568623076950_0001	CONTAINERID=container_1568623076950_0001_01_000001
2019-09-16 06:05:53,944 INFO org.apache.hadoop.yarn.server.resourcemanager.scheduler.SchedulerNode: Assigned container container_1568623076950_0001_01_000001 of capacity <memory:2048, vCores:1> on host e9a6a0455f0d:38503, which has 1 containers, <memory:2048, vCores:1> used and <memory:6144, vCores:7> available after allocation
2019-09-16 06:05:53,947 INFO org.apache.hadoop.yarn.server.resourcemanager.scheduler.capacity.LeafQueue: assignedContainer application attempt=appattempt_1568623076950_0001_000001 container=Container: [ContainerId: container_1568623076950_0001_01_000001, NodeId: e9a6a0455f0d:38503, NodeHttpAddress: e9a6a0455f0d:8042, Resource: <memory:2048, vCores:1>, Priority: 0, Token: null, ] queue=default: capacity=1.0, absoluteCapacity=1.0, usedResources=<memory:0, vCores:0>, usedCapacity=0.0, absoluteUsedCapacity=0.0, numApps=1, numContainers=0 clusterResource=<memory:8192, vCores:8>
2019-09-16 06:05:53,948 INFO org.apache.hadoop.yarn.server.resourcemanager.scheduler.capacity.ParentQueue: Re-sorting assigned queue: root.default stats: default: capacity=1.0, absoluteCapacity=1.0, usedResources=<memory:2048, vCores:1>, usedCapacity=0.25, absoluteUsedCapacity=0.25, numApps=1, numContainers=1
2019-09-16 06:05:53,948 INFO org.apache.hadoop.yarn.server.resourcemanager.scheduler.capacity.ParentQueue: assignedContainer queue=root usedCapacity=0.25 absoluteUsedCapacity=0.25 used=<memory:2048, vCores:1> cluster=<memory:8192, vCores:8>
2019-09-16 06:05:54,004 INFO org.apache.hadoop.yarn.server.resourcemanager.security.NMTokenSecretManagerInRM: Sending NMToken for nodeId : e9a6a0455f0d:38503 for container : container_1568623076950_0001_01_000001
2019-09-16 06:05:54,029 INFO org.apache.hadoop.yarn.server.resourcemanager.rmcontainer.RMContainerImpl: container_1568623076950_0001_01_000001 Container Transitioned from ALLOCATED to ACQUIRED
2019-09-16 06:05:54,029 INFO org.apache.hadoop.yarn.server.resourcemanager.security.NMTokenSecretManagerInRM: Clear node set for appattempt_1568623076950_0001_000001
2019-09-16 06:05:54,035 INFO org.apache.hadoop.yarn.server.resourcemanager.rmapp.attempt.RMAppAttemptImpl: Storing attempt: AppId: application_1568623076950_0001 AttemptId: appattempt_1568623076950_0001_000001 MasterContainer: Container: [ContainerId: container_1568623076950_0001_01_000001, NodeId: e9a6a0455f0d:38503, NodeHttpAddress: e9a6a0455f0d:8042, Resource: <memory:2048, vCores:1>, Priority: 0, Token: Token { kind: ContainerToken, service: 172.24.0.2:38503 }, ]
2019-09-16 06:05:54,095 INFO org.apache.hadoop.yarn.server.resourcemanager.rmapp.attempt.RMAppAttemptImpl: appattempt_1568623076950_0001_000001 State change from SCHEDULED to ALLOCATED_SAVING
2019-09-16 06:05:54,242 INFO org.apache.hadoop.yarn.server.resourcemanager.rmapp.attempt.RMAppAttemptImpl: appattempt_1568623076950_0001_000001 State change from ALLOCATED_SAVING to ALLOCATED
2019-09-16 06:05:54,258 INFO org.apache.hadoop.yarn.server.resourcemanager.amlauncher.AMLauncher: Launching masterappattempt_1568623076950_0001_000001
2019-09-16 06:05:54,348 INFO org.apache.hadoop.yarn.server.resourcemanager.amlauncher.AMLauncher: Setting up container Container: [ContainerId: container_1568623076950_0001_01_000001, NodeId: e9a6a0455f0d:38503, NodeHttpAddress: e9a6a0455f0d:8042, Resource: <memory:2048, vCores:1>, Priority: 0, Token: Token { kind: ContainerToken, service: 172.24.0.2:38503 }, ] for AM appattempt_1568623076950_0001_000001
2019-09-16 06:05:54,362 INFO org.apache.hadoop.yarn.server.resourcemanager.amlauncher.AMLauncher: Command to launch container container_1568623076950_0001_01_000001 : $JAVA_HOME/bin/java -Dlog4j.configuration=container-log4j.properties -Dyarn.app.container.log.dir=<LOG_DIR> -Dyarn.app.container.log.filesize=0 -Dhadoop.root.logger=INFO,CLA -Dhadoop.root.logfile=syslog  -Xmx1024m org.apache.hadoop.mapreduce.v2.app.MRAppMaster 1><LOG_DIR>/stdout 2><LOG_DIR>/stderr 
2019-09-16 06:05:54,364 INFO org.apache.hadoop.yarn.server.resourcemanager.security.AMRMTokenSecretManager: Create AMRMToken for ApplicationAttempt: appattempt_1568623076950_0001_000001
2019-09-16 06:05:54,368 INFO org.apache.hadoop.yarn.server.resourcemanager.security.AMRMTokenSecretManager: Creating password for appattempt_1568623076950_0001_000001
2019-09-16 06:05:55,173 INFO org.apache.hadoop.yarn.server.resourcemanager.amlauncher.AMLauncher: Done launching container Container: [ContainerId: container_1568623076950_0001_01_000001, NodeId: e9a6a0455f0d:38503, NodeHttpAddress: e9a6a0455f0d:8042, Resource: <memory:2048, vCores:1>, Priority: 0, Token: Token { kind: ContainerToken, service: 172.24.0.2:38503 }, ] for AM appattempt_1568623076950_0001_000001
2019-09-16 06:05:55,173 INFO org.apache.hadoop.yarn.server.resourcemanager.rmapp.attempt.RMAppAttemptImpl: appattempt_1568623076950_0001_000001 State change from ALLOCATED to LAUNCHED
2019-09-16 06:05:55,901 INFO org.apache.hadoop.yarn.server.resourcemanager.rmcontainer.RMContainerImpl: container_1568623076950_0001_01_000001 Container Transitioned from ACQUIRED to RUNNING
2019-09-16 06:06:02,823 INFO SecurityLogger.org.apache.hadoop.ipc.Server: Auth successful for appattempt_1568623076950_0001_000001 (auth:SIMPLE)
2019-09-16 06:06:02,840 INFO org.apache.hadoop.yarn.server.resourcemanager.ApplicationMasterService: AM registration appattempt_1568623076950_0001_000001
2019-09-16 06:06:02,842 INFO org.apache.hadoop.yarn.server.resourcemanager.RMAuditLogger: USER=root	IP=172.24.0.2	OPERATION=Register App Master	TARGET=ApplicationMasterService	RESULT=SUCCESS	APPID=application_1568623076950_0001	APPATTEMPTID=appattempt_1568623076950_0001_000001
2019-09-16 06:06:02,842 INFO org.apache.hadoop.yarn.server.resourcemanager.rmapp.attempt.RMAppAttemptImpl: appattempt_1568623076950_0001_000001 State change from LAUNCHED to RUNNING
2019-09-16 06:06:02,842 INFO org.apache.hadoop.yarn.server.resourcemanager.rmapp.RMAppImpl: application_1568623076950_0001 State change from ACCEPTED to RUNNING
2019-09-16 06:06:04,919 INFO org.apache.hadoop.yarn.server.resourcemanager.rmcontainer.RMContainerImpl: container_1568623076950_0001_01_000002 Container Transitioned from NEW to ALLOCATED
2019-09-16 06:06:04,919 INFO org.apache.hadoop.yarn.server.resourcemanager.RMAuditLogger: USER=root	OPERATION=AM Allocated Container	TARGET=SchedulerApp	RESULT=SUCCESS	APPID=application_1568623076950_0001	CONTAINERID=container_1568623076950_0001_01_000002
2019-09-16 06:06:04,919 INFO org.apache.hadoop.yarn.server.resourcemanager.scheduler.SchedulerNode: Assigned container container_1568623076950_0001_01_000002 of capacity <memory:1024, vCores:1> on host e9a6a0455f0d:38503, which has 2 containers, <memory:3072, vCores:2> used and <memory:5120, vCores:6> available after allocation
2019-09-16 06:06:04,920 INFO org.apache.hadoop.yarn.server.resourcemanager.scheduler.capacity.LeafQueue: assignedContainer application attempt=appattempt_1568623076950_0001_000001 container=Container: [ContainerId: container_1568623076950_0001_01_000002, NodeId: e9a6a0455f0d:38503, NodeHttpAddress: e9a6a0455f0d:8042, Resource: <memory:1024, vCores:1>, Priority: 20, Token: null, ] queue=default: capacity=1.0, absoluteCapacity=1.0, usedResources=<memory:2048, vCores:1>, usedCapacity=0.25, absoluteUsedCapacity=0.25, numApps=1, numContainers=1 clusterResource=<memory:8192, vCores:8>
2019-09-16 06:06:04,920 INFO org.apache.hadoop.yarn.server.resourcemanager.scheduler.capacity.ParentQueue: Re-sorting assigned queue: root.default stats: default: capacity=1.0, absoluteCapacity=1.0, usedResources=<memory:3072, vCores:2>, usedCapacity=0.375, absoluteUsedCapacity=0.375, numApps=1, numContainers=2
2019-09-16 06:06:04,920 INFO org.apache.hadoop.yarn.server.resourcemanager.scheduler.capacity.ParentQueue: assignedContainer queue=root usedCapacity=0.375 absoluteUsedCapacity=0.375 used=<memory:3072, vCores:2> cluster=<memory:8192, vCores:8>
2019-09-16 06:06:04,921 INFO org.apache.hadoop.yarn.server.resourcemanager.rmcontainer.RMContainerImpl: container_1568623076950_0001_01_000003 Container Transitioned from NEW to ALLOCATED
2019-09-16 06:06:04,921 INFO org.apache.hadoop.yarn.server.resourcemanager.RMAuditLogger: USER=root	OPERATION=AM Allocated Container	TARGET=SchedulerApp	RESULT=SUCCESS	APPID=application_1568623076950_0001	CONTAINERID=container_1568623076950_0001_01_000003
2019-09-16 06:06:04,921 INFO org.apache.hadoop.yarn.server.resourcemanager.scheduler.SchedulerNode: Assigned container container_1568623076950_0001_01_000003 of capacity <memory:1024, vCores:1> on host e9a6a0455f0d:38503, which has 3 containers, <memory:4096, vCores:3> used and <memory:4096, vCores:5> available after allocation
2019-09-16 06:06:04,921 INFO org.apache.hadoop.yarn.server.resourcemanager.scheduler.capacity.LeafQueue: assignedContainer application attempt=appattempt_1568623076950_0001_000001 container=Container: [ContainerId: container_1568623076950_0001_01_000003, NodeId: e9a6a0455f0d:38503, NodeHttpAddress: e9a6a0455f0d:8042, Resource: <memory:1024, vCores:1>, Priority: 20, Token: null, ] queue=default: capacity=1.0, absoluteCapacity=1.0, usedResources=<memory:3072, vCores:2>, usedCapacity=0.375, absoluteUsedCapacity=0.375, numApps=1, numContainers=2 clusterResource=<memory:8192, vCores:8>
2019-09-16 06:06:04,921 INFO org.apache.hadoop.yarn.server.resourcemanager.scheduler.capacity.ParentQueue: Re-sorting assigned queue: root.default stats: default: capacity=1.0, absoluteCapacity=1.0, usedResources=<memory:4096, vCores:3>, usedCapacity=0.5, absoluteUsedCapacity=0.5, numApps=1, numContainers=3
2019-09-16 06:06:04,922 INFO org.apache.hadoop.yarn.server.resourcemanager.scheduler.capacity.ParentQueue: assignedContainer queue=root usedCapacity=0.5 absoluteUsedCapacity=0.5 used=<memory:4096, vCores:3> cluster=<memory:8192, vCores:8>
2019-09-16 06:06:04,922 INFO org.apache.hadoop.yarn.server.resourcemanager.rmcontainer.RMContainerImpl: container_1568623076950_0001_01_000004 Container Transitioned from NEW to ALLOCATED
2019-09-16 06:06:04,922 INFO org.apache.hadoop.yarn.server.resourcemanager.RMAuditLogger: USER=root	OPERATION=AM Allocated Container	TARGET=SchedulerApp	RESULT=SUCCESS	APPID=application_1568623076950_0001	CONTAINERID=container_1568623076950_0001_01_000004
2019-09-16 06:06:04,922 INFO org.apache.hadoop.yarn.server.resourcemanager.scheduler.SchedulerNode: Assigned container container_1568623076950_0001_01_000004 of capacity <memory:1024, vCores:1> on host e9a6a0455f0d:38503, which has 4 containers, <memory:5120, vCores:4> used and <memory:3072, vCores:4> available after allocation
2019-09-16 06:06:04,923 INFO org.apache.hadoop.yarn.server.resourcemanager.scheduler.capacity.LeafQueue: assignedContainer application attempt=appattempt_1568623076950_0001_000001 container=Container: [ContainerId: container_1568623076950_0001_01_000004, NodeId: e9a6a0455f0d:38503, NodeHttpAddress: e9a6a0455f0d:8042, Resource: <memory:1024, vCores:1>, Priority: 20, Token: null, ] queue=default: capacity=1.0, absoluteCapacity=1.0, usedResources=<memory:4096, vCores:3>, usedCapacity=0.5, absoluteUsedCapacity=0.5, numApps=1, numContainers=3 clusterResource=<memory:8192, vCores:8>
2019-09-16 06:06:04,923 INFO org.apache.hadoop.yarn.server.resourcemanager.scheduler.capacity.ParentQueue: Re-sorting assigned queue: root.default stats: default: capacity=1.0, absoluteCapacity=1.0, usedResources=<memory:5120, vCores:4>, usedCapacity=0.625, absoluteUsedCapacity=0.625, numApps=1, numContainers=4
2019-09-16 06:06:04,923 INFO org.apache.hadoop.yarn.server.resourcemanager.scheduler.capacity.ParentQueue: assignedContainer queue=root usedCapacity=0.625 absoluteUsedCapacity=0.625 used=<memory:5120, vCores:4> cluster=<memory:8192, vCores:8>
2019-09-16 06:06:04,924 INFO org.apache.hadoop.yarn.server.resourcemanager.rmcontainer.RMContainerImpl: container_1568623076950_0001_01_000005 Container Transitioned from NEW to ALLOCATED
2019-09-16 06:06:04,924 INFO org.apache.hadoop.yarn.server.resourcemanager.RMAuditLogger: USER=root	OPERATION=AM Allocated Container	TARGET=SchedulerApp	RESULT=SUCCESS	APPID=application_1568623076950_0001	CONTAINERID=container_1568623076950_0001_01_000005
2019-09-16 06:06:04,924 INFO org.apache.hadoop.yarn.server.resourcemanager.scheduler.SchedulerNode: Assigned container container_1568623076950_0001_01_000005 of capacity <memory:1024, vCores:1> on host e9a6a0455f0d:38503, which has 5 containers, <memory:6144, vCores:5> used and <memory:2048, vCores:3> available after allocation
2019-09-16 06:06:04,924 INFO org.apache.hadoop.yarn.server.resourcemanager.scheduler.capacity.LeafQueue: assignedContainer application attempt=appattempt_1568623076950_0001_000001 container=Container: [ContainerId: container_1568623076950_0001_01_000005, NodeId: e9a6a0455f0d:38503, NodeHttpAddress: e9a6a0455f0d:8042, Resource: <memory:1024, vCores:1>, Priority: 20, Token: null, ] queue=default: capacity=1.0, absoluteCapacity=1.0, usedResources=<memory:5120, vCores:4>, usedCapacity=0.625, absoluteUsedCapacity=0.625, numApps=1, numContainers=4 clusterResource=<memory:8192, vCores:8>
2019-09-16 06:06:04,925 INFO org.apache.hadoop.yarn.server.resourcemanager.scheduler.capacity.ParentQueue: Re-sorting assigned queue: root.default stats: default: capacity=1.0, absoluteCapacity=1.0, usedResources=<memory:6144, vCores:5>, usedCapacity=0.75, absoluteUsedCapacity=0.75, numApps=1, numContainers=5
2019-09-16 06:06:04,925 INFO org.apache.hadoop.yarn.server.resourcemanager.scheduler.capacity.ParentQueue: assignedContainer queue=root usedCapacity=0.75 absoluteUsedCapacity=0.75 used=<memory:6144, vCores:5> cluster=<memory:8192, vCores:8>
2019-09-16 06:06:04,925 INFO org.apache.hadoop.yarn.server.resourcemanager.rmcontainer.RMContainerImpl: container_1568623076950_0001_01_000006 Container Transitioned from NEW to ALLOCATED
2019-09-16 06:06:04,925 INFO org.apache.hadoop.yarn.server.resourcemanager.RMAuditLogger: USER=root	OPERATION=AM Allocated Container	TARGET=SchedulerApp	RESULT=SUCCESS	APPID=application_1568623076950_0001	CONTAINERID=container_1568623076950_0001_01_000006
2019-09-16 06:06:04,926 INFO org.apache.hadoop.yarn.server.resourcemanager.scheduler.SchedulerNode: Assigned container container_1568623076950_0001_01_000006 of capacity <memory:1024, vCores:1> on host e9a6a0455f0d:38503, which has 6 containers, <memory:7168, vCores:6> used and <memory:1024, vCores:2> available after allocation
2019-09-16 06:06:04,926 INFO org.apache.hadoop.yarn.server.resourcemanager.scheduler.capacity.LeafQueue: assignedContainer application attempt=appattempt_1568623076950_0001_000001 container=Container: [ContainerId: container_1568623076950_0001_01_000006, NodeId: e9a6a0455f0d:38503, NodeHttpAddress: e9a6a0455f0d:8042, Resource: <memory:1024, vCores:1>, Priority: 20, Token: null, ] queue=default: capacity=1.0, absoluteCapacity=1.0, usedResources=<memory:6144, vCores:5>, usedCapacity=0.75, absoluteUsedCapacity=0.75, numApps=1, numContainers=5 clusterResource=<memory:8192, vCores:8>
2019-09-16 06:06:04,926 INFO org.apache.hadoop.yarn.server.resourcemanager.scheduler.capacity.ParentQueue: Re-sorting assigned queue: root.default stats: default: capacity=1.0, absoluteCapacity=1.0, usedResources=<memory:7168, vCores:6>, usedCapacity=0.875, absoluteUsedCapacity=0.875, numApps=1, numContainers=6
2019-09-16 06:06:04,926 INFO org.apache.hadoop.yarn.server.resourcemanager.scheduler.capacity.ParentQueue: assignedContainer queue=root usedCapacity=0.875 absoluteUsedCapacity=0.875 used=<memory:7168, vCores:6> cluster=<memory:8192, vCores:8>
2019-09-16 06:06:04,927 INFO org.apache.hadoop.yarn.server.resourcemanager.rmcontainer.RMContainerImpl: container_1568623076950_0001_01_000007 Container Transitioned from NEW to ALLOCATED
2019-09-16 06:06:04,927 INFO org.apache.hadoop.yarn.server.resourcemanager.RMAuditLogger: USER=root	OPERATION=AM Allocated Container	TARGET=SchedulerApp	RESULT=SUCCESS	APPID=application_1568623076950_0001	CONTAINERID=container_1568623076950_0001_01_000007
2019-09-16 06:06:04,927 INFO org.apache.hadoop.yarn.server.resourcemanager.scheduler.SchedulerNode: Assigned container container_1568623076950_0001_01_000007 of capacity <memory:1024, vCores:1> on host e9a6a0455f0d:38503, which has 7 containers, <memory:8192, vCores:7> used and <memory:0, vCores:1> available after allocation
2019-09-16 06:06:04,927 INFO org.apache.hadoop.yarn.server.resourcemanager.scheduler.capacity.LeafQueue: assignedContainer application attempt=appattempt_1568623076950_0001_000001 container=Container: [ContainerId: container_1568623076950_0001_01_000007, NodeId: e9a6a0455f0d:38503, NodeHttpAddress: e9a6a0455f0d:8042, Resource: <memory:1024, vCores:1>, Priority: 20, Token: null, ] queue=default: capacity=1.0, absoluteCapacity=1.0, usedResources=<memory:7168, vCores:6>, usedCapacity=0.875, absoluteUsedCapacity=0.875, numApps=1, numContainers=6 clusterResource=<memory:8192, vCores:8>
2019-09-16 06:06:04,928 INFO org.apache.hadoop.yarn.server.resourcemanager.scheduler.capacity.ParentQueue: Re-sorting assigned queue: root.default stats: default: capacity=1.0, absoluteCapacity=1.0, usedResources=<memory:8192, vCores:7>, usedCapacity=1.0, absoluteUsedCapacity=1.0, numApps=1, numContainers=7
2019-09-16 06:06:04,928 INFO org.apache.hadoop.yarn.server.resourcemanager.scheduler.capacity.ParentQueue: assignedContainer queue=root usedCapacity=1.0 absoluteUsedCapacity=1.0 used=<memory:8192, vCores:7> cluster=<memory:8192, vCores:8>
2019-09-16 06:06:04,953 INFO org.apache.hadoop.yarn.server.resourcemanager.security.NMTokenSecretManagerInRM: Sending NMToken for nodeId : e9a6a0455f0d:38503 for container : container_1568623076950_0001_01_000002
2019-09-16 06:06:04,954 INFO org.apache.hadoop.yarn.server.resourcemanager.rmcontainer.RMContainerImpl: container_1568623076950_0001_01_000002 Container Transitioned from ALLOCATED to ACQUIRED
2019-09-16 06:06:04,956 INFO org.apache.hadoop.yarn.server.resourcemanager.rmcontainer.RMContainerImpl: container_1568623076950_0001_01_000003 Container Transitioned from ALLOCATED to ACQUIRED
2019-09-16 06:06:04,957 INFO org.apache.hadoop.yarn.server.resourcemanager.rmcontainer.RMContainerImpl: container_1568623076950_0001_01_000004 Container Transitioned from ALLOCATED to ACQUIRED
2019-09-16 06:06:04,961 INFO org.apache.hadoop.yarn.server.resourcemanager.rmcontainer.RMContainerImpl: container_1568623076950_0001_01_000005 Container Transitioned from ALLOCATED to ACQUIRED
2019-09-16 06:06:04,963 INFO org.apache.hadoop.yarn.server.resourcemanager.rmcontainer.RMContainerImpl: container_1568623076950_0001_01_000006 Container Transitioned from ALLOCATED to ACQUIRED
2019-09-16 06:06:04,965 INFO org.apache.hadoop.yarn.server.resourcemanager.rmcontainer.RMContainerImpl: container_1568623076950_0001_01_000007 Container Transitioned from ALLOCATED to ACQUIRED
2019-09-16 06:06:05,954 INFO org.apache.hadoop.yarn.server.resourcemanager.rmcontainer.RMContainerImpl: container_1568623076950_0001_01_000002 Container Transitioned from ACQUIRED to RUNNING
2019-09-16 06:06:05,955 INFO org.apache.hadoop.yarn.server.resourcemanager.rmcontainer.RMContainerImpl: container_1568623076950_0001_01_000003 Container Transitioned from ACQUIRED to RUNNING
2019-09-16 06:06:05,955 INFO org.apache.hadoop.yarn.server.resourcemanager.rmcontainer.RMContainerImpl: container_1568623076950_0001_01_000004 Container Transitioned from ACQUIRED to RUNNING
2019-09-16 06:06:05,955 INFO org.apache.hadoop.yarn.server.resourcemanager.rmcontainer.RMContainerImpl: container_1568623076950_0001_01_000005 Container Transitioned from ACQUIRED to RUNNING
2019-09-16 06:06:05,956 INFO org.apache.hadoop.yarn.server.resourcemanager.rmcontainer.RMContainerImpl: container_1568623076950_0001_01_000006 Container Transitioned from ACQUIRED to RUNNING
2019-09-16 06:06:05,956 INFO org.apache.hadoop.yarn.server.resourcemanager.rmcontainer.RMContainerImpl: container_1568623076950_0001_01_000007 Container Transitioned from ACQUIRED to RUNNING
2019-09-16 06:06:24,035 INFO org.apache.hadoop.yarn.server.resourcemanager.rmcontainer.RMContainerImpl: container_1568623076950_0001_01_000004 Container Transitioned from RUNNING to COMPLETED
2019-09-16 06:06:24,065 INFO org.apache.hadoop.yarn.server.resourcemanager.scheduler.common.fica.FiCaSchedulerApp: Completed container: container_1568623076950_0001_01_000004 in state: COMPLETED event:FINISHED
2019-09-16 06:06:24,067 INFO org.apache.hadoop.yarn.server.resourcemanager.RMAuditLogger: USER=root	OPERATION=AM Released Container	TARGET=SchedulerApp	RESULT=SUCCESS	APPID=application_1568623076950_0001	CONTAINERID=container_1568623076950_0001_01_000004
2019-09-16 06:06:24,081 INFO org.apache.hadoop.yarn.server.resourcemanager.scheduler.SchedulerNode: Released container container_1568623076950_0001_01_000004 of capacity <memory:1024, vCores:1> on host e9a6a0455f0d:38503, which currently has 6 containers, <memory:7168, vCores:6> used and <memory:1024, vCores:2> available, release resources=true
2019-09-16 06:06:24,095 INFO org.apache.hadoop.yarn.server.resourcemanager.scheduler.capacity.LeafQueue: default used=<memory:7168, vCores:6> numContainers=6 user=root user-resources=<memory:7168, vCores:6>
2019-09-16 06:06:24,123 INFO org.apache.hadoop.yarn.server.resourcemanager.scheduler.capacity.LeafQueue: completedContainer container=Container: [ContainerId: container_1568623076950_0001_01_000004, NodeId: e9a6a0455f0d:38503, NodeHttpAddress: e9a6a0455f0d:8042, Resource: <memory:1024, vCores:1>, Priority: 20, Token: Token { kind: ContainerToken, service: 172.24.0.2:38503 }, ] queue=default: capacity=1.0, absoluteCapacity=1.0, usedResources=<memory:7168, vCores:6>, usedCapacity=0.875, absoluteUsedCapacity=0.875, numApps=1, numContainers=6 cluster=<memory:8192, vCores:8>
2019-09-16 06:06:24,123 INFO org.apache.hadoop.yarn.server.resourcemanager.scheduler.capacity.ParentQueue: completedContainer queue=root usedCapacity=0.875 absoluteUsedCapacity=0.875 used=<memory:7168, vCores:6> cluster=<memory:8192, vCores:8>
2019-09-16 06:06:24,135 INFO org.apache.hadoop.yarn.server.resourcemanager.scheduler.capacity.ParentQueue: Re-sorting completed queue: root.default stats: default: capacity=1.0, absoluteCapacity=1.0, usedResources=<memory:7168, vCores:6>, usedCapacity=0.875, absoluteUsedCapacity=0.875, numApps=1, numContainers=6
2019-09-16 06:06:24,137 INFO org.apache.hadoop.yarn.server.resourcemanager.scheduler.capacity.CapacityScheduler: Application attempt appattempt_1568623076950_0001_000001 released container container_1568623076950_0001_01_000004 on node: host: e9a6a0455f0d:38503 #containers=6 available=<memory:1024, vCores:2> used=<memory:7168, vCores:6> with event: FINISHED
2019-09-16 06:06:24,143 INFO org.apache.hadoop.yarn.server.resourcemanager.rmcontainer.RMContainerImpl: container_1568623076950_0001_01_000005 Container Transitioned from RUNNING to COMPLETED
2019-09-16 06:06:24,152 INFO org.apache.hadoop.yarn.server.resourcemanager.scheduler.common.fica.FiCaSchedulerApp: Completed container: container_1568623076950_0001_01_000005 in state: COMPLETED event:FINISHED
2019-09-16 06:06:24,154 INFO org.apache.hadoop.yarn.server.resourcemanager.RMAuditLogger: USER=root	OPERATION=AM Released Container	TARGET=SchedulerApp	RESULT=SUCCESS	APPID=application_1568623076950_0001	CONTAINERID=container_1568623076950_0001_01_000005
2019-09-16 06:06:24,155 INFO org.apache.hadoop.yarn.server.resourcemanager.scheduler.SchedulerNode: Released container container_1568623076950_0001_01_000005 of capacity <memory:1024, vCores:1> on host e9a6a0455f0d:38503, which currently has 5 containers, <memory:6144, vCores:5> used and <memory:2048, vCores:3> available, release resources=true
2019-09-16 06:06:24,156 INFO org.apache.hadoop.yarn.server.resourcemanager.scheduler.capacity.LeafQueue: default used=<memory:6144, vCores:5> numContainers=5 user=root user-resources=<memory:6144, vCores:5>
2019-09-16 06:06:24,163 INFO org.apache.hadoop.yarn.server.resourcemanager.scheduler.capacity.LeafQueue: completedContainer container=Container: [ContainerId: container_1568623076950_0001_01_000005, NodeId: e9a6a0455f0d:38503, NodeHttpAddress: e9a6a0455f0d:8042, Resource: <memory:1024, vCores:1>, Priority: 20, Token: Token { kind: ContainerToken, service: 172.24.0.2:38503 }, ] queue=default: capacity=1.0, absoluteCapacity=1.0, usedResources=<memory:6144, vCores:5>, usedCapacity=0.75, absoluteUsedCapacity=0.75, numApps=1, numContainers=5 cluster=<memory:8192, vCores:8>
2019-09-16 06:06:24,164 INFO org.apache.hadoop.yarn.server.resourcemanager.scheduler.capacity.ParentQueue: completedContainer queue=root usedCapacity=0.75 absoluteUsedCapacity=0.75 used=<memory:6144, vCores:5> cluster=<memory:8192, vCores:8>
2019-09-16 06:06:24,178 INFO org.apache.hadoop.yarn.server.resourcemanager.scheduler.capacity.ParentQueue: Re-sorting completed queue: root.default stats: default: capacity=1.0, absoluteCapacity=1.0, usedResources=<memory:6144, vCores:5>, usedCapacity=0.75, absoluteUsedCapacity=0.75, numApps=1, numContainers=5
2019-09-16 06:06:24,181 INFO org.apache.hadoop.yarn.server.resourcemanager.scheduler.capacity.CapacityScheduler: Application attempt appattempt_1568623076950_0001_000001 released container container_1568623076950_0001_01_000005 on node: host: e9a6a0455f0d:38503 #containers=5 available=<memory:2048, vCores:3> used=<memory:6144, vCores:5> with event: FINISHED
2019-09-16 06:06:24,205 INFO org.apache.hadoop.yarn.server.resourcemanager.rmcontainer.RMContainerImpl: container_1568623076950_0001_01_000007 Container Transitioned from RUNNING to COMPLETED
2019-09-16 06:06:24,209 INFO org.apache.hadoop.yarn.server.resourcemanager.scheduler.common.fica.FiCaSchedulerApp: Completed container: container_1568623076950_0001_01_000007 in state: COMPLETED event:FINISHED
2019-09-16 06:06:24,210 INFO org.apache.hadoop.yarn.server.resourcemanager.RMAuditLogger: USER=root	OPERATION=AM Released Container	TARGET=SchedulerApp	RESULT=SUCCESS	APPID=application_1568623076950_0001	CONTAINERID=container_1568623076950_0001_01_000007
2019-09-16 06:06:24,217 INFO org.apache.hadoop.yarn.server.resourcemanager.scheduler.SchedulerNode: Released container container_1568623076950_0001_01_000007 of capacity <memory:1024, vCores:1> on host e9a6a0455f0d:38503, which currently has 4 containers, <memory:5120, vCores:4> used and <memory:3072, vCores:4> available, release resources=true
2019-09-16 06:06:24,217 INFO org.apache.hadoop.yarn.server.resourcemanager.scheduler.capacity.LeafQueue: default used=<memory:5120, vCores:4> numContainers=4 user=root user-resources=<memory:5120, vCores:4>
2019-09-16 06:06:24,225 INFO org.apache.hadoop.yarn.server.resourcemanager.scheduler.capacity.LeafQueue: completedContainer container=Container: [ContainerId: container_1568623076950_0001_01_000007, NodeId: e9a6a0455f0d:38503, NodeHttpAddress: e9a6a0455f0d:8042, Resource: <memory:1024, vCores:1>, Priority: 20, Token: Token { kind: ContainerToken, service: 172.24.0.2:38503 }, ] queue=default: capacity=1.0, absoluteCapacity=1.0, usedResources=<memory:5120, vCores:4>, usedCapacity=0.625, absoluteUsedCapacity=0.625, numApps=1, numContainers=4 cluster=<memory:8192, vCores:8>
2019-09-16 06:06:24,232 INFO org.apache.hadoop.yarn.server.resourcemanager.scheduler.capacity.ParentQueue: completedContainer queue=root usedCapacity=0.625 absoluteUsedCapacity=0.625 used=<memory:5120, vCores:4> cluster=<memory:8192, vCores:8>
2019-09-16 06:06:24,233 INFO org.apache.hadoop.yarn.server.resourcemanager.scheduler.capacity.ParentQueue: Re-sorting completed queue: root.default stats: default: capacity=1.0, absoluteCapacity=1.0, usedResources=<memory:5120, vCores:4>, usedCapacity=0.625, absoluteUsedCapacity=0.625, numApps=1, numContainers=4
2019-09-16 06:06:24,236 INFO org.apache.hadoop.yarn.server.resourcemanager.scheduler.capacity.CapacityScheduler: Application attempt appattempt_1568623076950_0001_000001 released container container_1568623076950_0001_01_000007 on node: host: e9a6a0455f0d:38503 #containers=4 available=<memory:3072, vCores:4> used=<memory:5120, vCores:4> with event: FINISHED
2019-09-16 06:06:24,260 INFO org.apache.hadoop.yarn.server.resourcemanager.rmcontainer.RMContainerImpl: container_1568623076950_0001_01_000006 Container Transitioned from RUNNING to COMPLETED
2019-09-16 06:06:24,260 INFO org.apache.hadoop.yarn.server.resourcemanager.scheduler.common.fica.FiCaSchedulerApp: Completed container: container_1568623076950_0001_01_000006 in state: COMPLETED event:FINISHED
2019-09-16 06:06:24,261 INFO org.apache.hadoop.yarn.server.resourcemanager.RMAuditLogger: USER=root	OPERATION=AM Released Container	TARGET=SchedulerApp	RESULT=SUCCESS	APPID=application_1568623076950_0001	CONTAINERID=container_1568623076950_0001_01_000006
2019-09-16 06:06:24,270 INFO org.apache.hadoop.yarn.server.resourcemanager.scheduler.SchedulerNode: Released container container_1568623076950_0001_01_000006 of capacity <memory:1024, vCores:1> on host e9a6a0455f0d:38503, which currently has 3 containers, <memory:4096, vCores:3> used and <memory:4096, vCores:5> available, release resources=true
2019-09-16 06:06:24,270 INFO org.apache.hadoop.yarn.server.resourcemanager.scheduler.capacity.LeafQueue: default used=<memory:4096, vCores:3> numContainers=3 user=root user-resources=<memory:4096, vCores:3>
2019-09-16 06:06:24,275 INFO org.apache.hadoop.yarn.server.resourcemanager.scheduler.capacity.LeafQueue: completedContainer container=Container: [ContainerId: container_1568623076950_0001_01_000006, NodeId: e9a6a0455f0d:38503, NodeHttpAddress: e9a6a0455f0d:8042, Resource: <memory:1024, vCores:1>, Priority: 20, Token: Token { kind: ContainerToken, service: 172.24.0.2:38503 }, ] queue=default: capacity=1.0, absoluteCapacity=1.0, usedResources=<memory:4096, vCores:3>, usedCapacity=0.5, absoluteUsedCapacity=0.5, numApps=1, numContainers=3 cluster=<memory:8192, vCores:8>
2019-09-16 06:06:24,277 INFO org.apache.hadoop.yarn.server.resourcemanager.scheduler.capacity.ParentQueue: completedContainer queue=root usedCapacity=0.5 absoluteUsedCapacity=0.5 used=<memory:4096, vCores:3> cluster=<memory:8192, vCores:8>
2019-09-16 06:06:24,277 INFO org.apache.hadoop.yarn.server.resourcemanager.scheduler.capacity.ParentQueue: Re-sorting completed queue: root.default stats: default: capacity=1.0, absoluteCapacity=1.0, usedResources=<memory:4096, vCores:3>, usedCapacity=0.5, absoluteUsedCapacity=0.5, numApps=1, numContainers=3
2019-09-16 06:06:24,284 INFO org.apache.hadoop.yarn.server.resourcemanager.scheduler.capacity.CapacityScheduler: Application attempt appattempt_1568623076950_0001_000001 released container container_1568623076950_0001_01_000006 on node: host: e9a6a0455f0d:38503 #containers=3 available=<memory:4096, vCores:5> used=<memory:4096, vCores:3> with event: FINISHED
2019-09-16 06:06:24,291 INFO org.apache.hadoop.yarn.server.resourcemanager.rmcontainer.RMContainerImpl: container_1568623076950_0001_01_000003 Container Transitioned from RUNNING to COMPLETED
2019-09-16 06:06:24,292 INFO org.apache.hadoop.yarn.server.resourcemanager.scheduler.common.fica.FiCaSchedulerApp: Completed container: container_1568623076950_0001_01_000003 in state: COMPLETED event:FINISHED
2019-09-16 06:06:24,292 INFO org.apache.hadoop.yarn.server.resourcemanager.RMAuditLogger: USER=root	OPERATION=AM Released Container	TARGET=SchedulerApp	RESULT=SUCCESS	APPID=application_1568623076950_0001	CONTAINERID=container_1568623076950_0001_01_000003
2019-09-16 06:06:24,293 INFO org.apache.hadoop.yarn.server.resourcemanager.scheduler.SchedulerNode: Released container container_1568623076950_0001_01_000003 of capacity <memory:1024, vCores:1> on host e9a6a0455f0d:38503, which currently has 2 containers, <memory:3072, vCores:2> used and <memory:5120, vCores:6> available, release resources=true
2019-09-16 06:06:24,294 INFO org.apache.hadoop.yarn.server.resourcemanager.scheduler.capacity.LeafQueue: default used=<memory:3072, vCores:2> numContainers=2 user=root user-resources=<memory:3072, vCores:2>
2019-09-16 06:06:24,465 INFO org.apache.hadoop.yarn.server.resourcemanager.scheduler.capacity.LeafQueue: completedContainer container=Container: [ContainerId: container_1568623076950_0001_01_000003, NodeId: e9a6a0455f0d:38503, NodeHttpAddress: e9a6a0455f0d:8042, Resource: <memory:1024, vCores:1>, Priority: 20, Token: Token { kind: ContainerToken, service: 172.24.0.2:38503 }, ] queue=default: capacity=1.0, absoluteCapacity=1.0, usedResources=<memory:3072, vCores:2>, usedCapacity=0.375, absoluteUsedCapacity=0.375, numApps=1, numContainers=2 cluster=<memory:8192, vCores:8>
2019-09-16 06:06:24,505 INFO org.apache.hadoop.yarn.server.resourcemanager.scheduler.capacity.ParentQueue: completedContainer queue=root usedCapacity=0.375 absoluteUsedCapacity=0.375 used=<memory:3072, vCores:2> cluster=<memory:8192, vCores:8>
2019-09-16 06:06:24,516 INFO org.apache.hadoop.yarn.server.resourcemanager.scheduler.capacity.ParentQueue: Re-sorting completed queue: root.default stats: default: capacity=1.0, absoluteCapacity=1.0, usedResources=<memory:3072, vCores:2>, usedCapacity=0.375, absoluteUsedCapacity=0.375, numApps=1, numContainers=2
2019-09-16 06:06:24,531 INFO org.apache.hadoop.yarn.server.resourcemanager.scheduler.capacity.CapacityScheduler: Application attempt appattempt_1568623076950_0001_000001 released container container_1568623076950_0001_01_000003 on node: host: e9a6a0455f0d:38503 #containers=2 available=<memory:5120, vCores:6> used=<memory:3072, vCores:2> with event: FINISHED
2019-09-16 06:06:24,534 INFO org.apache.hadoop.yarn.server.resourcemanager.rmcontainer.RMContainerImpl: container_1568623076950_0001_01_000002 Container Transitioned from RUNNING to COMPLETED
2019-09-16 06:06:24,613 INFO org.apache.hadoop.yarn.server.resourcemanager.scheduler.common.fica.FiCaSchedulerApp: Completed container: container_1568623076950_0001_01_000002 in state: COMPLETED event:FINISHED
2019-09-16 06:06:24,688 INFO org.apache.hadoop.yarn.server.resourcemanager.RMAuditLogger: USER=root	OPERATION=AM Released Container	TARGET=SchedulerApp	RESULT=SUCCESS	APPID=application_1568623076950_0001	CONTAINERID=container_1568623076950_0001_01_000002
2019-09-16 06:06:24,695 INFO org.apache.hadoop.yarn.server.resourcemanager.scheduler.SchedulerNode: Released container container_1568623076950_0001_01_000002 of capacity <memory:1024, vCores:1> on host e9a6a0455f0d:38503, which currently has 1 containers, <memory:2048, vCores:1> used and <memory:6144, vCores:7> available, release resources=true
2019-09-16 06:06:24,698 INFO org.apache.hadoop.yarn.server.resourcemanager.scheduler.capacity.LeafQueue: default used=<memory:2048, vCores:1> numContainers=1 user=root user-resources=<memory:2048, vCores:1>
2019-09-16 06:06:24,714 INFO org.apache.hadoop.yarn.server.resourcemanager.scheduler.capacity.LeafQueue: completedContainer container=Container: [ContainerId: container_1568623076950_0001_01_000002, NodeId: e9a6a0455f0d:38503, NodeHttpAddress: e9a6a0455f0d:8042, Resource: <memory:1024, vCores:1>, Priority: 20, Token: Token { kind: ContainerToken, service: 172.24.0.2:38503 }, ] queue=default: capacity=1.0, absoluteCapacity=1.0, usedResources=<memory:2048, vCores:1>, usedCapacity=0.25, absoluteUsedCapacity=0.25, numApps=1, numContainers=1 cluster=<memory:8192, vCores:8>
2019-09-16 06:06:24,714 INFO org.apache.hadoop.yarn.server.resourcemanager.scheduler.capacity.ParentQueue: completedContainer queue=root usedCapacity=0.25 absoluteUsedCapacity=0.25 used=<memory:2048, vCores:1> cluster=<memory:8192, vCores:8>
2019-09-16 06:06:24,716 INFO org.apache.hadoop.yarn.server.resourcemanager.scheduler.capacity.ParentQueue: Re-sorting completed queue: root.default stats: default: capacity=1.0, absoluteCapacity=1.0, usedResources=<memory:2048, vCores:1>, usedCapacity=0.25, absoluteUsedCapacity=0.25, numApps=1, numContainers=1
2019-09-16 06:06:24,717 INFO org.apache.hadoop.yarn.server.resourcemanager.scheduler.capacity.CapacityScheduler: Application attempt appattempt_1568623076950_0001_000001 released container container_1568623076950_0001_01_000002 on node: host: e9a6a0455f0d:38503 #containers=1 available=<memory:6144, vCores:7> used=<memory:2048, vCores:1> with event: FINISHED
2019-09-16 06:06:24,718 INFO org.apache.hadoop.yarn.server.resourcemanager.rmcontainer.RMContainerImpl: container_1568623076950_0001_01_000008 Container Transitioned from NEW to ALLOCATED
2019-09-16 06:06:24,719 INFO org.apache.hadoop.yarn.server.resourcemanager.RMAuditLogger: USER=root	OPERATION=AM Allocated Container	TARGET=SchedulerApp	RESULT=SUCCESS	APPID=application_1568623076950_0001	CONTAINERID=container_1568623076950_0001_01_000008
2019-09-16 06:06:24,719 INFO org.apache.hadoop.yarn.server.resourcemanager.scheduler.SchedulerNode: Assigned container container_1568623076950_0001_01_000008 of capacity <memory:1024, vCores:1> on host e9a6a0455f0d:38503, which has 2 containers, <memory:3072, vCores:2> used and <memory:5120, vCores:6> available after allocation
2019-09-16 06:06:24,720 INFO org.apache.hadoop.yarn.server.resourcemanager.scheduler.capacity.LeafQueue: assignedContainer application attempt=appattempt_1568623076950_0001_000001 container=Container: [ContainerId: container_1568623076950_0001_01_000008, NodeId: e9a6a0455f0d:38503, NodeHttpAddress: e9a6a0455f0d:8042, Resource: <memory:1024, vCores:1>, Priority: 10, Token: null, ] queue=default: capacity=1.0, absoluteCapacity=1.0, usedResources=<memory:2048, vCores:1>, usedCapacity=0.25, absoluteUsedCapacity=0.25, numApps=1, numContainers=1 clusterResource=<memory:8192, vCores:8>
2019-09-16 06:06:24,721 INFO org.apache.hadoop.yarn.server.resourcemanager.scheduler.capacity.ParentQueue: Re-sorting assigned queue: root.default stats: default: capacity=1.0, absoluteCapacity=1.0, usedResources=<memory:3072, vCores:2>, usedCapacity=0.375, absoluteUsedCapacity=0.375, numApps=1, numContainers=2
2019-09-16 06:06:24,725 INFO org.apache.hadoop.yarn.server.resourcemanager.scheduler.capacity.ParentQueue: assignedContainer queue=root usedCapacity=0.375 absoluteUsedCapacity=0.375 used=<memory:3072, vCores:2> cluster=<memory:8192, vCores:8>
2019-09-16 06:06:24,984 INFO org.apache.hadoop.yarn.server.resourcemanager.rmcontainer.RMContainerImpl: container_1568623076950_0001_01_000009 Container Transitioned from NEW to ALLOCATED
2019-09-16 06:06:24,999 INFO org.apache.hadoop.yarn.server.resourcemanager.RMAuditLogger: USER=root	OPERATION=AM Allocated Container	TARGET=SchedulerApp	RESULT=SUCCESS	APPID=application_1568623076950_0001	CONTAINERID=container_1568623076950_0001_01_000009
2019-09-16 06:06:25,253 INFO org.apache.hadoop.yarn.server.resourcemanager.scheduler.SchedulerNode: Assigned container container_1568623076950_0001_01_000009 of capacity <memory:1024, vCores:1> on host e9a6a0455f0d:38503, which has 3 containers, <memory:4096, vCores:3> used and <memory:4096, vCores:5> available after allocation
2019-09-16 06:06:25,339 INFO org.apache.hadoop.yarn.server.resourcemanager.scheduler.capacity.LeafQueue: assignedContainer application attempt=appattempt_1568623076950_0001_000001 container=Container: [ContainerId: container_1568623076950_0001_01_000009, NodeId: e9a6a0455f0d:38503, NodeHttpAddress: e9a6a0455f0d:8042, Resource: <memory:1024, vCores:1>, Priority: 20, Token: null, ] queue=default: capacity=1.0, absoluteCapacity=1.0, usedResources=<memory:3072, vCores:2>, usedCapacity=0.375, absoluteUsedCapacity=0.375, numApps=1, numContainers=2 clusterResource=<memory:8192, vCores:8>
2019-09-16 06:06:25,358 INFO org.apache.hadoop.yarn.server.resourcemanager.scheduler.capacity.ParentQueue: Re-sorting assigned queue: root.default stats: default: capacity=1.0, absoluteCapacity=1.0, usedResources=<memory:4096, vCores:3>, usedCapacity=0.5, absoluteUsedCapacity=0.5, numApps=1, numContainers=3
2019-09-16 06:06:25,450 INFO org.apache.hadoop.yarn.server.resourcemanager.scheduler.capacity.ParentQueue: assignedContainer queue=root usedCapacity=0.5 absoluteUsedCapacity=0.5 used=<memory:4096, vCores:3> cluster=<memory:8192, vCores:8>
2019-09-16 06:06:25,657 INFO org.apache.hadoop.yarn.server.resourcemanager.rmcontainer.RMContainerImpl: container_1568623076950_0001_01_000010 Container Transitioned from NEW to ALLOCATED
2019-09-16 06:06:25,657 INFO org.apache.hadoop.yarn.server.resourcemanager.RMAuditLogger: USER=root	OPERATION=AM Allocated Container	TARGET=SchedulerApp	RESULT=SUCCESS	APPID=application_1568623076950_0001	CONTAINERID=container_1568623076950_0001_01_000010
2019-09-16 06:06:25,657 INFO org.apache.hadoop.yarn.server.resourcemanager.scheduler.SchedulerNode: Assigned container container_1568623076950_0001_01_000010 of capacity <memory:1024, vCores:1> on host e9a6a0455f0d:38503, which has 4 containers, <memory:5120, vCores:4> used and <memory:3072, vCores:4> available after allocation
2019-09-16 06:06:25,670 INFO org.apache.hadoop.yarn.server.resourcemanager.scheduler.capacity.LeafQueue: assignedContainer application attempt=appattempt_1568623076950_0001_000001 container=Container: [ContainerId: container_1568623076950_0001_01_000010, NodeId: e9a6a0455f0d:38503, NodeHttpAddress: e9a6a0455f0d:8042, Resource: <memory:1024, vCores:1>, Priority: 20, Token: null, ] queue=default: capacity=1.0, absoluteCapacity=1.0, usedResources=<memory:4096, vCores:3>, usedCapacity=0.5, absoluteUsedCapacity=0.5, numApps=1, numContainers=3 clusterResource=<memory:8192, vCores:8>
2019-09-16 06:06:25,690 INFO org.apache.hadoop.yarn.server.resourcemanager.scheduler.capacity.ParentQueue: Re-sorting assigned queue: root.default stats: default: capacity=1.0, absoluteCapacity=1.0, usedResources=<memory:5120, vCores:4>, usedCapacity=0.625, absoluteUsedCapacity=0.625, numApps=1, numContainers=4
2019-09-16 06:06:25,697 INFO org.apache.hadoop.yarn.server.resourcemanager.scheduler.capacity.ParentQueue: assignedContainer queue=root usedCapacity=0.625 absoluteUsedCapacity=0.625 used=<memory:5120, vCores:4> cluster=<memory:8192, vCores:8>
2019-09-16 06:06:26,732 INFO org.apache.hadoop.yarn.server.resourcemanager.rmcontainer.RMContainerImpl: container_1568623076950_0001_01_000008 Container Transitioned from ALLOCATED to ACQUIRED
2019-09-16 06:06:26,761 INFO org.apache.hadoop.yarn.server.resourcemanager.rmcontainer.RMContainerImpl: container_1568623076950_0001_01_000009 Container Transitioned from ALLOCATED to ACQUIRED
2019-09-16 06:06:26,801 INFO org.apache.hadoop.yarn.server.resourcemanager.rmcontainer.RMContainerImpl: container_1568623076950_0001_01_000010 Container Transitioned from ALLOCATED to ACQUIRED
2019-09-16 06:06:26,802 INFO org.apache.hadoop.yarn.server.resourcemanager.rmcontainer.RMContainerImpl: container_1568623076950_0001_01_000011 Container Transitioned from NEW to ALLOCATED
2019-09-16 06:06:26,802 INFO org.apache.hadoop.yarn.server.resourcemanager.RMAuditLogger: USER=root	OPERATION=AM Allocated Container	TARGET=SchedulerApp	RESULT=SUCCESS	APPID=application_1568623076950_0001	CONTAINERID=container_1568623076950_0001_01_000011
2019-09-16 06:06:26,804 INFO org.apache.hadoop.yarn.server.resourcemanager.scheduler.SchedulerNode: Assigned container container_1568623076950_0001_01_000011 of capacity <memory:1024, vCores:1> on host e9a6a0455f0d:38503, which has 5 containers, <memory:6144, vCores:5> used and <memory:2048, vCores:3> available after allocation
2019-09-16 06:06:26,826 INFO org.apache.hadoop.yarn.server.resourcemanager.scheduler.capacity.LeafQueue: assignedContainer application attempt=appattempt_1568623076950_0001_000001 container=Container: [ContainerId: container_1568623076950_0001_01_000011, NodeId: e9a6a0455f0d:38503, NodeHttpAddress: e9a6a0455f0d:8042, Resource: <memory:1024, vCores:1>, Priority: 20, Token: null, ] queue=default: capacity=1.0, absoluteCapacity=1.0, usedResources=<memory:5120, vCores:4>, usedCapacity=0.625, absoluteUsedCapacity=0.625, numApps=1, numContainers=4 clusterResource=<memory:8192, vCores:8>
2019-09-16 06:06:26,851 INFO org.apache.hadoop.yarn.server.resourcemanager.scheduler.capacity.ParentQueue: Re-sorting assigned queue: root.default stats: default: capacity=1.0, absoluteCapacity=1.0, usedResources=<memory:6144, vCores:5>, usedCapacity=0.75, absoluteUsedCapacity=0.75, numApps=1, numContainers=5
2019-09-16 06:06:26,852 INFO org.apache.hadoop.yarn.server.resourcemanager.scheduler.capacity.ParentQueue: assignedContainer queue=root usedCapacity=0.75 absoluteUsedCapacity=0.75 used=<memory:6144, vCores:5> cluster=<memory:8192, vCores:8>
2019-09-16 06:06:26,860 INFO org.apache.hadoop.yarn.server.resourcemanager.rmcontainer.RMContainerImpl: container_1568623076950_0001_01_000012 Container Transitioned from NEW to ALLOCATED
2019-09-16 06:06:26,880 INFO org.apache.hadoop.yarn.server.resourcemanager.RMAuditLogger: USER=root	OPERATION=AM Allocated Container	TARGET=SchedulerApp	RESULT=SUCCESS	APPID=application_1568623076950_0001	CONTAINERID=container_1568623076950_0001_01_000012
2019-09-16 06:06:26,892 INFO org.apache.hadoop.yarn.server.resourcemanager.scheduler.SchedulerNode: Assigned container container_1568623076950_0001_01_000012 of capacity <memory:1024, vCores:1> on host e9a6a0455f0d:38503, which has 6 containers, <memory:7168, vCores:6> used and <memory:1024, vCores:2> available after allocation
2019-09-16 06:06:26,912 INFO org.apache.hadoop.yarn.server.resourcemanager.scheduler.capacity.LeafQueue: assignedContainer application attempt=appattempt_1568623076950_0001_000001 container=Container: [ContainerId: container_1568623076950_0001_01_000012, NodeId: e9a6a0455f0d:38503, NodeHttpAddress: e9a6a0455f0d:8042, Resource: <memory:1024, vCores:1>, Priority: 20, Token: null, ] queue=default: capacity=1.0, absoluteCapacity=1.0, usedResources=<memory:6144, vCores:5>, usedCapacity=0.75, absoluteUsedCapacity=0.75, numApps=1, numContainers=5 clusterResource=<memory:8192, vCores:8>
2019-09-16 06:06:26,941 INFO org.apache.hadoop.yarn.server.resourcemanager.scheduler.capacity.ParentQueue: Re-sorting assigned queue: root.default stats: default: capacity=1.0, absoluteCapacity=1.0, usedResources=<memory:7168, vCores:6>, usedCapacity=0.875, absoluteUsedCapacity=0.875, numApps=1, numContainers=6
2019-09-16 06:06:26,942 INFO org.apache.hadoop.yarn.server.resourcemanager.scheduler.capacity.ParentQueue: assignedContainer queue=root usedCapacity=0.875 absoluteUsedCapacity=0.875 used=<memory:7168, vCores:6> cluster=<memory:8192, vCores:8>
2019-09-16 06:06:26,965 INFO org.apache.hadoop.yarn.server.resourcemanager.rmcontainer.RMContainerImpl: container_1568623076950_0001_01_000013 Container Transitioned from NEW to ALLOCATED
2019-09-16 06:06:26,965 INFO org.apache.hadoop.yarn.server.resourcemanager.RMAuditLogger: USER=root	OPERATION=AM Allocated Container	TARGET=SchedulerApp	RESULT=SUCCESS	APPID=application_1568623076950_0001	CONTAINERID=container_1568623076950_0001_01_000013
2019-09-16 06:06:26,966 INFO org.apache.hadoop.yarn.server.resourcemanager.scheduler.SchedulerNode: Assigned container container_1568623076950_0001_01_000013 of capacity <memory:1024, vCores:1> on host e9a6a0455f0d:38503, which has 7 containers, <memory:8192, vCores:7> used and <memory:0, vCores:1> available after allocation
2019-09-16 06:06:26,967 INFO org.apache.hadoop.yarn.server.resourcemanager.scheduler.capacity.LeafQueue: assignedContainer application attempt=appattempt_1568623076950_0001_000001 container=Container: [ContainerId: container_1568623076950_0001_01_000013, NodeId: e9a6a0455f0d:38503, NodeHttpAddress: e9a6a0455f0d:8042, Resource: <memory:1024, vCores:1>, Priority: 20, Token: null, ] queue=default: capacity=1.0, absoluteCapacity=1.0, usedResources=<memory:7168, vCores:6>, usedCapacity=0.875, absoluteUsedCapacity=0.875, numApps=1, numContainers=6 clusterResource=<memory:8192, vCores:8>
2019-09-16 06:06:26,987 INFO org.apache.hadoop.yarn.server.resourcemanager.scheduler.capacity.ParentQueue: Re-sorting assigned queue: root.default stats: default: capacity=1.0, absoluteCapacity=1.0, usedResources=<memory:8192, vCores:7>, usedCapacity=1.0, absoluteUsedCapacity=1.0, numApps=1, numContainers=7
2019-09-16 06:06:26,987 INFO org.apache.hadoop.yarn.server.resourcemanager.scheduler.capacity.ParentQueue: assignedContainer queue=root usedCapacity=1.0 absoluteUsedCapacity=1.0 used=<memory:8192, vCores:7> cluster=<memory:8192, vCores:8>
2019-09-16 06:06:28,074 INFO org.apache.hadoop.yarn.server.resourcemanager.scheduler.AppSchedulingInfo: checking for deactivate of application :application_1568623076950_0001
2019-09-16 06:06:28,130 INFO org.apache.hadoop.yarn.server.resourcemanager.rmcontainer.RMContainerImpl: container_1568623076950_0001_01_000011 Container Transitioned from ALLOCATED to ACQUIRED
2019-09-16 06:06:28,179 INFO org.apache.hadoop.yarn.server.resourcemanager.rmcontainer.RMContainerImpl: container_1568623076950_0001_01_000012 Container Transitioned from ALLOCATED to ACQUIRED
2019-09-16 06:06:28,208 INFO org.apache.hadoop.yarn.server.resourcemanager.rmcontainer.RMContainerImpl: container_1568623076950_0001_01_000013 Container Transitioned from ALLOCATED to ACQUIRED
2019-09-16 06:06:28,211 INFO org.apache.hadoop.yarn.server.resourcemanager.rmcontainer.RMContainerImpl: container_1568623076950_0001_01_000008 Container Transitioned from ACQUIRED to RUNNING
2019-09-16 06:06:28,213 INFO org.apache.hadoop.yarn.server.resourcemanager.rmcontainer.RMContainerImpl: container_1568623076950_0001_01_000009 Container Transitioned from ACQUIRED to RUNNING
2019-09-16 06:06:28,213 INFO org.apache.hadoop.yarn.server.resourcemanager.rmcontainer.RMContainerImpl: container_1568623076950_0001_01_000010 Container Transitioned from ACQUIRED to RUNNING
2019-09-16 06:06:29,212 INFO org.apache.hadoop.yarn.server.resourcemanager.rmcontainer.RMContainerImpl: container_1568623076950_0001_01_000011 Container Transitioned from ACQUIRED to RUNNING
2019-09-16 06:06:29,213 INFO org.apache.hadoop.yarn.server.resourcemanager.rmcontainer.RMContainerImpl: container_1568623076950_0001_01_000012 Container Transitioned from ACQUIRED to RUNNING
2019-09-16 06:06:29,213 INFO org.apache.hadoop.yarn.server.resourcemanager.rmcontainer.RMContainerImpl: container_1568623076950_0001_01_000013 Container Transitioned from ACQUIRED to RUNNING
2019-09-16 06:06:43,660 INFO org.apache.hadoop.yarn.server.resourcemanager.rmcontainer.RMContainerImpl: container_1568623076950_0001_01_000010 Container Transitioned from RUNNING to COMPLETED
2019-09-16 06:06:43,669 INFO org.apache.hadoop.yarn.server.resourcemanager.scheduler.common.fica.FiCaSchedulerApp: Completed container: container_1568623076950_0001_01_000010 in state: COMPLETED event:FINISHED
2019-09-16 06:06:43,669 INFO org.apache.hadoop.yarn.server.resourcemanager.RMAuditLogger: USER=root	OPERATION=AM Released Container	TARGET=SchedulerApp	RESULT=SUCCESS	APPID=application_1568623076950_0001	CONTAINERID=container_1568623076950_0001_01_000010
2019-09-16 06:06:43,670 INFO org.apache.hadoop.yarn.server.resourcemanager.scheduler.SchedulerNode: Released container container_1568623076950_0001_01_000010 of capacity <memory:1024, vCores:1> on host e9a6a0455f0d:38503, which currently has 6 containers, <memory:7168, vCores:6> used and <memory:1024, vCores:2> available, release resources=true
2019-09-16 06:06:43,670 INFO org.apache.hadoop.yarn.server.resourcemanager.scheduler.capacity.LeafQueue: default used=<memory:7168, vCores:6> numContainers=6 user=root user-resources=<memory:7168, vCores:6>
2019-09-16 06:06:43,671 INFO org.apache.hadoop.yarn.server.resourcemanager.scheduler.capacity.LeafQueue: completedContainer container=Container: [ContainerId: container_1568623076950_0001_01_000010, NodeId: e9a6a0455f0d:38503, NodeHttpAddress: e9a6a0455f0d:8042, Resource: <memory:1024, vCores:1>, Priority: 20, Token: Token { kind: ContainerToken, service: 172.24.0.2:38503 }, ] queue=default: capacity=1.0, absoluteCapacity=1.0, usedResources=<memory:7168, vCores:6>, usedCapacity=0.875, absoluteUsedCapacity=0.875, numApps=1, numContainers=6 cluster=<memory:8192, vCores:8>
2019-09-16 06:06:43,671 INFO org.apache.hadoop.yarn.server.resourcemanager.scheduler.capacity.ParentQueue: completedContainer queue=root usedCapacity=0.875 absoluteUsedCapacity=0.875 used=<memory:7168, vCores:6> cluster=<memory:8192, vCores:8>
2019-09-16 06:06:43,672 INFO org.apache.hadoop.yarn.server.resourcemanager.scheduler.capacity.ParentQueue: Re-sorting completed queue: root.default stats: default: capacity=1.0, absoluteCapacity=1.0, usedResources=<memory:7168, vCores:6>, usedCapacity=0.875, absoluteUsedCapacity=0.875, numApps=1, numContainers=6
2019-09-16 06:06:43,672 INFO org.apache.hadoop.yarn.server.resourcemanager.scheduler.capacity.CapacityScheduler: Application attempt appattempt_1568623076950_0001_000001 released container container_1568623076950_0001_01_000010 on node: host: e9a6a0455f0d:38503 #containers=6 available=<memory:1024, vCores:2> used=<memory:7168, vCores:6> with event: FINISHED
2019-09-16 06:06:43,673 INFO org.apache.hadoop.yarn.server.resourcemanager.rmcontainer.RMContainerImpl: container_1568623076950_0001_01_000009 Container Transitioned from RUNNING to COMPLETED
2019-09-16 06:06:43,674 INFO org.apache.hadoop.yarn.server.resourcemanager.scheduler.common.fica.FiCaSchedulerApp: Completed container: container_1568623076950_0001_01_000009 in state: COMPLETED event:FINISHED
2019-09-16 06:06:43,674 INFO org.apache.hadoop.yarn.server.resourcemanager.RMAuditLogger: USER=root	OPERATION=AM Released Container	TARGET=SchedulerApp	RESULT=SUCCESS	APPID=application_1568623076950_0001	CONTAINERID=container_1568623076950_0001_01_000009
2019-09-16 06:06:43,674 INFO org.apache.hadoop.yarn.server.resourcemanager.scheduler.SchedulerNode: Released container container_1568623076950_0001_01_000009 of capacity <memory:1024, vCores:1> on host e9a6a0455f0d:38503, which currently has 5 containers, <memory:6144, vCores:5> used and <memory:2048, vCores:3> available, release resources=true
2019-09-16 06:06:43,675 INFO org.apache.hadoop.yarn.server.resourcemanager.scheduler.capacity.LeafQueue: default used=<memory:6144, vCores:5> numContainers=5 user=root user-resources=<memory:6144, vCores:5>
2019-09-16 06:06:43,675 INFO org.apache.hadoop.yarn.server.resourcemanager.scheduler.capacity.LeafQueue: completedContainer container=Container: [ContainerId: container_1568623076950_0001_01_000009, NodeId: e9a6a0455f0d:38503, NodeHttpAddress: e9a6a0455f0d:8042, Resource: <memory:1024, vCores:1>, Priority: 20, Token: Token { kind: ContainerToken, service: 172.24.0.2:38503 }, ] queue=default: capacity=1.0, absoluteCapacity=1.0, usedResources=<memory:6144, vCores:5>, usedCapacity=0.75, absoluteUsedCapacity=0.75, numApps=1, numContainers=5 cluster=<memory:8192, vCores:8>
2019-09-16 06:06:43,675 INFO org.apache.hadoop.yarn.server.resourcemanager.scheduler.capacity.ParentQueue: completedContainer queue=root usedCapacity=0.75 absoluteUsedCapacity=0.75 used=<memory:6144, vCores:5> cluster=<memory:8192, vCores:8>
2019-09-16 06:06:43,676 INFO org.apache.hadoop.yarn.server.resourcemanager.scheduler.capacity.ParentQueue: Re-sorting completed queue: root.default stats: default: capacity=1.0, absoluteCapacity=1.0, usedResources=<memory:6144, vCores:5>, usedCapacity=0.75, absoluteUsedCapacity=0.75, numApps=1, numContainers=5
2019-09-16 06:06:43,676 INFO org.apache.hadoop.yarn.server.resourcemanager.scheduler.capacity.CapacityScheduler: Application attempt appattempt_1568623076950_0001_000001 released container container_1568623076950_0001_01_000009 on node: host: e9a6a0455f0d:38503 #containers=5 available=<memory:2048, vCores:3> used=<memory:6144, vCores:5> with event: FINISHED
2019-09-16 06:06:43,676 INFO org.apache.hadoop.yarn.server.resourcemanager.rmcontainer.RMContainerImpl: container_1568623076950_0001_01_000011 Container Transitioned from RUNNING to COMPLETED
2019-09-16 06:06:43,676 INFO org.apache.hadoop.yarn.server.resourcemanager.scheduler.common.fica.FiCaSchedulerApp: Completed container: container_1568623076950_0001_01_000011 in state: COMPLETED event:FINISHED
2019-09-16 06:06:43,677 INFO org.apache.hadoop.yarn.server.resourcemanager.RMAuditLogger: USER=root	OPERATION=AM Released Container	TARGET=SchedulerApp	RESULT=SUCCESS	APPID=application_1568623076950_0001	CONTAINERID=container_1568623076950_0001_01_000011
2019-09-16 06:06:43,677 INFO org.apache.hadoop.yarn.server.resourcemanager.scheduler.SchedulerNode: Released container container_1568623076950_0001_01_000011 of capacity <memory:1024, vCores:1> on host e9a6a0455f0d:38503, which currently has 4 containers, <memory:5120, vCores:4> used and <memory:3072, vCores:4> available, release resources=true
2019-09-16 06:06:43,677 INFO org.apache.hadoop.yarn.server.resourcemanager.scheduler.capacity.LeafQueue: default used=<memory:5120, vCores:4> numContainers=4 user=root user-resources=<memory:5120, vCores:4>
2019-09-16 06:06:43,678 INFO org.apache.hadoop.yarn.server.resourcemanager.scheduler.capacity.LeafQueue: completedContainer container=Container: [ContainerId: container_1568623076950_0001_01_000011, NodeId: e9a6a0455f0d:38503, NodeHttpAddress: e9a6a0455f0d:8042, Resource: <memory:1024, vCores:1>, Priority: 20, Token: Token { kind: ContainerToken, service: 172.24.0.2:38503 }, ] queue=default: capacity=1.0, absoluteCapacity=1.0, usedResources=<memory:5120, vCores:4>, usedCapacity=0.625, absoluteUsedCapacity=0.625, numApps=1, numContainers=4 cluster=<memory:8192, vCores:8>
2019-09-16 06:06:43,678 INFO org.apache.hadoop.yarn.server.resourcemanager.scheduler.capacity.ParentQueue: completedContainer queue=root usedCapacity=0.625 absoluteUsedCapacity=0.625 used=<memory:5120, vCores:4> cluster=<memory:8192, vCores:8>
2019-09-16 06:06:43,678 INFO org.apache.hadoop.yarn.server.resourcemanager.scheduler.capacity.ParentQueue: Re-sorting completed queue: root.default stats: default: capacity=1.0, absoluteCapacity=1.0, usedResources=<memory:5120, vCores:4>, usedCapacity=0.625, absoluteUsedCapacity=0.625, numApps=1, numContainers=4
2019-09-16 06:06:43,678 INFO org.apache.hadoop.yarn.server.resourcemanager.scheduler.capacity.CapacityScheduler: Application attempt appattempt_1568623076950_0001_000001 released container container_1568623076950_0001_01_000011 on node: host: e9a6a0455f0d:38503 #containers=4 available=<memory:3072, vCores:4> used=<memory:5120, vCores:4> with event: FINISHED
2019-09-16 06:06:43,679 INFO org.apache.hadoop.yarn.server.resourcemanager.rmcontainer.RMContainerImpl: container_1568623076950_0001_01_000013 Container Transitioned from RUNNING to COMPLETED
2019-09-16 06:06:43,679 INFO org.apache.hadoop.yarn.server.resourcemanager.scheduler.common.fica.FiCaSchedulerApp: Completed container: container_1568623076950_0001_01_000013 in state: COMPLETED event:FINISHED
2019-09-16 06:06:43,679 INFO org.apache.hadoop.yarn.server.resourcemanager.RMAuditLogger: USER=root	OPERATION=AM Released Container	TARGET=SchedulerApp	RESULT=SUCCESS	APPID=application_1568623076950_0001	CONTAINERID=container_1568623076950_0001_01_000013
2019-09-16 06:06:43,679 INFO org.apache.hadoop.yarn.server.resourcemanager.scheduler.SchedulerNode: Released container container_1568623076950_0001_01_000013 of capacity <memory:1024, vCores:1> on host e9a6a0455f0d:38503, which currently has 3 containers, <memory:4096, vCores:3> used and <memory:4096, vCores:5> available, release resources=true
2019-09-16 06:06:43,679 INFO org.apache.hadoop.yarn.server.resourcemanager.scheduler.capacity.LeafQueue: default used=<memory:4096, vCores:3> numContainers=3 user=root user-resources=<memory:4096, vCores:3>
2019-09-16 06:06:43,680 INFO org.apache.hadoop.yarn.server.resourcemanager.scheduler.capacity.LeafQueue: completedContainer container=Container: [ContainerId: container_1568623076950_0001_01_000013, NodeId: e9a6a0455f0d:38503, NodeHttpAddress: e9a6a0455f0d:8042, Resource: <memory:1024, vCores:1>, Priority: 20, Token: Token { kind: ContainerToken, service: 172.24.0.2:38503 }, ] queue=default: capacity=1.0, absoluteCapacity=1.0, usedResources=<memory:4096, vCores:3>, usedCapacity=0.5, absoluteUsedCapacity=0.5, numApps=1, numContainers=3 cluster=<memory:8192, vCores:8>
2019-09-16 06:06:43,680 INFO org.apache.hadoop.yarn.server.resourcemanager.scheduler.capacity.ParentQueue: completedContainer queue=root usedCapacity=0.5 absoluteUsedCapacity=0.5 used=<memory:4096, vCores:3> cluster=<memory:8192, vCores:8>
2019-09-16 06:06:43,680 INFO org.apache.hadoop.yarn.server.resourcemanager.scheduler.capacity.ParentQueue: Re-sorting completed queue: root.default stats: default: capacity=1.0, absoluteCapacity=1.0, usedResources=<memory:4096, vCores:3>, usedCapacity=0.5, absoluteUsedCapacity=0.5, numApps=1, numContainers=3
2019-09-16 06:06:43,681 INFO org.apache.hadoop.yarn.server.resourcemanager.scheduler.capacity.CapacityScheduler: Application attempt appattempt_1568623076950_0001_000001 released container container_1568623076950_0001_01_000013 on node: host: e9a6a0455f0d:38503 #containers=3 available=<memory:4096, vCores:5> used=<memory:4096, vCores:3> with event: FINISHED
2019-09-16 06:06:43,681 INFO org.apache.hadoop.yarn.server.resourcemanager.rmcontainer.RMContainerImpl: container_1568623076950_0001_01_000012 Container Transitioned from RUNNING to COMPLETED
2019-09-16 06:06:43,681 INFO org.apache.hadoop.yarn.server.resourcemanager.scheduler.common.fica.FiCaSchedulerApp: Completed container: container_1568623076950_0001_01_000012 in state: COMPLETED event:FINISHED
2019-09-16 06:06:43,681 INFO org.apache.hadoop.yarn.server.resourcemanager.RMAuditLogger: USER=root	OPERATION=AM Released Container	TARGET=SchedulerApp	RESULT=SUCCESS	APPID=application_1568623076950_0001	CONTAINERID=container_1568623076950_0001_01_000012
2019-09-16 06:06:43,682 INFO org.apache.hadoop.yarn.server.resourcemanager.scheduler.SchedulerNode: Released container container_1568623076950_0001_01_000012 of capacity <memory:1024, vCores:1> on host e9a6a0455f0d:38503, which currently has 2 containers, <memory:3072, vCores:2> used and <memory:5120, vCores:6> available, release resources=true
2019-09-16 06:06:43,682 INFO org.apache.hadoop.yarn.server.resourcemanager.scheduler.capacity.LeafQueue: default used=<memory:3072, vCores:2> numContainers=2 user=root user-resources=<memory:3072, vCores:2>
2019-09-16 06:06:43,682 INFO org.apache.hadoop.yarn.server.resourcemanager.scheduler.capacity.LeafQueue: completedContainer container=Container: [ContainerId: container_1568623076950_0001_01_000012, NodeId: e9a6a0455f0d:38503, NodeHttpAddress: e9a6a0455f0d:8042, Resource: <memory:1024, vCores:1>, Priority: 20, Token: Token { kind: ContainerToken, service: 172.24.0.2:38503 }, ] queue=default: capacity=1.0, absoluteCapacity=1.0, usedResources=<memory:3072, vCores:2>, usedCapacity=0.375, absoluteUsedCapacity=0.375, numApps=1, numContainers=2 cluster=<memory:8192, vCores:8>
2019-09-16 06:06:43,683 INFO org.apache.hadoop.yarn.server.resourcemanager.scheduler.capacity.ParentQueue: completedContainer queue=root usedCapacity=0.375 absoluteUsedCapacity=0.375 used=<memory:3072, vCores:2> cluster=<memory:8192, vCores:8>
2019-09-16 06:06:43,683 INFO org.apache.hadoop.yarn.server.resourcemanager.scheduler.capacity.ParentQueue: Re-sorting completed queue: root.default stats: default: capacity=1.0, absoluteCapacity=1.0, usedResources=<memory:3072, vCores:2>, usedCapacity=0.375, absoluteUsedCapacity=0.375, numApps=1, numContainers=2
2019-09-16 06:06:43,683 INFO org.apache.hadoop.yarn.server.resourcemanager.scheduler.capacity.CapacityScheduler: Application attempt appattempt_1568623076950_0001_000001 released container container_1568623076950_0001_01_000012 on node: host: e9a6a0455f0d:38503 #containers=2 available=<memory:5120, vCores:6> used=<memory:3072, vCores:2> with event: FINISHED
2019-09-16 06:06:43,684 INFO org.apache.hadoop.yarn.server.resourcemanager.rmcontainer.RMContainerImpl: container_1568623076950_0001_01_000014 Container Transitioned from NEW to ALLOCATED
2019-09-16 06:06:43,684 INFO org.apache.hadoop.yarn.server.resourcemanager.RMAuditLogger: USER=root	OPERATION=AM Allocated Container	TARGET=SchedulerApp	RESULT=SUCCESS	APPID=application_1568623076950_0001	CONTAINERID=container_1568623076950_0001_01_000014
2019-09-16 06:06:43,684 INFO org.apache.hadoop.yarn.server.resourcemanager.scheduler.SchedulerNode: Assigned container container_1568623076950_0001_01_000014 of capacity <memory:1024, vCores:1> on host e9a6a0455f0d:38503, which has 3 containers, <memory:4096, vCores:3> used and <memory:4096, vCores:5> available after allocation
2019-09-16 06:06:43,685 INFO org.apache.hadoop.yarn.server.resourcemanager.scheduler.capacity.LeafQueue: assignedContainer application attempt=appattempt_1568623076950_0001_000001 container=Container: [ContainerId: container_1568623076950_0001_01_000014, NodeId: e9a6a0455f0d:38503, NodeHttpAddress: e9a6a0455f0d:8042, Resource: <memory:1024, vCores:1>, Priority: 20, Token: null, ] queue=default: capacity=1.0, absoluteCapacity=1.0, usedResources=<memory:3072, vCores:2>, usedCapacity=0.375, absoluteUsedCapacity=0.375, numApps=1, numContainers=2 clusterResource=<memory:8192, vCores:8>
2019-09-16 06:06:43,685 INFO org.apache.hadoop.yarn.server.resourcemanager.scheduler.capacity.ParentQueue: Re-sorting assigned queue: root.default stats: default: capacity=1.0, absoluteCapacity=1.0, usedResources=<memory:4096, vCores:3>, usedCapacity=0.5, absoluteUsedCapacity=0.5, numApps=1, numContainers=3
2019-09-16 06:06:43,685 INFO org.apache.hadoop.yarn.server.resourcemanager.scheduler.capacity.ParentQueue: assignedContainer queue=root usedCapacity=0.5 absoluteUsedCapacity=0.5 used=<memory:4096, vCores:3> cluster=<memory:8192, vCores:8>
2019-09-16 06:06:43,686 INFO org.apache.hadoop.yarn.server.resourcemanager.rmcontainer.RMContainerImpl: container_1568623076950_0001_01_000015 Container Transitioned from NEW to ALLOCATED
2019-09-16 06:06:43,686 INFO org.apache.hadoop.yarn.server.resourcemanager.RMAuditLogger: USER=root	OPERATION=AM Allocated Container	TARGET=SchedulerApp	RESULT=SUCCESS	APPID=application_1568623076950_0001	CONTAINERID=container_1568623076950_0001_01_000015
2019-09-16 06:06:43,687 INFO org.apache.hadoop.yarn.server.resourcemanager.scheduler.SchedulerNode: Assigned container container_1568623076950_0001_01_000015 of capacity <memory:1024, vCores:1> on host e9a6a0455f0d:38503, which has 4 containers, <memory:5120, vCores:4> used and <memory:3072, vCores:4> available after allocation
2019-09-16 06:06:43,687 INFO org.apache.hadoop.yarn.server.resourcemanager.scheduler.capacity.LeafQueue: assignedContainer application attempt=appattempt_1568623076950_0001_000001 container=Container: [ContainerId: container_1568623076950_0001_01_000015, NodeId: e9a6a0455f0d:38503, NodeHttpAddress: e9a6a0455f0d:8042, Resource: <memory:1024, vCores:1>, Priority: 20, Token: null, ] queue=default: capacity=1.0, absoluteCapacity=1.0, usedResources=<memory:4096, vCores:3>, usedCapacity=0.5, absoluteUsedCapacity=0.5, numApps=1, numContainers=3 clusterResource=<memory:8192, vCores:8>
2019-09-16 06:06:43,688 INFO org.apache.hadoop.yarn.server.resourcemanager.scheduler.capacity.ParentQueue: Re-sorting assigned queue: root.default stats: default: capacity=1.0, absoluteCapacity=1.0, usedResources=<memory:5120, vCores:4>, usedCapacity=0.625, absoluteUsedCapacity=0.625, numApps=1, numContainers=4
2019-09-16 06:06:43,688 INFO org.apache.hadoop.yarn.server.resourcemanager.scheduler.capacity.ParentQueue: assignedContainer queue=root usedCapacity=0.625 absoluteUsedCapacity=0.625 used=<memory:5120, vCores:4> cluster=<memory:8192, vCores:8>
2019-09-16 06:06:43,690 INFO org.apache.hadoop.yarn.server.resourcemanager.rmcontainer.RMContainerImpl: container_1568623076950_0001_01_000016 Container Transitioned from NEW to ALLOCATED
2019-09-16 06:06:43,690 INFO org.apache.hadoop.yarn.server.resourcemanager.RMAuditLogger: USER=root	OPERATION=AM Allocated Container	TARGET=SchedulerApp	RESULT=SUCCESS	APPID=application_1568623076950_0001	CONTAINERID=container_1568623076950_0001_01_000016
2019-09-16 06:06:43,690 INFO org.apache.hadoop.yarn.server.resourcemanager.scheduler.SchedulerNode: Assigned container container_1568623076950_0001_01_000016 of capacity <memory:1024, vCores:1> on host e9a6a0455f0d:38503, which has 5 containers, <memory:6144, vCores:5> used and <memory:2048, vCores:3> available after allocation
2019-09-16 06:06:43,691 INFO org.apache.hadoop.yarn.server.resourcemanager.scheduler.capacity.LeafQueue: assignedContainer application attempt=appattempt_1568623076950_0001_000001 container=Container: [ContainerId: container_1568623076950_0001_01_000016, NodeId: e9a6a0455f0d:38503, NodeHttpAddress: e9a6a0455f0d:8042, Resource: <memory:1024, vCores:1>, Priority: 20, Token: null, ] queue=default: capacity=1.0, absoluteCapacity=1.0, usedResources=<memory:5120, vCores:4>, usedCapacity=0.625, absoluteUsedCapacity=0.625, numApps=1, numContainers=4 clusterResource=<memory:8192, vCores:8>
2019-09-16 06:06:43,691 INFO org.apache.hadoop.yarn.server.resourcemanager.scheduler.capacity.ParentQueue: Re-sorting assigned queue: root.default stats: default: capacity=1.0, absoluteCapacity=1.0, usedResources=<memory:6144, vCores:5>, usedCapacity=0.75, absoluteUsedCapacity=0.75, numApps=1, numContainers=5
2019-09-16 06:06:43,691 INFO org.apache.hadoop.yarn.server.resourcemanager.scheduler.capacity.ParentQueue: assignedContainer queue=root usedCapacity=0.75 absoluteUsedCapacity=0.75 used=<memory:6144, vCores:5> cluster=<memory:8192, vCores:8>
2019-09-16 06:06:43,692 INFO org.apache.hadoop.yarn.server.resourcemanager.rmcontainer.RMContainerImpl: container_1568623076950_0001_01_000017 Container Transitioned from NEW to ALLOCATED
2019-09-16 06:06:43,692 INFO org.apache.hadoop.yarn.server.resourcemanager.RMAuditLogger: USER=root	OPERATION=AM Allocated Container	TARGET=SchedulerApp	RESULT=SUCCESS	APPID=application_1568623076950_0001	CONTAINERID=container_1568623076950_0001_01_000017
2019-09-16 06:06:43,692 INFO org.apache.hadoop.yarn.server.resourcemanager.scheduler.SchedulerNode: Assigned container container_1568623076950_0001_01_000017 of capacity <memory:1024, vCores:1> on host e9a6a0455f0d:38503, which has 6 containers, <memory:7168, vCores:6> used and <memory:1024, vCores:2> available after allocation
2019-09-16 06:06:43,693 INFO org.apache.hadoop.yarn.server.resourcemanager.scheduler.capacity.LeafQueue: assignedContainer application attempt=appattempt_1568623076950_0001_000001 container=Container: [ContainerId: container_1568623076950_0001_01_000017, NodeId: e9a6a0455f0d:38503, NodeHttpAddress: e9a6a0455f0d:8042, Resource: <memory:1024, vCores:1>, Priority: 20, Token: null, ] queue=default: capacity=1.0, absoluteCapacity=1.0, usedResources=<memory:6144, vCores:5>, usedCapacity=0.75, absoluteUsedCapacity=0.75, numApps=1, numContainers=5 clusterResource=<memory:8192, vCores:8>
2019-09-16 06:06:43,693 INFO org.apache.hadoop.yarn.server.resourcemanager.scheduler.capacity.ParentQueue: Re-sorting assigned queue: root.default stats: default: capacity=1.0, absoluteCapacity=1.0, usedResources=<memory:7168, vCores:6>, usedCapacity=0.875, absoluteUsedCapacity=0.875, numApps=1, numContainers=6
2019-09-16 06:06:43,693 INFO org.apache.hadoop.yarn.server.resourcemanager.scheduler.capacity.ParentQueue: assignedContainer queue=root usedCapacity=0.875 absoluteUsedCapacity=0.875 used=<memory:7168, vCores:6> cluster=<memory:8192, vCores:8>
2019-09-16 06:06:43,695 INFO org.apache.hadoop.yarn.server.resourcemanager.rmcontainer.RMContainerImpl: container_1568623076950_0001_01_000018 Container Transitioned from NEW to ALLOCATED
2019-09-16 06:06:43,695 INFO org.apache.hadoop.yarn.server.resourcemanager.RMAuditLogger: USER=root	OPERATION=AM Allocated Container	TARGET=SchedulerApp	RESULT=SUCCESS	APPID=application_1568623076950_0001	CONTAINERID=container_1568623076950_0001_01_000018
2019-09-16 06:06:43,695 INFO org.apache.hadoop.yarn.server.resourcemanager.scheduler.SchedulerNode: Assigned container container_1568623076950_0001_01_000018 of capacity <memory:1024, vCores:1> on host e9a6a0455f0d:38503, which has 7 containers, <memory:8192, vCores:7> used and <memory:0, vCores:1> available after allocation
2019-09-16 06:06:43,696 INFO org.apache.hadoop.yarn.server.resourcemanager.scheduler.capacity.LeafQueue: assignedContainer application attempt=appattempt_1568623076950_0001_000001 container=Container: [ContainerId: container_1568623076950_0001_01_000018, NodeId: e9a6a0455f0d:38503, NodeHttpAddress: e9a6a0455f0d:8042, Resource: <memory:1024, vCores:1>, Priority: 20, Token: null, ] queue=default: capacity=1.0, absoluteCapacity=1.0, usedResources=<memory:7168, vCores:6>, usedCapacity=0.875, absoluteUsedCapacity=0.875, numApps=1, numContainers=6 clusterResource=<memory:8192, vCores:8>
2019-09-16 06:06:43,697 INFO org.apache.hadoop.yarn.server.resourcemanager.scheduler.capacity.ParentQueue: Re-sorting assigned queue: root.default stats: default: capacity=1.0, absoluteCapacity=1.0, usedResources=<memory:8192, vCores:7>, usedCapacity=1.0, absoluteUsedCapacity=1.0, numApps=1, numContainers=7
2019-09-16 06:06:43,697 INFO org.apache.hadoop.yarn.server.resourcemanager.scheduler.capacity.ParentQueue: assignedContainer queue=root usedCapacity=1.0 absoluteUsedCapacity=1.0 used=<memory:8192, vCores:7> cluster=<memory:8192, vCores:8>
2019-09-16 06:06:43,873 INFO org.apache.hadoop.yarn.server.resourcemanager.rmcontainer.RMContainerImpl: container_1568623076950_0001_01_000014 Container Transitioned from ALLOCATED to ACQUIRED
2019-09-16 06:06:43,876 INFO org.apache.hadoop.yarn.server.resourcemanager.rmcontainer.RMContainerImpl: container_1568623076950_0001_01_000015 Container Transitioned from ALLOCATED to ACQUIRED
2019-09-16 06:06:43,878 INFO org.apache.hadoop.yarn.server.resourcemanager.rmcontainer.RMContainerImpl: container_1568623076950_0001_01_000016 Container Transitioned from ALLOCATED to ACQUIRED
2019-09-16 06:06:43,880 INFO org.apache.hadoop.yarn.server.resourcemanager.rmcontainer.RMContainerImpl: container_1568623076950_0001_01_000017 Container Transitioned from ALLOCATED to ACQUIRED
2019-09-16 06:06:43,883 INFO org.apache.hadoop.yarn.server.resourcemanager.rmcontainer.RMContainerImpl: container_1568623076950_0001_01_000018 Container Transitioned from ALLOCATED to ACQUIRED
2019-09-16 06:06:44,642 INFO org.apache.hadoop.yarn.server.resourcemanager.rmcontainer.RMContainerImpl: container_1568623076950_0001_01_000014 Container Transitioned from ACQUIRED to RUNNING
2019-09-16 06:06:44,643 INFO org.apache.hadoop.yarn.server.resourcemanager.rmcontainer.RMContainerImpl: container_1568623076950_0001_01_000015 Container Transitioned from ACQUIRED to RUNNING
2019-09-16 06:06:44,643 INFO org.apache.hadoop.yarn.server.resourcemanager.rmcontainer.RMContainerImpl: container_1568623076950_0001_01_000016 Container Transitioned from ACQUIRED to RUNNING
2019-09-16 06:06:44,644 INFO org.apache.hadoop.yarn.server.resourcemanager.rmcontainer.RMContainerImpl: container_1568623076950_0001_01_000017 Container Transitioned from ACQUIRED to RUNNING
2019-09-16 06:06:44,644 INFO org.apache.hadoop.yarn.server.resourcemanager.rmcontainer.RMContainerImpl: container_1568623076950_0001_01_000018 Container Transitioned from ACQUIRED to RUNNING
2019-09-16 06:06:54,194 INFO org.apache.hadoop.yarn.server.resourcemanager.rmcontainer.RMContainerImpl: container_1568623076950_0001_01_000017 Container Transitioned from RUNNING to COMPLETED
2019-09-16 06:06:54,195 INFO org.apache.hadoop.yarn.server.resourcemanager.scheduler.common.fica.FiCaSchedulerApp: Completed container: container_1568623076950_0001_01_000017 in state: COMPLETED event:FINISHED
2019-09-16 06:06:54,195 INFO org.apache.hadoop.yarn.server.resourcemanager.RMAuditLogger: USER=root	OPERATION=AM Released Container	TARGET=SchedulerApp	RESULT=SUCCESS	APPID=application_1568623076950_0001	CONTAINERID=container_1568623076950_0001_01_000017
2019-09-16 06:06:54,195 INFO org.apache.hadoop.yarn.server.resourcemanager.scheduler.SchedulerNode: Released container container_1568623076950_0001_01_000017 of capacity <memory:1024, vCores:1> on host e9a6a0455f0d:38503, which currently has 6 containers, <memory:7168, vCores:6> used and <memory:1024, vCores:2> available, release resources=true
2019-09-16 06:06:54,195 INFO org.apache.hadoop.yarn.server.resourcemanager.scheduler.capacity.LeafQueue: default used=<memory:7168, vCores:6> numContainers=6 user=root user-resources=<memory:7168, vCores:6>
2019-09-16 06:06:54,196 INFO org.apache.hadoop.yarn.server.resourcemanager.scheduler.capacity.LeafQueue: completedContainer container=Container: [ContainerId: container_1568623076950_0001_01_000017, NodeId: e9a6a0455f0d:38503, NodeHttpAddress: e9a6a0455f0d:8042, Resource: <memory:1024, vCores:1>, Priority: 20, Token: Token { kind: ContainerToken, service: 172.24.0.2:38503 }, ] queue=default: capacity=1.0, absoluteCapacity=1.0, usedResources=<memory:7168, vCores:6>, usedCapacity=0.875, absoluteUsedCapacity=0.875, numApps=1, numContainers=6 cluster=<memory:8192, vCores:8>
2019-09-16 06:06:54,196 INFO org.apache.hadoop.yarn.server.resourcemanager.scheduler.capacity.ParentQueue: completedContainer queue=root usedCapacity=0.875 absoluteUsedCapacity=0.875 used=<memory:7168, vCores:6> cluster=<memory:8192, vCores:8>
2019-09-16 06:06:54,196 INFO org.apache.hadoop.yarn.server.resourcemanager.scheduler.capacity.ParentQueue: Re-sorting completed queue: root.default stats: default: capacity=1.0, absoluteCapacity=1.0, usedResources=<memory:7168, vCores:6>, usedCapacity=0.875, absoluteUsedCapacity=0.875, numApps=1, numContainers=6
2019-09-16 06:06:54,197 INFO org.apache.hadoop.yarn.server.resourcemanager.scheduler.capacity.CapacityScheduler: Application attempt appattempt_1568623076950_0001_000001 released container container_1568623076950_0001_01_000017 on node: host: e9a6a0455f0d:38503 #containers=6 available=<memory:1024, vCores:2> used=<memory:7168, vCores:6> with event: FINISHED
2019-09-16 06:06:54,197 INFO org.apache.hadoop.yarn.server.resourcemanager.rmcontainer.RMContainerImpl: container_1568623076950_0001_01_000016 Container Transitioned from RUNNING to COMPLETED
2019-09-16 06:06:54,197 INFO org.apache.hadoop.yarn.server.resourcemanager.scheduler.common.fica.FiCaSchedulerApp: Completed container: container_1568623076950_0001_01_000016 in state: COMPLETED event:FINISHED
2019-09-16 06:06:54,198 INFO org.apache.hadoop.yarn.server.resourcemanager.RMAuditLogger: USER=root	OPERATION=AM Released Container	TARGET=SchedulerApp	RESULT=SUCCESS	APPID=application_1568623076950_0001	CONTAINERID=container_1568623076950_0001_01_000016
2019-09-16 06:06:54,198 INFO org.apache.hadoop.yarn.server.resourcemanager.scheduler.SchedulerNode: Released container container_1568623076950_0001_01_000016 of capacity <memory:1024, vCores:1> on host e9a6a0455f0d:38503, which currently has 5 containers, <memory:6144, vCores:5> used and <memory:2048, vCores:3> available, release resources=true
2019-09-16 06:06:54,198 INFO org.apache.hadoop.yarn.server.resourcemanager.scheduler.capacity.LeafQueue: default used=<memory:6144, vCores:5> numContainers=5 user=root user-resources=<memory:6144, vCores:5>
2019-09-16 06:06:54,199 INFO org.apache.hadoop.yarn.server.resourcemanager.scheduler.capacity.LeafQueue: completedContainer container=Container: [ContainerId: container_1568623076950_0001_01_000016, NodeId: e9a6a0455f0d:38503, NodeHttpAddress: e9a6a0455f0d:8042, Resource: <memory:1024, vCores:1>, Priority: 20, Token: Token { kind: ContainerToken, service: 172.24.0.2:38503 }, ] queue=default: capacity=1.0, absoluteCapacity=1.0, usedResources=<memory:6144, vCores:5>, usedCapacity=0.75, absoluteUsedCapacity=0.75, numApps=1, numContainers=5 cluster=<memory:8192, vCores:8>
2019-09-16 06:06:54,199 INFO org.apache.hadoop.yarn.server.resourcemanager.scheduler.capacity.ParentQueue: completedContainer queue=root usedCapacity=0.75 absoluteUsedCapacity=0.75 used=<memory:6144, vCores:5> cluster=<memory:8192, vCores:8>
2019-09-16 06:06:54,199 INFO org.apache.hadoop.yarn.server.resourcemanager.scheduler.capacity.ParentQueue: Re-sorting completed queue: root.default stats: default: capacity=1.0, absoluteCapacity=1.0, usedResources=<memory:6144, vCores:5>, usedCapacity=0.75, absoluteUsedCapacity=0.75, numApps=1, numContainers=5
2019-09-16 06:06:54,200 INFO org.apache.hadoop.yarn.server.resourcemanager.scheduler.capacity.CapacityScheduler: Application attempt appattempt_1568623076950_0001_000001 released container container_1568623076950_0001_01_000016 on node: host: e9a6a0455f0d:38503 #containers=5 available=<memory:2048, vCores:3> used=<memory:6144, vCores:5> with event: FINISHED
2019-09-16 06:06:54,200 INFO org.apache.hadoop.yarn.server.resourcemanager.rmcontainer.RMContainerImpl: container_1568623076950_0001_01_000015 Container Transitioned from RUNNING to COMPLETED
2019-09-16 06:06:54,200 INFO org.apache.hadoop.yarn.server.resourcemanager.scheduler.common.fica.FiCaSchedulerApp: Completed container: container_1568623076950_0001_01_000015 in state: COMPLETED event:FINISHED
2019-09-16 06:06:54,200 INFO org.apache.hadoop.yarn.server.resourcemanager.RMAuditLogger: USER=root	OPERATION=AM Released Container	TARGET=SchedulerApp	RESULT=SUCCESS	APPID=application_1568623076950_0001	CONTAINERID=container_1568623076950_0001_01_000015
2019-09-16 06:06:54,200 INFO org.apache.hadoop.yarn.server.resourcemanager.scheduler.SchedulerNode: Released container container_1568623076950_0001_01_000015 of capacity <memory:1024, vCores:1> on host e9a6a0455f0d:38503, which currently has 4 containers, <memory:5120, vCores:4> used and <memory:3072, vCores:4> available, release resources=true
2019-09-16 06:06:54,201 INFO org.apache.hadoop.yarn.server.resourcemanager.scheduler.capacity.LeafQueue: default used=<memory:5120, vCores:4> numContainers=4 user=root user-resources=<memory:5120, vCores:4>
2019-09-16 06:06:54,201 INFO org.apache.hadoop.yarn.server.resourcemanager.scheduler.capacity.LeafQueue: completedContainer container=Container: [ContainerId: container_1568623076950_0001_01_000015, NodeId: e9a6a0455f0d:38503, NodeHttpAddress: e9a6a0455f0d:8042, Resource: <memory:1024, vCores:1>, Priority: 20, Token: Token { kind: ContainerToken, service: 172.24.0.2:38503 }, ] queue=default: capacity=1.0, absoluteCapacity=1.0, usedResources=<memory:5120, vCores:4>, usedCapacity=0.625, absoluteUsedCapacity=0.625, numApps=1, numContainers=4 cluster=<memory:8192, vCores:8>
2019-09-16 06:06:54,201 INFO org.apache.hadoop.yarn.server.resourcemanager.scheduler.capacity.ParentQueue: completedContainer queue=root usedCapacity=0.625 absoluteUsedCapacity=0.625 used=<memory:5120, vCores:4> cluster=<memory:8192, vCores:8>
2019-09-16 06:06:54,202 INFO org.apache.hadoop.yarn.server.resourcemanager.scheduler.capacity.ParentQueue: Re-sorting completed queue: root.default stats: default: capacity=1.0, absoluteCapacity=1.0, usedResources=<memory:5120, vCores:4>, usedCapacity=0.625, absoluteUsedCapacity=0.625, numApps=1, numContainers=4
2019-09-16 06:06:54,202 INFO org.apache.hadoop.yarn.server.resourcemanager.scheduler.capacity.CapacityScheduler: Application attempt appattempt_1568623076950_0001_000001 released container container_1568623076950_0001_01_000015 on node: host: e9a6a0455f0d:38503 #containers=4 available=<memory:3072, vCores:4> used=<memory:5120, vCores:4> with event: FINISHED
2019-09-16 06:06:54,202 INFO org.apache.hadoop.yarn.server.resourcemanager.rmcontainer.RMContainerImpl: container_1568623076950_0001_01_000018 Container Transitioned from RUNNING to COMPLETED
2019-09-16 06:06:54,202 INFO org.apache.hadoop.yarn.server.resourcemanager.scheduler.common.fica.FiCaSchedulerApp: Completed container: container_1568623076950_0001_01_000018 in state: COMPLETED event:FINISHED
2019-09-16 06:06:54,203 INFO org.apache.hadoop.yarn.server.resourcemanager.RMAuditLogger: USER=root	OPERATION=AM Released Container	TARGET=SchedulerApp	RESULT=SUCCESS	APPID=application_1568623076950_0001	CONTAINERID=container_1568623076950_0001_01_000018
2019-09-16 06:06:54,203 INFO org.apache.hadoop.yarn.server.resourcemanager.scheduler.SchedulerNode: Released container container_1568623076950_0001_01_000018 of capacity <memory:1024, vCores:1> on host e9a6a0455f0d:38503, which currently has 3 containers, <memory:4096, vCores:3> used and <memory:4096, vCores:5> available, release resources=true
2019-09-16 06:06:54,203 INFO org.apache.hadoop.yarn.server.resourcemanager.scheduler.capacity.LeafQueue: default used=<memory:4096, vCores:3> numContainers=3 user=root user-resources=<memory:4096, vCores:3>
2019-09-16 06:06:54,204 INFO org.apache.hadoop.yarn.server.resourcemanager.scheduler.capacity.LeafQueue: completedContainer container=Container: [ContainerId: container_1568623076950_0001_01_000018, NodeId: e9a6a0455f0d:38503, NodeHttpAddress: e9a6a0455f0d:8042, Resource: <memory:1024, vCores:1>, Priority: 20, Token: Token { kind: ContainerToken, service: 172.24.0.2:38503 }, ] queue=default: capacity=1.0, absoluteCapacity=1.0, usedResources=<memory:4096, vCores:3>, usedCapacity=0.5, absoluteUsedCapacity=0.5, numApps=1, numContainers=3 cluster=<memory:8192, vCores:8>
2019-09-16 06:06:54,204 INFO org.apache.hadoop.yarn.server.resourcemanager.scheduler.capacity.ParentQueue: completedContainer queue=root usedCapacity=0.5 absoluteUsedCapacity=0.5 used=<memory:4096, vCores:3> cluster=<memory:8192, vCores:8>
2019-09-16 06:06:54,204 INFO org.apache.hadoop.yarn.server.resourcemanager.scheduler.capacity.ParentQueue: Re-sorting completed queue: root.default stats: default: capacity=1.0, absoluteCapacity=1.0, usedResources=<memory:4096, vCores:3>, usedCapacity=0.5, absoluteUsedCapacity=0.5, numApps=1, numContainers=3
2019-09-16 06:06:54,204 INFO org.apache.hadoop.yarn.server.resourcemanager.scheduler.capacity.CapacityScheduler: Application attempt appattempt_1568623076950_0001_000001 released container container_1568623076950_0001_01_000018 on node: host: e9a6a0455f0d:38503 #containers=3 available=<memory:4096, vCores:5> used=<memory:4096, vCores:3> with event: FINISHED
2019-09-16 06:06:54,205 INFO org.apache.hadoop.yarn.server.resourcemanager.rmcontainer.RMContainerImpl: container_1568623076950_0001_01_000014 Container Transitioned from RUNNING to COMPLETED
2019-09-16 06:06:54,205 INFO org.apache.hadoop.yarn.server.resourcemanager.scheduler.common.fica.FiCaSchedulerApp: Completed container: container_1568623076950_0001_01_000014 in state: COMPLETED event:FINISHED
2019-09-16 06:06:54,205 INFO org.apache.hadoop.yarn.server.resourcemanager.RMAuditLogger: USER=root	OPERATION=AM Released Container	TARGET=SchedulerApp	RESULT=SUCCESS	APPID=application_1568623076950_0001	CONTAINERID=container_1568623076950_0001_01_000014
2019-09-16 06:06:54,205 INFO org.apache.hadoop.yarn.server.resourcemanager.scheduler.SchedulerNode: Released container container_1568623076950_0001_01_000014 of capacity <memory:1024, vCores:1> on host e9a6a0455f0d:38503, which currently has 2 containers, <memory:3072, vCores:2> used and <memory:5120, vCores:6> available, release resources=true
2019-09-16 06:06:54,206 INFO org.apache.hadoop.yarn.server.resourcemanager.scheduler.capacity.LeafQueue: default used=<memory:3072, vCores:2> numContainers=2 user=root user-resources=<memory:3072, vCores:2>
2019-09-16 06:06:54,206 INFO org.apache.hadoop.yarn.server.resourcemanager.scheduler.capacity.LeafQueue: completedContainer container=Container: [ContainerId: container_1568623076950_0001_01_000014, NodeId: e9a6a0455f0d:38503, NodeHttpAddress: e9a6a0455f0d:8042, Resource: <memory:1024, vCores:1>, Priority: 20, Token: Token { kind: ContainerToken, service: 172.24.0.2:38503 }, ] queue=default: capacity=1.0, absoluteCapacity=1.0, usedResources=<memory:3072, vCores:2>, usedCapacity=0.375, absoluteUsedCapacity=0.375, numApps=1, numContainers=2 cluster=<memory:8192, vCores:8>
2019-09-16 06:06:54,206 INFO org.apache.hadoop.yarn.server.resourcemanager.scheduler.capacity.ParentQueue: completedContainer queue=root usedCapacity=0.375 absoluteUsedCapacity=0.375 used=<memory:3072, vCores:2> cluster=<memory:8192, vCores:8>
2019-09-16 06:06:54,207 INFO org.apache.hadoop.yarn.server.resourcemanager.scheduler.capacity.ParentQueue: Re-sorting completed queue: root.default stats: default: capacity=1.0, absoluteCapacity=1.0, usedResources=<memory:3072, vCores:2>, usedCapacity=0.375, absoluteUsedCapacity=0.375, numApps=1, numContainers=2
2019-09-16 06:06:54,207 INFO org.apache.hadoop.yarn.server.resourcemanager.scheduler.capacity.CapacityScheduler: Application attempt appattempt_1568623076950_0001_000001 released container container_1568623076950_0001_01_000014 on node: host: e9a6a0455f0d:38503 #containers=2 available=<memory:5120, vCores:6> used=<memory:3072, vCores:2> with event: FINISHED
2019-09-16 06:06:54,208 INFO org.apache.hadoop.yarn.server.resourcemanager.rmcontainer.RMContainerImpl: container_1568623076950_0001_01_000019 Container Transitioned from NEW to ALLOCATED
2019-09-16 06:06:54,208 INFO org.apache.hadoop.yarn.server.resourcemanager.RMAuditLogger: USER=root	OPERATION=AM Allocated Container	TARGET=SchedulerApp	RESULT=SUCCESS	APPID=application_1568623076950_0001	CONTAINERID=container_1568623076950_0001_01_000019
2019-09-16 06:06:54,208 INFO org.apache.hadoop.yarn.server.resourcemanager.scheduler.SchedulerNode: Assigned container container_1568623076950_0001_01_000019 of capacity <memory:1024, vCores:1> on host e9a6a0455f0d:38503, which has 3 containers, <memory:4096, vCores:3> used and <memory:4096, vCores:5> available after allocation
2019-09-16 06:06:54,208 INFO org.apache.hadoop.yarn.server.resourcemanager.scheduler.capacity.LeafQueue: assignedContainer application attempt=appattempt_1568623076950_0001_000001 container=Container: [ContainerId: container_1568623076950_0001_01_000019, NodeId: e9a6a0455f0d:38503, NodeHttpAddress: e9a6a0455f0d:8042, Resource: <memory:1024, vCores:1>, Priority: 20, Token: null, ] queue=default: capacity=1.0, absoluteCapacity=1.0, usedResources=<memory:3072, vCores:2>, usedCapacity=0.375, absoluteUsedCapacity=0.375, numApps=1, numContainers=2 clusterResource=<memory:8192, vCores:8>
2019-09-16 06:06:54,209 INFO org.apache.hadoop.yarn.server.resourcemanager.scheduler.capacity.ParentQueue: Re-sorting assigned queue: root.default stats: default: capacity=1.0, absoluteCapacity=1.0, usedResources=<memory:4096, vCores:3>, usedCapacity=0.5, absoluteUsedCapacity=0.5, numApps=1, numContainers=3
2019-09-16 06:06:54,209 INFO org.apache.hadoop.yarn.server.resourcemanager.scheduler.capacity.ParentQueue: assignedContainer queue=root usedCapacity=0.5 absoluteUsedCapacity=0.5 used=<memory:4096, vCores:3> cluster=<memory:8192, vCores:8>
2019-09-16 06:06:54,210 INFO org.apache.hadoop.yarn.server.resourcemanager.rmcontainer.RMContainerImpl: container_1568623076950_0001_01_000020 Container Transitioned from NEW to ALLOCATED
2019-09-16 06:06:54,210 INFO org.apache.hadoop.yarn.server.resourcemanager.RMAuditLogger: USER=root	OPERATION=AM Allocated Container	TARGET=SchedulerApp	RESULT=SUCCESS	APPID=application_1568623076950_0001	CONTAINERID=container_1568623076950_0001_01_000020
2019-09-16 06:06:54,210 INFO org.apache.hadoop.yarn.server.resourcemanager.scheduler.SchedulerNode: Assigned container container_1568623076950_0001_01_000020 of capacity <memory:1024, vCores:1> on host e9a6a0455f0d:38503, which has 4 containers, <memory:5120, vCores:4> used and <memory:3072, vCores:4> available after allocation
2019-09-16 06:06:54,211 INFO org.apache.hadoop.yarn.server.resourcemanager.scheduler.capacity.LeafQueue: assignedContainer application attempt=appattempt_1568623076950_0001_000001 container=Container: [ContainerId: container_1568623076950_0001_01_000020, NodeId: e9a6a0455f0d:38503, NodeHttpAddress: e9a6a0455f0d:8042, Resource: <memory:1024, vCores:1>, Priority: 20, Token: null, ] queue=default: capacity=1.0, absoluteCapacity=1.0, usedResources=<memory:4096, vCores:3>, usedCapacity=0.5, absoluteUsedCapacity=0.5, numApps=1, numContainers=3 clusterResource=<memory:8192, vCores:8>
2019-09-16 06:06:54,211 INFO org.apache.hadoop.yarn.server.resourcemanager.scheduler.capacity.ParentQueue: Re-sorting assigned queue: root.default stats: default: capacity=1.0, absoluteCapacity=1.0, usedResources=<memory:5120, vCores:4>, usedCapacity=0.625, absoluteUsedCapacity=0.625, numApps=1, numContainers=4
2019-09-16 06:06:54,212 INFO org.apache.hadoop.yarn.server.resourcemanager.scheduler.capacity.ParentQueue: assignedContainer queue=root usedCapacity=0.625 absoluteUsedCapacity=0.625 used=<memory:5120, vCores:4> cluster=<memory:8192, vCores:8>
2019-09-16 06:06:54,212 INFO org.apache.hadoop.yarn.server.resourcemanager.rmcontainer.RMContainerImpl: container_1568623076950_0001_01_000021 Container Transitioned from NEW to ALLOCATED
2019-09-16 06:06:54,212 INFO org.apache.hadoop.yarn.server.resourcemanager.RMAuditLogger: USER=root	OPERATION=AM Allocated Container	TARGET=SchedulerApp	RESULT=SUCCESS	APPID=application_1568623076950_0001	CONTAINERID=container_1568623076950_0001_01_000021
2019-09-16 06:06:54,212 INFO org.apache.hadoop.yarn.server.resourcemanager.scheduler.SchedulerNode: Assigned container container_1568623076950_0001_01_000021 of capacity <memory:1024, vCores:1> on host e9a6a0455f0d:38503, which has 5 containers, <memory:6144, vCores:5> used and <memory:2048, vCores:3> available after allocation
2019-09-16 06:06:54,213 INFO org.apache.hadoop.yarn.server.resourcemanager.scheduler.capacity.LeafQueue: assignedContainer application attempt=appattempt_1568623076950_0001_000001 container=Container: [ContainerId: container_1568623076950_0001_01_000021, NodeId: e9a6a0455f0d:38503, NodeHttpAddress: e9a6a0455f0d:8042, Resource: <memory:1024, vCores:1>, Priority: 20, Token: null, ] queue=default: capacity=1.0, absoluteCapacity=1.0, usedResources=<memory:5120, vCores:4>, usedCapacity=0.625, absoluteUsedCapacity=0.625, numApps=1, numContainers=4 clusterResource=<memory:8192, vCores:8>
2019-09-16 06:06:54,213 INFO org.apache.hadoop.yarn.server.resourcemanager.scheduler.capacity.ParentQueue: Re-sorting assigned queue: root.default stats: default: capacity=1.0, absoluteCapacity=1.0, usedResources=<memory:6144, vCores:5>, usedCapacity=0.75, absoluteUsedCapacity=0.75, numApps=1, numContainers=5
2019-09-16 06:06:54,214 INFO org.apache.hadoop.yarn.server.resourcemanager.scheduler.capacity.ParentQueue: assignedContainer queue=root usedCapacity=0.75 absoluteUsedCapacity=0.75 used=<memory:6144, vCores:5> cluster=<memory:8192, vCores:8>
2019-09-16 06:06:54,214 INFO org.apache.hadoop.yarn.server.resourcemanager.rmcontainer.RMContainerImpl: container_1568623076950_0001_01_000022 Container Transitioned from NEW to ALLOCATED
2019-09-16 06:06:54,214 INFO org.apache.hadoop.yarn.server.resourcemanager.RMAuditLogger: USER=root	OPERATION=AM Allocated Container	TARGET=SchedulerApp	RESULT=SUCCESS	APPID=application_1568623076950_0001	CONTAINERID=container_1568623076950_0001_01_000022
2019-09-16 06:06:54,215 INFO org.apache.hadoop.yarn.server.resourcemanager.scheduler.SchedulerNode: Assigned container container_1568623076950_0001_01_000022 of capacity <memory:1024, vCores:1> on host e9a6a0455f0d:38503, which has 6 containers, <memory:7168, vCores:6> used and <memory:1024, vCores:2> available after allocation
2019-09-16 06:06:54,215 INFO org.apache.hadoop.yarn.server.resourcemanager.scheduler.capacity.LeafQueue: assignedContainer application attempt=appattempt_1568623076950_0001_000001 container=Container: [ContainerId: container_1568623076950_0001_01_000022, NodeId: e9a6a0455f0d:38503, NodeHttpAddress: e9a6a0455f0d:8042, Resource: <memory:1024, vCores:1>, Priority: 20, Token: null, ] queue=default: capacity=1.0, absoluteCapacity=1.0, usedResources=<memory:6144, vCores:5>, usedCapacity=0.75, absoluteUsedCapacity=0.75, numApps=1, numContainers=5 clusterResource=<memory:8192, vCores:8>
2019-09-16 06:06:54,216 INFO org.apache.hadoop.yarn.server.resourcemanager.scheduler.capacity.ParentQueue: Re-sorting assigned queue: root.default stats: default: capacity=1.0, absoluteCapacity=1.0, usedResources=<memory:7168, vCores:6>, usedCapacity=0.875, absoluteUsedCapacity=0.875, numApps=1, numContainers=6
2019-09-16 06:06:54,216 INFO org.apache.hadoop.yarn.server.resourcemanager.scheduler.capacity.ParentQueue: assignedContainer queue=root usedCapacity=0.875 absoluteUsedCapacity=0.875 used=<memory:7168, vCores:6> cluster=<memory:8192, vCores:8>
2019-09-16 06:06:54,216 INFO org.apache.hadoop.yarn.server.resourcemanager.rmcontainer.RMContainerImpl: container_1568623076950_0001_01_000023 Container Transitioned from NEW to ALLOCATED
2019-09-16 06:06:54,216 INFO org.apache.hadoop.yarn.server.resourcemanager.RMAuditLogger: USER=root	OPERATION=AM Allocated Container	TARGET=SchedulerApp	RESULT=SUCCESS	APPID=application_1568623076950_0001	CONTAINERID=container_1568623076950_0001_01_000023
2019-09-16 06:06:54,217 INFO org.apache.hadoop.yarn.server.resourcemanager.scheduler.SchedulerNode: Assigned container container_1568623076950_0001_01_000023 of capacity <memory:1024, vCores:1> on host e9a6a0455f0d:38503, which has 7 containers, <memory:8192, vCores:7> used and <memory:0, vCores:1> available after allocation
2019-09-16 06:06:54,217 INFO org.apache.hadoop.yarn.server.resourcemanager.scheduler.capacity.LeafQueue: assignedContainer application attempt=appattempt_1568623076950_0001_000001 container=Container: [ContainerId: container_1568623076950_0001_01_000023, NodeId: e9a6a0455f0d:38503, NodeHttpAddress: e9a6a0455f0d:8042, Resource: <memory:1024, vCores:1>, Priority: 20, Token: null, ] queue=default: capacity=1.0, absoluteCapacity=1.0, usedResources=<memory:7168, vCores:6>, usedCapacity=0.875, absoluteUsedCapacity=0.875, numApps=1, numContainers=6 clusterResource=<memory:8192, vCores:8>
2019-09-16 06:06:54,218 INFO org.apache.hadoop.yarn.server.resourcemanager.scheduler.capacity.ParentQueue: Re-sorting assigned queue: root.default stats: default: capacity=1.0, absoluteCapacity=1.0, usedResources=<memory:8192, vCores:7>, usedCapacity=1.0, absoluteUsedCapacity=1.0, numApps=1, numContainers=7
2019-09-16 06:06:54,218 INFO org.apache.hadoop.yarn.server.resourcemanager.scheduler.capacity.ParentQueue: assignedContainer queue=root usedCapacity=1.0 absoluteUsedCapacity=1.0 used=<memory:8192, vCores:7> cluster=<memory:8192, vCores:8>
2019-09-16 06:06:54,941 INFO org.apache.hadoop.yarn.server.resourcemanager.rmcontainer.RMContainerImpl: container_1568623076950_0001_01_000019 Container Transitioned from ALLOCATED to ACQUIRED
2019-09-16 06:06:54,944 INFO org.apache.hadoop.yarn.server.resourcemanager.rmcontainer.RMContainerImpl: container_1568623076950_0001_01_000020 Container Transitioned from ALLOCATED to ACQUIRED
2019-09-16 06:06:54,946 INFO org.apache.hadoop.yarn.server.resourcemanager.rmcontainer.RMContainerImpl: container_1568623076950_0001_01_000021 Container Transitioned from ALLOCATED to ACQUIRED
2019-09-16 06:06:54,949 INFO org.apache.hadoop.yarn.server.resourcemanager.rmcontainer.RMContainerImpl: container_1568623076950_0001_01_000022 Container Transitioned from ALLOCATED to ACQUIRED
2019-09-16 06:06:54,951 INFO org.apache.hadoop.yarn.server.resourcemanager.rmcontainer.RMContainerImpl: container_1568623076950_0001_01_000023 Container Transitioned from ALLOCATED to ACQUIRED
2019-09-16 06:06:55,244 INFO org.apache.hadoop.yarn.server.resourcemanager.rmcontainer.RMContainerImpl: container_1568623076950_0001_01_000019 Container Transitioned from ACQUIRED to RUNNING
2019-09-16 06:06:55,244 INFO org.apache.hadoop.yarn.server.resourcemanager.rmcontainer.RMContainerImpl: container_1568623076950_0001_01_000020 Container Transitioned from ACQUIRED to RUNNING
2019-09-16 06:06:55,245 INFO org.apache.hadoop.yarn.server.resourcemanager.rmcontainer.RMContainerImpl: container_1568623076950_0001_01_000021 Container Transitioned from ACQUIRED to RUNNING
2019-09-16 06:06:55,245 INFO org.apache.hadoop.yarn.server.resourcemanager.rmcontainer.RMContainerImpl: container_1568623076950_0001_01_000022 Container Transitioned from ACQUIRED to RUNNING
2019-09-16 06:06:55,246 INFO org.apache.hadoop.yarn.server.resourcemanager.rmcontainer.RMContainerImpl: container_1568623076950_0001_01_000023 Container Transitioned from ACQUIRED to RUNNING
2019-09-16 06:07:04,502 INFO org.apache.hadoop.yarn.server.resourcemanager.rmcontainer.RMContainerImpl: container_1568623076950_0001_01_000022 Container Transitioned from RUNNING to COMPLETED
2019-09-16 06:07:04,502 INFO org.apache.hadoop.yarn.server.resourcemanager.scheduler.common.fica.FiCaSchedulerApp: Completed container: container_1568623076950_0001_01_000022 in state: COMPLETED event:FINISHED
2019-09-16 06:07:04,502 INFO org.apache.hadoop.yarn.server.resourcemanager.RMAuditLogger: USER=root	OPERATION=AM Released Container	TARGET=SchedulerApp	RESULT=SUCCESS	APPID=application_1568623076950_0001	CONTAINERID=container_1568623076950_0001_01_000022
2019-09-16 06:07:04,503 INFO org.apache.hadoop.yarn.server.resourcemanager.scheduler.SchedulerNode: Released container container_1568623076950_0001_01_000022 of capacity <memory:1024, vCores:1> on host e9a6a0455f0d:38503, which currently has 6 containers, <memory:7168, vCores:6> used and <memory:1024, vCores:2> available, release resources=true
2019-09-16 06:07:04,503 INFO org.apache.hadoop.yarn.server.resourcemanager.scheduler.capacity.LeafQueue: default used=<memory:7168, vCores:6> numContainers=6 user=root user-resources=<memory:7168, vCores:6>
2019-09-16 06:07:04,506 INFO org.apache.hadoop.yarn.server.resourcemanager.scheduler.capacity.LeafQueue: completedContainer container=Container: [ContainerId: container_1568623076950_0001_01_000022, NodeId: e9a6a0455f0d:38503, NodeHttpAddress: e9a6a0455f0d:8042, Resource: <memory:1024, vCores:1>, Priority: 20, Token: Token { kind: ContainerToken, service: 172.24.0.2:38503 }, ] queue=default: capacity=1.0, absoluteCapacity=1.0, usedResources=<memory:7168, vCores:6>, usedCapacity=0.875, absoluteUsedCapacity=0.875, numApps=1, numContainers=6 cluster=<memory:8192, vCores:8>
2019-09-16 06:07:04,506 INFO org.apache.hadoop.yarn.server.resourcemanager.scheduler.capacity.ParentQueue: completedContainer queue=root usedCapacity=0.875 absoluteUsedCapacity=0.875 used=<memory:7168, vCores:6> cluster=<memory:8192, vCores:8>
2019-09-16 06:07:04,506 INFO org.apache.hadoop.yarn.server.resourcemanager.scheduler.capacity.ParentQueue: Re-sorting completed queue: root.default stats: default: capacity=1.0, absoluteCapacity=1.0, usedResources=<memory:7168, vCores:6>, usedCapacity=0.875, absoluteUsedCapacity=0.875, numApps=1, numContainers=6
2019-09-16 06:07:04,507 INFO org.apache.hadoop.yarn.server.resourcemanager.scheduler.capacity.CapacityScheduler: Application attempt appattempt_1568623076950_0001_000001 released container container_1568623076950_0001_01_000022 on node: host: e9a6a0455f0d:38503 #containers=6 available=<memory:1024, vCores:2> used=<memory:7168, vCores:6> with event: FINISHED
2019-09-16 06:07:04,508 INFO org.apache.hadoop.yarn.server.resourcemanager.rmcontainer.RMContainerImpl: container_1568623076950_0001_01_000023 Container Transitioned from RUNNING to COMPLETED
2019-09-16 06:07:04,509 INFO org.apache.hadoop.yarn.server.resourcemanager.scheduler.common.fica.FiCaSchedulerApp: Completed container: container_1568623076950_0001_01_000023 in state: COMPLETED event:FINISHED
2019-09-16 06:07:04,509 INFO org.apache.hadoop.yarn.server.resourcemanager.RMAuditLogger: USER=root	OPERATION=AM Released Container	TARGET=SchedulerApp	RESULT=SUCCESS	APPID=application_1568623076950_0001	CONTAINERID=container_1568623076950_0001_01_000023
2019-09-16 06:07:04,509 INFO org.apache.hadoop.yarn.server.resourcemanager.scheduler.SchedulerNode: Released container container_1568623076950_0001_01_000023 of capacity <memory:1024, vCores:1> on host e9a6a0455f0d:38503, which currently has 5 containers, <memory:6144, vCores:5> used and <memory:2048, vCores:3> available, release resources=true
2019-09-16 06:07:04,510 INFO org.apache.hadoop.yarn.server.resourcemanager.scheduler.capacity.LeafQueue: default used=<memory:6144, vCores:5> numContainers=5 user=root user-resources=<memory:6144, vCores:5>
2019-09-16 06:07:04,510 INFO org.apache.hadoop.yarn.server.resourcemanager.scheduler.capacity.LeafQueue: completedContainer container=Container: [ContainerId: container_1568623076950_0001_01_000023, NodeId: e9a6a0455f0d:38503, NodeHttpAddress: e9a6a0455f0d:8042, Resource: <memory:1024, vCores:1>, Priority: 20, Token: Token { kind: ContainerToken, service: 172.24.0.2:38503 }, ] queue=default: capacity=1.0, absoluteCapacity=1.0, usedResources=<memory:6144, vCores:5>, usedCapacity=0.75, absoluteUsedCapacity=0.75, numApps=1, numContainers=5 cluster=<memory:8192, vCores:8>
2019-09-16 06:07:04,511 INFO org.apache.hadoop.yarn.server.resourcemanager.scheduler.capacity.ParentQueue: completedContainer queue=root usedCapacity=0.75 absoluteUsedCapacity=0.75 used=<memory:6144, vCores:5> cluster=<memory:8192, vCores:8>
2019-09-16 06:07:04,511 INFO org.apache.hadoop.yarn.server.resourcemanager.scheduler.capacity.ParentQueue: Re-sorting completed queue: root.default stats: default: capacity=1.0, absoluteCapacity=1.0, usedResources=<memory:6144, vCores:5>, usedCapacity=0.75, absoluteUsedCapacity=0.75, numApps=1, numContainers=5
2019-09-16 06:07:04,511 INFO org.apache.hadoop.yarn.server.resourcemanager.scheduler.capacity.CapacityScheduler: Application attempt appattempt_1568623076950_0001_000001 released container container_1568623076950_0001_01_000023 on node: host: e9a6a0455f0d:38503 #containers=5 available=<memory:2048, vCores:3> used=<memory:6144, vCores:5> with event: FINISHED
2019-09-16 06:07:04,512 INFO org.apache.hadoop.yarn.server.resourcemanager.rmcontainer.RMContainerImpl: container_1568623076950_0001_01_000024 Container Transitioned from NEW to ALLOCATED
2019-09-16 06:07:04,512 INFO org.apache.hadoop.yarn.server.resourcemanager.RMAuditLogger: USER=root	OPERATION=AM Allocated Container	TARGET=SchedulerApp	RESULT=SUCCESS	APPID=application_1568623076950_0001	CONTAINERID=container_1568623076950_0001_01_000024
2019-09-16 06:07:04,512 INFO org.apache.hadoop.yarn.server.resourcemanager.scheduler.SchedulerNode: Assigned container container_1568623076950_0001_01_000024 of capacity <memory:1024, vCores:1> on host e9a6a0455f0d:38503, which has 6 containers, <memory:7168, vCores:6> used and <memory:1024, vCores:2> available after allocation
2019-09-16 06:07:04,513 INFO org.apache.hadoop.yarn.server.resourcemanager.scheduler.capacity.LeafQueue: assignedContainer application attempt=appattempt_1568623076950_0001_000001 container=Container: [ContainerId: container_1568623076950_0001_01_000024, NodeId: e9a6a0455f0d:38503, NodeHttpAddress: e9a6a0455f0d:8042, Resource: <memory:1024, vCores:1>, Priority: 20, Token: null, ] queue=default: capacity=1.0, absoluteCapacity=1.0, usedResources=<memory:6144, vCores:5>, usedCapacity=0.75, absoluteUsedCapacity=0.75, numApps=1, numContainers=5 clusterResource=<memory:8192, vCores:8>
2019-09-16 06:07:04,513 INFO org.apache.hadoop.yarn.server.resourcemanager.scheduler.capacity.ParentQueue: Re-sorting assigned queue: root.default stats: default: capacity=1.0, absoluteCapacity=1.0, usedResources=<memory:7168, vCores:6>, usedCapacity=0.875, absoluteUsedCapacity=0.875, numApps=1, numContainers=6
2019-09-16 06:07:04,514 INFO org.apache.hadoop.yarn.server.resourcemanager.scheduler.capacity.ParentQueue: assignedContainer queue=root usedCapacity=0.875 absoluteUsedCapacity=0.875 used=<memory:7168, vCores:6> cluster=<memory:8192, vCores:8>
2019-09-16 06:07:04,514 INFO org.apache.hadoop.yarn.server.resourcemanager.rmcontainer.RMContainerImpl: container_1568623076950_0001_01_000025 Container Transitioned from NEW to ALLOCATED
2019-09-16 06:07:04,514 INFO org.apache.hadoop.yarn.server.resourcemanager.RMAuditLogger: USER=root	OPERATION=AM Allocated Container	TARGET=SchedulerApp	RESULT=SUCCESS	APPID=application_1568623076950_0001	CONTAINERID=container_1568623076950_0001_01_000025
2019-09-16 06:07:04,515 INFO org.apache.hadoop.yarn.server.resourcemanager.scheduler.SchedulerNode: Assigned container container_1568623076950_0001_01_000025 of capacity <memory:1024, vCores:1> on host e9a6a0455f0d:38503, which has 7 containers, <memory:8192, vCores:7> used and <memory:0, vCores:1> available after allocation
2019-09-16 06:07:04,515 INFO org.apache.hadoop.yarn.server.resourcemanager.scheduler.capacity.LeafQueue: assignedContainer application attempt=appattempt_1568623076950_0001_000001 container=Container: [ContainerId: container_1568623076950_0001_01_000025, NodeId: e9a6a0455f0d:38503, NodeHttpAddress: e9a6a0455f0d:8042, Resource: <memory:1024, vCores:1>, Priority: 20, Token: null, ] queue=default: capacity=1.0, absoluteCapacity=1.0, usedResources=<memory:7168, vCores:6>, usedCapacity=0.875, absoluteUsedCapacity=0.875, numApps=1, numContainers=6 clusterResource=<memory:8192, vCores:8>
2019-09-16 06:07:04,516 INFO org.apache.hadoop.yarn.server.resourcemanager.scheduler.capacity.ParentQueue: Re-sorting assigned queue: root.default stats: default: capacity=1.0, absoluteCapacity=1.0, usedResources=<memory:8192, vCores:7>, usedCapacity=1.0, absoluteUsedCapacity=1.0, numApps=1, numContainers=7
2019-09-16 06:07:04,516 INFO org.apache.hadoop.yarn.server.resourcemanager.scheduler.capacity.ParentQueue: assignedContainer queue=root usedCapacity=1.0 absoluteUsedCapacity=1.0 used=<memory:8192, vCores:7> cluster=<memory:8192, vCores:8>
2019-09-16 06:07:05,142 INFO org.apache.hadoop.yarn.server.resourcemanager.rmcontainer.RMContainerImpl: container_1568623076950_0001_01_000024 Container Transitioned from ALLOCATED to ACQUIRED
2019-09-16 06:07:05,199 INFO org.apache.hadoop.yarn.server.resourcemanager.rmcontainer.RMContainerImpl: container_1568623076950_0001_01_000025 Container Transitioned from ALLOCATED to ACQUIRED
2019-09-16 06:07:05,558 INFO org.apache.hadoop.yarn.server.resourcemanager.rmcontainer.RMContainerImpl: container_1568623076950_0001_01_000024 Container Transitioned from ACQUIRED to RUNNING
2019-09-16 06:07:05,559 INFO org.apache.hadoop.yarn.server.resourcemanager.rmcontainer.RMContainerImpl: container_1568623076950_0001_01_000025 Container Transitioned from ACQUIRED to RUNNING
2019-09-16 06:07:05,560 INFO org.apache.hadoop.yarn.server.resourcemanager.rmcontainer.RMContainerImpl: container_1568623076950_0001_01_000019 Container Transitioned from RUNNING to COMPLETED
2019-09-16 06:07:05,560 INFO org.apache.hadoop.yarn.server.resourcemanager.scheduler.common.fica.FiCaSchedulerApp: Completed container: container_1568623076950_0001_01_000019 in state: COMPLETED event:FINISHED
2019-09-16 06:07:05,560 INFO org.apache.hadoop.yarn.server.resourcemanager.RMAuditLogger: USER=root	OPERATION=AM Released Container	TARGET=SchedulerApp	RESULT=SUCCESS	APPID=application_1568623076950_0001	CONTAINERID=container_1568623076950_0001_01_000019
2019-09-16 06:07:05,560 INFO org.apache.hadoop.yarn.server.resourcemanager.scheduler.SchedulerNode: Released container container_1568623076950_0001_01_000019 of capacity <memory:1024, vCores:1> on host e9a6a0455f0d:38503, which currently has 6 containers, <memory:7168, vCores:6> used and <memory:1024, vCores:2> available, release resources=true
2019-09-16 06:07:05,560 INFO org.apache.hadoop.yarn.server.resourcemanager.scheduler.capacity.LeafQueue: default used=<memory:7168, vCores:6> numContainers=6 user=root user-resources=<memory:7168, vCores:6>
2019-09-16 06:07:05,562 INFO org.apache.hadoop.yarn.server.resourcemanager.scheduler.capacity.LeafQueue: completedContainer container=Container: [ContainerId: container_1568623076950_0001_01_000019, NodeId: e9a6a0455f0d:38503, NodeHttpAddress: e9a6a0455f0d:8042, Resource: <memory:1024, vCores:1>, Priority: 20, Token: Token { kind: ContainerToken, service: 172.24.0.2:38503 }, ] queue=default: capacity=1.0, absoluteCapacity=1.0, usedResources=<memory:7168, vCores:6>, usedCapacity=0.875, absoluteUsedCapacity=0.875, numApps=1, numContainers=6 cluster=<memory:8192, vCores:8>
2019-09-16 06:07:05,562 INFO org.apache.hadoop.yarn.server.resourcemanager.scheduler.capacity.ParentQueue: completedContainer queue=root usedCapacity=0.875 absoluteUsedCapacity=0.875 used=<memory:7168, vCores:6> cluster=<memory:8192, vCores:8>
2019-09-16 06:07:05,562 INFO org.apache.hadoop.yarn.server.resourcemanager.scheduler.capacity.ParentQueue: Re-sorting completed queue: root.default stats: default: capacity=1.0, absoluteCapacity=1.0, usedResources=<memory:7168, vCores:6>, usedCapacity=0.875, absoluteUsedCapacity=0.875, numApps=1, numContainers=6
2019-09-16 06:07:05,563 INFO org.apache.hadoop.yarn.server.resourcemanager.scheduler.capacity.CapacityScheduler: Application attempt appattempt_1568623076950_0001_000001 released container container_1568623076950_0001_01_000019 on node: host: e9a6a0455f0d:38503 #containers=6 available=<memory:1024, vCores:2> used=<memory:7168, vCores:6> with event: FINISHED
2019-09-16 06:07:05,563 INFO org.apache.hadoop.yarn.server.resourcemanager.rmcontainer.RMContainerImpl: container_1568623076950_0001_01_000020 Container Transitioned from RUNNING to COMPLETED
2019-09-16 06:07:05,563 INFO org.apache.hadoop.yarn.server.resourcemanager.scheduler.common.fica.FiCaSchedulerApp: Completed container: container_1568623076950_0001_01_000020 in state: COMPLETED event:FINISHED
2019-09-16 06:07:05,564 INFO org.apache.hadoop.yarn.server.resourcemanager.RMAuditLogger: USER=root	OPERATION=AM Released Container	TARGET=SchedulerApp	RESULT=SUCCESS	APPID=application_1568623076950_0001	CONTAINERID=container_1568623076950_0001_01_000020
2019-09-16 06:07:05,564 INFO org.apache.hadoop.yarn.server.resourcemanager.scheduler.SchedulerNode: Released container container_1568623076950_0001_01_000020 of capacity <memory:1024, vCores:1> on host e9a6a0455f0d:38503, which currently has 5 containers, <memory:6144, vCores:5> used and <memory:2048, vCores:3> available, release resources=true
2019-09-16 06:07:05,564 INFO org.apache.hadoop.yarn.server.resourcemanager.scheduler.capacity.LeafQueue: default used=<memory:6144, vCores:5> numContainers=5 user=root user-resources=<memory:6144, vCores:5>
2019-09-16 06:07:05,565 INFO org.apache.hadoop.yarn.server.resourcemanager.scheduler.capacity.LeafQueue: completedContainer container=Container: [ContainerId: container_1568623076950_0001_01_000020, NodeId: e9a6a0455f0d:38503, NodeHttpAddress: e9a6a0455f0d:8042, Resource: <memory:1024, vCores:1>, Priority: 20, Token: Token { kind: ContainerToken, service: 172.24.0.2:38503 }, ] queue=default: capacity=1.0, absoluteCapacity=1.0, usedResources=<memory:6144, vCores:5>, usedCapacity=0.75, absoluteUsedCapacity=0.75, numApps=1, numContainers=5 cluster=<memory:8192, vCores:8>
2019-09-16 06:07:05,565 INFO org.apache.hadoop.yarn.server.resourcemanager.scheduler.capacity.ParentQueue: completedContainer queue=root usedCapacity=0.75 absoluteUsedCapacity=0.75 used=<memory:6144, vCores:5> cluster=<memory:8192, vCores:8>
2019-09-16 06:07:05,565 INFO org.apache.hadoop.yarn.server.resourcemanager.scheduler.capacity.ParentQueue: Re-sorting completed queue: root.default stats: default: capacity=1.0, absoluteCapacity=1.0, usedResources=<memory:6144, vCores:5>, usedCapacity=0.75, absoluteUsedCapacity=0.75, numApps=1, numContainers=5
2019-09-16 06:07:05,566 INFO org.apache.hadoop.yarn.server.resourcemanager.scheduler.capacity.CapacityScheduler: Application attempt appattempt_1568623076950_0001_000001 released container container_1568623076950_0001_01_000020 on node: host: e9a6a0455f0d:38503 #containers=5 available=<memory:2048, vCores:3> used=<memory:6144, vCores:5> with event: FINISHED
2019-09-16 06:07:05,566 INFO org.apache.hadoop.yarn.server.resourcemanager.rmcontainer.RMContainerImpl: container_1568623076950_0001_01_000021 Container Transitioned from RUNNING to COMPLETED
2019-09-16 06:07:05,566 INFO org.apache.hadoop.yarn.server.resourcemanager.scheduler.common.fica.FiCaSchedulerApp: Completed container: container_1568623076950_0001_01_000021 in state: COMPLETED event:FINISHED
2019-09-16 06:07:05,728 INFO org.apache.hadoop.yarn.server.resourcemanager.RMAuditLogger: USER=root	OPERATION=AM Released Container	TARGET=SchedulerApp	RESULT=SUCCESS	APPID=application_1568623076950_0001	CONTAINERID=container_1568623076950_0001_01_000021
2019-09-16 06:07:05,728 INFO org.apache.hadoop.yarn.server.resourcemanager.scheduler.SchedulerNode: Released container container_1568623076950_0001_01_000021 of capacity <memory:1024, vCores:1> on host e9a6a0455f0d:38503, which currently has 4 containers, <memory:5120, vCores:4> used and <memory:3072, vCores:4> available, release resources=true
2019-09-16 06:07:05,729 INFO org.apache.hadoop.yarn.server.resourcemanager.scheduler.capacity.LeafQueue: default used=<memory:5120, vCores:4> numContainers=4 user=root user-resources=<memory:5120, vCores:4>
2019-09-16 06:07:05,729 INFO org.apache.hadoop.yarn.server.resourcemanager.scheduler.capacity.LeafQueue: completedContainer container=Container: [ContainerId: container_1568623076950_0001_01_000021, NodeId: e9a6a0455f0d:38503, NodeHttpAddress: e9a6a0455f0d:8042, Resource: <memory:1024, vCores:1>, Priority: 20, Token: Token { kind: ContainerToken, service: 172.24.0.2:38503 }, ] queue=default: capacity=1.0, absoluteCapacity=1.0, usedResources=<memory:5120, vCores:4>, usedCapacity=0.625, absoluteUsedCapacity=0.625, numApps=1, numContainers=4 cluster=<memory:8192, vCores:8>
2019-09-16 06:07:05,730 INFO org.apache.hadoop.yarn.server.resourcemanager.scheduler.capacity.ParentQueue: completedContainer queue=root usedCapacity=0.625 absoluteUsedCapacity=0.625 used=<memory:5120, vCores:4> cluster=<memory:8192, vCores:8>
2019-09-16 06:07:05,730 INFO org.apache.hadoop.yarn.server.resourcemanager.scheduler.capacity.ParentQueue: Re-sorting completed queue: root.default stats: default: capacity=1.0, absoluteCapacity=1.0, usedResources=<memory:5120, vCores:4>, usedCapacity=0.625, absoluteUsedCapacity=0.625, numApps=1, numContainers=4
2019-09-16 06:07:05,730 INFO org.apache.hadoop.yarn.server.resourcemanager.scheduler.capacity.CapacityScheduler: Application attempt appattempt_1568623076950_0001_000001 released container container_1568623076950_0001_01_000021 on node: host: e9a6a0455f0d:38503 #containers=4 available=<memory:3072, vCores:4> used=<memory:5120, vCores:4> with event: FINISHED
2019-09-16 06:07:05,731 INFO org.apache.hadoop.yarn.server.resourcemanager.rmcontainer.RMContainerImpl: container_1568623076950_0001_01_000026 Container Transitioned from NEW to ALLOCATED
2019-09-16 06:07:05,731 INFO org.apache.hadoop.yarn.server.resourcemanager.RMAuditLogger: USER=root	OPERATION=AM Allocated Container	TARGET=SchedulerApp	RESULT=SUCCESS	APPID=application_1568623076950_0001	CONTAINERID=container_1568623076950_0001_01_000026
2019-09-16 06:07:05,732 INFO org.apache.hadoop.yarn.server.resourcemanager.scheduler.SchedulerNode: Assigned container container_1568623076950_0001_01_000026 of capacity <memory:1024, vCores:1> on host e9a6a0455f0d:38503, which has 5 containers, <memory:6144, vCores:5> used and <memory:2048, vCores:3> available after allocation
2019-09-16 06:07:05,732 INFO org.apache.hadoop.yarn.server.resourcemanager.scheduler.capacity.LeafQueue: assignedContainer application attempt=appattempt_1568623076950_0001_000001 container=Container: [ContainerId: container_1568623076950_0001_01_000026, NodeId: e9a6a0455f0d:38503, NodeHttpAddress: e9a6a0455f0d:8042, Resource: <memory:1024, vCores:1>, Priority: 20, Token: null, ] queue=default: capacity=1.0, absoluteCapacity=1.0, usedResources=<memory:5120, vCores:4>, usedCapacity=0.625, absoluteUsedCapacity=0.625, numApps=1, numContainers=4 clusterResource=<memory:8192, vCores:8>
2019-09-16 06:07:05,733 INFO org.apache.hadoop.yarn.server.resourcemanager.scheduler.capacity.ParentQueue: Re-sorting assigned queue: root.default stats: default: capacity=1.0, absoluteCapacity=1.0, usedResources=<memory:6144, vCores:5>, usedCapacity=0.75, absoluteUsedCapacity=0.75, numApps=1, numContainers=5
2019-09-16 06:07:05,733 INFO org.apache.hadoop.yarn.server.resourcemanager.scheduler.capacity.ParentQueue: assignedContainer queue=root usedCapacity=0.75 absoluteUsedCapacity=0.75 used=<memory:6144, vCores:5> cluster=<memory:8192, vCores:8>
2019-09-16 06:07:05,734 INFO org.apache.hadoop.yarn.server.resourcemanager.rmcontainer.RMContainerImpl: container_1568623076950_0001_01_000027 Container Transitioned from NEW to ALLOCATED
2019-09-16 06:07:05,734 INFO org.apache.hadoop.yarn.server.resourcemanager.RMAuditLogger: USER=root	OPERATION=AM Allocated Container	TARGET=SchedulerApp	RESULT=SUCCESS	APPID=application_1568623076950_0001	CONTAINERID=container_1568623076950_0001_01_000027
2019-09-16 06:07:05,735 INFO org.apache.hadoop.yarn.server.resourcemanager.scheduler.SchedulerNode: Assigned container container_1568623076950_0001_01_000027 of capacity <memory:1024, vCores:1> on host e9a6a0455f0d:38503, which has 6 containers, <memory:7168, vCores:6> used and <memory:1024, vCores:2> available after allocation
2019-09-16 06:07:05,735 INFO org.apache.hadoop.yarn.server.resourcemanager.scheduler.capacity.LeafQueue: assignedContainer application attempt=appattempt_1568623076950_0001_000001 container=Container: [ContainerId: container_1568623076950_0001_01_000027, NodeId: e9a6a0455f0d:38503, NodeHttpAddress: e9a6a0455f0d:8042, Resource: <memory:1024, vCores:1>, Priority: 20, Token: null, ] queue=default: capacity=1.0, absoluteCapacity=1.0, usedResources=<memory:6144, vCores:5>, usedCapacity=0.75, absoluteUsedCapacity=0.75, numApps=1, numContainers=5 clusterResource=<memory:8192, vCores:8>
2019-09-16 06:07:05,736 INFO org.apache.hadoop.yarn.server.resourcemanager.scheduler.capacity.ParentQueue: Re-sorting assigned queue: root.default stats: default: capacity=1.0, absoluteCapacity=1.0, usedResources=<memory:7168, vCores:6>, usedCapacity=0.875, absoluteUsedCapacity=0.875, numApps=1, numContainers=6
2019-09-16 06:07:05,736 INFO org.apache.hadoop.yarn.server.resourcemanager.scheduler.capacity.ParentQueue: assignedContainer queue=root usedCapacity=0.875 absoluteUsedCapacity=0.875 used=<memory:7168, vCores:6> cluster=<memory:8192, vCores:8>
2019-09-16 06:07:05,737 INFO org.apache.hadoop.yarn.server.resourcemanager.rmcontainer.RMContainerImpl: container_1568623076950_0001_01_000028 Container Transitioned from NEW to ALLOCATED
2019-09-16 06:07:05,795 INFO org.apache.hadoop.yarn.server.resourcemanager.RMAuditLogger: USER=root	OPERATION=AM Allocated Container	TARGET=SchedulerApp	RESULT=SUCCESS	APPID=application_1568623076950_0001	CONTAINERID=container_1568623076950_0001_01_000028
2019-09-16 06:07:05,795 INFO org.apache.hadoop.yarn.server.resourcemanager.scheduler.SchedulerNode: Assigned container container_1568623076950_0001_01_000028 of capacity <memory:1024, vCores:1> on host e9a6a0455f0d:38503, which has 7 containers, <memory:8192, vCores:7> used and <memory:0, vCores:1> available after allocation
2019-09-16 06:07:05,796 INFO org.apache.hadoop.yarn.server.resourcemanager.scheduler.capacity.LeafQueue: assignedContainer application attempt=appattempt_1568623076950_0001_000001 container=Container: [ContainerId: container_1568623076950_0001_01_000028, NodeId: e9a6a0455f0d:38503, NodeHttpAddress: e9a6a0455f0d:8042, Resource: <memory:1024, vCores:1>, Priority: 20, Token: null, ] queue=default: capacity=1.0, absoluteCapacity=1.0, usedResources=<memory:7168, vCores:6>, usedCapacity=0.875, absoluteUsedCapacity=0.875, numApps=1, numContainers=6 clusterResource=<memory:8192, vCores:8>
2019-09-16 06:07:05,796 INFO org.apache.hadoop.yarn.server.resourcemanager.scheduler.capacity.ParentQueue: Re-sorting assigned queue: root.default stats: default: capacity=1.0, absoluteCapacity=1.0, usedResources=<memory:8192, vCores:7>, usedCapacity=1.0, absoluteUsedCapacity=1.0, numApps=1, numContainers=7
2019-09-16 06:07:05,796 INFO org.apache.hadoop.yarn.server.resourcemanager.scheduler.capacity.ParentQueue: assignedContainer queue=root usedCapacity=1.0 absoluteUsedCapacity=1.0 used=<memory:8192, vCores:7> cluster=<memory:8192, vCores:8>
2019-09-16 06:07:06,328 INFO org.apache.hadoop.yarn.server.resourcemanager.rmcontainer.RMContainerImpl: container_1568623076950_0001_01_000026 Container Transitioned from ALLOCATED to ACQUIRED
2019-09-16 06:07:06,337 INFO org.apache.hadoop.yarn.server.resourcemanager.rmcontainer.RMContainerImpl: container_1568623076950_0001_01_000027 Container Transitioned from ALLOCATED to ACQUIRED
2019-09-16 06:07:06,348 INFO org.apache.hadoop.yarn.server.resourcemanager.rmcontainer.RMContainerImpl: container_1568623076950_0001_01_000028 Container Transitioned from ALLOCATED to ACQUIRED
2019-09-16 06:07:06,546 INFO org.apache.hadoop.yarn.server.resourcemanager.rmcontainer.RMContainerImpl: container_1568623076950_0001_01_000026 Container Transitioned from ACQUIRED to RUNNING
2019-09-16 06:07:06,546 INFO org.apache.hadoop.yarn.server.resourcemanager.rmcontainer.RMContainerImpl: container_1568623076950_0001_01_000027 Container Transitioned from ACQUIRED to RUNNING
2019-09-16 06:07:06,546 INFO org.apache.hadoop.yarn.server.resourcemanager.rmcontainer.RMContainerImpl: container_1568623076950_0001_01_000028 Container Transitioned from ACQUIRED to RUNNING
2019-09-16 06:07:13,901 INFO org.apache.hadoop.yarn.server.resourcemanager.rmcontainer.RMContainerImpl: container_1568623076950_0001_01_000024 Container Transitioned from RUNNING to COMPLETED
2019-09-16 06:07:13,901 INFO org.apache.hadoop.yarn.server.resourcemanager.scheduler.common.fica.FiCaSchedulerApp: Completed container: container_1568623076950_0001_01_000024 in state: COMPLETED event:FINISHED
2019-09-16 06:07:13,901 INFO org.apache.hadoop.yarn.server.resourcemanager.RMAuditLogger: USER=root	OPERATION=AM Released Container	TARGET=SchedulerApp	RESULT=SUCCESS	APPID=application_1568623076950_0001	CONTAINERID=container_1568623076950_0001_01_000024
2019-09-16 06:07:13,901 INFO org.apache.hadoop.yarn.server.resourcemanager.scheduler.SchedulerNode: Released container container_1568623076950_0001_01_000024 of capacity <memory:1024, vCores:1> on host e9a6a0455f0d:38503, which currently has 6 containers, <memory:7168, vCores:6> used and <memory:1024, vCores:2> available, release resources=true
2019-09-16 06:07:13,902 INFO org.apache.hadoop.yarn.server.resourcemanager.scheduler.capacity.LeafQueue: default used=<memory:7168, vCores:6> numContainers=6 user=root user-resources=<memory:7168, vCores:6>
2019-09-16 06:07:13,902 INFO org.apache.hadoop.yarn.server.resourcemanager.scheduler.capacity.LeafQueue: completedContainer container=Container: [ContainerId: container_1568623076950_0001_01_000024, NodeId: e9a6a0455f0d:38503, NodeHttpAddress: e9a6a0455f0d:8042, Resource: <memory:1024, vCores:1>, Priority: 20, Token: Token { kind: ContainerToken, service: 172.24.0.2:38503 }, ] queue=default: capacity=1.0, absoluteCapacity=1.0, usedResources=<memory:7168, vCores:6>, usedCapacity=0.875, absoluteUsedCapacity=0.875, numApps=1, numContainers=6 cluster=<memory:8192, vCores:8>
2019-09-16 06:07:13,902 INFO org.apache.hadoop.yarn.server.resourcemanager.scheduler.capacity.ParentQueue: completedContainer queue=root usedCapacity=0.875 absoluteUsedCapacity=0.875 used=<memory:7168, vCores:6> cluster=<memory:8192, vCores:8>
2019-09-16 06:07:13,903 INFO org.apache.hadoop.yarn.server.resourcemanager.scheduler.capacity.ParentQueue: Re-sorting completed queue: root.default stats: default: capacity=1.0, absoluteCapacity=1.0, usedResources=<memory:7168, vCores:6>, usedCapacity=0.875, absoluteUsedCapacity=0.875, numApps=1, numContainers=6
2019-09-16 06:07:13,903 INFO org.apache.hadoop.yarn.server.resourcemanager.scheduler.capacity.CapacityScheduler: Application attempt appattempt_1568623076950_0001_000001 released container container_1568623076950_0001_01_000024 on node: host: e9a6a0455f0d:38503 #containers=6 available=<memory:1024, vCores:2> used=<memory:7168, vCores:6> with event: FINISHED
2019-09-16 06:07:13,903 INFO org.apache.hadoop.yarn.server.resourcemanager.rmcontainer.RMContainerImpl: container_1568623076950_0001_01_000025 Container Transitioned from RUNNING to COMPLETED
2019-09-16 06:07:13,904 INFO org.apache.hadoop.yarn.server.resourcemanager.scheduler.common.fica.FiCaSchedulerApp: Completed container: container_1568623076950_0001_01_000025 in state: COMPLETED event:FINISHED
2019-09-16 06:07:13,904 INFO org.apache.hadoop.yarn.server.resourcemanager.RMAuditLogger: USER=root	OPERATION=AM Released Container	TARGET=SchedulerApp	RESULT=SUCCESS	APPID=application_1568623076950_0001	CONTAINERID=container_1568623076950_0001_01_000025
2019-09-16 06:07:13,904 INFO org.apache.hadoop.yarn.server.resourcemanager.scheduler.SchedulerNode: Released container container_1568623076950_0001_01_000025 of capacity <memory:1024, vCores:1> on host e9a6a0455f0d:38503, which currently has 5 containers, <memory:6144, vCores:5> used and <memory:2048, vCores:3> available, release resources=true
2019-09-16 06:07:13,904 INFO org.apache.hadoop.yarn.server.resourcemanager.scheduler.capacity.LeafQueue: default used=<memory:6144, vCores:5> numContainers=5 user=root user-resources=<memory:6144, vCores:5>
2019-09-16 06:07:13,904 INFO org.apache.hadoop.yarn.server.resourcemanager.scheduler.capacity.LeafQueue: completedContainer container=Container: [ContainerId: container_1568623076950_0001_01_000025, NodeId: e9a6a0455f0d:38503, NodeHttpAddress: e9a6a0455f0d:8042, Resource: <memory:1024, vCores:1>, Priority: 20, Token: Token { kind: ContainerToken, service: 172.24.0.2:38503 }, ] queue=default: capacity=1.0, absoluteCapacity=1.0, usedResources=<memory:6144, vCores:5>, usedCapacity=0.75, absoluteUsedCapacity=0.75, numApps=1, numContainers=5 cluster=<memory:8192, vCores:8>
2019-09-16 06:07:13,905 INFO org.apache.hadoop.yarn.server.resourcemanager.scheduler.capacity.ParentQueue: completedContainer queue=root usedCapacity=0.75 absoluteUsedCapacity=0.75 used=<memory:6144, vCores:5> cluster=<memory:8192, vCores:8>
2019-09-16 06:07:13,905 INFO org.apache.hadoop.yarn.server.resourcemanager.scheduler.capacity.ParentQueue: Re-sorting completed queue: root.default stats: default: capacity=1.0, absoluteCapacity=1.0, usedResources=<memory:6144, vCores:5>, usedCapacity=0.75, absoluteUsedCapacity=0.75, numApps=1, numContainers=5
2019-09-16 06:07:13,905 INFO org.apache.hadoop.yarn.server.resourcemanager.scheduler.capacity.CapacityScheduler: Application attempt appattempt_1568623076950_0001_000001 released container container_1568623076950_0001_01_000025 on node: host: e9a6a0455f0d:38503 #containers=5 available=<memory:2048, vCores:3> used=<memory:6144, vCores:5> with event: FINISHED
2019-09-16 06:07:13,907 INFO org.apache.hadoop.yarn.server.resourcemanager.rmcontainer.RMContainerImpl: container_1568623076950_0001_01_000029 Container Transitioned from NEW to ALLOCATED
2019-09-16 06:07:13,908 INFO org.apache.hadoop.yarn.server.resourcemanager.RMAuditLogger: USER=root	OPERATION=AM Allocated Container	TARGET=SchedulerApp	RESULT=SUCCESS	APPID=application_1568623076950_0001	CONTAINERID=container_1568623076950_0001_01_000029
2019-09-16 06:07:13,908 INFO org.apache.hadoop.yarn.server.resourcemanager.scheduler.SchedulerNode: Assigned container container_1568623076950_0001_01_000029 of capacity <memory:1024, vCores:1> on host e9a6a0455f0d:38503, which has 6 containers, <memory:7168, vCores:6> used and <memory:1024, vCores:2> available after allocation
2019-09-16 06:07:13,908 INFO org.apache.hadoop.yarn.server.resourcemanager.scheduler.capacity.LeafQueue: assignedContainer application attempt=appattempt_1568623076950_0001_000001 container=Container: [ContainerId: container_1568623076950_0001_01_000029, NodeId: e9a6a0455f0d:38503, NodeHttpAddress: e9a6a0455f0d:8042, Resource: <memory:1024, vCores:1>, Priority: 20, Token: null, ] queue=default: capacity=1.0, absoluteCapacity=1.0, usedResources=<memory:6144, vCores:5>, usedCapacity=0.75, absoluteUsedCapacity=0.75, numApps=1, numContainers=5 clusterResource=<memory:8192, vCores:8>
2019-09-16 06:07:13,909 INFO org.apache.hadoop.yarn.server.resourcemanager.scheduler.capacity.ParentQueue: Re-sorting assigned queue: root.default stats: default: capacity=1.0, absoluteCapacity=1.0, usedResources=<memory:7168, vCores:6>, usedCapacity=0.875, absoluteUsedCapacity=0.875, numApps=1, numContainers=6
2019-09-16 06:07:13,909 INFO org.apache.hadoop.yarn.server.resourcemanager.scheduler.capacity.ParentQueue: assignedContainer queue=root usedCapacity=0.875 absoluteUsedCapacity=0.875 used=<memory:7168, vCores:6> cluster=<memory:8192, vCores:8>
2019-09-16 06:07:13,910 INFO org.apache.hadoop.yarn.server.resourcemanager.rmcontainer.RMContainerImpl: container_1568623076950_0001_01_000030 Container Transitioned from NEW to ALLOCATED
2019-09-16 06:07:13,910 INFO org.apache.hadoop.yarn.server.resourcemanager.RMAuditLogger: USER=root	OPERATION=AM Allocated Container	TARGET=SchedulerApp	RESULT=SUCCESS	APPID=application_1568623076950_0001	CONTAINERID=container_1568623076950_0001_01_000030
2019-09-16 06:07:13,910 INFO org.apache.hadoop.yarn.server.resourcemanager.scheduler.SchedulerNode: Assigned container container_1568623076950_0001_01_000030 of capacity <memory:1024, vCores:1> on host e9a6a0455f0d:38503, which has 7 containers, <memory:8192, vCores:7> used and <memory:0, vCores:1> available after allocation
2019-09-16 06:07:13,912 INFO org.apache.hadoop.yarn.server.resourcemanager.scheduler.capacity.LeafQueue: assignedContainer application attempt=appattempt_1568623076950_0001_000001 container=Container: [ContainerId: container_1568623076950_0001_01_000030, NodeId: e9a6a0455f0d:38503, NodeHttpAddress: e9a6a0455f0d:8042, Resource: <memory:1024, vCores:1>, Priority: 20, Token: null, ] queue=default: capacity=1.0, absoluteCapacity=1.0, usedResources=<memory:7168, vCores:6>, usedCapacity=0.875, absoluteUsedCapacity=0.875, numApps=1, numContainers=6 clusterResource=<memory:8192, vCores:8>
2019-09-16 06:07:13,913 INFO org.apache.hadoop.yarn.server.resourcemanager.scheduler.capacity.ParentQueue: Re-sorting assigned queue: root.default stats: default: capacity=1.0, absoluteCapacity=1.0, usedResources=<memory:8192, vCores:7>, usedCapacity=1.0, absoluteUsedCapacity=1.0, numApps=1, numContainers=7
2019-09-16 06:07:13,914 INFO org.apache.hadoop.yarn.server.resourcemanager.scheduler.capacity.ParentQueue: assignedContainer queue=root usedCapacity=1.0 absoluteUsedCapacity=1.0 used=<memory:8192, vCores:7> cluster=<memory:8192, vCores:8>
2019-09-16 06:07:14,330 INFO org.apache.hadoop.yarn.server.resourcemanager.rmcontainer.RMContainerImpl: container_1568623076950_0001_01_000027 Container Transitioned from RUNNING to COMPLETED
2019-09-16 06:07:14,330 INFO org.apache.hadoop.yarn.server.resourcemanager.scheduler.common.fica.FiCaSchedulerApp: Completed container: container_1568623076950_0001_01_000027 in state: COMPLETED event:FINISHED
2019-09-16 06:07:14,330 INFO org.apache.hadoop.yarn.server.resourcemanager.RMAuditLogger: USER=root	OPERATION=AM Released Container	TARGET=SchedulerApp	RESULT=SUCCESS	APPID=application_1568623076950_0001	CONTAINERID=container_1568623076950_0001_01_000027
2019-09-16 06:07:14,332 INFO org.apache.hadoop.yarn.server.resourcemanager.scheduler.SchedulerNode: Released container container_1568623076950_0001_01_000027 of capacity <memory:1024, vCores:1> on host e9a6a0455f0d:38503, which currently has 6 containers, <memory:7168, vCores:6> used and <memory:1024, vCores:2> available, release resources=true
2019-09-16 06:07:14,332 INFO org.apache.hadoop.yarn.server.resourcemanager.scheduler.capacity.LeafQueue: default used=<memory:7168, vCores:6> numContainers=6 user=root user-resources=<memory:7168, vCores:6>
2019-09-16 06:07:14,333 INFO org.apache.hadoop.yarn.server.resourcemanager.scheduler.capacity.LeafQueue: completedContainer container=Container: [ContainerId: container_1568623076950_0001_01_000027, NodeId: e9a6a0455f0d:38503, NodeHttpAddress: e9a6a0455f0d:8042, Resource: <memory:1024, vCores:1>, Priority: 20, Token: Token { kind: ContainerToken, service: 172.24.0.2:38503 }, ] queue=default: capacity=1.0, absoluteCapacity=1.0, usedResources=<memory:7168, vCores:6>, usedCapacity=0.875, absoluteUsedCapacity=0.875, numApps=1, numContainers=6 cluster=<memory:8192, vCores:8>
2019-09-16 06:07:14,333 INFO org.apache.hadoop.yarn.server.resourcemanager.scheduler.capacity.ParentQueue: completedContainer queue=root usedCapacity=0.875 absoluteUsedCapacity=0.875 used=<memory:7168, vCores:6> cluster=<memory:8192, vCores:8>
2019-09-16 06:07:14,333 INFO org.apache.hadoop.yarn.server.resourcemanager.scheduler.capacity.ParentQueue: Re-sorting completed queue: root.default stats: default: capacity=1.0, absoluteCapacity=1.0, usedResources=<memory:7168, vCores:6>, usedCapacity=0.875, absoluteUsedCapacity=0.875, numApps=1, numContainers=6
2019-09-16 06:07:14,334 INFO org.apache.hadoop.yarn.server.resourcemanager.scheduler.capacity.CapacityScheduler: Application attempt appattempt_1568623076950_0001_000001 released container container_1568623076950_0001_01_000027 on node: host: e9a6a0455f0d:38503 #containers=6 available=<memory:1024, vCores:2> used=<memory:7168, vCores:6> with event: FINISHED
2019-09-16 06:07:14,335 INFO org.apache.hadoop.yarn.server.resourcemanager.rmcontainer.RMContainerImpl: container_1568623076950_0001_01_000031 Container Transitioned from NEW to ALLOCATED
2019-09-16 06:07:14,335 INFO org.apache.hadoop.yarn.server.resourcemanager.RMAuditLogger: USER=root	OPERATION=AM Allocated Container	TARGET=SchedulerApp	RESULT=SUCCESS	APPID=application_1568623076950_0001	CONTAINERID=container_1568623076950_0001_01_000031
2019-09-16 06:07:14,335 INFO org.apache.hadoop.yarn.server.resourcemanager.scheduler.SchedulerNode: Assigned container container_1568623076950_0001_01_000031 of capacity <memory:1024, vCores:1> on host e9a6a0455f0d:38503, which has 7 containers, <memory:8192, vCores:7> used and <memory:0, vCores:1> available after allocation
2019-09-16 06:07:14,336 INFO org.apache.hadoop.yarn.server.resourcemanager.scheduler.capacity.LeafQueue: assignedContainer application attempt=appattempt_1568623076950_0001_000001 container=Container: [ContainerId: container_1568623076950_0001_01_000031, NodeId: e9a6a0455f0d:38503, NodeHttpAddress: e9a6a0455f0d:8042, Resource: <memory:1024, vCores:1>, Priority: 20, Token: null, ] queue=default: capacity=1.0, absoluteCapacity=1.0, usedResources=<memory:7168, vCores:6>, usedCapacity=0.875, absoluteUsedCapacity=0.875, numApps=1, numContainers=6 clusterResource=<memory:8192, vCores:8>
2019-09-16 06:07:14,336 INFO org.apache.hadoop.yarn.server.resourcemanager.scheduler.capacity.ParentQueue: Re-sorting assigned queue: root.default stats: default: capacity=1.0, absoluteCapacity=1.0, usedResources=<memory:8192, vCores:7>, usedCapacity=1.0, absoluteUsedCapacity=1.0, numApps=1, numContainers=7
2019-09-16 06:07:14,337 INFO org.apache.hadoop.yarn.server.resourcemanager.scheduler.capacity.ParentQueue: assignedContainer queue=root usedCapacity=1.0 absoluteUsedCapacity=1.0 used=<memory:8192, vCores:7> cluster=<memory:8192, vCores:8>
2019-09-16 06:07:14,406 INFO org.apache.hadoop.yarn.server.resourcemanager.rmcontainer.RMContainerImpl: container_1568623076950_0001_01_000026 Container Transitioned from RUNNING to COMPLETED
2019-09-16 06:07:14,406 INFO org.apache.hadoop.yarn.server.resourcemanager.scheduler.common.fica.FiCaSchedulerApp: Completed container: container_1568623076950_0001_01_000026 in state: COMPLETED event:FINISHED
2019-09-16 06:07:14,406 INFO org.apache.hadoop.yarn.server.resourcemanager.RMAuditLogger: USER=root	OPERATION=AM Released Container	TARGET=SchedulerApp	RESULT=SUCCESS	APPID=application_1568623076950_0001	CONTAINERID=container_1568623076950_0001_01_000026
2019-09-16 06:07:14,406 INFO org.apache.hadoop.yarn.server.resourcemanager.scheduler.SchedulerNode: Released container container_1568623076950_0001_01_000026 of capacity <memory:1024, vCores:1> on host e9a6a0455f0d:38503, which currently has 6 containers, <memory:7168, vCores:6> used and <memory:1024, vCores:2> available, release resources=true
2019-09-16 06:07:14,407 INFO org.apache.hadoop.yarn.server.resourcemanager.scheduler.capacity.LeafQueue: default used=<memory:7168, vCores:6> numContainers=6 user=root user-resources=<memory:7168, vCores:6>
2019-09-16 06:07:14,409 INFO org.apache.hadoop.yarn.server.resourcemanager.scheduler.capacity.LeafQueue: completedContainer container=Container: [ContainerId: container_1568623076950_0001_01_000026, NodeId: e9a6a0455f0d:38503, NodeHttpAddress: e9a6a0455f0d:8042, Resource: <memory:1024, vCores:1>, Priority: 20, Token: Token { kind: ContainerToken, service: 172.24.0.2:38503 }, ] queue=default: capacity=1.0, absoluteCapacity=1.0, usedResources=<memory:7168, vCores:6>, usedCapacity=0.875, absoluteUsedCapacity=0.875, numApps=1, numContainers=6 cluster=<memory:8192, vCores:8>
2019-09-16 06:07:14,409 INFO org.apache.hadoop.yarn.server.resourcemanager.scheduler.capacity.ParentQueue: completedContainer queue=root usedCapacity=0.875 absoluteUsedCapacity=0.875 used=<memory:7168, vCores:6> cluster=<memory:8192, vCores:8>
2019-09-16 06:07:14,409 INFO org.apache.hadoop.yarn.server.resourcemanager.scheduler.capacity.ParentQueue: Re-sorting completed queue: root.default stats: default: capacity=1.0, absoluteCapacity=1.0, usedResources=<memory:7168, vCores:6>, usedCapacity=0.875, absoluteUsedCapacity=0.875, numApps=1, numContainers=6
2019-09-16 06:07:14,410 INFO org.apache.hadoop.yarn.server.resourcemanager.scheduler.capacity.CapacityScheduler: Application attempt appattempt_1568623076950_0001_000001 released container container_1568623076950_0001_01_000026 on node: host: e9a6a0455f0d:38503 #containers=6 available=<memory:1024, vCores:2> used=<memory:7168, vCores:6> with event: FINISHED
2019-09-16 06:07:14,411 INFO org.apache.hadoop.yarn.server.resourcemanager.rmcontainer.RMContainerImpl: container_1568623076950_0001_01_000032 Container Transitioned from NEW to ALLOCATED
2019-09-16 06:07:14,411 INFO org.apache.hadoop.yarn.server.resourcemanager.RMAuditLogger: USER=root	OPERATION=AM Allocated Container	TARGET=SchedulerApp	RESULT=SUCCESS	APPID=application_1568623076950_0001	CONTAINERID=container_1568623076950_0001_01_000032
2019-09-16 06:07:14,411 INFO org.apache.hadoop.yarn.server.resourcemanager.scheduler.SchedulerNode: Assigned container container_1568623076950_0001_01_000032 of capacity <memory:1024, vCores:1> on host e9a6a0455f0d:38503, which has 7 containers, <memory:8192, vCores:7> used and <memory:0, vCores:1> available after allocation
2019-09-16 06:07:14,412 INFO org.apache.hadoop.yarn.server.resourcemanager.scheduler.capacity.LeafQueue: assignedContainer application attempt=appattempt_1568623076950_0001_000001 container=Container: [ContainerId: container_1568623076950_0001_01_000032, NodeId: e9a6a0455f0d:38503, NodeHttpAddress: e9a6a0455f0d:8042, Resource: <memory:1024, vCores:1>, Priority: 20, Token: null, ] queue=default: capacity=1.0, absoluteCapacity=1.0, usedResources=<memory:7168, vCores:6>, usedCapacity=0.875, absoluteUsedCapacity=0.875, numApps=1, numContainers=6 clusterResource=<memory:8192, vCores:8>
2019-09-16 06:07:14,412 INFO org.apache.hadoop.yarn.server.resourcemanager.scheduler.capacity.ParentQueue: Re-sorting assigned queue: root.default stats: default: capacity=1.0, absoluteCapacity=1.0, usedResources=<memory:8192, vCores:7>, usedCapacity=1.0, absoluteUsedCapacity=1.0, numApps=1, numContainers=7
2019-09-16 06:07:14,413 INFO org.apache.hadoop.yarn.server.resourcemanager.scheduler.capacity.ParentQueue: assignedContainer queue=root usedCapacity=1.0 absoluteUsedCapacity=1.0 used=<memory:8192, vCores:7> cluster=<memory:8192, vCores:8>
2019-09-16 06:07:14,418 INFO org.apache.hadoop.yarn.server.resourcemanager.rmcontainer.RMContainerImpl: container_1568623076950_0001_01_000029 Container Transitioned from ALLOCATED to ACQUIRED
2019-09-16 06:07:14,422 INFO org.apache.hadoop.yarn.server.resourcemanager.rmcontainer.RMContainerImpl: container_1568623076950_0001_01_000030 Container Transitioned from ALLOCATED to ACQUIRED
2019-09-16 06:07:14,426 INFO org.apache.hadoop.yarn.server.resourcemanager.rmcontainer.RMContainerImpl: container_1568623076950_0001_01_000031 Container Transitioned from ALLOCATED to ACQUIRED
2019-09-16 06:07:14,430 INFO org.apache.hadoop.yarn.server.resourcemanager.rmcontainer.RMContainerImpl: container_1568623076950_0001_01_000032 Container Transitioned from ALLOCATED to ACQUIRED
2019-09-16 06:07:15,408 INFO org.apache.hadoop.yarn.server.resourcemanager.rmcontainer.RMContainerImpl: container_1568623076950_0001_01_000029 Container Transitioned from ACQUIRED to RUNNING
2019-09-16 06:07:15,409 INFO org.apache.hadoop.yarn.server.resourcemanager.rmcontainer.RMContainerImpl: container_1568623076950_0001_01_000030 Container Transitioned from ACQUIRED to RUNNING
2019-09-16 06:07:15,409 INFO org.apache.hadoop.yarn.server.resourcemanager.rmcontainer.RMContainerImpl: container_1568623076950_0001_01_000031 Container Transitioned from ACQUIRED to RUNNING
2019-09-16 06:07:15,410 INFO org.apache.hadoop.yarn.server.resourcemanager.rmcontainer.RMContainerImpl: container_1568623076950_0001_01_000032 Container Transitioned from ACQUIRED to RUNNING
2019-09-16 06:07:15,410 INFO org.apache.hadoop.yarn.server.resourcemanager.rmcontainer.RMContainerImpl: container_1568623076950_0001_01_000028 Container Transitioned from RUNNING to COMPLETED
2019-09-16 06:07:15,410 INFO org.apache.hadoop.yarn.server.resourcemanager.scheduler.common.fica.FiCaSchedulerApp: Completed container: container_1568623076950_0001_01_000028 in state: COMPLETED event:FINISHED
2019-09-16 06:07:15,410 INFO org.apache.hadoop.yarn.server.resourcemanager.RMAuditLogger: USER=root	OPERATION=AM Released Container	TARGET=SchedulerApp	RESULT=SUCCESS	APPID=application_1568623076950_0001	CONTAINERID=container_1568623076950_0001_01_000028
2019-09-16 06:07:15,410 INFO org.apache.hadoop.yarn.server.resourcemanager.scheduler.SchedulerNode: Released container container_1568623076950_0001_01_000028 of capacity <memory:1024, vCores:1> on host e9a6a0455f0d:38503, which currently has 6 containers, <memory:7168, vCores:6> used and <memory:1024, vCores:2> available, release resources=true
2019-09-16 06:07:15,410 INFO org.apache.hadoop.yarn.server.resourcemanager.scheduler.capacity.LeafQueue: default used=<memory:7168, vCores:6> numContainers=6 user=root user-resources=<memory:7168, vCores:6>
2019-09-16 06:07:15,413 INFO org.apache.hadoop.yarn.server.resourcemanager.scheduler.capacity.LeafQueue: completedContainer container=Container: [ContainerId: container_1568623076950_0001_01_000028, NodeId: e9a6a0455f0d:38503, NodeHttpAddress: e9a6a0455f0d:8042, Resource: <memory:1024, vCores:1>, Priority: 20, Token: Token { kind: ContainerToken, service: 172.24.0.2:38503 }, ] queue=default: capacity=1.0, absoluteCapacity=1.0, usedResources=<memory:7168, vCores:6>, usedCapacity=0.875, absoluteUsedCapacity=0.875, numApps=1, numContainers=6 cluster=<memory:8192, vCores:8>
2019-09-16 06:07:15,414 INFO org.apache.hadoop.yarn.server.resourcemanager.scheduler.capacity.ParentQueue: completedContainer queue=root usedCapacity=0.875 absoluteUsedCapacity=0.875 used=<memory:7168, vCores:6> cluster=<memory:8192, vCores:8>
2019-09-16 06:07:15,414 INFO org.apache.hadoop.yarn.server.resourcemanager.scheduler.capacity.ParentQueue: Re-sorting completed queue: root.default stats: default: capacity=1.0, absoluteCapacity=1.0, usedResources=<memory:7168, vCores:6>, usedCapacity=0.875, absoluteUsedCapacity=0.875, numApps=1, numContainers=6
2019-09-16 06:07:15,414 INFO org.apache.hadoop.yarn.server.resourcemanager.scheduler.capacity.CapacityScheduler: Application attempt appattempt_1568623076950_0001_000001 released container container_1568623076950_0001_01_000028 on node: host: e9a6a0455f0d:38503 #containers=6 available=<memory:1024, vCores:2> used=<memory:7168, vCores:6> with event: FINISHED
2019-09-16 06:07:15,415 INFO org.apache.hadoop.yarn.server.resourcemanager.rmcontainer.RMContainerImpl: container_1568623076950_0001_01_000033 Container Transitioned from NEW to ALLOCATED
2019-09-16 06:07:15,415 INFO org.apache.hadoop.yarn.server.resourcemanager.RMAuditLogger: USER=root	OPERATION=AM Allocated Container	TARGET=SchedulerApp	RESULT=SUCCESS	APPID=application_1568623076950_0001	CONTAINERID=container_1568623076950_0001_01_000033
2019-09-16 06:07:15,416 INFO org.apache.hadoop.yarn.server.resourcemanager.scheduler.SchedulerNode: Assigned container container_1568623076950_0001_01_000033 of capacity <memory:1024, vCores:1> on host e9a6a0455f0d:38503, which has 7 containers, <memory:8192, vCores:7> used and <memory:0, vCores:1> available after allocation
2019-09-16 06:07:15,416 INFO org.apache.hadoop.yarn.server.resourcemanager.scheduler.capacity.LeafQueue: assignedContainer application attempt=appattempt_1568623076950_0001_000001 container=Container: [ContainerId: container_1568623076950_0001_01_000033, NodeId: e9a6a0455f0d:38503, NodeHttpAddress: e9a6a0455f0d:8042, Resource: <memory:1024, vCores:1>, Priority: 20, Token: null, ] queue=default: capacity=1.0, absoluteCapacity=1.0, usedResources=<memory:7168, vCores:6>, usedCapacity=0.875, absoluteUsedCapacity=0.875, numApps=1, numContainers=6 clusterResource=<memory:8192, vCores:8>
2019-09-16 06:07:15,417 INFO org.apache.hadoop.yarn.server.resourcemanager.scheduler.capacity.ParentQueue: Re-sorting assigned queue: root.default stats: default: capacity=1.0, absoluteCapacity=1.0, usedResources=<memory:8192, vCores:7>, usedCapacity=1.0, absoluteUsedCapacity=1.0, numApps=1, numContainers=7
2019-09-16 06:07:15,417 INFO org.apache.hadoop.yarn.server.resourcemanager.scheduler.capacity.ParentQueue: assignedContainer queue=root usedCapacity=1.0 absoluteUsedCapacity=1.0 used=<memory:8192, vCores:7> cluster=<memory:8192, vCores:8>
2019-09-16 06:07:15,447 INFO org.apache.hadoop.yarn.server.resourcemanager.rmcontainer.RMContainerImpl: container_1568623076950_0001_01_000033 Container Transitioned from ALLOCATED to ACQUIRED
2019-09-16 06:07:16,417 INFO org.apache.hadoop.yarn.server.resourcemanager.rmcontainer.RMContainerImpl: container_1568623076950_0001_01_000033 Container Transitioned from ACQUIRED to RUNNING
2019-09-16 06:07:16,461 INFO org.apache.hadoop.yarn.server.resourcemanager.scheduler.AppSchedulingInfo: checking for deactivate of application :application_1568623076950_0001
2019-09-16 06:07:22,687 INFO org.apache.hadoop.yarn.server.resourcemanager.rmcontainer.RMContainerImpl: container_1568623076950_0001_01_000031 Container Transitioned from RUNNING to COMPLETED
2019-09-16 06:07:22,688 INFO org.apache.hadoop.yarn.server.resourcemanager.scheduler.common.fica.FiCaSchedulerApp: Completed container: container_1568623076950_0001_01_000031 in state: COMPLETED event:FINISHED
2019-09-16 06:07:22,688 INFO org.apache.hadoop.yarn.server.resourcemanager.RMAuditLogger: USER=root	OPERATION=AM Released Container	TARGET=SchedulerApp	RESULT=SUCCESS	APPID=application_1568623076950_0001	CONTAINERID=container_1568623076950_0001_01_000031
2019-09-16 06:07:22,689 INFO org.apache.hadoop.yarn.server.resourcemanager.scheduler.SchedulerNode: Released container container_1568623076950_0001_01_000031 of capacity <memory:1024, vCores:1> on host e9a6a0455f0d:38503, which currently has 6 containers, <memory:7168, vCores:6> used and <memory:1024, vCores:2> available, release resources=true
2019-09-16 06:07:22,690 INFO org.apache.hadoop.yarn.server.resourcemanager.scheduler.capacity.LeafQueue: default used=<memory:7168, vCores:6> numContainers=6 user=root user-resources=<memory:7168, vCores:6>
2019-09-16 06:07:22,692 INFO org.apache.hadoop.yarn.server.resourcemanager.scheduler.capacity.LeafQueue: completedContainer container=Container: [ContainerId: container_1568623076950_0001_01_000031, NodeId: e9a6a0455f0d:38503, NodeHttpAddress: e9a6a0455f0d:8042, Resource: <memory:1024, vCores:1>, Priority: 20, Token: Token { kind: ContainerToken, service: 172.24.0.2:38503 }, ] queue=default: capacity=1.0, absoluteCapacity=1.0, usedResources=<memory:7168, vCores:6>, usedCapacity=0.875, absoluteUsedCapacity=0.875, numApps=1, numContainers=6 cluster=<memory:8192, vCores:8>
2019-09-16 06:07:22,692 INFO org.apache.hadoop.yarn.server.resourcemanager.scheduler.capacity.ParentQueue: completedContainer queue=root usedCapacity=0.875 absoluteUsedCapacity=0.875 used=<memory:7168, vCores:6> cluster=<memory:8192, vCores:8>
2019-09-16 06:07:22,693 INFO org.apache.hadoop.yarn.server.resourcemanager.scheduler.capacity.ParentQueue: Re-sorting completed queue: root.default stats: default: capacity=1.0, absoluteCapacity=1.0, usedResources=<memory:7168, vCores:6>, usedCapacity=0.875, absoluteUsedCapacity=0.875, numApps=1, numContainers=6
2019-09-16 06:07:22,694 INFO org.apache.hadoop.yarn.server.resourcemanager.scheduler.capacity.CapacityScheduler: Application attempt appattempt_1568623076950_0001_000001 released container container_1568623076950_0001_01_000031 on node: host: e9a6a0455f0d:38503 #containers=6 available=<memory:1024, vCores:2> used=<memory:7168, vCores:6> with event: FINISHED
2019-09-16 06:07:22,848 INFO org.apache.hadoop.yarn.server.resourcemanager.rmcontainer.RMContainerImpl: container_1568623076950_0001_01_000030 Container Transitioned from RUNNING to COMPLETED
2019-09-16 06:07:22,848 INFO org.apache.hadoop.yarn.server.resourcemanager.scheduler.common.fica.FiCaSchedulerApp: Completed container: container_1568623076950_0001_01_000030 in state: COMPLETED event:FINISHED
2019-09-16 06:07:22,848 INFO org.apache.hadoop.yarn.server.resourcemanager.RMAuditLogger: USER=root	OPERATION=AM Released Container	TARGET=SchedulerApp	RESULT=SUCCESS	APPID=application_1568623076950_0001	CONTAINERID=container_1568623076950_0001_01_000030
2019-09-16 06:07:22,849 INFO org.apache.hadoop.yarn.server.resourcemanager.scheduler.SchedulerNode: Released container container_1568623076950_0001_01_000030 of capacity <memory:1024, vCores:1> on host e9a6a0455f0d:38503, which currently has 5 containers, <memory:6144, vCores:5> used and <memory:2048, vCores:3> available, release resources=true
2019-09-16 06:07:22,849 INFO org.apache.hadoop.yarn.server.resourcemanager.scheduler.capacity.LeafQueue: default used=<memory:6144, vCores:5> numContainers=5 user=root user-resources=<memory:6144, vCores:5>
2019-09-16 06:07:22,850 INFO org.apache.hadoop.yarn.server.resourcemanager.scheduler.capacity.LeafQueue: completedContainer container=Container: [ContainerId: container_1568623076950_0001_01_000030, NodeId: e9a6a0455f0d:38503, NodeHttpAddress: e9a6a0455f0d:8042, Resource: <memory:1024, vCores:1>, Priority: 20, Token: Token { kind: ContainerToken, service: 172.24.0.2:38503 }, ] queue=default: capacity=1.0, absoluteCapacity=1.0, usedResources=<memory:6144, vCores:5>, usedCapacity=0.75, absoluteUsedCapacity=0.75, numApps=1, numContainers=5 cluster=<memory:8192, vCores:8>
2019-09-16 06:07:22,850 INFO org.apache.hadoop.yarn.server.resourcemanager.scheduler.capacity.ParentQueue: completedContainer queue=root usedCapacity=0.75 absoluteUsedCapacity=0.75 used=<memory:6144, vCores:5> cluster=<memory:8192, vCores:8>
2019-09-16 06:07:22,852 INFO org.apache.hadoop.yarn.server.resourcemanager.scheduler.capacity.ParentQueue: Re-sorting completed queue: root.default stats: default: capacity=1.0, absoluteCapacity=1.0, usedResources=<memory:6144, vCores:5>, usedCapacity=0.75, absoluteUsedCapacity=0.75, numApps=1, numContainers=5
2019-09-16 06:07:22,852 INFO org.apache.hadoop.yarn.server.resourcemanager.scheduler.capacity.CapacityScheduler: Application attempt appattempt_1568623076950_0001_000001 released container container_1568623076950_0001_01_000030 on node: host: e9a6a0455f0d:38503 #containers=5 available=<memory:2048, vCores:3> used=<memory:6144, vCores:5> with event: FINISHED
2019-09-16 06:07:22,949 INFO org.apache.hadoop.yarn.server.resourcemanager.rmcontainer.RMContainerImpl: container_1568623076950_0001_01_000029 Container Transitioned from RUNNING to COMPLETED
2019-09-16 06:07:22,951 INFO org.apache.hadoop.yarn.server.resourcemanager.scheduler.common.fica.FiCaSchedulerApp: Completed container: container_1568623076950_0001_01_000029 in state: COMPLETED event:FINISHED
2019-09-16 06:07:22,952 INFO org.apache.hadoop.yarn.server.resourcemanager.RMAuditLogger: USER=root	OPERATION=AM Released Container	TARGET=SchedulerApp	RESULT=SUCCESS	APPID=application_1568623076950_0001	CONTAINERID=container_1568623076950_0001_01_000029
2019-09-16 06:07:22,952 INFO org.apache.hadoop.yarn.server.resourcemanager.scheduler.SchedulerNode: Released container container_1568623076950_0001_01_000029 of capacity <memory:1024, vCores:1> on host e9a6a0455f0d:38503, which currently has 4 containers, <memory:5120, vCores:4> used and <memory:3072, vCores:4> available, release resources=true
2019-09-16 06:07:22,952 INFO org.apache.hadoop.yarn.server.resourcemanager.scheduler.capacity.LeafQueue: default used=<memory:5120, vCores:4> numContainers=4 user=root user-resources=<memory:5120, vCores:4>
2019-09-16 06:07:22,953 INFO org.apache.hadoop.yarn.server.resourcemanager.scheduler.capacity.LeafQueue: completedContainer container=Container: [ContainerId: container_1568623076950_0001_01_000029, NodeId: e9a6a0455f0d:38503, NodeHttpAddress: e9a6a0455f0d:8042, Resource: <memory:1024, vCores:1>, Priority: 20, Token: Token { kind: ContainerToken, service: 172.24.0.2:38503 }, ] queue=default: capacity=1.0, absoluteCapacity=1.0, usedResources=<memory:5120, vCores:4>, usedCapacity=0.625, absoluteUsedCapacity=0.625, numApps=1, numContainers=4 cluster=<memory:8192, vCores:8>
2019-09-16 06:07:22,953 INFO org.apache.hadoop.yarn.server.resourcemanager.scheduler.capacity.ParentQueue: completedContainer queue=root usedCapacity=0.625 absoluteUsedCapacity=0.625 used=<memory:5120, vCores:4> cluster=<memory:8192, vCores:8>
2019-09-16 06:07:22,954 INFO org.apache.hadoop.yarn.server.resourcemanager.scheduler.capacity.ParentQueue: Re-sorting completed queue: root.default stats: default: capacity=1.0, absoluteCapacity=1.0, usedResources=<memory:5120, vCores:4>, usedCapacity=0.625, absoluteUsedCapacity=0.625, numApps=1, numContainers=4
2019-09-16 06:07:22,954 INFO org.apache.hadoop.yarn.server.resourcemanager.scheduler.capacity.CapacityScheduler: Application attempt appattempt_1568623076950_0001_000001 released container container_1568623076950_0001_01_000029 on node: host: e9a6a0455f0d:38503 #containers=4 available=<memory:3072, vCores:4> used=<memory:5120, vCores:4> with event: FINISHED
2019-09-16 06:07:23,490 INFO org.apache.hadoop.yarn.server.resourcemanager.rmcontainer.RMContainerImpl: container_1568623076950_0001_01_000032 Container Transitioned from RUNNING to COMPLETED
2019-09-16 06:07:23,490 INFO org.apache.hadoop.yarn.server.resourcemanager.scheduler.common.fica.FiCaSchedulerApp: Completed container: container_1568623076950_0001_01_000032 in state: COMPLETED event:FINISHED
2019-09-16 06:07:23,490 INFO org.apache.hadoop.yarn.server.resourcemanager.RMAuditLogger: USER=root	OPERATION=AM Released Container	TARGET=SchedulerApp	RESULT=SUCCESS	APPID=application_1568623076950_0001	CONTAINERID=container_1568623076950_0001_01_000032
2019-09-16 06:07:23,490 INFO org.apache.hadoop.yarn.server.resourcemanager.scheduler.SchedulerNode: Released container container_1568623076950_0001_01_000032 of capacity <memory:1024, vCores:1> on host e9a6a0455f0d:38503, which currently has 3 containers, <memory:4096, vCores:3> used and <memory:4096, vCores:5> available, release resources=true
2019-09-16 06:07:23,491 INFO org.apache.hadoop.yarn.server.resourcemanager.scheduler.capacity.LeafQueue: default used=<memory:4096, vCores:3> numContainers=3 user=root user-resources=<memory:4096, vCores:3>
2019-09-16 06:07:23,492 INFO org.apache.hadoop.yarn.server.resourcemanager.scheduler.capacity.LeafQueue: completedContainer container=Container: [ContainerId: container_1568623076950_0001_01_000032, NodeId: e9a6a0455f0d:38503, NodeHttpAddress: e9a6a0455f0d:8042, Resource: <memory:1024, vCores:1>, Priority: 20, Token: Token { kind: ContainerToken, service: 172.24.0.2:38503 }, ] queue=default: capacity=1.0, absoluteCapacity=1.0, usedResources=<memory:4096, vCores:3>, usedCapacity=0.5, absoluteUsedCapacity=0.5, numApps=1, numContainers=3 cluster=<memory:8192, vCores:8>
2019-09-16 06:07:23,492 INFO org.apache.hadoop.yarn.server.resourcemanager.scheduler.capacity.ParentQueue: completedContainer queue=root usedCapacity=0.5 absoluteUsedCapacity=0.5 used=<memory:4096, vCores:3> cluster=<memory:8192, vCores:8>
2019-09-16 06:07:23,492 INFO org.apache.hadoop.yarn.server.resourcemanager.scheduler.capacity.ParentQueue: Re-sorting completed queue: root.default stats: default: capacity=1.0, absoluteCapacity=1.0, usedResources=<memory:4096, vCores:3>, usedCapacity=0.5, absoluteUsedCapacity=0.5, numApps=1, numContainers=3
2019-09-16 06:07:23,493 INFO org.apache.hadoop.yarn.server.resourcemanager.scheduler.capacity.CapacityScheduler: Application attempt appattempt_1568623076950_0001_000001 released container container_1568623076950_0001_01_000032 on node: host: e9a6a0455f0d:38503 #containers=3 available=<memory:4096, vCores:5> used=<memory:4096, vCores:3> with event: FINISHED
2019-09-16 06:07:23,502 INFO org.apache.hadoop.yarn.server.resourcemanager.scheduler.AppSchedulingInfo: checking for deactivate of application :application_1568623076950_0001
2019-09-16 06:07:24,270 INFO org.apache.hadoop.yarn.server.resourcemanager.rmcontainer.RMContainerImpl: container_1568623076950_0001_01_000033 Container Transitioned from RUNNING to COMPLETED
2019-09-16 06:07:24,270 INFO org.apache.hadoop.yarn.server.resourcemanager.scheduler.common.fica.FiCaSchedulerApp: Completed container: container_1568623076950_0001_01_000033 in state: COMPLETED event:FINISHED
2019-09-16 06:07:24,270 INFO org.apache.hadoop.yarn.server.resourcemanager.RMAuditLogger: USER=root	OPERATION=AM Released Container	TARGET=SchedulerApp	RESULT=SUCCESS	APPID=application_1568623076950_0001	CONTAINERID=container_1568623076950_0001_01_000033
2019-09-16 06:07:24,270 INFO org.apache.hadoop.yarn.server.resourcemanager.scheduler.SchedulerNode: Released container container_1568623076950_0001_01_000033 of capacity <memory:1024, vCores:1> on host e9a6a0455f0d:38503, which currently has 2 containers, <memory:3072, vCores:2> used and <memory:5120, vCores:6> available, release resources=true
2019-09-16 06:07:24,271 INFO org.apache.hadoop.yarn.server.resourcemanager.scheduler.capacity.LeafQueue: default used=<memory:3072, vCores:2> numContainers=2 user=root user-resources=<memory:3072, vCores:2>
2019-09-16 06:07:24,271 INFO org.apache.hadoop.yarn.server.resourcemanager.scheduler.capacity.LeafQueue: completedContainer container=Container: [ContainerId: container_1568623076950_0001_01_000033, NodeId: e9a6a0455f0d:38503, NodeHttpAddress: e9a6a0455f0d:8042, Resource: <memory:1024, vCores:1>, Priority: 20, Token: Token { kind: ContainerToken, service: 172.24.0.2:38503 }, ] queue=default: capacity=1.0, absoluteCapacity=1.0, usedResources=<memory:3072, vCores:2>, usedCapacity=0.375, absoluteUsedCapacity=0.375, numApps=1, numContainers=2 cluster=<memory:8192, vCores:8>
2019-09-16 06:07:24,271 INFO org.apache.hadoop.yarn.server.resourcemanager.scheduler.capacity.ParentQueue: completedContainer queue=root usedCapacity=0.375 absoluteUsedCapacity=0.375 used=<memory:3072, vCores:2> cluster=<memory:8192, vCores:8>
2019-09-16 06:07:24,271 INFO org.apache.hadoop.yarn.server.resourcemanager.scheduler.capacity.ParentQueue: Re-sorting completed queue: root.default stats: default: capacity=1.0, absoluteCapacity=1.0, usedResources=<memory:3072, vCores:2>, usedCapacity=0.375, absoluteUsedCapacity=0.375, numApps=1, numContainers=2
2019-09-16 06:07:24,272 INFO org.apache.hadoop.yarn.server.resourcemanager.scheduler.capacity.CapacityScheduler: Application attempt appattempt_1568623076950_0001_000001 released container container_1568623076950_0001_01_000033 on node: host: e9a6a0455f0d:38503 #containers=2 available=<memory:5120, vCores:6> used=<memory:3072, vCores:2> with event: FINISHED
2019-09-16 06:07:24,996 INFO org.apache.hadoop.yarn.server.resourcemanager.rmapp.attempt.RMAppAttemptImpl: Updating application attempt appattempt_1568623076950_0001_000001 with final state: FINISHING, and exit status: -1000
2019-09-16 06:07:25,004 INFO org.apache.hadoop.yarn.server.resourcemanager.rmapp.attempt.RMAppAttemptImpl: appattempt_1568623076950_0001_000001 State change from RUNNING to FINAL_SAVING
2019-09-16 06:07:25,005 INFO org.apache.hadoop.yarn.server.resourcemanager.rmapp.RMAppImpl: Updating application application_1568623076950_0001 with final state: FINISHING
2019-09-16 06:07:25,007 INFO org.apache.hadoop.yarn.server.resourcemanager.rmapp.RMAppImpl: application_1568623076950_0001 State change from RUNNING to FINAL_SAVING
2019-09-16 06:07:25,007 INFO org.apache.hadoop.yarn.server.resourcemanager.recovery.RMStateStore: Updating info for app: application_1568623076950_0001
2019-09-16 06:07:25,007 INFO org.apache.hadoop.yarn.server.resourcemanager.rmapp.attempt.RMAppAttemptImpl: appattempt_1568623076950_0001_000001 State change from FINAL_SAVING to FINISHING
2019-09-16 06:07:25,008 INFO org.apache.hadoop.yarn.server.resourcemanager.rmapp.RMAppImpl: application_1568623076950_0001 State change from FINAL_SAVING to FINISHING
2019-09-16 06:07:25,273 INFO org.apache.hadoop.yarn.server.resourcemanager.rmcontainer.RMContainerImpl: container_1568623076950_0001_01_000008 Container Transitioned from RUNNING to COMPLETED
2019-09-16 06:07:25,274 INFO org.apache.hadoop.yarn.server.resourcemanager.scheduler.common.fica.FiCaSchedulerApp: Completed container: container_1568623076950_0001_01_000008 in state: COMPLETED event:FINISHED
2019-09-16 06:07:25,274 INFO org.apache.hadoop.yarn.server.resourcemanager.RMAuditLogger: USER=root	OPERATION=AM Released Container	TARGET=SchedulerApp	RESULT=SUCCESS	APPID=application_1568623076950_0001	CONTAINERID=container_1568623076950_0001_01_000008
2019-09-16 06:07:25,274 INFO org.apache.hadoop.yarn.server.resourcemanager.scheduler.SchedulerNode: Released container container_1568623076950_0001_01_000008 of capacity <memory:1024, vCores:1> on host e9a6a0455f0d:38503, which currently has 1 containers, <memory:2048, vCores:1> used and <memory:6144, vCores:7> available, release resources=true
2019-09-16 06:07:25,274 INFO org.apache.hadoop.yarn.server.resourcemanager.scheduler.capacity.LeafQueue: default used=<memory:2048, vCores:1> numContainers=1 user=root user-resources=<memory:2048, vCores:1>
2019-09-16 06:07:25,274 INFO org.apache.hadoop.yarn.server.resourcemanager.scheduler.capacity.LeafQueue: completedContainer container=Container: [ContainerId: container_1568623076950_0001_01_000008, NodeId: e9a6a0455f0d:38503, NodeHttpAddress: e9a6a0455f0d:8042, Resource: <memory:1024, vCores:1>, Priority: 10, Token: Token { kind: ContainerToken, service: 172.24.0.2:38503 }, ] queue=default: capacity=1.0, absoluteCapacity=1.0, usedResources=<memory:2048, vCores:1>, usedCapacity=0.25, absoluteUsedCapacity=0.25, numApps=1, numContainers=1 cluster=<memory:8192, vCores:8>
2019-09-16 06:07:25,274 INFO org.apache.hadoop.yarn.server.resourcemanager.scheduler.capacity.ParentQueue: completedContainer queue=root usedCapacity=0.25 absoluteUsedCapacity=0.25 used=<memory:2048, vCores:1> cluster=<memory:8192, vCores:8>
2019-09-16 06:07:25,275 INFO org.apache.hadoop.yarn.server.resourcemanager.scheduler.capacity.ParentQueue: Re-sorting completed queue: root.default stats: default: capacity=1.0, absoluteCapacity=1.0, usedResources=<memory:2048, vCores:1>, usedCapacity=0.25, absoluteUsedCapacity=0.25, numApps=1, numContainers=1
2019-09-16 06:07:25,275 INFO org.apache.hadoop.yarn.server.resourcemanager.scheduler.capacity.CapacityScheduler: Application attempt appattempt_1568623076950_0001_000001 released container container_1568623076950_0001_01_000008 on node: host: e9a6a0455f0d:38503 #containers=1 available=<memory:6144, vCores:7> used=<memory:2048, vCores:1> with event: FINISHED
2019-09-16 06:07:26,015 INFO org.apache.hadoop.yarn.server.resourcemanager.ApplicationMasterService: application_1568623076950_0001 unregistered successfully. 
2019-09-16 06:07:26,799 INFO org.apache.hadoop.yarn.server.resourcemanager.ClientRMService: Allocated new applicationId: 2
2019-09-16 06:07:27,135 INFO org.apache.hadoop.yarn.server.resourcemanager.ClientRMService: Application with id 2 submitted by user root
2019-09-16 06:07:27,135 INFO org.apache.hadoop.yarn.server.resourcemanager.rmapp.RMAppImpl: Storing application with id application_1568623076950_0002
2019-09-16 06:07:27,135 INFO org.apache.hadoop.yarn.server.resourcemanager.RMAuditLogger: USER=root	IP=172.24.0.2	OPERATION=Submit Application Request	TARGET=ClientRMService	RESULT=SUCCESS	APPID=application_1568623076950_0002
2019-09-16 06:07:27,135 INFO org.apache.hadoop.yarn.server.resourcemanager.rmapp.RMAppImpl: application_1568623076950_0002 State change from NEW to NEW_SAVING
2019-09-16 06:07:27,135 INFO org.apache.hadoop.yarn.server.resourcemanager.recovery.RMStateStore: Storing info for app: application_1568623076950_0002
2019-09-16 06:07:27,136 INFO org.apache.hadoop.yarn.server.resourcemanager.rmapp.RMAppImpl: application_1568623076950_0002 State change from NEW_SAVING to SUBMITTED
2019-09-16 06:07:27,136 INFO org.apache.hadoop.yarn.server.resourcemanager.scheduler.capacity.ParentQueue: Application added - appId: application_1568623076950_0002 user: root leaf-queue of parent: root #applications: 2
2019-09-16 06:07:27,137 INFO org.apache.hadoop.yarn.server.resourcemanager.scheduler.capacity.CapacityScheduler: Accepted application application_1568623076950_0002 from user: root, in queue: default
2019-09-16 06:07:27,138 INFO org.apache.hadoop.yarn.server.resourcemanager.rmapp.RMAppImpl: application_1568623076950_0002 State change from SUBMITTED to ACCEPTED
2019-09-16 06:07:27,138 INFO org.apache.hadoop.yarn.server.resourcemanager.ApplicationMasterService: Registering app attempt : appattempt_1568623076950_0002_000001
2019-09-16 06:07:27,138 INFO org.apache.hadoop.yarn.server.resourcemanager.rmapp.attempt.RMAppAttemptImpl: appattempt_1568623076950_0002_000001 State change from NEW to SUBMITTED
2019-09-16 06:07:27,138 INFO org.apache.hadoop.yarn.server.resourcemanager.scheduler.capacity.LeafQueue: not starting application as amIfStarted exceeds amLimit
2019-09-16 06:07:27,139 INFO org.apache.hadoop.yarn.server.resourcemanager.scheduler.capacity.LeafQueue: Application added - appId: application_1568623076950_0002 user: org.apache.hadoop.yarn.server.resourcemanager.scheduler.capacity.LeafQueue$User@1619372c, leaf-queue: default #user-pending-applications: 1 #user-active-applications: 1 #queue-pending-applications: 1 #queue-active-applications: 1
2019-09-16 06:07:27,139 INFO org.apache.hadoop.yarn.server.resourcemanager.scheduler.capacity.CapacityScheduler: Added Application Attempt appattempt_1568623076950_0002_000001 to scheduler from user root in queue default
2019-09-16 06:07:27,140 INFO org.apache.hadoop.yarn.server.resourcemanager.rmapp.attempt.RMAppAttemptImpl: appattempt_1568623076950_0002_000001 State change from SUBMITTED to SCHEDULED
2019-09-16 06:07:31,288 INFO org.apache.hadoop.yarn.server.resourcemanager.rmcontainer.RMContainerImpl: container_1568623076950_0001_01_000001 Container Transitioned from RUNNING to COMPLETED
2019-09-16 06:07:31,288 INFO org.apache.hadoop.yarn.server.resourcemanager.ApplicationMasterService: Unregistering app attempt : appattempt_1568623076950_0001_000001
2019-09-16 06:07:31,288 INFO org.apache.hadoop.yarn.server.resourcemanager.scheduler.common.fica.FiCaSchedulerApp: Completed container: container_1568623076950_0001_01_000001 in state: COMPLETED event:FINISHED
2019-09-16 06:07:31,289 INFO org.apache.hadoop.yarn.server.resourcemanager.RMAuditLogger: USER=root	OPERATION=AM Released Container	TARGET=SchedulerApp	RESULT=SUCCESS	APPID=application_1568623076950_0001	CONTAINERID=container_1568623076950_0001_01_000001
2019-09-16 06:07:31,289 INFO org.apache.hadoop.yarn.server.resourcemanager.scheduler.SchedulerNode: Released container container_1568623076950_0001_01_000001 of capacity <memory:2048, vCores:1> on host e9a6a0455f0d:38503, which currently has 0 containers, <memory:0, vCores:0> used and <memory:8192, vCores:8> available, release resources=true
2019-09-16 06:07:31,289 INFO org.apache.hadoop.yarn.server.resourcemanager.scheduler.capacity.LeafQueue: default used=<memory:0, vCores:0> numContainers=0 user=root user-resources=<memory:0, vCores:0>
2019-09-16 06:07:31,290 INFO org.apache.hadoop.yarn.server.resourcemanager.scheduler.capacity.LeafQueue: completedContainer container=Container: [ContainerId: container_1568623076950_0001_01_000001, NodeId: e9a6a0455f0d:38503, NodeHttpAddress: e9a6a0455f0d:8042, Resource: <memory:2048, vCores:1>, Priority: 0, Token: Token { kind: ContainerToken, service: 172.24.0.2:38503 }, ] queue=default: capacity=1.0, absoluteCapacity=1.0, usedResources=<memory:0, vCores:0>, usedCapacity=0.0, absoluteUsedCapacity=0.0, numApps=2, numContainers=0 cluster=<memory:8192, vCores:8>
2019-09-16 06:07:31,290 INFO org.apache.hadoop.yarn.server.resourcemanager.scheduler.capacity.ParentQueue: completedContainer queue=root usedCapacity=0.0 absoluteUsedCapacity=0.0 used=<memory:0, vCores:0> cluster=<memory:8192, vCores:8>
2019-09-16 06:07:31,290 INFO org.apache.hadoop.yarn.server.resourcemanager.scheduler.capacity.ParentQueue: Re-sorting completed queue: root.default stats: default: capacity=1.0, absoluteCapacity=1.0, usedResources=<memory:0, vCores:0>, usedCapacity=0.0, absoluteUsedCapacity=0.0, numApps=2, numContainers=0
2019-09-16 06:07:31,292 INFO org.apache.hadoop.yarn.server.resourcemanager.scheduler.capacity.CapacityScheduler: Application attempt appattempt_1568623076950_0001_000001 released container container_1568623076950_0001_01_000001 on node: host: e9a6a0455f0d:38503 #containers=0 available=<memory:8192, vCores:8> used=<memory:0, vCores:0> with event: FINISHED
2019-09-16 06:07:31,292 INFO org.apache.hadoop.yarn.server.resourcemanager.security.AMRMTokenSecretManager: Application finished, removing password for appattempt_1568623076950_0001_000001
2019-09-16 06:07:31,293 INFO org.apache.hadoop.yarn.server.resourcemanager.rmapp.attempt.RMAppAttemptImpl: appattempt_1568623076950_0001_000001 State change from FINISHING to FINISHED
2019-09-16 06:07:31,304 INFO org.apache.hadoop.yarn.server.resourcemanager.rmapp.RMAppImpl: application_1568623076950_0001 State change from FINISHING to FINISHED
2019-09-16 06:07:31,304 INFO org.apache.hadoop.yarn.server.resourcemanager.scheduler.capacity.CapacityScheduler: Application Attempt appattempt_1568623076950_0001_000001 is done. finalState=FINISHED
2019-09-16 06:07:31,305 INFO org.apache.hadoop.yarn.server.resourcemanager.scheduler.AppSchedulingInfo: Application application_1568623076950_0001 requests cleared
2019-09-16 06:07:31,305 WARN org.apache.hadoop.yarn.server.resourcemanager.scheduler.capacity.LeafQueue: maximum-am-resource-percent is insufficient to start a single application in queue, it is likely set too low. skipping enforcement to allow at least one application to start
2019-09-16 06:07:31,305 INFO org.apache.hadoop.yarn.server.resourcemanager.amlauncher.AMLauncher: Cleaning master appattempt_1568623076950_0001_000001
2019-09-16 06:07:31,306 WARN org.apache.hadoop.yarn.server.resourcemanager.scheduler.capacity.LeafQueue: maximum-am-resource-percent is insufficient to start a single application in queue for user, it is likely set too low. skipping enforcement to allow at least one application to start
2019-09-16 06:07:31,306 INFO org.apache.hadoop.yarn.server.resourcemanager.scheduler.capacity.LeafQueue: Application application_1568623076950_0002 from user: root activated in queue: default
2019-09-16 06:07:31,306 INFO org.apache.hadoop.yarn.server.resourcemanager.scheduler.capacity.LeafQueue: Application removed - appId: application_1568623076950_0001 user: root queue: default #user-pending-applications: 0 #user-active-applications: 1 #queue-pending-applications: 0 #queue-active-applications: 1
2019-09-16 06:07:31,306 INFO org.apache.hadoop.yarn.server.resourcemanager.scheduler.capacity.ParentQueue: Application removed - appId: application_1568623076950_0001 user: root leaf-queue of parent: root #applications: 1
2019-09-16 06:07:31,307 INFO org.apache.hadoop.yarn.server.resourcemanager.RMAuditLogger: USER=root	OPERATION=Application Finished - Succeeded	TARGET=RMAppManager	RESULT=SUCCESS	APPID=application_1568623076950_0001
2019-09-16 06:07:31,318 INFO org.apache.hadoop.yarn.server.resourcemanager.RMAppManager$ApplicationSummary: appId=application_1568623076950_0001,name=grep-search,user=root,queue=default,state=FINISHED,trackingUrl=http://e9a6a0455f0d:8088/proxy/application_1568623076950_0001/,appMasterHost=e9a6a0455f0d,startTime=1568628353554,finishTime=1568628445005,finalStatus=SUCCEEDED,memorySeconds=671169,vcoreSeconds=543,preemptedAMContainers=0,preemptedNonAMContainers=0,preemptedResources=<memory:0\, vCores:0>,applicationType=MAPREDUCE
2019-09-16 06:07:31,340 INFO org.apache.hadoop.yarn.server.resourcemanager.rmcontainer.RMContainerImpl: container_1568623076950_0002_01_000001 Container Transitioned from NEW to ALLOCATED
2019-09-16 06:07:31,340 INFO org.apache.hadoop.yarn.server.resourcemanager.RMAuditLogger: USER=root	OPERATION=AM Allocated Container	TARGET=SchedulerApp	RESULT=SUCCESS	APPID=application_1568623076950_0002	CONTAINERID=container_1568623076950_0002_01_000001
2019-09-16 06:07:31,341 INFO org.apache.hadoop.yarn.server.resourcemanager.scheduler.SchedulerNode: Assigned container container_1568623076950_0002_01_000001 of capacity <memory:2048, vCores:1> on host e9a6a0455f0d:38503, which has 1 containers, <memory:2048, vCores:1> used and <memory:6144, vCores:7> available after allocation
2019-09-16 06:07:31,342 INFO org.apache.hadoop.yarn.server.resourcemanager.scheduler.capacity.LeafQueue: assignedContainer application attempt=appattempt_1568623076950_0002_000001 container=Container: [ContainerId: container_1568623076950_0002_01_000001, NodeId: e9a6a0455f0d:38503, NodeHttpAddress: e9a6a0455f0d:8042, Resource: <memory:2048, vCores:1>, Priority: 0, Token: null, ] queue=default: capacity=1.0, absoluteCapacity=1.0, usedResources=<memory:0, vCores:0>, usedCapacity=0.0, absoluteUsedCapacity=0.0, numApps=1, numContainers=0 clusterResource=<memory:8192, vCores:8>
2019-09-16 06:07:31,343 INFO org.apache.hadoop.yarn.server.resourcemanager.scheduler.capacity.ParentQueue: Re-sorting assigned queue: root.default stats: default: capacity=1.0, absoluteCapacity=1.0, usedResources=<memory:2048, vCores:1>, usedCapacity=0.25, absoluteUsedCapacity=0.25, numApps=1, numContainers=1
2019-09-16 06:07:31,343 INFO org.apache.hadoop.yarn.server.resourcemanager.scheduler.capacity.ParentQueue: assignedContainer queue=root usedCapacity=0.25 absoluteUsedCapacity=0.25 used=<memory:2048, vCores:1> cluster=<memory:8192, vCores:8>
2019-09-16 06:07:31,346 INFO org.apache.hadoop.yarn.server.resourcemanager.security.NMTokenSecretManagerInRM: Sending NMToken for nodeId : e9a6a0455f0d:38503 for container : container_1568623076950_0002_01_000001
2019-09-16 06:07:31,348 INFO org.apache.hadoop.yarn.server.resourcemanager.rmcontainer.RMContainerImpl: container_1568623076950_0002_01_000001 Container Transitioned from ALLOCATED to ACQUIRED
2019-09-16 06:07:31,349 INFO org.apache.hadoop.yarn.server.resourcemanager.security.NMTokenSecretManagerInRM: Clear node set for appattempt_1568623076950_0002_000001
2019-09-16 06:07:31,349 INFO org.apache.hadoop.yarn.server.resourcemanager.rmapp.attempt.RMAppAttemptImpl: Storing attempt: AppId: application_1568623076950_0002 AttemptId: appattempt_1568623076950_0002_000001 MasterContainer: Container: [ContainerId: container_1568623076950_0002_01_000001, NodeId: e9a6a0455f0d:38503, NodeHttpAddress: e9a6a0455f0d:8042, Resource: <memory:2048, vCores:1>, Priority: 0, Token: Token { kind: ContainerToken, service: 172.24.0.2:38503 }, ]
2019-09-16 06:07:31,349 INFO org.apache.hadoop.yarn.server.resourcemanager.rmapp.attempt.RMAppAttemptImpl: appattempt_1568623076950_0002_000001 State change from SCHEDULED to ALLOCATED_SAVING
2019-09-16 06:07:31,350 INFO org.apache.hadoop.yarn.server.resourcemanager.rmapp.attempt.RMAppAttemptImpl: appattempt_1568623076950_0002_000001 State change from ALLOCATED_SAVING to ALLOCATED
2019-09-16 06:07:31,360 INFO org.apache.hadoop.yarn.server.resourcemanager.amlauncher.AMLauncher: Launching masterappattempt_1568623076950_0002_000001
2019-09-16 06:07:31,363 INFO org.apache.hadoop.yarn.server.resourcemanager.amlauncher.AMLauncher: Setting up container Container: [ContainerId: container_1568623076950_0002_01_000001, NodeId: e9a6a0455f0d:38503, NodeHttpAddress: e9a6a0455f0d:8042, Resource: <memory:2048, vCores:1>, Priority: 0, Token: Token { kind: ContainerToken, service: 172.24.0.2:38503 }, ] for AM appattempt_1568623076950_0002_000001
2019-09-16 06:07:31,364 INFO org.apache.hadoop.yarn.server.resourcemanager.amlauncher.AMLauncher: Command to launch container container_1568623076950_0002_01_000001 : $JAVA_HOME/bin/java -Dlog4j.configuration=container-log4j.properties -Dyarn.app.container.log.dir=<LOG_DIR> -Dyarn.app.container.log.filesize=0 -Dhadoop.root.logger=INFO,CLA -Dhadoop.root.logfile=syslog  -Xmx1024m org.apache.hadoop.mapreduce.v2.app.MRAppMaster 1><LOG_DIR>/stdout 2><LOG_DIR>/stderr 
2019-09-16 06:07:31,364 INFO org.apache.hadoop.yarn.server.resourcemanager.security.AMRMTokenSecretManager: Create AMRMToken for ApplicationAttempt: appattempt_1568623076950_0002_000001
2019-09-16 06:07:31,364 INFO org.apache.hadoop.yarn.server.resourcemanager.security.AMRMTokenSecretManager: Creating password for appattempt_1568623076950_0002_000001
2019-09-16 06:07:31,378 INFO org.apache.hadoop.yarn.server.resourcemanager.amlauncher.AMLauncher: Done launching container Container: [ContainerId: container_1568623076950_0002_01_000001, NodeId: e9a6a0455f0d:38503, NodeHttpAddress: e9a6a0455f0d:8042, Resource: <memory:2048, vCores:1>, Priority: 0, Token: Token { kind: ContainerToken, service: 172.24.0.2:38503 }, ] for AM appattempt_1568623076950_0002_000001
2019-09-16 06:07:31,378 INFO org.apache.hadoop.yarn.server.resourcemanager.rmapp.attempt.RMAppAttemptImpl: appattempt_1568623076950_0002_000001 State change from ALLOCATED to LAUNCHED
2019-09-16 06:07:32,346 INFO org.apache.hadoop.yarn.server.resourcemanager.rmcontainer.RMContainerImpl: container_1568623076950_0002_01_000001 Container Transitioned from ACQUIRED to RUNNING
2019-09-16 06:07:32,346 INFO org.apache.hadoop.yarn.server.resourcemanager.scheduler.capacity.CapacityScheduler: Null container completed...
2019-09-16 06:07:35,252 INFO SecurityLogger.org.apache.hadoop.ipc.Server: Auth successful for appattempt_1568623076950_0002_000001 (auth:SIMPLE)
2019-09-16 06:07:35,255 INFO org.apache.hadoop.yarn.server.resourcemanager.ApplicationMasterService: AM registration appattempt_1568623076950_0002_000001
2019-09-16 06:07:35,255 INFO org.apache.hadoop.yarn.server.resourcemanager.RMAuditLogger: USER=root	IP=172.24.0.2	OPERATION=Register App Master	TARGET=ApplicationMasterService	RESULT=SUCCESS	APPID=application_1568623076950_0002	APPATTEMPTID=appattempt_1568623076950_0002_000001
2019-09-16 06:07:35,255 INFO org.apache.hadoop.yarn.server.resourcemanager.rmapp.attempt.RMAppAttemptImpl: appattempt_1568623076950_0002_000001 State change from LAUNCHED to RUNNING
2019-09-16 06:07:35,255 INFO org.apache.hadoop.yarn.server.resourcemanager.rmapp.RMAppImpl: application_1568623076950_0002 State change from ACCEPTED to RUNNING
2019-09-16 06:07:36,356 INFO org.apache.hadoop.yarn.server.resourcemanager.rmcontainer.RMContainerImpl: container_1568623076950_0002_01_000002 Container Transitioned from NEW to ALLOCATED
2019-09-16 06:07:36,356 INFO org.apache.hadoop.yarn.server.resourcemanager.RMAuditLogger: USER=root	OPERATION=AM Allocated Container	TARGET=SchedulerApp	RESULT=SUCCESS	APPID=application_1568623076950_0002	CONTAINERID=container_1568623076950_0002_01_000002
2019-09-16 06:07:36,356 INFO org.apache.hadoop.yarn.server.resourcemanager.scheduler.SchedulerNode: Assigned container container_1568623076950_0002_01_000002 of capacity <memory:1024, vCores:1> on host e9a6a0455f0d:38503, which has 2 containers, <memory:3072, vCores:2> used and <memory:5120, vCores:6> available after allocation
2019-09-16 06:07:36,357 INFO org.apache.hadoop.yarn.server.resourcemanager.scheduler.capacity.LeafQueue: assignedContainer application attempt=appattempt_1568623076950_0002_000001 container=Container: [ContainerId: container_1568623076950_0002_01_000002, NodeId: e9a6a0455f0d:38503, NodeHttpAddress: e9a6a0455f0d:8042, Resource: <memory:1024, vCores:1>, Priority: 20, Token: null, ] queue=default: capacity=1.0, absoluteCapacity=1.0, usedResources=<memory:2048, vCores:1>, usedCapacity=0.25, absoluteUsedCapacity=0.25, numApps=1, numContainers=1 clusterResource=<memory:8192, vCores:8>
2019-09-16 06:07:36,358 INFO org.apache.hadoop.yarn.server.resourcemanager.scheduler.capacity.ParentQueue: Re-sorting assigned queue: root.default stats: default: capacity=1.0, absoluteCapacity=1.0, usedResources=<memory:3072, vCores:2>, usedCapacity=0.375, absoluteUsedCapacity=0.375, numApps=1, numContainers=2
2019-09-16 06:07:36,358 INFO org.apache.hadoop.yarn.server.resourcemanager.scheduler.capacity.ParentQueue: assignedContainer queue=root usedCapacity=0.375 absoluteUsedCapacity=0.375 used=<memory:3072, vCores:2> cluster=<memory:8192, vCores:8>
2019-09-16 06:07:37,340 INFO org.apache.hadoop.yarn.server.resourcemanager.security.NMTokenSecretManagerInRM: Sending NMToken for nodeId : e9a6a0455f0d:38503 for container : container_1568623076950_0002_01_000002
2019-09-16 06:07:37,343 INFO org.apache.hadoop.yarn.server.resourcemanager.rmcontainer.RMContainerImpl: container_1568623076950_0002_01_000002 Container Transitioned from ALLOCATED to ACQUIRED
2019-09-16 06:07:38,353 INFO org.apache.hadoop.yarn.server.resourcemanager.scheduler.AppSchedulingInfo: checking for deactivate of application :application_1568623076950_0002
2019-09-16 06:07:38,359 INFO org.apache.hadoop.yarn.server.resourcemanager.rmcontainer.RMContainerImpl: container_1568623076950_0002_01_000002 Container Transitioned from ACQUIRED to RUNNING
2019-09-16 06:07:41,118 INFO org.apache.hadoop.yarn.server.resourcemanager.rmcontainer.RMContainerImpl: container_1568623076950_0002_01_000002 Container Transitioned from RUNNING to COMPLETED
2019-09-16 06:07:41,119 INFO org.apache.hadoop.yarn.server.resourcemanager.scheduler.common.fica.FiCaSchedulerApp: Completed container: container_1568623076950_0002_01_000002 in state: COMPLETED event:FINISHED
2019-09-16 06:07:41,119 INFO org.apache.hadoop.yarn.server.resourcemanager.RMAuditLogger: USER=root	OPERATION=AM Released Container	TARGET=SchedulerApp	RESULT=SUCCESS	APPID=application_1568623076950_0002	CONTAINERID=container_1568623076950_0002_01_000002
2019-09-16 06:07:41,119 INFO org.apache.hadoop.yarn.server.resourcemanager.scheduler.SchedulerNode: Released container container_1568623076950_0002_01_000002 of capacity <memory:1024, vCores:1> on host e9a6a0455f0d:38503, which currently has 1 containers, <memory:2048, vCores:1> used and <memory:6144, vCores:7> available, release resources=true
2019-09-16 06:07:41,119 INFO org.apache.hadoop.yarn.server.resourcemanager.scheduler.capacity.LeafQueue: default used=<memory:2048, vCores:1> numContainers=1 user=root user-resources=<memory:2048, vCores:1>
2019-09-16 06:07:41,120 INFO org.apache.hadoop.yarn.server.resourcemanager.scheduler.capacity.LeafQueue: completedContainer container=Container: [ContainerId: container_1568623076950_0002_01_000002, NodeId: e9a6a0455f0d:38503, NodeHttpAddress: e9a6a0455f0d:8042, Resource: <memory:1024, vCores:1>, Priority: 20, Token: Token { kind: ContainerToken, service: 172.24.0.2:38503 }, ] queue=default: capacity=1.0, absoluteCapacity=1.0, usedResources=<memory:2048, vCores:1>, usedCapacity=0.25, absoluteUsedCapacity=0.25, numApps=1, numContainers=1 cluster=<memory:8192, vCores:8>
2019-09-16 06:07:41,120 INFO org.apache.hadoop.yarn.server.resourcemanager.scheduler.capacity.ParentQueue: completedContainer queue=root usedCapacity=0.25 absoluteUsedCapacity=0.25 used=<memory:2048, vCores:1> cluster=<memory:8192, vCores:8>
2019-09-16 06:07:41,120 INFO org.apache.hadoop.yarn.server.resourcemanager.scheduler.capacity.ParentQueue: Re-sorting completed queue: root.default stats: default: capacity=1.0, absoluteCapacity=1.0, usedResources=<memory:2048, vCores:1>, usedCapacity=0.25, absoluteUsedCapacity=0.25, numApps=1, numContainers=1
2019-09-16 06:07:41,121 INFO org.apache.hadoop.yarn.server.resourcemanager.scheduler.capacity.CapacityScheduler: Application attempt appattempt_1568623076950_0002_000001 released container container_1568623076950_0002_01_000002 on node: host: e9a6a0455f0d:38503 #containers=1 available=<memory:6144, vCores:7> used=<memory:2048, vCores:1> with event: FINISHED
2019-09-16 06:07:42,120 INFO org.apache.hadoop.yarn.server.resourcemanager.rmcontainer.RMContainerImpl: container_1568623076950_0002_01_000003 Container Transitioned from NEW to ALLOCATED
2019-09-16 06:07:42,121 INFO org.apache.hadoop.yarn.server.resourcemanager.RMAuditLogger: USER=root	OPERATION=AM Allocated Container	TARGET=SchedulerApp	RESULT=SUCCESS	APPID=application_1568623076950_0002	CONTAINERID=container_1568623076950_0002_01_000003
2019-09-16 06:07:42,121 INFO org.apache.hadoop.yarn.server.resourcemanager.scheduler.SchedulerNode: Assigned container container_1568623076950_0002_01_000003 of capacity <memory:1024, vCores:1> on host e9a6a0455f0d:38503, which has 2 containers, <memory:3072, vCores:2> used and <memory:5120, vCores:6> available after allocation
2019-09-16 06:07:42,121 INFO org.apache.hadoop.yarn.server.resourcemanager.scheduler.capacity.LeafQueue: assignedContainer application attempt=appattempt_1568623076950_0002_000001 container=Container: [ContainerId: container_1568623076950_0002_01_000003, NodeId: e9a6a0455f0d:38503, NodeHttpAddress: e9a6a0455f0d:8042, Resource: <memory:1024, vCores:1>, Priority: 10, Token: null, ] queue=default: capacity=1.0, absoluteCapacity=1.0, usedResources=<memory:2048, vCores:1>, usedCapacity=0.25, absoluteUsedCapacity=0.25, numApps=1, numContainers=1 clusterResource=<memory:8192, vCores:8>
2019-09-16 06:07:42,122 INFO org.apache.hadoop.yarn.server.resourcemanager.scheduler.capacity.ParentQueue: Re-sorting assigned queue: root.default stats: default: capacity=1.0, absoluteCapacity=1.0, usedResources=<memory:3072, vCores:2>, usedCapacity=0.375, absoluteUsedCapacity=0.375, numApps=1, numContainers=2
2019-09-16 06:07:42,122 INFO org.apache.hadoop.yarn.server.resourcemanager.scheduler.capacity.ParentQueue: assignedContainer queue=root usedCapacity=0.375 absoluteUsedCapacity=0.375 used=<memory:3072, vCores:2> cluster=<memory:8192, vCores:8>
2019-09-16 06:07:42,397 INFO org.apache.hadoop.yarn.server.resourcemanager.rmcontainer.RMContainerImpl: container_1568623076950_0002_01_000003 Container Transitioned from ALLOCATED to ACQUIRED
2019-09-16 06:07:43,122 INFO org.apache.hadoop.yarn.server.resourcemanager.rmcontainer.RMContainerImpl: container_1568623076950_0002_01_000003 Container Transitioned from ACQUIRED to RUNNING
2019-09-16 06:07:43,402 INFO org.apache.hadoop.yarn.server.resourcemanager.scheduler.AppSchedulingInfo: checking for deactivate of application :application_1568623076950_0002
2019-09-16 06:07:45,512 INFO org.apache.hadoop.yarn.server.resourcemanager.rmapp.attempt.RMAppAttemptImpl: Updating application attempt appattempt_1568623076950_0002_000001 with final state: FINISHING, and exit status: -1000
2019-09-16 06:07:45,512 INFO org.apache.hadoop.yarn.server.resourcemanager.rmapp.attempt.RMAppAttemptImpl: appattempt_1568623076950_0002_000001 State change from RUNNING to FINAL_SAVING
2019-09-16 06:07:45,512 INFO org.apache.hadoop.yarn.server.resourcemanager.rmapp.RMAppImpl: Updating application application_1568623076950_0002 with final state: FINISHING
2019-09-16 06:07:45,512 INFO org.apache.hadoop.yarn.server.resourcemanager.recovery.RMStateStore: Updating info for app: application_1568623076950_0002
2019-09-16 06:07:45,512 INFO org.apache.hadoop.yarn.server.resourcemanager.rmapp.RMAppImpl: application_1568623076950_0002 State change from RUNNING to FINAL_SAVING
2019-09-16 06:07:45,512 INFO org.apache.hadoop.yarn.server.resourcemanager.rmapp.attempt.RMAppAttemptImpl: appattempt_1568623076950_0002_000001 State change from FINAL_SAVING to FINISHING
2019-09-16 06:07:45,513 INFO org.apache.hadoop.yarn.server.resourcemanager.rmapp.RMAppImpl: application_1568623076950_0002 State change from FINAL_SAVING to FINISHING
2019-09-16 06:07:46,256 INFO org.apache.hadoop.yarn.server.resourcemanager.rmcontainer.RMContainerImpl: container_1568623076950_0002_01_000003 Container Transitioned from RUNNING to COMPLETED
2019-09-16 06:07:46,256 INFO org.apache.hadoop.yarn.server.resourcemanager.scheduler.common.fica.FiCaSchedulerApp: Completed container: container_1568623076950_0002_01_000003 in state: COMPLETED event:FINISHED
2019-09-16 06:07:46,256 INFO org.apache.hadoop.yarn.server.resourcemanager.RMAuditLogger: USER=root	OPERATION=AM Released Container	TARGET=SchedulerApp	RESULT=SUCCESS	APPID=application_1568623076950_0002	CONTAINERID=container_1568623076950_0002_01_000003
2019-09-16 06:07:46,256 INFO org.apache.hadoop.yarn.server.resourcemanager.scheduler.SchedulerNode: Released container container_1568623076950_0002_01_000003 of capacity <memory:1024, vCores:1> on host e9a6a0455f0d:38503, which currently has 1 containers, <memory:2048, vCores:1> used and <memory:6144, vCores:7> available, release resources=true
2019-09-16 06:07:46,257 INFO org.apache.hadoop.yarn.server.resourcemanager.scheduler.capacity.LeafQueue: default used=<memory:2048, vCores:1> numContainers=1 user=root user-resources=<memory:2048, vCores:1>
2019-09-16 06:07:46,257 INFO org.apache.hadoop.yarn.server.resourcemanager.scheduler.capacity.LeafQueue: completedContainer container=Container: [ContainerId: container_1568623076950_0002_01_000003, NodeId: e9a6a0455f0d:38503, NodeHttpAddress: e9a6a0455f0d:8042, Resource: <memory:1024, vCores:1>, Priority: 10, Token: Token { kind: ContainerToken, service: 172.24.0.2:38503 }, ] queue=default: capacity=1.0, absoluteCapacity=1.0, usedResources=<memory:2048, vCores:1>, usedCapacity=0.25, absoluteUsedCapacity=0.25, numApps=1, numContainers=1 cluster=<memory:8192, vCores:8>
2019-09-16 06:07:46,258 INFO org.apache.hadoop.yarn.server.resourcemanager.scheduler.capacity.ParentQueue: completedContainer queue=root usedCapacity=0.25 absoluteUsedCapacity=0.25 used=<memory:2048, vCores:1> cluster=<memory:8192, vCores:8>
2019-09-16 06:07:46,258 INFO org.apache.hadoop.yarn.server.resourcemanager.scheduler.capacity.ParentQueue: Re-sorting completed queue: root.default stats: default: capacity=1.0, absoluteCapacity=1.0, usedResources=<memory:2048, vCores:1>, usedCapacity=0.25, absoluteUsedCapacity=0.25, numApps=1, numContainers=1
2019-09-16 06:07:46,258 INFO org.apache.hadoop.yarn.server.resourcemanager.scheduler.capacity.CapacityScheduler: Application attempt appattempt_1568623076950_0002_000001 released container container_1568623076950_0002_01_000003 on node: host: e9a6a0455f0d:38503 #containers=1 available=<memory:6144, vCores:7> used=<memory:2048, vCores:1> with event: FINISHED
2019-09-16 06:07:46,516 INFO org.apache.hadoop.yarn.server.resourcemanager.ApplicationMasterService: application_1568623076950_0002 unregistered successfully. 
2019-09-16 06:07:52,270 INFO org.apache.hadoop.yarn.server.resourcemanager.ApplicationMasterService: Unregistering app attempt : appattempt_1568623076950_0002_000001
2019-09-16 06:07:52,270 INFO org.apache.hadoop.yarn.server.resourcemanager.rmcontainer.RMContainerImpl: container_1568623076950_0002_01_000001 Container Transitioned from RUNNING to COMPLETED
2019-09-16 06:07:52,270 INFO org.apache.hadoop.yarn.server.resourcemanager.scheduler.common.fica.FiCaSchedulerApp: Completed container: container_1568623076950_0002_01_000001 in state: COMPLETED event:FINISHED
2019-09-16 06:07:52,270 INFO org.apache.hadoop.yarn.server.resourcemanager.security.AMRMTokenSecretManager: Application finished, removing password for appattempt_1568623076950_0002_000001
2019-09-16 06:07:52,271 INFO org.apache.hadoop.yarn.server.resourcemanager.RMAuditLogger: USER=root	OPERATION=AM Released Container	TARGET=SchedulerApp	RESULT=SUCCESS	APPID=application_1568623076950_0002	CONTAINERID=container_1568623076950_0002_01_000001
2019-09-16 06:07:52,271 INFO org.apache.hadoop.yarn.server.resourcemanager.rmapp.attempt.RMAppAttemptImpl: appattempt_1568623076950_0002_000001 State change from FINISHING to FINISHED
2019-09-16 06:07:52,271 INFO org.apache.hadoop.yarn.server.resourcemanager.rmapp.RMAppImpl: application_1568623076950_0002 State change from FINISHING to FINISHED
2019-09-16 06:07:52,271 INFO org.apache.hadoop.yarn.server.resourcemanager.scheduler.SchedulerNode: Released container container_1568623076950_0002_01_000001 of capacity <memory:2048, vCores:1> on host e9a6a0455f0d:38503, which currently has 0 containers, <memory:0, vCores:0> used and <memory:8192, vCores:8> available, release resources=true
2019-09-16 06:07:52,271 INFO org.apache.hadoop.yarn.server.resourcemanager.RMAuditLogger: USER=root	OPERATION=Application Finished - Succeeded	TARGET=RMAppManager	RESULT=SUCCESS	APPID=application_1568623076950_0002
2019-09-16 06:07:52,271 INFO org.apache.hadoop.yarn.server.resourcemanager.scheduler.capacity.LeafQueue: default used=<memory:0, vCores:0> numContainers=0 user=root user-resources=<memory:0, vCores:0>
2019-09-16 06:07:52,272 INFO org.apache.hadoop.yarn.server.resourcemanager.amlauncher.AMLauncher: Cleaning master appattempt_1568623076950_0002_000001
2019-09-16 06:07:52,272 INFO org.apache.hadoop.yarn.server.resourcemanager.scheduler.capacity.LeafQueue: completedContainer container=Container: [ContainerId: container_1568623076950_0002_01_000001, NodeId: e9a6a0455f0d:38503, NodeHttpAddress: e9a6a0455f0d:8042, Resource: <memory:2048, vCores:1>, Priority: 0, Token: Token { kind: ContainerToken, service: 172.24.0.2:38503 }, ] queue=default: capacity=1.0, absoluteCapacity=1.0, usedResources=<memory:0, vCores:0>, usedCapacity=0.0, absoluteUsedCapacity=0.0, numApps=1, numContainers=0 cluster=<memory:8192, vCores:8>
2019-09-16 06:07:52,272 INFO org.apache.hadoop.yarn.server.resourcemanager.scheduler.capacity.ParentQueue: completedContainer queue=root usedCapacity=0.0 absoluteUsedCapacity=0.0 used=<memory:0, vCores:0> cluster=<memory:8192, vCores:8>
2019-09-16 06:07:52,272 INFO org.apache.hadoop.yarn.server.resourcemanager.scheduler.capacity.ParentQueue: Re-sorting completed queue: root.default stats: default: capacity=1.0, absoluteCapacity=1.0, usedResources=<memory:0, vCores:0>, usedCapacity=0.0, absoluteUsedCapacity=0.0, numApps=1, numContainers=0
2019-09-16 06:07:52,273 INFO org.apache.hadoop.yarn.server.resourcemanager.RMAppManager$ApplicationSummary: appId=application_1568623076950_0002,name=grep-sort,user=root,queue=default,state=FINISHED,trackingUrl=http://e9a6a0455f0d:8088/proxy/application_1568623076950_0002/,appMasterHost=e9a6a0455f0d,startTime=1568628447134,finishTime=1568628465512,finalStatus=SUCCEEDED,memorySeconds=51978,vcoreSeconds=28,preemptedAMContainers=0,preemptedNonAMContainers=0,preemptedResources=<memory:0\, vCores:0>,applicationType=MAPREDUCE
2019-09-16 06:07:52,273 INFO org.apache.hadoop.yarn.server.resourcemanager.scheduler.capacity.CapacityScheduler: Application attempt appattempt_1568623076950_0002_000001 released container container_1568623076950_0002_01_000001 on node: host: e9a6a0455f0d:38503 #containers=0 available=<memory:8192, vCores:8> used=<memory:0, vCores:0> with event: FINISHED
2019-09-16 06:07:52,273 INFO org.apache.hadoop.yarn.server.resourcemanager.scheduler.capacity.CapacityScheduler: Application Attempt appattempt_1568623076950_0002_000001 is done. finalState=FINISHED
2019-09-16 06:07:52,273 INFO org.apache.hadoop.yarn.server.resourcemanager.scheduler.AppSchedulingInfo: Application application_1568623076950_0002 requests cleared
2019-09-16 06:07:52,273 INFO org.apache.hadoop.yarn.server.resourcemanager.scheduler.capacity.LeafQueue: Application removed - appId: application_1568623076950_0002 user: root queue: default #user-pending-applications: 0 #user-active-applications: 0 #queue-pending-applications: 0 #queue-active-applications: 0
2019-09-16 06:07:52,273 INFO org.apache.hadoop.yarn.server.resourcemanager.scheduler.capacity.ParentQueue: Application removed - appId: application_1568623076950_0002 user: root leaf-queue of parent: root #applications: 0
2019-09-16 06:07:53,293 INFO org.apache.hadoop.yarn.server.resourcemanager.scheduler.capacity.CapacityScheduler: Null container completed...
2019-09-16 06:28:50,872 INFO org.apache.hadoop.yarn.server.resourcemanager.ClientRMService: Allocated new applicationId: 3
2019-09-16 06:28:51,906 INFO org.apache.hadoop.yarn.server.resourcemanager.ClientRMService: Application with id 3 submitted by user root
2019-09-16 06:28:51,906 INFO org.apache.hadoop.yarn.server.resourcemanager.rmapp.RMAppImpl: Storing application with id application_1568623076950_0003
2019-09-16 06:28:51,906 INFO org.apache.hadoop.yarn.server.resourcemanager.RMAuditLogger: USER=root	IP=172.24.0.2	OPERATION=Submit Application Request	TARGET=ClientRMService	RESULT=SUCCESS	APPID=application_1568623076950_0003
2019-09-16 06:28:51,906 INFO org.apache.hadoop.yarn.server.resourcemanager.rmapp.RMAppImpl: application_1568623076950_0003 State change from NEW to NEW_SAVING
2019-09-16 06:28:51,907 INFO org.apache.hadoop.yarn.server.resourcemanager.recovery.RMStateStore: Storing info for app: application_1568623076950_0003
2019-09-16 06:28:51,907 INFO org.apache.hadoop.yarn.server.resourcemanager.rmapp.RMAppImpl: application_1568623076950_0003 State change from NEW_SAVING to SUBMITTED
2019-09-16 06:28:51,907 INFO org.apache.hadoop.yarn.server.resourcemanager.scheduler.capacity.ParentQueue: Application added - appId: application_1568623076950_0003 user: root leaf-queue of parent: root #applications: 1
2019-09-16 06:28:51,907 INFO org.apache.hadoop.yarn.server.resourcemanager.scheduler.capacity.CapacityScheduler: Accepted application application_1568623076950_0003 from user: root, in queue: default
2019-09-16 06:28:51,908 INFO org.apache.hadoop.yarn.server.resourcemanager.rmapp.RMAppImpl: application_1568623076950_0003 State change from SUBMITTED to ACCEPTED
2019-09-16 06:28:51,908 INFO org.apache.hadoop.yarn.server.resourcemanager.ApplicationMasterService: Registering app attempt : appattempt_1568623076950_0003_000001
2019-09-16 06:28:51,908 INFO org.apache.hadoop.yarn.server.resourcemanager.rmapp.attempt.RMAppAttemptImpl: appattempt_1568623076950_0003_000001 State change from NEW to SUBMITTED
2019-09-16 06:28:51,908 WARN org.apache.hadoop.yarn.server.resourcemanager.scheduler.capacity.LeafQueue: maximum-am-resource-percent is insufficient to start a single application in queue, it is likely set too low. skipping enforcement to allow at least one application to start
2019-09-16 06:28:51,908 WARN org.apache.hadoop.yarn.server.resourcemanager.scheduler.capacity.LeafQueue: maximum-am-resource-percent is insufficient to start a single application in queue for user, it is likely set too low. skipping enforcement to allow at least one application to start
2019-09-16 06:28:51,909 INFO org.apache.hadoop.yarn.server.resourcemanager.scheduler.capacity.LeafQueue: Application application_1568623076950_0003 from user: root activated in queue: default
2019-09-16 06:28:51,909 INFO org.apache.hadoop.yarn.server.resourcemanager.scheduler.capacity.LeafQueue: Application added - appId: application_1568623076950_0003 user: org.apache.hadoop.yarn.server.resourcemanager.scheduler.capacity.LeafQueue$User@68cefc31, leaf-queue: default #user-pending-applications: 0 #user-active-applications: 1 #queue-pending-applications: 0 #queue-active-applications: 1
2019-09-16 06:28:51,909 INFO org.apache.hadoop.yarn.server.resourcemanager.scheduler.capacity.CapacityScheduler: Added Application Attempt appattempt_1568623076950_0003_000001 to scheduler from user root in queue default
2019-09-16 06:28:51,910 INFO org.apache.hadoop.yarn.server.resourcemanager.rmapp.attempt.RMAppAttemptImpl: appattempt_1568623076950_0003_000001 State change from SUBMITTED to SCHEDULED
2019-09-16 06:28:51,915 INFO org.apache.hadoop.yarn.server.resourcemanager.rmcontainer.RMContainerImpl: container_1568623076950_0003_01_000001 Container Transitioned from NEW to ALLOCATED
2019-09-16 06:28:51,915 INFO org.apache.hadoop.yarn.server.resourcemanager.RMAuditLogger: USER=root	OPERATION=AM Allocated Container	TARGET=SchedulerApp	RESULT=SUCCESS	APPID=application_1568623076950_0003	CONTAINERID=container_1568623076950_0003_01_000001
2019-09-16 06:28:51,915 INFO org.apache.hadoop.yarn.server.resourcemanager.scheduler.SchedulerNode: Assigned container container_1568623076950_0003_01_000001 of capacity <memory:2048, vCores:1> on host e9a6a0455f0d:38503, which has 1 containers, <memory:2048, vCores:1> used and <memory:6144, vCores:7> available after allocation
2019-09-16 06:28:51,916 INFO org.apache.hadoop.yarn.server.resourcemanager.scheduler.capacity.LeafQueue: assignedContainer application attempt=appattempt_1568623076950_0003_000001 container=Container: [ContainerId: container_1568623076950_0003_01_000001, NodeId: e9a6a0455f0d:38503, NodeHttpAddress: e9a6a0455f0d:8042, Resource: <memory:2048, vCores:1>, Priority: 0, Token: null, ] queue=default: capacity=1.0, absoluteCapacity=1.0, usedResources=<memory:0, vCores:0>, usedCapacity=0.0, absoluteUsedCapacity=0.0, numApps=1, numContainers=0 clusterResource=<memory:8192, vCores:8>
2019-09-16 06:28:51,916 INFO org.apache.hadoop.yarn.server.resourcemanager.scheduler.capacity.ParentQueue: Re-sorting assigned queue: root.default stats: default: capacity=1.0, absoluteCapacity=1.0, usedResources=<memory:2048, vCores:1>, usedCapacity=0.25, absoluteUsedCapacity=0.25, numApps=1, numContainers=1
2019-09-16 06:28:51,916 INFO org.apache.hadoop.yarn.server.resourcemanager.scheduler.capacity.ParentQueue: assignedContainer queue=root usedCapacity=0.25 absoluteUsedCapacity=0.25 used=<memory:2048, vCores:1> cluster=<memory:8192, vCores:8>
2019-09-16 06:28:51,917 INFO org.apache.hadoop.yarn.server.resourcemanager.security.NMTokenSecretManagerInRM: Sending NMToken for nodeId : e9a6a0455f0d:38503 for container : container_1568623076950_0003_01_000001
2019-09-16 06:28:51,918 INFO org.apache.hadoop.yarn.server.resourcemanager.rmcontainer.RMContainerImpl: container_1568623076950_0003_01_000001 Container Transitioned from ALLOCATED to ACQUIRED
2019-09-16 06:28:51,918 INFO org.apache.hadoop.yarn.server.resourcemanager.security.NMTokenSecretManagerInRM: Clear node set for appattempt_1568623076950_0003_000001
2019-09-16 06:28:51,918 INFO org.apache.hadoop.yarn.server.resourcemanager.rmapp.attempt.RMAppAttemptImpl: Storing attempt: AppId: application_1568623076950_0003 AttemptId: appattempt_1568623076950_0003_000001 MasterContainer: Container: [ContainerId: container_1568623076950_0003_01_000001, NodeId: e9a6a0455f0d:38503, NodeHttpAddress: e9a6a0455f0d:8042, Resource: <memory:2048, vCores:1>, Priority: 0, Token: Token { kind: ContainerToken, service: 172.24.0.2:38503 }, ]
2019-09-16 06:28:51,918 INFO org.apache.hadoop.yarn.server.resourcemanager.rmapp.attempt.RMAppAttemptImpl: appattempt_1568623076950_0003_000001 State change from SCHEDULED to ALLOCATED_SAVING
2019-09-16 06:28:51,918 INFO org.apache.hadoop.yarn.server.resourcemanager.rmapp.attempt.RMAppAttemptImpl: appattempt_1568623076950_0003_000001 State change from ALLOCATED_SAVING to ALLOCATED
2019-09-16 06:28:51,919 INFO org.apache.hadoop.yarn.server.resourcemanager.amlauncher.AMLauncher: Launching masterappattempt_1568623076950_0003_000001
2019-09-16 06:28:51,920 INFO org.apache.hadoop.yarn.server.resourcemanager.amlauncher.AMLauncher: Setting up container Container: [ContainerId: container_1568623076950_0003_01_000001, NodeId: e9a6a0455f0d:38503, NodeHttpAddress: e9a6a0455f0d:8042, Resource: <memory:2048, vCores:1>, Priority: 0, Token: Token { kind: ContainerToken, service: 172.24.0.2:38503 }, ] for AM appattempt_1568623076950_0003_000001
2019-09-16 06:28:51,920 INFO org.apache.hadoop.yarn.server.resourcemanager.amlauncher.AMLauncher: Command to launch container container_1568623076950_0003_01_000001 : $JAVA_HOME/bin/java -Dlog4j.configuration=container-log4j.properties -Dyarn.app.container.log.dir=<LOG_DIR> -Dyarn.app.container.log.filesize=0 -Dhadoop.root.logger=INFO,CLA -Dhadoop.root.logfile=syslog  -Xmx1024m org.apache.hadoop.mapreduce.v2.app.MRAppMaster 1><LOG_DIR>/stdout 2><LOG_DIR>/stderr 
2019-09-16 06:28:51,920 INFO org.apache.hadoop.yarn.server.resourcemanager.security.AMRMTokenSecretManager: Create AMRMToken for ApplicationAttempt: appattempt_1568623076950_0003_000001
2019-09-16 06:28:51,920 INFO org.apache.hadoop.yarn.server.resourcemanager.security.AMRMTokenSecretManager: Creating password for appattempt_1568623076950_0003_000001
2019-09-16 06:28:51,931 INFO org.apache.hadoop.yarn.server.resourcemanager.amlauncher.AMLauncher: Done launching container Container: [ContainerId: container_1568623076950_0003_01_000001, NodeId: e9a6a0455f0d:38503, NodeHttpAddress: e9a6a0455f0d:8042, Resource: <memory:2048, vCores:1>, Priority: 0, Token: Token { kind: ContainerToken, service: 172.24.0.2:38503 }, ] for AM appattempt_1568623076950_0003_000001
2019-09-16 06:28:51,932 INFO org.apache.hadoop.yarn.server.resourcemanager.rmapp.attempt.RMAppAttemptImpl: appattempt_1568623076950_0003_000001 State change from ALLOCATED to LAUNCHED
2019-09-16 06:28:52,916 INFO org.apache.hadoop.yarn.server.resourcemanager.rmcontainer.RMContainerImpl: container_1568623076950_0003_01_000001 Container Transitioned from ACQUIRED to RUNNING
2019-09-16 06:28:57,989 INFO SecurityLogger.org.apache.hadoop.ipc.Server: Auth successful for appattempt_1568623076950_0003_000001 (auth:SIMPLE)
2019-09-16 06:28:57,993 INFO org.apache.hadoop.yarn.server.resourcemanager.ApplicationMasterService: AM registration appattempt_1568623076950_0003_000001
2019-09-16 06:28:57,994 INFO org.apache.hadoop.yarn.server.resourcemanager.RMAuditLogger: USER=root	IP=172.24.0.2	OPERATION=Register App Master	TARGET=ApplicationMasterService	RESULT=SUCCESS	APPID=application_1568623076950_0003	APPATTEMPTID=appattempt_1568623076950_0003_000001
2019-09-16 06:28:57,994 INFO org.apache.hadoop.yarn.server.resourcemanager.rmapp.attempt.RMAppAttemptImpl: appattempt_1568623076950_0003_000001 State change from LAUNCHED to RUNNING
2019-09-16 06:28:57,994 INFO org.apache.hadoop.yarn.server.resourcemanager.rmapp.RMAppImpl: application_1568623076950_0003 State change from ACCEPTED to RUNNING
2019-09-16 06:28:59,133 INFO org.apache.hadoop.yarn.server.resourcemanager.rmcontainer.RMContainerImpl: container_1568623076950_0003_01_000002 Container Transitioned from NEW to ALLOCATED
2019-09-16 06:28:59,133 INFO org.apache.hadoop.yarn.server.resourcemanager.RMAuditLogger: USER=root	OPERATION=AM Allocated Container	TARGET=SchedulerApp	RESULT=SUCCESS	APPID=application_1568623076950_0003	CONTAINERID=container_1568623076950_0003_01_000002
2019-09-16 06:28:59,133 INFO org.apache.hadoop.yarn.server.resourcemanager.scheduler.SchedulerNode: Assigned container container_1568623076950_0003_01_000002 of capacity <memory:1024, vCores:1> on host e9a6a0455f0d:38503, which has 2 containers, <memory:3072, vCores:2> used and <memory:5120, vCores:6> available after allocation
2019-09-16 06:28:59,134 INFO org.apache.hadoop.yarn.server.resourcemanager.scheduler.capacity.LeafQueue: assignedContainer application attempt=appattempt_1568623076950_0003_000001 container=Container: [ContainerId: container_1568623076950_0003_01_000002, NodeId: e9a6a0455f0d:38503, NodeHttpAddress: e9a6a0455f0d:8042, Resource: <memory:1024, vCores:1>, Priority: 20, Token: null, ] queue=default: capacity=1.0, absoluteCapacity=1.0, usedResources=<memory:2048, vCores:1>, usedCapacity=0.25, absoluteUsedCapacity=0.25, numApps=1, numContainers=1 clusterResource=<memory:8192, vCores:8>
2019-09-16 06:28:59,135 INFO org.apache.hadoop.yarn.server.resourcemanager.scheduler.capacity.ParentQueue: Re-sorting assigned queue: root.default stats: default: capacity=1.0, absoluteCapacity=1.0, usedResources=<memory:3072, vCores:2>, usedCapacity=0.375, absoluteUsedCapacity=0.375, numApps=1, numContainers=2
2019-09-16 06:28:59,135 INFO org.apache.hadoop.yarn.server.resourcemanager.scheduler.capacity.ParentQueue: assignedContainer queue=root usedCapacity=0.375 absoluteUsedCapacity=0.375 used=<memory:3072, vCores:2> cluster=<memory:8192, vCores:8>
2019-09-16 06:28:59,136 INFO org.apache.hadoop.yarn.server.resourcemanager.rmcontainer.RMContainerImpl: container_1568623076950_0003_01_000003 Container Transitioned from NEW to ALLOCATED
2019-09-16 06:28:59,136 INFO org.apache.hadoop.yarn.server.resourcemanager.RMAuditLogger: USER=root	OPERATION=AM Allocated Container	TARGET=SchedulerApp	RESULT=SUCCESS	APPID=application_1568623076950_0003	CONTAINERID=container_1568623076950_0003_01_000003
2019-09-16 06:28:59,136 INFO org.apache.hadoop.yarn.server.resourcemanager.scheduler.SchedulerNode: Assigned container container_1568623076950_0003_01_000003 of capacity <memory:1024, vCores:1> on host e9a6a0455f0d:38503, which has 3 containers, <memory:4096, vCores:3> used and <memory:4096, vCores:5> available after allocation
2019-09-16 06:28:59,137 INFO org.apache.hadoop.yarn.server.resourcemanager.scheduler.capacity.LeafQueue: assignedContainer application attempt=appattempt_1568623076950_0003_000001 container=Container: [ContainerId: container_1568623076950_0003_01_000003, NodeId: e9a6a0455f0d:38503, NodeHttpAddress: e9a6a0455f0d:8042, Resource: <memory:1024, vCores:1>, Priority: 20, Token: null, ] queue=default: capacity=1.0, absoluteCapacity=1.0, usedResources=<memory:3072, vCores:2>, usedCapacity=0.375, absoluteUsedCapacity=0.375, numApps=1, numContainers=2 clusterResource=<memory:8192, vCores:8>
2019-09-16 06:28:59,137 INFO org.apache.hadoop.yarn.server.resourcemanager.scheduler.capacity.ParentQueue: Re-sorting assigned queue: root.default stats: default: capacity=1.0, absoluteCapacity=1.0, usedResources=<memory:4096, vCores:3>, usedCapacity=0.5, absoluteUsedCapacity=0.5, numApps=1, numContainers=3
2019-09-16 06:28:59,137 INFO org.apache.hadoop.yarn.server.resourcemanager.scheduler.capacity.ParentQueue: assignedContainer queue=root usedCapacity=0.5 absoluteUsedCapacity=0.5 used=<memory:4096, vCores:3> cluster=<memory:8192, vCores:8>
2019-09-16 06:28:59,138 INFO org.apache.hadoop.yarn.server.resourcemanager.rmcontainer.RMContainerImpl: container_1568623076950_0003_01_000004 Container Transitioned from NEW to ALLOCATED
2019-09-16 06:28:59,139 INFO org.apache.hadoop.yarn.server.resourcemanager.RMAuditLogger: USER=root	OPERATION=AM Allocated Container	TARGET=SchedulerApp	RESULT=SUCCESS	APPID=application_1568623076950_0003	CONTAINERID=container_1568623076950_0003_01_000004
2019-09-16 06:28:59,139 INFO org.apache.hadoop.yarn.server.resourcemanager.scheduler.SchedulerNode: Assigned container container_1568623076950_0003_01_000004 of capacity <memory:1024, vCores:1> on host e9a6a0455f0d:38503, which has 4 containers, <memory:5120, vCores:4> used and <memory:3072, vCores:4> available after allocation
2019-09-16 06:28:59,139 INFO org.apache.hadoop.yarn.server.resourcemanager.scheduler.capacity.LeafQueue: assignedContainer application attempt=appattempt_1568623076950_0003_000001 container=Container: [ContainerId: container_1568623076950_0003_01_000004, NodeId: e9a6a0455f0d:38503, NodeHttpAddress: e9a6a0455f0d:8042, Resource: <memory:1024, vCores:1>, Priority: 20, Token: null, ] queue=default: capacity=1.0, absoluteCapacity=1.0, usedResources=<memory:4096, vCores:3>, usedCapacity=0.5, absoluteUsedCapacity=0.5, numApps=1, numContainers=3 clusterResource=<memory:8192, vCores:8>
2019-09-16 06:28:59,140 INFO org.apache.hadoop.yarn.server.resourcemanager.scheduler.capacity.ParentQueue: Re-sorting assigned queue: root.default stats: default: capacity=1.0, absoluteCapacity=1.0, usedResources=<memory:5120, vCores:4>, usedCapacity=0.625, absoluteUsedCapacity=0.625, numApps=1, numContainers=4
2019-09-16 06:28:59,140 INFO org.apache.hadoop.yarn.server.resourcemanager.scheduler.capacity.ParentQueue: assignedContainer queue=root usedCapacity=0.625 absoluteUsedCapacity=0.625 used=<memory:5120, vCores:4> cluster=<memory:8192, vCores:8>
2019-09-16 06:28:59,140 INFO org.apache.hadoop.yarn.server.resourcemanager.rmcontainer.RMContainerImpl: container_1568623076950_0003_01_000005 Container Transitioned from NEW to ALLOCATED
2019-09-16 06:28:59,140 INFO org.apache.hadoop.yarn.server.resourcemanager.RMAuditLogger: USER=root	OPERATION=AM Allocated Container	TARGET=SchedulerApp	RESULT=SUCCESS	APPID=application_1568623076950_0003	CONTAINERID=container_1568623076950_0003_01_000005
2019-09-16 06:28:59,141 INFO org.apache.hadoop.yarn.server.resourcemanager.scheduler.SchedulerNode: Assigned container container_1568623076950_0003_01_000005 of capacity <memory:1024, vCores:1> on host e9a6a0455f0d:38503, which has 5 containers, <memory:6144, vCores:5> used and <memory:2048, vCores:3> available after allocation
2019-09-16 06:28:59,141 INFO org.apache.hadoop.yarn.server.resourcemanager.scheduler.capacity.LeafQueue: assignedContainer application attempt=appattempt_1568623076950_0003_000001 container=Container: [ContainerId: container_1568623076950_0003_01_000005, NodeId: e9a6a0455f0d:38503, NodeHttpAddress: e9a6a0455f0d:8042, Resource: <memory:1024, vCores:1>, Priority: 20, Token: null, ] queue=default: capacity=1.0, absoluteCapacity=1.0, usedResources=<memory:5120, vCores:4>, usedCapacity=0.625, absoluteUsedCapacity=0.625, numApps=1, numContainers=4 clusterResource=<memory:8192, vCores:8>
2019-09-16 06:28:59,141 INFO org.apache.hadoop.yarn.server.resourcemanager.scheduler.capacity.ParentQueue: Re-sorting assigned queue: root.default stats: default: capacity=1.0, absoluteCapacity=1.0, usedResources=<memory:6144, vCores:5>, usedCapacity=0.75, absoluteUsedCapacity=0.75, numApps=1, numContainers=5
2019-09-16 06:28:59,141 INFO org.apache.hadoop.yarn.server.resourcemanager.scheduler.capacity.ParentQueue: assignedContainer queue=root usedCapacity=0.75 absoluteUsedCapacity=0.75 used=<memory:6144, vCores:5> cluster=<memory:8192, vCores:8>
2019-09-16 06:28:59,141 INFO org.apache.hadoop.yarn.server.resourcemanager.rmcontainer.RMContainerImpl: container_1568623076950_0003_01_000006 Container Transitioned from NEW to ALLOCATED
2019-09-16 06:28:59,141 INFO org.apache.hadoop.yarn.server.resourcemanager.RMAuditLogger: USER=root	OPERATION=AM Allocated Container	TARGET=SchedulerApp	RESULT=SUCCESS	APPID=application_1568623076950_0003	CONTAINERID=container_1568623076950_0003_01_000006
2019-09-16 06:28:59,141 INFO org.apache.hadoop.yarn.server.resourcemanager.scheduler.SchedulerNode: Assigned container container_1568623076950_0003_01_000006 of capacity <memory:1024, vCores:1> on host e9a6a0455f0d:38503, which has 6 containers, <memory:7168, vCores:6> used and <memory:1024, vCores:2> available after allocation
2019-09-16 06:28:59,141 INFO org.apache.hadoop.yarn.server.resourcemanager.scheduler.capacity.LeafQueue: assignedContainer application attempt=appattempt_1568623076950_0003_000001 container=Container: [ContainerId: container_1568623076950_0003_01_000006, NodeId: e9a6a0455f0d:38503, NodeHttpAddress: e9a6a0455f0d:8042, Resource: <memory:1024, vCores:1>, Priority: 20, Token: null, ] queue=default: capacity=1.0, absoluteCapacity=1.0, usedResources=<memory:6144, vCores:5>, usedCapacity=0.75, absoluteUsedCapacity=0.75, numApps=1, numContainers=5 clusterResource=<memory:8192, vCores:8>
2019-09-16 06:28:59,141 INFO org.apache.hadoop.yarn.server.resourcemanager.scheduler.capacity.ParentQueue: Re-sorting assigned queue: root.default stats: default: capacity=1.0, absoluteCapacity=1.0, usedResources=<memory:7168, vCores:6>, usedCapacity=0.875, absoluteUsedCapacity=0.875, numApps=1, numContainers=6
2019-09-16 06:28:59,141 INFO org.apache.hadoop.yarn.server.resourcemanager.scheduler.capacity.ParentQueue: assignedContainer queue=root usedCapacity=0.875 absoluteUsedCapacity=0.875 used=<memory:7168, vCores:6> cluster=<memory:8192, vCores:8>
2019-09-16 06:28:59,142 INFO org.apache.hadoop.yarn.server.resourcemanager.rmcontainer.RMContainerImpl: container_1568623076950_0003_01_000007 Container Transitioned from NEW to ALLOCATED
2019-09-16 06:28:59,142 INFO org.apache.hadoop.yarn.server.resourcemanager.RMAuditLogger: USER=root	OPERATION=AM Allocated Container	TARGET=SchedulerApp	RESULT=SUCCESS	APPID=application_1568623076950_0003	CONTAINERID=container_1568623076950_0003_01_000007
2019-09-16 06:28:59,142 INFO org.apache.hadoop.yarn.server.resourcemanager.scheduler.SchedulerNode: Assigned container container_1568623076950_0003_01_000007 of capacity <memory:1024, vCores:1> on host e9a6a0455f0d:38503, which has 7 containers, <memory:8192, vCores:7> used and <memory:0, vCores:1> available after allocation
2019-09-16 06:28:59,142 INFO org.apache.hadoop.yarn.server.resourcemanager.scheduler.capacity.LeafQueue: assignedContainer application attempt=appattempt_1568623076950_0003_000001 container=Container: [ContainerId: container_1568623076950_0003_01_000007, NodeId: e9a6a0455f0d:38503, NodeHttpAddress: e9a6a0455f0d:8042, Resource: <memory:1024, vCores:1>, Priority: 20, Token: null, ] queue=default: capacity=1.0, absoluteCapacity=1.0, usedResources=<memory:7168, vCores:6>, usedCapacity=0.875, absoluteUsedCapacity=0.875, numApps=1, numContainers=6 clusterResource=<memory:8192, vCores:8>
2019-09-16 06:28:59,142 INFO org.apache.hadoop.yarn.server.resourcemanager.scheduler.capacity.ParentQueue: Re-sorting assigned queue: root.default stats: default: capacity=1.0, absoluteCapacity=1.0, usedResources=<memory:8192, vCores:7>, usedCapacity=1.0, absoluteUsedCapacity=1.0, numApps=1, numContainers=7
2019-09-16 06:28:59,142 INFO org.apache.hadoop.yarn.server.resourcemanager.scheduler.capacity.ParentQueue: assignedContainer queue=root usedCapacity=1.0 absoluteUsedCapacity=1.0 used=<memory:8192, vCores:7> cluster=<memory:8192, vCores:8>
2019-09-16 06:29:00,053 INFO org.apache.hadoop.yarn.server.resourcemanager.security.NMTokenSecretManagerInRM: Sending NMToken for nodeId : e9a6a0455f0d:38503 for container : container_1568623076950_0003_01_000002
2019-09-16 06:29:00,055 INFO org.apache.hadoop.yarn.server.resourcemanager.rmcontainer.RMContainerImpl: container_1568623076950_0003_01_000002 Container Transitioned from ALLOCATED to ACQUIRED
2019-09-16 06:29:00,056 INFO org.apache.hadoop.yarn.server.resourcemanager.rmcontainer.RMContainerImpl: container_1568623076950_0003_01_000003 Container Transitioned from ALLOCATED to ACQUIRED
2019-09-16 06:29:00,057 INFO org.apache.hadoop.yarn.server.resourcemanager.rmcontainer.RMContainerImpl: container_1568623076950_0003_01_000004 Container Transitioned from ALLOCATED to ACQUIRED
2019-09-16 06:29:00,057 INFO org.apache.hadoop.yarn.server.resourcemanager.rmcontainer.RMContainerImpl: container_1568623076950_0003_01_000005 Container Transitioned from ALLOCATED to ACQUIRED
2019-09-16 06:29:00,058 INFO org.apache.hadoop.yarn.server.resourcemanager.rmcontainer.RMContainerImpl: container_1568623076950_0003_01_000006 Container Transitioned from ALLOCATED to ACQUIRED
2019-09-16 06:29:00,060 INFO org.apache.hadoop.yarn.server.resourcemanager.rmcontainer.RMContainerImpl: container_1568623076950_0003_01_000007 Container Transitioned from ALLOCATED to ACQUIRED
2019-09-16 06:29:01,137 INFO org.apache.hadoop.yarn.server.resourcemanager.rmcontainer.RMContainerImpl: container_1568623076950_0003_01_000002 Container Transitioned from ACQUIRED to RUNNING
2019-09-16 06:29:01,137 INFO org.apache.hadoop.yarn.server.resourcemanager.rmcontainer.RMContainerImpl: container_1568623076950_0003_01_000003 Container Transitioned from ACQUIRED to RUNNING
2019-09-16 06:29:01,137 INFO org.apache.hadoop.yarn.server.resourcemanager.rmcontainer.RMContainerImpl: container_1568623076950_0003_01_000004 Container Transitioned from ACQUIRED to RUNNING
2019-09-16 06:29:01,137 INFO org.apache.hadoop.yarn.server.resourcemanager.rmcontainer.RMContainerImpl: container_1568623076950_0003_01_000005 Container Transitioned from ACQUIRED to RUNNING
2019-09-16 06:29:01,137 INFO org.apache.hadoop.yarn.server.resourcemanager.rmcontainer.RMContainerImpl: container_1568623076950_0003_01_000006 Container Transitioned from ACQUIRED to RUNNING
2019-09-16 06:29:01,137 INFO org.apache.hadoop.yarn.server.resourcemanager.rmcontainer.RMContainerImpl: container_1568623076950_0003_01_000007 Container Transitioned from ACQUIRED to RUNNING
2019-09-16 06:29:16,485 INFO org.apache.hadoop.yarn.server.resourcemanager.rmcontainer.RMContainerImpl: container_1568623076950_0003_01_000003 Container Transitioned from RUNNING to COMPLETED
2019-09-16 06:29:16,486 INFO org.apache.hadoop.yarn.server.resourcemanager.scheduler.common.fica.FiCaSchedulerApp: Completed container: container_1568623076950_0003_01_000003 in state: COMPLETED event:FINISHED
2019-09-16 06:29:16,486 INFO org.apache.hadoop.yarn.server.resourcemanager.RMAuditLogger: USER=root	OPERATION=AM Released Container	TARGET=SchedulerApp	RESULT=SUCCESS	APPID=application_1568623076950_0003	CONTAINERID=container_1568623076950_0003_01_000003
2019-09-16 06:29:16,486 INFO org.apache.hadoop.yarn.server.resourcemanager.scheduler.SchedulerNode: Released container container_1568623076950_0003_01_000003 of capacity <memory:1024, vCores:1> on host e9a6a0455f0d:38503, which currently has 6 containers, <memory:7168, vCores:6> used and <memory:1024, vCores:2> available, release resources=true
2019-09-16 06:29:16,486 INFO org.apache.hadoop.yarn.server.resourcemanager.scheduler.capacity.LeafQueue: default used=<memory:7168, vCores:6> numContainers=6 user=root user-resources=<memory:7168, vCores:6>
2019-09-16 06:29:16,501 INFO org.apache.hadoop.yarn.server.resourcemanager.scheduler.capacity.LeafQueue: completedContainer container=Container: [ContainerId: container_1568623076950_0003_01_000003, NodeId: e9a6a0455f0d:38503, NodeHttpAddress: e9a6a0455f0d:8042, Resource: <memory:1024, vCores:1>, Priority: 20, Token: Token { kind: ContainerToken, service: 172.24.0.2:38503 }, ] queue=default: capacity=1.0, absoluteCapacity=1.0, usedResources=<memory:7168, vCores:6>, usedCapacity=0.875, absoluteUsedCapacity=0.875, numApps=1, numContainers=6 cluster=<memory:8192, vCores:8>
2019-09-16 06:29:16,502 INFO org.apache.hadoop.yarn.server.resourcemanager.scheduler.capacity.ParentQueue: completedContainer queue=root usedCapacity=0.875 absoluteUsedCapacity=0.875 used=<memory:7168, vCores:6> cluster=<memory:8192, vCores:8>
2019-09-16 06:29:16,502 INFO org.apache.hadoop.yarn.server.resourcemanager.scheduler.capacity.ParentQueue: Re-sorting completed queue: root.default stats: default: capacity=1.0, absoluteCapacity=1.0, usedResources=<memory:7168, vCores:6>, usedCapacity=0.875, absoluteUsedCapacity=0.875, numApps=1, numContainers=6
2019-09-16 06:29:16,502 INFO org.apache.hadoop.yarn.server.resourcemanager.scheduler.capacity.CapacityScheduler: Application attempt appattempt_1568623076950_0003_000001 released container container_1568623076950_0003_01_000003 on node: host: e9a6a0455f0d:38503 #containers=6 available=<memory:1024, vCores:2> used=<memory:7168, vCores:6> with event: FINISHED
2019-09-16 06:29:16,502 INFO org.apache.hadoop.yarn.server.resourcemanager.rmcontainer.RMContainerImpl: container_1568623076950_0003_01_000007 Container Transitioned from RUNNING to COMPLETED
2019-09-16 06:29:16,502 INFO org.apache.hadoop.yarn.server.resourcemanager.scheduler.common.fica.FiCaSchedulerApp: Completed container: container_1568623076950_0003_01_000007 in state: COMPLETED event:FINISHED
2019-09-16 06:29:16,502 INFO org.apache.hadoop.yarn.server.resourcemanager.RMAuditLogger: USER=root	OPERATION=AM Released Container	TARGET=SchedulerApp	RESULT=SUCCESS	APPID=application_1568623076950_0003	CONTAINERID=container_1568623076950_0003_01_000007
2019-09-16 06:29:16,502 INFO org.apache.hadoop.yarn.server.resourcemanager.scheduler.SchedulerNode: Released container container_1568623076950_0003_01_000007 of capacity <memory:1024, vCores:1> on host e9a6a0455f0d:38503, which currently has 5 containers, <memory:6144, vCores:5> used and <memory:2048, vCores:3> available, release resources=true
2019-09-16 06:29:16,502 INFO org.apache.hadoop.yarn.server.resourcemanager.scheduler.capacity.LeafQueue: default used=<memory:6144, vCores:5> numContainers=5 user=root user-resources=<memory:6144, vCores:5>
2019-09-16 06:29:16,502 INFO org.apache.hadoop.yarn.server.resourcemanager.scheduler.capacity.LeafQueue: completedContainer container=Container: [ContainerId: container_1568623076950_0003_01_000007, NodeId: e9a6a0455f0d:38503, NodeHttpAddress: e9a6a0455f0d:8042, Resource: <memory:1024, vCores:1>, Priority: 20, Token: Token { kind: ContainerToken, service: 172.24.0.2:38503 }, ] queue=default: capacity=1.0, absoluteCapacity=1.0, usedResources=<memory:6144, vCores:5>, usedCapacity=0.75, absoluteUsedCapacity=0.75, numApps=1, numContainers=5 cluster=<memory:8192, vCores:8>
2019-09-16 06:29:16,503 INFO org.apache.hadoop.yarn.server.resourcemanager.scheduler.capacity.ParentQueue: completedContainer queue=root usedCapacity=0.75 absoluteUsedCapacity=0.75 used=<memory:6144, vCores:5> cluster=<memory:8192, vCores:8>
2019-09-16 06:29:16,503 INFO org.apache.hadoop.yarn.server.resourcemanager.scheduler.capacity.ParentQueue: Re-sorting completed queue: root.default stats: default: capacity=1.0, absoluteCapacity=1.0, usedResources=<memory:6144, vCores:5>, usedCapacity=0.75, absoluteUsedCapacity=0.75, numApps=1, numContainers=5
2019-09-16 06:29:16,503 INFO org.apache.hadoop.yarn.server.resourcemanager.scheduler.capacity.CapacityScheduler: Application attempt appattempt_1568623076950_0003_000001 released container container_1568623076950_0003_01_000007 on node: host: e9a6a0455f0d:38503 #containers=5 available=<memory:2048, vCores:3> used=<memory:6144, vCores:5> with event: FINISHED
2019-09-16 06:29:16,503 INFO org.apache.hadoop.yarn.server.resourcemanager.rmcontainer.RMContainerImpl: container_1568623076950_0003_01_000005 Container Transitioned from RUNNING to COMPLETED
2019-09-16 06:29:16,503 INFO org.apache.hadoop.yarn.server.resourcemanager.scheduler.common.fica.FiCaSchedulerApp: Completed container: container_1568623076950_0003_01_000005 in state: COMPLETED event:FINISHED
2019-09-16 06:29:16,503 INFO org.apache.hadoop.yarn.server.resourcemanager.RMAuditLogger: USER=root	OPERATION=AM Released Container	TARGET=SchedulerApp	RESULT=SUCCESS	APPID=application_1568623076950_0003	CONTAINERID=container_1568623076950_0003_01_000005
2019-09-16 06:29:16,503 INFO org.apache.hadoop.yarn.server.resourcemanager.scheduler.SchedulerNode: Released container container_1568623076950_0003_01_000005 of capacity <memory:1024, vCores:1> on host e9a6a0455f0d:38503, which currently has 4 containers, <memory:5120, vCores:4> used and <memory:3072, vCores:4> available, release resources=true
2019-09-16 06:29:16,503 INFO org.apache.hadoop.yarn.server.resourcemanager.scheduler.capacity.LeafQueue: default used=<memory:5120, vCores:4> numContainers=4 user=root user-resources=<memory:5120, vCores:4>
2019-09-16 06:29:16,503 INFO org.apache.hadoop.yarn.server.resourcemanager.scheduler.capacity.LeafQueue: completedContainer container=Container: [ContainerId: container_1568623076950_0003_01_000005, NodeId: e9a6a0455f0d:38503, NodeHttpAddress: e9a6a0455f0d:8042, Resource: <memory:1024, vCores:1>, Priority: 20, Token: Token { kind: ContainerToken, service: 172.24.0.2:38503 }, ] queue=default: capacity=1.0, absoluteCapacity=1.0, usedResources=<memory:5120, vCores:4>, usedCapacity=0.625, absoluteUsedCapacity=0.625, numApps=1, numContainers=4 cluster=<memory:8192, vCores:8>
2019-09-16 06:29:16,503 INFO org.apache.hadoop.yarn.server.resourcemanager.scheduler.capacity.ParentQueue: completedContainer queue=root usedCapacity=0.625 absoluteUsedCapacity=0.625 used=<memory:5120, vCores:4> cluster=<memory:8192, vCores:8>
2019-09-16 06:29:16,503 INFO org.apache.hadoop.yarn.server.resourcemanager.scheduler.capacity.ParentQueue: Re-sorting completed queue: root.default stats: default: capacity=1.0, absoluteCapacity=1.0, usedResources=<memory:5120, vCores:4>, usedCapacity=0.625, absoluteUsedCapacity=0.625, numApps=1, numContainers=4
2019-09-16 06:29:16,503 INFO org.apache.hadoop.yarn.server.resourcemanager.scheduler.capacity.CapacityScheduler: Application attempt appattempt_1568623076950_0003_000001 released container container_1568623076950_0003_01_000005 on node: host: e9a6a0455f0d:38503 #containers=4 available=<memory:3072, vCores:4> used=<memory:5120, vCores:4> with event: FINISHED
2019-09-16 06:29:16,503 INFO org.apache.hadoop.yarn.server.resourcemanager.rmcontainer.RMContainerImpl: container_1568623076950_0003_01_000006 Container Transitioned from RUNNING to COMPLETED
2019-09-16 06:29:16,504 INFO org.apache.hadoop.yarn.server.resourcemanager.scheduler.common.fica.FiCaSchedulerApp: Completed container: container_1568623076950_0003_01_000006 in state: COMPLETED event:FINISHED
2019-09-16 06:29:16,504 INFO org.apache.hadoop.yarn.server.resourcemanager.RMAuditLogger: USER=root	OPERATION=AM Released Container	TARGET=SchedulerApp	RESULT=SUCCESS	APPID=application_1568623076950_0003	CONTAINERID=container_1568623076950_0003_01_000006
2019-09-16 06:29:16,504 INFO org.apache.hadoop.yarn.server.resourcemanager.scheduler.SchedulerNode: Released container container_1568623076950_0003_01_000006 of capacity <memory:1024, vCores:1> on host e9a6a0455f0d:38503, which currently has 3 containers, <memory:4096, vCores:3> used and <memory:4096, vCores:5> available, release resources=true
2019-09-16 06:29:16,504 INFO org.apache.hadoop.yarn.server.resourcemanager.scheduler.capacity.LeafQueue: default used=<memory:4096, vCores:3> numContainers=3 user=root user-resources=<memory:4096, vCores:3>
2019-09-16 06:29:16,505 INFO org.apache.hadoop.yarn.server.resourcemanager.scheduler.capacity.LeafQueue: completedContainer container=Container: [ContainerId: container_1568623076950_0003_01_000006, NodeId: e9a6a0455f0d:38503, NodeHttpAddress: e9a6a0455f0d:8042, Resource: <memory:1024, vCores:1>, Priority: 20, Token: Token { kind: ContainerToken, service: 172.24.0.2:38503 }, ] queue=default: capacity=1.0, absoluteCapacity=1.0, usedResources=<memory:4096, vCores:3>, usedCapacity=0.5, absoluteUsedCapacity=0.5, numApps=1, numContainers=3 cluster=<memory:8192, vCores:8>
2019-09-16 06:29:16,505 INFO org.apache.hadoop.yarn.server.resourcemanager.scheduler.capacity.ParentQueue: completedContainer queue=root usedCapacity=0.5 absoluteUsedCapacity=0.5 used=<memory:4096, vCores:3> cluster=<memory:8192, vCores:8>
2019-09-16 06:29:16,505 INFO org.apache.hadoop.yarn.server.resourcemanager.scheduler.capacity.ParentQueue: Re-sorting completed queue: root.default stats: default: capacity=1.0, absoluteCapacity=1.0, usedResources=<memory:4096, vCores:3>, usedCapacity=0.5, absoluteUsedCapacity=0.5, numApps=1, numContainers=3
2019-09-16 06:29:16,505 INFO org.apache.hadoop.yarn.server.resourcemanager.scheduler.capacity.CapacityScheduler: Application attempt appattempt_1568623076950_0003_000001 released container container_1568623076950_0003_01_000006 on node: host: e9a6a0455f0d:38503 #containers=3 available=<memory:4096, vCores:5> used=<memory:4096, vCores:3> with event: FINISHED
2019-09-16 06:29:16,505 INFO org.apache.hadoop.yarn.server.resourcemanager.rmcontainer.RMContainerImpl: container_1568623076950_0003_01_000004 Container Transitioned from RUNNING to COMPLETED
2019-09-16 06:29:16,505 INFO org.apache.hadoop.yarn.server.resourcemanager.scheduler.common.fica.FiCaSchedulerApp: Completed container: container_1568623076950_0003_01_000004 in state: COMPLETED event:FINISHED
2019-09-16 06:29:16,505 INFO org.apache.hadoop.yarn.server.resourcemanager.RMAuditLogger: USER=root	OPERATION=AM Released Container	TARGET=SchedulerApp	RESULT=SUCCESS	APPID=application_1568623076950_0003	CONTAINERID=container_1568623076950_0003_01_000004
2019-09-16 06:29:16,505 INFO org.apache.hadoop.yarn.server.resourcemanager.scheduler.SchedulerNode: Released container container_1568623076950_0003_01_000004 of capacity <memory:1024, vCores:1> on host e9a6a0455f0d:38503, which currently has 2 containers, <memory:3072, vCores:2> used and <memory:5120, vCores:6> available, release resources=true
2019-09-16 06:29:16,505 INFO org.apache.hadoop.yarn.server.resourcemanager.scheduler.capacity.LeafQueue: default used=<memory:3072, vCores:2> numContainers=2 user=root user-resources=<memory:3072, vCores:2>
2019-09-16 06:29:16,505 INFO org.apache.hadoop.yarn.server.resourcemanager.scheduler.capacity.LeafQueue: completedContainer container=Container: [ContainerId: container_1568623076950_0003_01_000004, NodeId: e9a6a0455f0d:38503, NodeHttpAddress: e9a6a0455f0d:8042, Resource: <memory:1024, vCores:1>, Priority: 20, Token: Token { kind: ContainerToken, service: 172.24.0.2:38503 }, ] queue=default: capacity=1.0, absoluteCapacity=1.0, usedResources=<memory:3072, vCores:2>, usedCapacity=0.375, absoluteUsedCapacity=0.375, numApps=1, numContainers=2 cluster=<memory:8192, vCores:8>
2019-09-16 06:29:16,506 INFO org.apache.hadoop.yarn.server.resourcemanager.scheduler.capacity.ParentQueue: completedContainer queue=root usedCapacity=0.375 absoluteUsedCapacity=0.375 used=<memory:3072, vCores:2> cluster=<memory:8192, vCores:8>
2019-09-16 06:29:16,506 INFO org.apache.hadoop.yarn.server.resourcemanager.scheduler.capacity.ParentQueue: Re-sorting completed queue: root.default stats: default: capacity=1.0, absoluteCapacity=1.0, usedResources=<memory:3072, vCores:2>, usedCapacity=0.375, absoluteUsedCapacity=0.375, numApps=1, numContainers=2
2019-09-16 06:29:16,506 INFO org.apache.hadoop.yarn.server.resourcemanager.scheduler.capacity.CapacityScheduler: Application attempt appattempt_1568623076950_0003_000001 released container container_1568623076950_0003_01_000004 on node: host: e9a6a0455f0d:38503 #containers=2 available=<memory:5120, vCores:6> used=<memory:3072, vCores:2> with event: FINISHED
2019-09-16 06:29:16,506 INFO org.apache.hadoop.yarn.server.resourcemanager.rmcontainer.RMContainerImpl: container_1568623076950_0003_01_000002 Container Transitioned from RUNNING to COMPLETED
2019-09-16 06:29:16,506 INFO org.apache.hadoop.yarn.server.resourcemanager.scheduler.common.fica.FiCaSchedulerApp: Completed container: container_1568623076950_0003_01_000002 in state: COMPLETED event:FINISHED
2019-09-16 06:29:16,506 INFO org.apache.hadoop.yarn.server.resourcemanager.RMAuditLogger: USER=root	OPERATION=AM Released Container	TARGET=SchedulerApp	RESULT=SUCCESS	APPID=application_1568623076950_0003	CONTAINERID=container_1568623076950_0003_01_000002
2019-09-16 06:29:16,506 INFO org.apache.hadoop.yarn.server.resourcemanager.scheduler.SchedulerNode: Released container container_1568623076950_0003_01_000002 of capacity <memory:1024, vCores:1> on host e9a6a0455f0d:38503, which currently has 1 containers, <memory:2048, vCores:1> used and <memory:6144, vCores:7> available, release resources=true
2019-09-16 06:29:16,506 INFO org.apache.hadoop.yarn.server.resourcemanager.scheduler.capacity.LeafQueue: default used=<memory:2048, vCores:1> numContainers=1 user=root user-resources=<memory:2048, vCores:1>
2019-09-16 06:29:16,506 INFO org.apache.hadoop.yarn.server.resourcemanager.scheduler.capacity.LeafQueue: completedContainer container=Container: [ContainerId: container_1568623076950_0003_01_000002, NodeId: e9a6a0455f0d:38503, NodeHttpAddress: e9a6a0455f0d:8042, Resource: <memory:1024, vCores:1>, Priority: 20, Token: Token { kind: ContainerToken, service: 172.24.0.2:38503 }, ] queue=default: capacity=1.0, absoluteCapacity=1.0, usedResources=<memory:2048, vCores:1>, usedCapacity=0.25, absoluteUsedCapacity=0.25, numApps=1, numContainers=1 cluster=<memory:8192, vCores:8>
2019-09-16 06:29:16,506 INFO org.apache.hadoop.yarn.server.resourcemanager.scheduler.capacity.ParentQueue: completedContainer queue=root usedCapacity=0.25 absoluteUsedCapacity=0.25 used=<memory:2048, vCores:1> cluster=<memory:8192, vCores:8>
2019-09-16 06:29:16,507 INFO org.apache.hadoop.yarn.server.resourcemanager.scheduler.capacity.ParentQueue: Re-sorting completed queue: root.default stats: default: capacity=1.0, absoluteCapacity=1.0, usedResources=<memory:2048, vCores:1>, usedCapacity=0.25, absoluteUsedCapacity=0.25, numApps=1, numContainers=1
2019-09-16 06:29:16,507 INFO org.apache.hadoop.yarn.server.resourcemanager.scheduler.capacity.CapacityScheduler: Application attempt appattempt_1568623076950_0003_000001 released container container_1568623076950_0003_01_000002 on node: host: e9a6a0455f0d:38503 #containers=1 available=<memory:6144, vCores:7> used=<memory:2048, vCores:1> with event: FINISHED
2019-09-16 06:29:16,508 INFO org.apache.hadoop.yarn.server.resourcemanager.rmcontainer.RMContainerImpl: container_1568623076950_0003_01_000008 Container Transitioned from NEW to ALLOCATED
2019-09-16 06:29:16,533 INFO org.apache.hadoop.yarn.server.resourcemanager.RMAuditLogger: USER=root	OPERATION=AM Allocated Container	TARGET=SchedulerApp	RESULT=SUCCESS	APPID=application_1568623076950_0003	CONTAINERID=container_1568623076950_0003_01_000008
2019-09-16 06:29:16,533 INFO org.apache.hadoop.yarn.server.resourcemanager.scheduler.SchedulerNode: Assigned container container_1568623076950_0003_01_000008 of capacity <memory:1024, vCores:1> on host e9a6a0455f0d:38503, which has 2 containers, <memory:3072, vCores:2> used and <memory:5120, vCores:6> available after allocation
2019-09-16 06:29:16,533 INFO org.apache.hadoop.yarn.server.resourcemanager.scheduler.capacity.LeafQueue: assignedContainer application attempt=appattempt_1568623076950_0003_000001 container=Container: [ContainerId: container_1568623076950_0003_01_000008, NodeId: e9a6a0455f0d:38503, NodeHttpAddress: e9a6a0455f0d:8042, Resource: <memory:1024, vCores:1>, Priority: 10, Token: null, ] queue=default: capacity=1.0, absoluteCapacity=1.0, usedResources=<memory:2048, vCores:1>, usedCapacity=0.25, absoluteUsedCapacity=0.25, numApps=1, numContainers=1 clusterResource=<memory:8192, vCores:8>
2019-09-16 06:29:16,534 INFO org.apache.hadoop.yarn.server.resourcemanager.scheduler.capacity.ParentQueue: Re-sorting assigned queue: root.default stats: default: capacity=1.0, absoluteCapacity=1.0, usedResources=<memory:3072, vCores:2>, usedCapacity=0.375, absoluteUsedCapacity=0.375, numApps=1, numContainers=2
2019-09-16 06:29:16,534 INFO org.apache.hadoop.yarn.server.resourcemanager.scheduler.capacity.ParentQueue: assignedContainer queue=root usedCapacity=0.375 absoluteUsedCapacity=0.375 used=<memory:3072, vCores:2> cluster=<memory:8192, vCores:8>
2019-09-16 06:29:17,517 INFO org.apache.hadoop.yarn.server.resourcemanager.rmcontainer.RMContainerImpl: container_1568623076950_0003_01_000009 Container Transitioned from NEW to ALLOCATED
2019-09-16 06:29:17,518 INFO org.apache.hadoop.yarn.server.resourcemanager.RMAuditLogger: USER=root	OPERATION=AM Allocated Container	TARGET=SchedulerApp	RESULT=SUCCESS	APPID=application_1568623076950_0003	CONTAINERID=container_1568623076950_0003_01_000009
2019-09-16 06:29:17,518 INFO org.apache.hadoop.yarn.server.resourcemanager.scheduler.SchedulerNode: Assigned container container_1568623076950_0003_01_000009 of capacity <memory:1024, vCores:1> on host e9a6a0455f0d:38503, which has 3 containers, <memory:4096, vCores:3> used and <memory:4096, vCores:5> available after allocation
2019-09-16 06:29:17,519 INFO org.apache.hadoop.yarn.server.resourcemanager.scheduler.capacity.LeafQueue: assignedContainer application attempt=appattempt_1568623076950_0003_000001 container=Container: [ContainerId: container_1568623076950_0003_01_000009, NodeId: e9a6a0455f0d:38503, NodeHttpAddress: e9a6a0455f0d:8042, Resource: <memory:1024, vCores:1>, Priority: 20, Token: null, ] queue=default: capacity=1.0, absoluteCapacity=1.0, usedResources=<memory:3072, vCores:2>, usedCapacity=0.375, absoluteUsedCapacity=0.375, numApps=1, numContainers=2 clusterResource=<memory:8192, vCores:8>
2019-09-16 06:29:17,519 INFO org.apache.hadoop.yarn.server.resourcemanager.scheduler.capacity.ParentQueue: Re-sorting assigned queue: root.default stats: default: capacity=1.0, absoluteCapacity=1.0, usedResources=<memory:4096, vCores:3>, usedCapacity=0.5, absoluteUsedCapacity=0.5, numApps=1, numContainers=3
2019-09-16 06:29:17,527 INFO org.apache.hadoop.yarn.server.resourcemanager.scheduler.capacity.ParentQueue: assignedContainer queue=root usedCapacity=0.5 absoluteUsedCapacity=0.5 used=<memory:4096, vCores:3> cluster=<memory:8192, vCores:8>
2019-09-16 06:29:17,568 INFO org.apache.hadoop.yarn.server.resourcemanager.rmcontainer.RMContainerImpl: container_1568623076950_0003_01_000008 Container Transitioned from ALLOCATED to ACQUIRED
2019-09-16 06:29:17,773 INFO org.apache.hadoop.yarn.server.resourcemanager.rmcontainer.RMContainerImpl: container_1568623076950_0003_01_000009 Container Transitioned from ALLOCATED to ACQUIRED
2019-09-16 06:29:17,781 INFO org.apache.hadoop.yarn.server.resourcemanager.rmcontainer.RMContainerImpl: container_1568623076950_0003_01_000010 Container Transitioned from NEW to ALLOCATED
2019-09-16 06:29:17,784 INFO org.apache.hadoop.yarn.server.resourcemanager.RMAuditLogger: USER=root	OPERATION=AM Allocated Container	TARGET=SchedulerApp	RESULT=SUCCESS	APPID=application_1568623076950_0003	CONTAINERID=container_1568623076950_0003_01_000010
2019-09-16 06:29:17,785 INFO org.apache.hadoop.yarn.server.resourcemanager.scheduler.SchedulerNode: Assigned container container_1568623076950_0003_01_000010 of capacity <memory:1024, vCores:1> on host e9a6a0455f0d:38503, which has 4 containers, <memory:5120, vCores:4> used and <memory:3072, vCores:4> available after allocation
2019-09-16 06:29:17,805 INFO org.apache.hadoop.yarn.server.resourcemanager.scheduler.capacity.LeafQueue: assignedContainer application attempt=appattempt_1568623076950_0003_000001 container=Container: [ContainerId: container_1568623076950_0003_01_000010, NodeId: e9a6a0455f0d:38503, NodeHttpAddress: e9a6a0455f0d:8042, Resource: <memory:1024, vCores:1>, Priority: 20, Token: null, ] queue=default: capacity=1.0, absoluteCapacity=1.0, usedResources=<memory:4096, vCores:3>, usedCapacity=0.5, absoluteUsedCapacity=0.5, numApps=1, numContainers=3 clusterResource=<memory:8192, vCores:8>
2019-09-16 06:29:17,808 INFO org.apache.hadoop.yarn.server.resourcemanager.scheduler.capacity.ParentQueue: Re-sorting assigned queue: root.default stats: default: capacity=1.0, absoluteCapacity=1.0, usedResources=<memory:5120, vCores:4>, usedCapacity=0.625, absoluteUsedCapacity=0.625, numApps=1, numContainers=4
2019-09-16 06:29:17,815 INFO org.apache.hadoop.yarn.server.resourcemanager.scheduler.capacity.ParentQueue: assignedContainer queue=root usedCapacity=0.625 absoluteUsedCapacity=0.625 used=<memory:5120, vCores:4> cluster=<memory:8192, vCores:8>
2019-09-16 06:29:17,816 INFO org.apache.hadoop.yarn.server.resourcemanager.rmcontainer.RMContainerImpl: container_1568623076950_0003_01_000011 Container Transitioned from NEW to ALLOCATED
2019-09-16 06:29:17,816 INFO org.apache.hadoop.yarn.server.resourcemanager.RMAuditLogger: USER=root	OPERATION=AM Allocated Container	TARGET=SchedulerApp	RESULT=SUCCESS	APPID=application_1568623076950_0003	CONTAINERID=container_1568623076950_0003_01_000011
2019-09-16 06:29:17,816 INFO org.apache.hadoop.yarn.server.resourcemanager.scheduler.SchedulerNode: Assigned container container_1568623076950_0003_01_000011 of capacity <memory:1024, vCores:1> on host e9a6a0455f0d:38503, which has 5 containers, <memory:6144, vCores:5> used and <memory:2048, vCores:3> available after allocation
2019-09-16 06:29:17,839 INFO org.apache.hadoop.yarn.server.resourcemanager.scheduler.capacity.LeafQueue: assignedContainer application attempt=appattempt_1568623076950_0003_000001 container=Container: [ContainerId: container_1568623076950_0003_01_000011, NodeId: e9a6a0455f0d:38503, NodeHttpAddress: e9a6a0455f0d:8042, Resource: <memory:1024, vCores:1>, Priority: 20, Token: null, ] queue=default: capacity=1.0, absoluteCapacity=1.0, usedResources=<memory:5120, vCores:4>, usedCapacity=0.625, absoluteUsedCapacity=0.625, numApps=1, numContainers=4 clusterResource=<memory:8192, vCores:8>
2019-09-16 06:29:17,845 INFO org.apache.hadoop.yarn.server.resourcemanager.scheduler.capacity.ParentQueue: Re-sorting assigned queue: root.default stats: default: capacity=1.0, absoluteCapacity=1.0, usedResources=<memory:6144, vCores:5>, usedCapacity=0.75, absoluteUsedCapacity=0.75, numApps=1, numContainers=5
2019-09-16 06:29:17,855 INFO org.apache.hadoop.yarn.server.resourcemanager.scheduler.capacity.ParentQueue: assignedContainer queue=root usedCapacity=0.75 absoluteUsedCapacity=0.75 used=<memory:6144, vCores:5> cluster=<memory:8192, vCores:8>
2019-09-16 06:29:17,856 INFO org.apache.hadoop.yarn.server.resourcemanager.rmcontainer.RMContainerImpl: container_1568623076950_0003_01_000012 Container Transitioned from NEW to ALLOCATED
2019-09-16 06:29:17,856 INFO org.apache.hadoop.yarn.server.resourcemanager.RMAuditLogger: USER=root	OPERATION=AM Allocated Container	TARGET=SchedulerApp	RESULT=SUCCESS	APPID=application_1568623076950_0003	CONTAINERID=container_1568623076950_0003_01_000012
2019-09-16 06:29:17,856 INFO org.apache.hadoop.yarn.server.resourcemanager.scheduler.SchedulerNode: Assigned container container_1568623076950_0003_01_000012 of capacity <memory:1024, vCores:1> on host e9a6a0455f0d:38503, which has 6 containers, <memory:7168, vCores:6> used and <memory:1024, vCores:2> available after allocation
2019-09-16 06:29:17,856 INFO org.apache.hadoop.yarn.server.resourcemanager.scheduler.capacity.LeafQueue: assignedContainer application attempt=appattempt_1568623076950_0003_000001 container=Container: [ContainerId: container_1568623076950_0003_01_000012, NodeId: e9a6a0455f0d:38503, NodeHttpAddress: e9a6a0455f0d:8042, Resource: <memory:1024, vCores:1>, Priority: 20, Token: null, ] queue=default: capacity=1.0, absoluteCapacity=1.0, usedResources=<memory:6144, vCores:5>, usedCapacity=0.75, absoluteUsedCapacity=0.75, numApps=1, numContainers=5 clusterResource=<memory:8192, vCores:8>
2019-09-16 06:29:17,856 INFO org.apache.hadoop.yarn.server.resourcemanager.scheduler.capacity.ParentQueue: Re-sorting assigned queue: root.default stats: default: capacity=1.0, absoluteCapacity=1.0, usedResources=<memory:7168, vCores:6>, usedCapacity=0.875, absoluteUsedCapacity=0.875, numApps=1, numContainers=6
2019-09-16 06:29:17,856 INFO org.apache.hadoop.yarn.server.resourcemanager.scheduler.capacity.ParentQueue: assignedContainer queue=root usedCapacity=0.875 absoluteUsedCapacity=0.875 used=<memory:7168, vCores:6> cluster=<memory:8192, vCores:8>
2019-09-16 06:29:17,856 INFO org.apache.hadoop.yarn.server.resourcemanager.rmcontainer.RMContainerImpl: container_1568623076950_0003_01_000013 Container Transitioned from NEW to ALLOCATED
2019-09-16 06:29:17,856 INFO org.apache.hadoop.yarn.server.resourcemanager.RMAuditLogger: USER=root	OPERATION=AM Allocated Container	TARGET=SchedulerApp	RESULT=SUCCESS	APPID=application_1568623076950_0003	CONTAINERID=container_1568623076950_0003_01_000013
2019-09-16 06:29:17,856 INFO org.apache.hadoop.yarn.server.resourcemanager.scheduler.SchedulerNode: Assigned container container_1568623076950_0003_01_000013 of capacity <memory:1024, vCores:1> on host e9a6a0455f0d:38503, which has 7 containers, <memory:8192, vCores:7> used and <memory:0, vCores:1> available after allocation
2019-09-16 06:29:17,857 INFO org.apache.hadoop.yarn.server.resourcemanager.scheduler.capacity.LeafQueue: assignedContainer application attempt=appattempt_1568623076950_0003_000001 container=Container: [ContainerId: container_1568623076950_0003_01_000013, NodeId: e9a6a0455f0d:38503, NodeHttpAddress: e9a6a0455f0d:8042, Resource: <memory:1024, vCores:1>, Priority: 20, Token: null, ] queue=default: capacity=1.0, absoluteCapacity=1.0, usedResources=<memory:7168, vCores:6>, usedCapacity=0.875, absoluteUsedCapacity=0.875, numApps=1, numContainers=6 clusterResource=<memory:8192, vCores:8>
2019-09-16 06:29:17,857 INFO org.apache.hadoop.yarn.server.resourcemanager.scheduler.capacity.ParentQueue: Re-sorting assigned queue: root.default stats: default: capacity=1.0, absoluteCapacity=1.0, usedResources=<memory:8192, vCores:7>, usedCapacity=1.0, absoluteUsedCapacity=1.0, numApps=1, numContainers=7
2019-09-16 06:29:17,857 INFO org.apache.hadoop.yarn.server.resourcemanager.scheduler.capacity.ParentQueue: assignedContainer queue=root usedCapacity=1.0 absoluteUsedCapacity=1.0 used=<memory:8192, vCores:7> cluster=<memory:8192, vCores:8>
2019-09-16 06:29:18,556 INFO org.apache.hadoop.yarn.server.resourcemanager.rmcontainer.RMContainerImpl: container_1568623076950_0003_01_000008 Container Transitioned from ACQUIRED to RUNNING
2019-09-16 06:29:18,556 INFO org.apache.hadoop.yarn.server.resourcemanager.rmcontainer.RMContainerImpl: container_1568623076950_0003_01_000009 Container Transitioned from ACQUIRED to RUNNING
2019-09-16 06:29:18,825 INFO org.apache.hadoop.yarn.server.resourcemanager.scheduler.AppSchedulingInfo: checking for deactivate of application :application_1568623076950_0003
2019-09-16 06:29:18,826 INFO org.apache.hadoop.yarn.server.resourcemanager.rmcontainer.RMContainerImpl: container_1568623076950_0003_01_000010 Container Transitioned from ALLOCATED to ACQUIRED
2019-09-16 06:29:18,828 INFO org.apache.hadoop.yarn.server.resourcemanager.rmcontainer.RMContainerImpl: container_1568623076950_0003_01_000011 Container Transitioned from ALLOCATED to ACQUIRED
2019-09-16 06:29:18,829 INFO org.apache.hadoop.yarn.server.resourcemanager.rmcontainer.RMContainerImpl: container_1568623076950_0003_01_000012 Container Transitioned from ALLOCATED to ACQUIRED
2019-09-16 06:29:18,831 INFO org.apache.hadoop.yarn.server.resourcemanager.rmcontainer.RMContainerImpl: container_1568623076950_0003_01_000013 Container Transitioned from ALLOCATED to ACQUIRED
2019-09-16 06:29:19,517 INFO org.apache.hadoop.yarn.server.resourcemanager.rmcontainer.RMContainerImpl: container_1568623076950_0003_01_000010 Container Transitioned from ACQUIRED to RUNNING
2019-09-16 06:29:19,517 INFO org.apache.hadoop.yarn.server.resourcemanager.rmcontainer.RMContainerImpl: container_1568623076950_0003_01_000011 Container Transitioned from ACQUIRED to RUNNING
2019-09-16 06:29:19,517 INFO org.apache.hadoop.yarn.server.resourcemanager.rmcontainer.RMContainerImpl: container_1568623076950_0003_01_000012 Container Transitioned from ACQUIRED to RUNNING
2019-09-16 06:29:19,517 INFO org.apache.hadoop.yarn.server.resourcemanager.rmcontainer.RMContainerImpl: container_1568623076950_0003_01_000013 Container Transitioned from ACQUIRED to RUNNING
2019-09-16 06:29:34,064 INFO org.apache.hadoop.yarn.server.resourcemanager.rmcontainer.RMContainerImpl: container_1568623076950_0003_01_000013 Container Transitioned from RUNNING to COMPLETED
2019-09-16 06:29:34,065 INFO org.apache.hadoop.yarn.server.resourcemanager.scheduler.common.fica.FiCaSchedulerApp: Completed container: container_1568623076950_0003_01_000013 in state: COMPLETED event:FINISHED
2019-09-16 06:29:34,065 INFO org.apache.hadoop.yarn.server.resourcemanager.RMAuditLogger: USER=root	OPERATION=AM Released Container	TARGET=SchedulerApp	RESULT=SUCCESS	APPID=application_1568623076950_0003	CONTAINERID=container_1568623076950_0003_01_000013
2019-09-16 06:29:34,065 INFO org.apache.hadoop.yarn.server.resourcemanager.scheduler.SchedulerNode: Released container container_1568623076950_0003_01_000013 of capacity <memory:1024, vCores:1> on host e9a6a0455f0d:38503, which currently has 6 containers, <memory:7168, vCores:6> used and <memory:1024, vCores:2> available, release resources=true
2019-09-16 06:29:34,065 INFO org.apache.hadoop.yarn.server.resourcemanager.scheduler.capacity.LeafQueue: default used=<memory:7168, vCores:6> numContainers=6 user=root user-resources=<memory:7168, vCores:6>
2019-09-16 06:29:34,069 INFO org.apache.hadoop.yarn.server.resourcemanager.scheduler.capacity.LeafQueue: completedContainer container=Container: [ContainerId: container_1568623076950_0003_01_000013, NodeId: e9a6a0455f0d:38503, NodeHttpAddress: e9a6a0455f0d:8042, Resource: <memory:1024, vCores:1>, Priority: 20, Token: Token { kind: ContainerToken, service: 172.24.0.2:38503 }, ] queue=default: capacity=1.0, absoluteCapacity=1.0, usedResources=<memory:7168, vCores:6>, usedCapacity=0.875, absoluteUsedCapacity=0.875, numApps=1, numContainers=6 cluster=<memory:8192, vCores:8>
2019-09-16 06:29:34,069 INFO org.apache.hadoop.yarn.server.resourcemanager.scheduler.capacity.ParentQueue: completedContainer queue=root usedCapacity=0.875 absoluteUsedCapacity=0.875 used=<memory:7168, vCores:6> cluster=<memory:8192, vCores:8>
2019-09-16 06:29:34,069 INFO org.apache.hadoop.yarn.server.resourcemanager.scheduler.capacity.ParentQueue: Re-sorting completed queue: root.default stats: default: capacity=1.0, absoluteCapacity=1.0, usedResources=<memory:7168, vCores:6>, usedCapacity=0.875, absoluteUsedCapacity=0.875, numApps=1, numContainers=6
2019-09-16 06:29:34,069 INFO org.apache.hadoop.yarn.server.resourcemanager.scheduler.capacity.CapacityScheduler: Application attempt appattempt_1568623076950_0003_000001 released container container_1568623076950_0003_01_000013 on node: host: e9a6a0455f0d:38503 #containers=6 available=<memory:1024, vCores:2> used=<memory:7168, vCores:6> with event: FINISHED
2019-09-16 06:29:34,069 INFO org.apache.hadoop.yarn.server.resourcemanager.rmcontainer.RMContainerImpl: container_1568623076950_0003_01_000010 Container Transitioned from RUNNING to COMPLETED
2019-09-16 06:29:34,069 INFO org.apache.hadoop.yarn.server.resourcemanager.scheduler.common.fica.FiCaSchedulerApp: Completed container: container_1568623076950_0003_01_000010 in state: COMPLETED event:FINISHED
2019-09-16 06:29:34,069 INFO org.apache.hadoop.yarn.server.resourcemanager.RMAuditLogger: USER=root	OPERATION=AM Released Container	TARGET=SchedulerApp	RESULT=SUCCESS	APPID=application_1568623076950_0003	CONTAINERID=container_1568623076950_0003_01_000010
2019-09-16 06:29:34,069 INFO org.apache.hadoop.yarn.server.resourcemanager.scheduler.SchedulerNode: Released container container_1568623076950_0003_01_000010 of capacity <memory:1024, vCores:1> on host e9a6a0455f0d:38503, which currently has 5 containers, <memory:6144, vCores:5> used and <memory:2048, vCores:3> available, release resources=true
2019-09-16 06:29:34,069 INFO org.apache.hadoop.yarn.server.resourcemanager.scheduler.capacity.LeafQueue: default used=<memory:6144, vCores:5> numContainers=5 user=root user-resources=<memory:6144, vCores:5>
2019-09-16 06:29:34,069 INFO org.apache.hadoop.yarn.server.resourcemanager.scheduler.capacity.LeafQueue: completedContainer container=Container: [ContainerId: container_1568623076950_0003_01_000010, NodeId: e9a6a0455f0d:38503, NodeHttpAddress: e9a6a0455f0d:8042, Resource: <memory:1024, vCores:1>, Priority: 20, Token: Token { kind: ContainerToken, service: 172.24.0.2:38503 }, ] queue=default: capacity=1.0, absoluteCapacity=1.0, usedResources=<memory:6144, vCores:5>, usedCapacity=0.75, absoluteUsedCapacity=0.75, numApps=1, numContainers=5 cluster=<memory:8192, vCores:8>
2019-09-16 06:29:34,070 INFO org.apache.hadoop.yarn.server.resourcemanager.scheduler.capacity.ParentQueue: completedContainer queue=root usedCapacity=0.75 absoluteUsedCapacity=0.75 used=<memory:6144, vCores:5> cluster=<memory:8192, vCores:8>
2019-09-16 06:29:34,070 INFO org.apache.hadoop.yarn.server.resourcemanager.scheduler.capacity.ParentQueue: Re-sorting completed queue: root.default stats: default: capacity=1.0, absoluteCapacity=1.0, usedResources=<memory:6144, vCores:5>, usedCapacity=0.75, absoluteUsedCapacity=0.75, numApps=1, numContainers=5
2019-09-16 06:29:34,070 INFO org.apache.hadoop.yarn.server.resourcemanager.scheduler.capacity.CapacityScheduler: Application attempt appattempt_1568623076950_0003_000001 released container container_1568623076950_0003_01_000010 on node: host: e9a6a0455f0d:38503 #containers=5 available=<memory:2048, vCores:3> used=<memory:6144, vCores:5> with event: FINISHED
2019-09-16 06:29:34,070 INFO org.apache.hadoop.yarn.server.resourcemanager.rmcontainer.RMContainerImpl: container_1568623076950_0003_01_000009 Container Transitioned from RUNNING to COMPLETED
2019-09-16 06:29:34,070 INFO org.apache.hadoop.yarn.server.resourcemanager.scheduler.common.fica.FiCaSchedulerApp: Completed container: container_1568623076950_0003_01_000009 in state: COMPLETED event:FINISHED
2019-09-16 06:29:34,070 INFO org.apache.hadoop.yarn.server.resourcemanager.RMAuditLogger: USER=root	OPERATION=AM Released Container	TARGET=SchedulerApp	RESULT=SUCCESS	APPID=application_1568623076950_0003	CONTAINERID=container_1568623076950_0003_01_000009
2019-09-16 06:29:34,070 INFO org.apache.hadoop.yarn.server.resourcemanager.scheduler.SchedulerNode: Released container container_1568623076950_0003_01_000009 of capacity <memory:1024, vCores:1> on host e9a6a0455f0d:38503, which currently has 4 containers, <memory:5120, vCores:4> used and <memory:3072, vCores:4> available, release resources=true
2019-09-16 06:29:34,070 INFO org.apache.hadoop.yarn.server.resourcemanager.scheduler.capacity.LeafQueue: default used=<memory:5120, vCores:4> numContainers=4 user=root user-resources=<memory:5120, vCores:4>
2019-09-16 06:29:34,070 INFO org.apache.hadoop.yarn.server.resourcemanager.scheduler.capacity.LeafQueue: completedContainer container=Container: [ContainerId: container_1568623076950_0003_01_000009, NodeId: e9a6a0455f0d:38503, NodeHttpAddress: e9a6a0455f0d:8042, Resource: <memory:1024, vCores:1>, Priority: 20, Token: Token { kind: ContainerToken, service: 172.24.0.2:38503 }, ] queue=default: capacity=1.0, absoluteCapacity=1.0, usedResources=<memory:5120, vCores:4>, usedCapacity=0.625, absoluteUsedCapacity=0.625, numApps=1, numContainers=4 cluster=<memory:8192, vCores:8>
2019-09-16 06:29:34,070 INFO org.apache.hadoop.yarn.server.resourcemanager.scheduler.capacity.ParentQueue: completedContainer queue=root usedCapacity=0.625 absoluteUsedCapacity=0.625 used=<memory:5120, vCores:4> cluster=<memory:8192, vCores:8>
2019-09-16 06:29:34,070 INFO org.apache.hadoop.yarn.server.resourcemanager.scheduler.capacity.ParentQueue: Re-sorting completed queue: root.default stats: default: capacity=1.0, absoluteCapacity=1.0, usedResources=<memory:5120, vCores:4>, usedCapacity=0.625, absoluteUsedCapacity=0.625, numApps=1, numContainers=4
2019-09-16 06:29:34,070 INFO org.apache.hadoop.yarn.server.resourcemanager.scheduler.capacity.CapacityScheduler: Application attempt appattempt_1568623076950_0003_000001 released container container_1568623076950_0003_01_000009 on node: host: e9a6a0455f0d:38503 #containers=4 available=<memory:3072, vCores:4> used=<memory:5120, vCores:4> with event: FINISHED
2019-09-16 06:29:34,070 INFO org.apache.hadoop.yarn.server.resourcemanager.rmcontainer.RMContainerImpl: container_1568623076950_0003_01_000012 Container Transitioned from RUNNING to COMPLETED
2019-09-16 06:29:34,070 INFO org.apache.hadoop.yarn.server.resourcemanager.scheduler.common.fica.FiCaSchedulerApp: Completed container: container_1568623076950_0003_01_000012 in state: COMPLETED event:FINISHED
2019-09-16 06:29:34,071 INFO org.apache.hadoop.yarn.server.resourcemanager.RMAuditLogger: USER=root	OPERATION=AM Released Container	TARGET=SchedulerApp	RESULT=SUCCESS	APPID=application_1568623076950_0003	CONTAINERID=container_1568623076950_0003_01_000012
2019-09-16 06:29:34,071 INFO org.apache.hadoop.yarn.server.resourcemanager.scheduler.SchedulerNode: Released container container_1568623076950_0003_01_000012 of capacity <memory:1024, vCores:1> on host e9a6a0455f0d:38503, which currently has 3 containers, <memory:4096, vCores:3> used and <memory:4096, vCores:5> available, release resources=true
2019-09-16 06:29:34,071 INFO org.apache.hadoop.yarn.server.resourcemanager.scheduler.capacity.LeafQueue: default used=<memory:4096, vCores:3> numContainers=3 user=root user-resources=<memory:4096, vCores:3>
2019-09-16 06:29:34,071 INFO org.apache.hadoop.yarn.server.resourcemanager.scheduler.capacity.LeafQueue: completedContainer container=Container: [ContainerId: container_1568623076950_0003_01_000012, NodeId: e9a6a0455f0d:38503, NodeHttpAddress: e9a6a0455f0d:8042, Resource: <memory:1024, vCores:1>, Priority: 20, Token: Token { kind: ContainerToken, service: 172.24.0.2:38503 }, ] queue=default: capacity=1.0, absoluteCapacity=1.0, usedResources=<memory:4096, vCores:3>, usedCapacity=0.5, absoluteUsedCapacity=0.5, numApps=1, numContainers=3 cluster=<memory:8192, vCores:8>
2019-09-16 06:29:34,071 INFO org.apache.hadoop.yarn.server.resourcemanager.scheduler.capacity.ParentQueue: completedContainer queue=root usedCapacity=0.5 absoluteUsedCapacity=0.5 used=<memory:4096, vCores:3> cluster=<memory:8192, vCores:8>
2019-09-16 06:29:34,072 INFO org.apache.hadoop.yarn.server.resourcemanager.scheduler.capacity.ParentQueue: Re-sorting completed queue: root.default stats: default: capacity=1.0, absoluteCapacity=1.0, usedResources=<memory:4096, vCores:3>, usedCapacity=0.5, absoluteUsedCapacity=0.5, numApps=1, numContainers=3
2019-09-16 06:29:34,072 INFO org.apache.hadoop.yarn.server.resourcemanager.scheduler.capacity.CapacityScheduler: Application attempt appattempt_1568623076950_0003_000001 released container container_1568623076950_0003_01_000012 on node: host: e9a6a0455f0d:38503 #containers=3 available=<memory:4096, vCores:5> used=<memory:4096, vCores:3> with event: FINISHED
2019-09-16 06:29:34,072 INFO org.apache.hadoop.yarn.server.resourcemanager.rmcontainer.RMContainerImpl: container_1568623076950_0003_01_000011 Container Transitioned from RUNNING to COMPLETED
2019-09-16 06:29:34,072 INFO org.apache.hadoop.yarn.server.resourcemanager.scheduler.common.fica.FiCaSchedulerApp: Completed container: container_1568623076950_0003_01_000011 in state: COMPLETED event:FINISHED
2019-09-16 06:29:34,072 INFO org.apache.hadoop.yarn.server.resourcemanager.RMAuditLogger: USER=root	OPERATION=AM Released Container	TARGET=SchedulerApp	RESULT=SUCCESS	APPID=application_1568623076950_0003	CONTAINERID=container_1568623076950_0003_01_000011
2019-09-16 06:29:34,072 INFO org.apache.hadoop.yarn.server.resourcemanager.scheduler.SchedulerNode: Released container container_1568623076950_0003_01_000011 of capacity <memory:1024, vCores:1> on host e9a6a0455f0d:38503, which currently has 2 containers, <memory:3072, vCores:2> used and <memory:5120, vCores:6> available, release resources=true
2019-09-16 06:29:34,072 INFO org.apache.hadoop.yarn.server.resourcemanager.scheduler.capacity.LeafQueue: default used=<memory:3072, vCores:2> numContainers=2 user=root user-resources=<memory:3072, vCores:2>
2019-09-16 06:29:34,073 INFO org.apache.hadoop.yarn.server.resourcemanager.scheduler.capacity.LeafQueue: completedContainer container=Container: [ContainerId: container_1568623076950_0003_01_000011, NodeId: e9a6a0455f0d:38503, NodeHttpAddress: e9a6a0455f0d:8042, Resource: <memory:1024, vCores:1>, Priority: 20, Token: Token { kind: ContainerToken, service: 172.24.0.2:38503 }, ] queue=default: capacity=1.0, absoluteCapacity=1.0, usedResources=<memory:3072, vCores:2>, usedCapacity=0.375, absoluteUsedCapacity=0.375, numApps=1, numContainers=2 cluster=<memory:8192, vCores:8>
2019-09-16 06:29:34,073 INFO org.apache.hadoop.yarn.server.resourcemanager.scheduler.capacity.ParentQueue: completedContainer queue=root usedCapacity=0.375 absoluteUsedCapacity=0.375 used=<memory:3072, vCores:2> cluster=<memory:8192, vCores:8>
2019-09-16 06:29:34,073 INFO org.apache.hadoop.yarn.server.resourcemanager.scheduler.capacity.ParentQueue: Re-sorting completed queue: root.default stats: default: capacity=1.0, absoluteCapacity=1.0, usedResources=<memory:3072, vCores:2>, usedCapacity=0.375, absoluteUsedCapacity=0.375, numApps=1, numContainers=2
2019-09-16 06:29:34,073 INFO org.apache.hadoop.yarn.server.resourcemanager.scheduler.capacity.CapacityScheduler: Application attempt appattempt_1568623076950_0003_000001 released container container_1568623076950_0003_01_000011 on node: host: e9a6a0455f0d:38503 #containers=2 available=<memory:5120, vCores:6> used=<memory:3072, vCores:2> with event: FINISHED
2019-09-16 06:29:34,073 INFO org.apache.hadoop.yarn.server.resourcemanager.rmcontainer.RMContainerImpl: container_1568623076950_0003_01_000014 Container Transitioned from NEW to ALLOCATED
2019-09-16 06:29:34,073 INFO org.apache.hadoop.yarn.server.resourcemanager.RMAuditLogger: USER=root	OPERATION=AM Allocated Container	TARGET=SchedulerApp	RESULT=SUCCESS	APPID=application_1568623076950_0003	CONTAINERID=container_1568623076950_0003_01_000014
2019-09-16 06:29:34,073 INFO org.apache.hadoop.yarn.server.resourcemanager.scheduler.SchedulerNode: Assigned container container_1568623076950_0003_01_000014 of capacity <memory:1024, vCores:1> on host e9a6a0455f0d:38503, which has 3 containers, <memory:4096, vCores:3> used and <memory:4096, vCores:5> available after allocation
2019-09-16 06:29:34,073 INFO org.apache.hadoop.yarn.server.resourcemanager.scheduler.capacity.LeafQueue: assignedContainer application attempt=appattempt_1568623076950_0003_000001 container=Container: [ContainerId: container_1568623076950_0003_01_000014, NodeId: e9a6a0455f0d:38503, NodeHttpAddress: e9a6a0455f0d:8042, Resource: <memory:1024, vCores:1>, Priority: 20, Token: null, ] queue=default: capacity=1.0, absoluteCapacity=1.0, usedResources=<memory:3072, vCores:2>, usedCapacity=0.375, absoluteUsedCapacity=0.375, numApps=1, numContainers=2 clusterResource=<memory:8192, vCores:8>
2019-09-16 06:29:34,073 INFO org.apache.hadoop.yarn.server.resourcemanager.scheduler.capacity.ParentQueue: Re-sorting assigned queue: root.default stats: default: capacity=1.0, absoluteCapacity=1.0, usedResources=<memory:4096, vCores:3>, usedCapacity=0.5, absoluteUsedCapacity=0.5, numApps=1, numContainers=3
2019-09-16 06:29:34,073 INFO org.apache.hadoop.yarn.server.resourcemanager.scheduler.capacity.ParentQueue: assignedContainer queue=root usedCapacity=0.5 absoluteUsedCapacity=0.5 used=<memory:4096, vCores:3> cluster=<memory:8192, vCores:8>
2019-09-16 06:29:34,074 INFO org.apache.hadoop.yarn.server.resourcemanager.rmcontainer.RMContainerImpl: container_1568623076950_0003_01_000015 Container Transitioned from NEW to ALLOCATED
2019-09-16 06:29:34,074 INFO org.apache.hadoop.yarn.server.resourcemanager.RMAuditLogger: USER=root	OPERATION=AM Allocated Container	TARGET=SchedulerApp	RESULT=SUCCESS	APPID=application_1568623076950_0003	CONTAINERID=container_1568623076950_0003_01_000015
2019-09-16 06:29:34,074 INFO org.apache.hadoop.yarn.server.resourcemanager.scheduler.SchedulerNode: Assigned container container_1568623076950_0003_01_000015 of capacity <memory:1024, vCores:1> on host e9a6a0455f0d:38503, which has 4 containers, <memory:5120, vCores:4> used and <memory:3072, vCores:4> available after allocation
2019-09-16 06:29:34,074 INFO org.apache.hadoop.yarn.server.resourcemanager.scheduler.capacity.LeafQueue: assignedContainer application attempt=appattempt_1568623076950_0003_000001 container=Container: [ContainerId: container_1568623076950_0003_01_000015, NodeId: e9a6a0455f0d:38503, NodeHttpAddress: e9a6a0455f0d:8042, Resource: <memory:1024, vCores:1>, Priority: 20, Token: null, ] queue=default: capacity=1.0, absoluteCapacity=1.0, usedResources=<memory:4096, vCores:3>, usedCapacity=0.5, absoluteUsedCapacity=0.5, numApps=1, numContainers=3 clusterResource=<memory:8192, vCores:8>
2019-09-16 06:29:34,075 INFO org.apache.hadoop.yarn.server.resourcemanager.scheduler.capacity.ParentQueue: Re-sorting assigned queue: root.default stats: default: capacity=1.0, absoluteCapacity=1.0, usedResources=<memory:5120, vCores:4>, usedCapacity=0.625, absoluteUsedCapacity=0.625, numApps=1, numContainers=4
2019-09-16 06:29:34,075 INFO org.apache.hadoop.yarn.server.resourcemanager.scheduler.capacity.ParentQueue: assignedContainer queue=root usedCapacity=0.625 absoluteUsedCapacity=0.625 used=<memory:5120, vCores:4> cluster=<memory:8192, vCores:8>
2019-09-16 06:29:34,076 INFO org.apache.hadoop.yarn.server.resourcemanager.rmcontainer.RMContainerImpl: container_1568623076950_0003_01_000016 Container Transitioned from NEW to ALLOCATED
2019-09-16 06:29:34,076 INFO org.apache.hadoop.yarn.server.resourcemanager.RMAuditLogger: USER=root	OPERATION=AM Allocated Container	TARGET=SchedulerApp	RESULT=SUCCESS	APPID=application_1568623076950_0003	CONTAINERID=container_1568623076950_0003_01_000016
2019-09-16 06:29:34,076 INFO org.apache.hadoop.yarn.server.resourcemanager.scheduler.SchedulerNode: Assigned container container_1568623076950_0003_01_000016 of capacity <memory:1024, vCores:1> on host e9a6a0455f0d:38503, which has 5 containers, <memory:6144, vCores:5> used and <memory:2048, vCores:3> available after allocation
2019-09-16 06:29:34,076 INFO org.apache.hadoop.yarn.server.resourcemanager.scheduler.capacity.LeafQueue: assignedContainer application attempt=appattempt_1568623076950_0003_000001 container=Container: [ContainerId: container_1568623076950_0003_01_000016, NodeId: e9a6a0455f0d:38503, NodeHttpAddress: e9a6a0455f0d:8042, Resource: <memory:1024, vCores:1>, Priority: 20, Token: null, ] queue=default: capacity=1.0, absoluteCapacity=1.0, usedResources=<memory:5120, vCores:4>, usedCapacity=0.625, absoluteUsedCapacity=0.625, numApps=1, numContainers=4 clusterResource=<memory:8192, vCores:8>
2019-09-16 06:29:34,077 INFO org.apache.hadoop.yarn.server.resourcemanager.scheduler.capacity.ParentQueue: Re-sorting assigned queue: root.default stats: default: capacity=1.0, absoluteCapacity=1.0, usedResources=<memory:6144, vCores:5>, usedCapacity=0.75, absoluteUsedCapacity=0.75, numApps=1, numContainers=5
2019-09-16 06:29:34,077 INFO org.apache.hadoop.yarn.server.resourcemanager.scheduler.capacity.ParentQueue: assignedContainer queue=root usedCapacity=0.75 absoluteUsedCapacity=0.75 used=<memory:6144, vCores:5> cluster=<memory:8192, vCores:8>
2019-09-16 06:29:34,078 INFO org.apache.hadoop.yarn.server.resourcemanager.rmcontainer.RMContainerImpl: container_1568623076950_0003_01_000017 Container Transitioned from NEW to ALLOCATED
2019-09-16 06:29:34,078 INFO org.apache.hadoop.yarn.server.resourcemanager.RMAuditLogger: USER=root	OPERATION=AM Allocated Container	TARGET=SchedulerApp	RESULT=SUCCESS	APPID=application_1568623076950_0003	CONTAINERID=container_1568623076950_0003_01_000017
2019-09-16 06:29:34,079 INFO org.apache.hadoop.yarn.server.resourcemanager.scheduler.SchedulerNode: Assigned container container_1568623076950_0003_01_000017 of capacity <memory:1024, vCores:1> on host e9a6a0455f0d:38503, which has 6 containers, <memory:7168, vCores:6> used and <memory:1024, vCores:2> available after allocation
2019-09-16 06:29:34,079 INFO org.apache.hadoop.yarn.server.resourcemanager.scheduler.capacity.LeafQueue: assignedContainer application attempt=appattempt_1568623076950_0003_000001 container=Container: [ContainerId: container_1568623076950_0003_01_000017, NodeId: e9a6a0455f0d:38503, NodeHttpAddress: e9a6a0455f0d:8042, Resource: <memory:1024, vCores:1>, Priority: 20, Token: null, ] queue=default: capacity=1.0, absoluteCapacity=1.0, usedResources=<memory:6144, vCores:5>, usedCapacity=0.75, absoluteUsedCapacity=0.75, numApps=1, numContainers=5 clusterResource=<memory:8192, vCores:8>
2019-09-16 06:29:34,080 INFO org.apache.hadoop.yarn.server.resourcemanager.scheduler.capacity.ParentQueue: Re-sorting assigned queue: root.default stats: default: capacity=1.0, absoluteCapacity=1.0, usedResources=<memory:7168, vCores:6>, usedCapacity=0.875, absoluteUsedCapacity=0.875, numApps=1, numContainers=6
2019-09-16 06:29:34,080 INFO org.apache.hadoop.yarn.server.resourcemanager.scheduler.capacity.ParentQueue: assignedContainer queue=root usedCapacity=0.875 absoluteUsedCapacity=0.875 used=<memory:7168, vCores:6> cluster=<memory:8192, vCores:8>
2019-09-16 06:29:34,080 INFO org.apache.hadoop.yarn.server.resourcemanager.rmcontainer.RMContainerImpl: container_1568623076950_0003_01_000018 Container Transitioned from NEW to ALLOCATED
2019-09-16 06:29:34,080 INFO org.apache.hadoop.yarn.server.resourcemanager.RMAuditLogger: USER=root	OPERATION=AM Allocated Container	TARGET=SchedulerApp	RESULT=SUCCESS	APPID=application_1568623076950_0003	CONTAINERID=container_1568623076950_0003_01_000018
2019-09-16 06:29:34,080 INFO org.apache.hadoop.yarn.server.resourcemanager.scheduler.SchedulerNode: Assigned container container_1568623076950_0003_01_000018 of capacity <memory:1024, vCores:1> on host e9a6a0455f0d:38503, which has 7 containers, <memory:8192, vCores:7> used and <memory:0, vCores:1> available after allocation
2019-09-16 06:29:34,080 INFO org.apache.hadoop.yarn.server.resourcemanager.scheduler.capacity.LeafQueue: assignedContainer application attempt=appattempt_1568623076950_0003_000001 container=Container: [ContainerId: container_1568623076950_0003_01_000018, NodeId: e9a6a0455f0d:38503, NodeHttpAddress: e9a6a0455f0d:8042, Resource: <memory:1024, vCores:1>, Priority: 20, Token: null, ] queue=default: capacity=1.0, absoluteCapacity=1.0, usedResources=<memory:7168, vCores:6>, usedCapacity=0.875, absoluteUsedCapacity=0.875, numApps=1, numContainers=6 clusterResource=<memory:8192, vCores:8>
2019-09-16 06:29:34,081 INFO org.apache.hadoop.yarn.server.resourcemanager.scheduler.capacity.ParentQueue: Re-sorting assigned queue: root.default stats: default: capacity=1.0, absoluteCapacity=1.0, usedResources=<memory:8192, vCores:7>, usedCapacity=1.0, absoluteUsedCapacity=1.0, numApps=1, numContainers=7
2019-09-16 06:29:34,081 INFO org.apache.hadoop.yarn.server.resourcemanager.scheduler.capacity.ParentQueue: assignedContainer queue=root usedCapacity=1.0 absoluteUsedCapacity=1.0 used=<memory:8192, vCores:7> cluster=<memory:8192, vCores:8>
2019-09-16 06:29:34,698 INFO org.apache.hadoop.yarn.server.resourcemanager.rmcontainer.RMContainerImpl: container_1568623076950_0003_01_000014 Container Transitioned from ALLOCATED to ACQUIRED
2019-09-16 06:29:34,699 INFO org.apache.hadoop.yarn.server.resourcemanager.rmcontainer.RMContainerImpl: container_1568623076950_0003_01_000015 Container Transitioned from ALLOCATED to ACQUIRED
2019-09-16 06:29:34,700 INFO org.apache.hadoop.yarn.server.resourcemanager.rmcontainer.RMContainerImpl: container_1568623076950_0003_01_000016 Container Transitioned from ALLOCATED to ACQUIRED
2019-09-16 06:29:34,701 INFO org.apache.hadoop.yarn.server.resourcemanager.rmcontainer.RMContainerImpl: container_1568623076950_0003_01_000017 Container Transitioned from ALLOCATED to ACQUIRED
2019-09-16 06:29:34,702 INFO org.apache.hadoop.yarn.server.resourcemanager.rmcontainer.RMContainerImpl: container_1568623076950_0003_01_000018 Container Transitioned from ALLOCATED to ACQUIRED
2019-09-16 06:29:35,068 INFO org.apache.hadoop.yarn.server.resourcemanager.rmcontainer.RMContainerImpl: container_1568623076950_0003_01_000014 Container Transitioned from ACQUIRED to RUNNING
2019-09-16 06:29:35,069 INFO org.apache.hadoop.yarn.server.resourcemanager.rmcontainer.RMContainerImpl: container_1568623076950_0003_01_000015 Container Transitioned from ACQUIRED to RUNNING
2019-09-16 06:29:35,069 INFO org.apache.hadoop.yarn.server.resourcemanager.rmcontainer.RMContainerImpl: container_1568623076950_0003_01_000016 Container Transitioned from ACQUIRED to RUNNING
2019-09-16 06:29:35,069 INFO org.apache.hadoop.yarn.server.resourcemanager.rmcontainer.RMContainerImpl: container_1568623076950_0003_01_000017 Container Transitioned from ACQUIRED to RUNNING
2019-09-16 06:29:35,069 INFO org.apache.hadoop.yarn.server.resourcemanager.rmcontainer.RMContainerImpl: container_1568623076950_0003_01_000018 Container Transitioned from ACQUIRED to RUNNING
2019-09-16 06:29:43,335 INFO org.apache.hadoop.yarn.server.resourcemanager.rmcontainer.RMContainerImpl: container_1568623076950_0003_01_000014 Container Transitioned from RUNNING to COMPLETED
2019-09-16 06:29:43,335 INFO org.apache.hadoop.yarn.server.resourcemanager.scheduler.common.fica.FiCaSchedulerApp: Completed container: container_1568623076950_0003_01_000014 in state: COMPLETED event:FINISHED
2019-09-16 06:29:43,336 INFO org.apache.hadoop.yarn.server.resourcemanager.RMAuditLogger: USER=root	OPERATION=AM Released Container	TARGET=SchedulerApp	RESULT=SUCCESS	APPID=application_1568623076950_0003	CONTAINERID=container_1568623076950_0003_01_000014
2019-09-16 06:29:43,340 INFO org.apache.hadoop.yarn.server.resourcemanager.scheduler.SchedulerNode: Released container container_1568623076950_0003_01_000014 of capacity <memory:1024, vCores:1> on host e9a6a0455f0d:38503, which currently has 6 containers, <memory:7168, vCores:6> used and <memory:1024, vCores:2> available, release resources=true
2019-09-16 06:29:43,340 INFO org.apache.hadoop.yarn.server.resourcemanager.scheduler.capacity.LeafQueue: default used=<memory:7168, vCores:6> numContainers=6 user=root user-resources=<memory:7168, vCores:6>
2019-09-16 06:29:43,349 INFO org.apache.hadoop.yarn.server.resourcemanager.scheduler.capacity.LeafQueue: completedContainer container=Container: [ContainerId: container_1568623076950_0003_01_000014, NodeId: e9a6a0455f0d:38503, NodeHttpAddress: e9a6a0455f0d:8042, Resource: <memory:1024, vCores:1>, Priority: 20, Token: Token { kind: ContainerToken, service: 172.24.0.2:38503 }, ] queue=default: capacity=1.0, absoluteCapacity=1.0, usedResources=<memory:7168, vCores:6>, usedCapacity=0.875, absoluteUsedCapacity=0.875, numApps=1, numContainers=6 cluster=<memory:8192, vCores:8>
2019-09-16 06:29:43,349 INFO org.apache.hadoop.yarn.server.resourcemanager.scheduler.capacity.ParentQueue: completedContainer queue=root usedCapacity=0.875 absoluteUsedCapacity=0.875 used=<memory:7168, vCores:6> cluster=<memory:8192, vCores:8>
2019-09-16 06:29:43,349 INFO org.apache.hadoop.yarn.server.resourcemanager.scheduler.capacity.ParentQueue: Re-sorting completed queue: root.default stats: default: capacity=1.0, absoluteCapacity=1.0, usedResources=<memory:7168, vCores:6>, usedCapacity=0.875, absoluteUsedCapacity=0.875, numApps=1, numContainers=6
2019-09-16 06:29:43,349 INFO org.apache.hadoop.yarn.server.resourcemanager.scheduler.capacity.CapacityScheduler: Application attempt appattempt_1568623076950_0003_000001 released container container_1568623076950_0003_01_000014 on node: host: e9a6a0455f0d:38503 #containers=6 available=<memory:1024, vCores:2> used=<memory:7168, vCores:6> with event: FINISHED
2019-09-16 06:29:43,350 INFO org.apache.hadoop.yarn.server.resourcemanager.rmcontainer.RMContainerImpl: container_1568623076950_0003_01_000019 Container Transitioned from NEW to ALLOCATED
2019-09-16 06:29:43,351 INFO org.apache.hadoop.yarn.server.resourcemanager.RMAuditLogger: USER=root	OPERATION=AM Allocated Container	TARGET=SchedulerApp	RESULT=SUCCESS	APPID=application_1568623076950_0003	CONTAINERID=container_1568623076950_0003_01_000019
2019-09-16 06:29:43,351 INFO org.apache.hadoop.yarn.server.resourcemanager.scheduler.SchedulerNode: Assigned container container_1568623076950_0003_01_000019 of capacity <memory:1024, vCores:1> on host e9a6a0455f0d:38503, which has 7 containers, <memory:8192, vCores:7> used and <memory:0, vCores:1> available after allocation
2019-09-16 06:29:43,351 INFO org.apache.hadoop.yarn.server.resourcemanager.scheduler.capacity.LeafQueue: assignedContainer application attempt=appattempt_1568623076950_0003_000001 container=Container: [ContainerId: container_1568623076950_0003_01_000019, NodeId: e9a6a0455f0d:38503, NodeHttpAddress: e9a6a0455f0d:8042, Resource: <memory:1024, vCores:1>, Priority: 20, Token: null, ] queue=default: capacity=1.0, absoluteCapacity=1.0, usedResources=<memory:7168, vCores:6>, usedCapacity=0.875, absoluteUsedCapacity=0.875, numApps=1, numContainers=6 clusterResource=<memory:8192, vCores:8>
2019-09-16 06:29:43,351 INFO org.apache.hadoop.yarn.server.resourcemanager.scheduler.capacity.ParentQueue: Re-sorting assigned queue: root.default stats: default: capacity=1.0, absoluteCapacity=1.0, usedResources=<memory:8192, vCores:7>, usedCapacity=1.0, absoluteUsedCapacity=1.0, numApps=1, numContainers=7
2019-09-16 06:29:43,351 INFO org.apache.hadoop.yarn.server.resourcemanager.scheduler.capacity.ParentQueue: assignedContainer queue=root usedCapacity=1.0 absoluteUsedCapacity=1.0 used=<memory:8192, vCores:7> cluster=<memory:8192, vCores:8>
2019-09-16 06:29:43,428 INFO org.apache.hadoop.yarn.server.resourcemanager.rmcontainer.RMContainerImpl: container_1568623076950_0003_01_000015 Container Transitioned from RUNNING to COMPLETED
2019-09-16 06:29:43,428 INFO org.apache.hadoop.yarn.server.resourcemanager.scheduler.common.fica.FiCaSchedulerApp: Completed container: container_1568623076950_0003_01_000015 in state: COMPLETED event:FINISHED
2019-09-16 06:29:43,428 INFO org.apache.hadoop.yarn.server.resourcemanager.RMAuditLogger: USER=root	OPERATION=AM Released Container	TARGET=SchedulerApp	RESULT=SUCCESS	APPID=application_1568623076950_0003	CONTAINERID=container_1568623076950_0003_01_000015
2019-09-16 06:29:43,428 INFO org.apache.hadoop.yarn.server.resourcemanager.scheduler.SchedulerNode: Released container container_1568623076950_0003_01_000015 of capacity <memory:1024, vCores:1> on host e9a6a0455f0d:38503, which currently has 6 containers, <memory:7168, vCores:6> used and <memory:1024, vCores:2> available, release resources=true
2019-09-16 06:29:43,428 INFO org.apache.hadoop.yarn.server.resourcemanager.scheduler.capacity.LeafQueue: default used=<memory:7168, vCores:6> numContainers=6 user=root user-resources=<memory:7168, vCores:6>
2019-09-16 06:29:43,429 INFO org.apache.hadoop.yarn.server.resourcemanager.scheduler.capacity.LeafQueue: completedContainer container=Container: [ContainerId: container_1568623076950_0003_01_000015, NodeId: e9a6a0455f0d:38503, NodeHttpAddress: e9a6a0455f0d:8042, Resource: <memory:1024, vCores:1>, Priority: 20, Token: Token { kind: ContainerToken, service: 172.24.0.2:38503 }, ] queue=default: capacity=1.0, absoluteCapacity=1.0, usedResources=<memory:7168, vCores:6>, usedCapacity=0.875, absoluteUsedCapacity=0.875, numApps=1, numContainers=6 cluster=<memory:8192, vCores:8>
2019-09-16 06:29:43,429 INFO org.apache.hadoop.yarn.server.resourcemanager.scheduler.capacity.ParentQueue: completedContainer queue=root usedCapacity=0.875 absoluteUsedCapacity=0.875 used=<memory:7168, vCores:6> cluster=<memory:8192, vCores:8>
2019-09-16 06:29:43,429 INFO org.apache.hadoop.yarn.server.resourcemanager.scheduler.capacity.ParentQueue: Re-sorting completed queue: root.default stats: default: capacity=1.0, absoluteCapacity=1.0, usedResources=<memory:7168, vCores:6>, usedCapacity=0.875, absoluteUsedCapacity=0.875, numApps=1, numContainers=6
2019-09-16 06:29:43,429 INFO org.apache.hadoop.yarn.server.resourcemanager.scheduler.capacity.CapacityScheduler: Application attempt appattempt_1568623076950_0003_000001 released container container_1568623076950_0003_01_000015 on node: host: e9a6a0455f0d:38503 #containers=6 available=<memory:1024, vCores:2> used=<memory:7168, vCores:6> with event: FINISHED
2019-09-16 06:29:43,429 INFO org.apache.hadoop.yarn.server.resourcemanager.rmcontainer.RMContainerImpl: container_1568623076950_0003_01_000020 Container Transitioned from NEW to ALLOCATED
2019-09-16 06:29:43,430 INFO org.apache.hadoop.yarn.server.resourcemanager.RMAuditLogger: USER=root	OPERATION=AM Allocated Container	TARGET=SchedulerApp	RESULT=SUCCESS	APPID=application_1568623076950_0003	CONTAINERID=container_1568623076950_0003_01_000020
2019-09-16 06:29:43,430 INFO org.apache.hadoop.yarn.server.resourcemanager.scheduler.SchedulerNode: Assigned container container_1568623076950_0003_01_000020 of capacity <memory:1024, vCores:1> on host e9a6a0455f0d:38503, which has 7 containers, <memory:8192, vCores:7> used and <memory:0, vCores:1> available after allocation
2019-09-16 06:29:43,430 INFO org.apache.hadoop.yarn.server.resourcemanager.scheduler.capacity.LeafQueue: assignedContainer application attempt=appattempt_1568623076950_0003_000001 container=Container: [ContainerId: container_1568623076950_0003_01_000020, NodeId: e9a6a0455f0d:38503, NodeHttpAddress: e9a6a0455f0d:8042, Resource: <memory:1024, vCores:1>, Priority: 20, Token: null, ] queue=default: capacity=1.0, absoluteCapacity=1.0, usedResources=<memory:7168, vCores:6>, usedCapacity=0.875, absoluteUsedCapacity=0.875, numApps=1, numContainers=6 clusterResource=<memory:8192, vCores:8>
2019-09-16 06:29:43,430 INFO org.apache.hadoop.yarn.server.resourcemanager.scheduler.capacity.ParentQueue: Re-sorting assigned queue: root.default stats: default: capacity=1.0, absoluteCapacity=1.0, usedResources=<memory:8192, vCores:7>, usedCapacity=1.0, absoluteUsedCapacity=1.0, numApps=1, numContainers=7
2019-09-16 06:29:43,430 INFO org.apache.hadoop.yarn.server.resourcemanager.scheduler.capacity.ParentQueue: assignedContainer queue=root usedCapacity=1.0 absoluteUsedCapacity=1.0 used=<memory:8192, vCores:7> cluster=<memory:8192, vCores:8>
2019-09-16 06:29:43,459 INFO org.apache.hadoop.yarn.server.resourcemanager.rmcontainer.RMContainerImpl: container_1568623076950_0003_01_000017 Container Transitioned from RUNNING to COMPLETED
2019-09-16 06:29:43,459 INFO org.apache.hadoop.yarn.server.resourcemanager.scheduler.common.fica.FiCaSchedulerApp: Completed container: container_1568623076950_0003_01_000017 in state: COMPLETED event:FINISHED
2019-09-16 06:29:43,459 INFO org.apache.hadoop.yarn.server.resourcemanager.RMAuditLogger: USER=root	OPERATION=AM Released Container	TARGET=SchedulerApp	RESULT=SUCCESS	APPID=application_1568623076950_0003	CONTAINERID=container_1568623076950_0003_01_000017
2019-09-16 06:29:43,459 INFO org.apache.hadoop.yarn.server.resourcemanager.scheduler.SchedulerNode: Released container container_1568623076950_0003_01_000017 of capacity <memory:1024, vCores:1> on host e9a6a0455f0d:38503, which currently has 6 containers, <memory:7168, vCores:6> used and <memory:1024, vCores:2> available, release resources=true
2019-09-16 06:29:43,459 INFO org.apache.hadoop.yarn.server.resourcemanager.scheduler.capacity.LeafQueue: default used=<memory:7168, vCores:6> numContainers=6 user=root user-resources=<memory:7168, vCores:6>
2019-09-16 06:29:43,459 INFO org.apache.hadoop.yarn.server.resourcemanager.scheduler.capacity.LeafQueue: completedContainer container=Container: [ContainerId: container_1568623076950_0003_01_000017, NodeId: e9a6a0455f0d:38503, NodeHttpAddress: e9a6a0455f0d:8042, Resource: <memory:1024, vCores:1>, Priority: 20, Token: Token { kind: ContainerToken, service: 172.24.0.2:38503 }, ] queue=default: capacity=1.0, absoluteCapacity=1.0, usedResources=<memory:7168, vCores:6>, usedCapacity=0.875, absoluteUsedCapacity=0.875, numApps=1, numContainers=6 cluster=<memory:8192, vCores:8>
2019-09-16 06:29:43,460 INFO org.apache.hadoop.yarn.server.resourcemanager.scheduler.capacity.ParentQueue: completedContainer queue=root usedCapacity=0.875 absoluteUsedCapacity=0.875 used=<memory:7168, vCores:6> cluster=<memory:8192, vCores:8>
2019-09-16 06:29:43,460 INFO org.apache.hadoop.yarn.server.resourcemanager.scheduler.capacity.ParentQueue: Re-sorting completed queue: root.default stats: default: capacity=1.0, absoluteCapacity=1.0, usedResources=<memory:7168, vCores:6>, usedCapacity=0.875, absoluteUsedCapacity=0.875, numApps=1, numContainers=6
2019-09-16 06:29:43,460 INFO org.apache.hadoop.yarn.server.resourcemanager.scheduler.capacity.CapacityScheduler: Application attempt appattempt_1568623076950_0003_000001 released container container_1568623076950_0003_01_000017 on node: host: e9a6a0455f0d:38503 #containers=6 available=<memory:1024, vCores:2> used=<memory:7168, vCores:6> with event: FINISHED
2019-09-16 06:29:43,460 INFO org.apache.hadoop.yarn.server.resourcemanager.rmcontainer.RMContainerImpl: container_1568623076950_0003_01_000021 Container Transitioned from NEW to ALLOCATED
2019-09-16 06:29:43,460 INFO org.apache.hadoop.yarn.server.resourcemanager.RMAuditLogger: USER=root	OPERATION=AM Allocated Container	TARGET=SchedulerApp	RESULT=SUCCESS	APPID=application_1568623076950_0003	CONTAINERID=container_1568623076950_0003_01_000021
2019-09-16 06:29:43,460 INFO org.apache.hadoop.yarn.server.resourcemanager.scheduler.SchedulerNode: Assigned container container_1568623076950_0003_01_000021 of capacity <memory:1024, vCores:1> on host e9a6a0455f0d:38503, which has 7 containers, <memory:8192, vCores:7> used and <memory:0, vCores:1> available after allocation
2019-09-16 06:29:43,460 INFO org.apache.hadoop.yarn.server.resourcemanager.scheduler.capacity.LeafQueue: assignedContainer application attempt=appattempt_1568623076950_0003_000001 container=Container: [ContainerId: container_1568623076950_0003_01_000021, NodeId: e9a6a0455f0d:38503, NodeHttpAddress: e9a6a0455f0d:8042, Resource: <memory:1024, vCores:1>, Priority: 20, Token: null, ] queue=default: capacity=1.0, absoluteCapacity=1.0, usedResources=<memory:7168, vCores:6>, usedCapacity=0.875, absoluteUsedCapacity=0.875, numApps=1, numContainers=6 clusterResource=<memory:8192, vCores:8>
2019-09-16 06:29:43,460 INFO org.apache.hadoop.yarn.server.resourcemanager.scheduler.capacity.ParentQueue: Re-sorting assigned queue: root.default stats: default: capacity=1.0, absoluteCapacity=1.0, usedResources=<memory:8192, vCores:7>, usedCapacity=1.0, absoluteUsedCapacity=1.0, numApps=1, numContainers=7
2019-09-16 06:29:43,460 INFO org.apache.hadoop.yarn.server.resourcemanager.scheduler.capacity.ParentQueue: assignedContainer queue=root usedCapacity=1.0 absoluteUsedCapacity=1.0 used=<memory:8192, vCores:7> cluster=<memory:8192, vCores:8>
2019-09-16 06:29:43,543 INFO org.apache.hadoop.yarn.server.resourcemanager.rmcontainer.RMContainerImpl: container_1568623076950_0003_01_000018 Container Transitioned from RUNNING to COMPLETED
2019-09-16 06:29:43,543 INFO org.apache.hadoop.yarn.server.resourcemanager.scheduler.common.fica.FiCaSchedulerApp: Completed container: container_1568623076950_0003_01_000018 in state: COMPLETED event:FINISHED
2019-09-16 06:29:43,543 INFO org.apache.hadoop.yarn.server.resourcemanager.RMAuditLogger: USER=root	OPERATION=AM Released Container	TARGET=SchedulerApp	RESULT=SUCCESS	APPID=application_1568623076950_0003	CONTAINERID=container_1568623076950_0003_01_000018
2019-09-16 06:29:43,550 INFO org.apache.hadoop.yarn.server.resourcemanager.scheduler.SchedulerNode: Released container container_1568623076950_0003_01_000018 of capacity <memory:1024, vCores:1> on host e9a6a0455f0d:38503, which currently has 6 containers, <memory:7168, vCores:6> used and <memory:1024, vCores:2> available, release resources=true
2019-09-16 06:29:43,550 INFO org.apache.hadoop.yarn.server.resourcemanager.scheduler.capacity.LeafQueue: default used=<memory:7168, vCores:6> numContainers=6 user=root user-resources=<memory:7168, vCores:6>
2019-09-16 06:29:43,551 INFO org.apache.hadoop.yarn.server.resourcemanager.scheduler.capacity.LeafQueue: completedContainer container=Container: [ContainerId: container_1568623076950_0003_01_000018, NodeId: e9a6a0455f0d:38503, NodeHttpAddress: e9a6a0455f0d:8042, Resource: <memory:1024, vCores:1>, Priority: 20, Token: Token { kind: ContainerToken, service: 172.24.0.2:38503 }, ] queue=default: capacity=1.0, absoluteCapacity=1.0, usedResources=<memory:7168, vCores:6>, usedCapacity=0.875, absoluteUsedCapacity=0.875, numApps=1, numContainers=6 cluster=<memory:8192, vCores:8>
2019-09-16 06:29:43,552 INFO org.apache.hadoop.yarn.server.resourcemanager.scheduler.capacity.ParentQueue: completedContainer queue=root usedCapacity=0.875 absoluteUsedCapacity=0.875 used=<memory:7168, vCores:6> cluster=<memory:8192, vCores:8>
2019-09-16 06:29:43,552 INFO org.apache.hadoop.yarn.server.resourcemanager.scheduler.capacity.ParentQueue: Re-sorting completed queue: root.default stats: default: capacity=1.0, absoluteCapacity=1.0, usedResources=<memory:7168, vCores:6>, usedCapacity=0.875, absoluteUsedCapacity=0.875, numApps=1, numContainers=6
2019-09-16 06:29:43,552 INFO org.apache.hadoop.yarn.server.resourcemanager.scheduler.capacity.CapacityScheduler: Application attempt appattempt_1568623076950_0003_000001 released container container_1568623076950_0003_01_000018 on node: host: e9a6a0455f0d:38503 #containers=6 available=<memory:1024, vCores:2> used=<memory:7168, vCores:6> with event: FINISHED
2019-09-16 06:29:43,552 INFO org.apache.hadoop.yarn.server.resourcemanager.rmcontainer.RMContainerImpl: container_1568623076950_0003_01_000022 Container Transitioned from NEW to ALLOCATED
2019-09-16 06:29:43,552 INFO org.apache.hadoop.yarn.server.resourcemanager.RMAuditLogger: USER=root	OPERATION=AM Allocated Container	TARGET=SchedulerApp	RESULT=SUCCESS	APPID=application_1568623076950_0003	CONTAINERID=container_1568623076950_0003_01_000022
2019-09-16 06:29:43,552 INFO org.apache.hadoop.yarn.server.resourcemanager.scheduler.SchedulerNode: Assigned container container_1568623076950_0003_01_000022 of capacity <memory:1024, vCores:1> on host e9a6a0455f0d:38503, which has 7 containers, <memory:8192, vCores:7> used and <memory:0, vCores:1> available after allocation
2019-09-16 06:29:43,552 INFO org.apache.hadoop.yarn.server.resourcemanager.scheduler.capacity.LeafQueue: assignedContainer application attempt=appattempt_1568623076950_0003_000001 container=Container: [ContainerId: container_1568623076950_0003_01_000022, NodeId: e9a6a0455f0d:38503, NodeHttpAddress: e9a6a0455f0d:8042, Resource: <memory:1024, vCores:1>, Priority: 20, Token: null, ] queue=default: capacity=1.0, absoluteCapacity=1.0, usedResources=<memory:7168, vCores:6>, usedCapacity=0.875, absoluteUsedCapacity=0.875, numApps=1, numContainers=6 clusterResource=<memory:8192, vCores:8>
2019-09-16 06:29:43,553 INFO org.apache.hadoop.yarn.server.resourcemanager.scheduler.capacity.ParentQueue: Re-sorting assigned queue: root.default stats: default: capacity=1.0, absoluteCapacity=1.0, usedResources=<memory:8192, vCores:7>, usedCapacity=1.0, absoluteUsedCapacity=1.0, numApps=1, numContainers=7
2019-09-16 06:29:43,553 INFO org.apache.hadoop.yarn.server.resourcemanager.scheduler.capacity.ParentQueue: assignedContainer queue=root usedCapacity=1.0 absoluteUsedCapacity=1.0 used=<memory:8192, vCores:7> cluster=<memory:8192, vCores:8>
2019-09-16 06:29:43,752 INFO org.apache.hadoop.yarn.server.resourcemanager.rmcontainer.RMContainerImpl: container_1568623076950_0003_01_000019 Container Transitioned from ALLOCATED to ACQUIRED
2019-09-16 06:29:43,755 INFO org.apache.hadoop.yarn.server.resourcemanager.rmcontainer.RMContainerImpl: container_1568623076950_0003_01_000020 Container Transitioned from ALLOCATED to ACQUIRED
2019-09-16 06:29:43,758 INFO org.apache.hadoop.yarn.server.resourcemanager.rmcontainer.RMContainerImpl: container_1568623076950_0003_01_000021 Container Transitioned from ALLOCATED to ACQUIRED
2019-09-16 06:29:43,760 INFO org.apache.hadoop.yarn.server.resourcemanager.rmcontainer.RMContainerImpl: container_1568623076950_0003_01_000022 Container Transitioned from ALLOCATED to ACQUIRED
2019-09-16 06:29:44,546 INFO org.apache.hadoop.yarn.server.resourcemanager.rmcontainer.RMContainerImpl: container_1568623076950_0003_01_000019 Container Transitioned from ACQUIRED to RUNNING
2019-09-16 06:29:44,546 INFO org.apache.hadoop.yarn.server.resourcemanager.rmcontainer.RMContainerImpl: container_1568623076950_0003_01_000020 Container Transitioned from ACQUIRED to RUNNING
2019-09-16 06:29:44,546 INFO org.apache.hadoop.yarn.server.resourcemanager.rmcontainer.RMContainerImpl: container_1568623076950_0003_01_000021 Container Transitioned from ACQUIRED to RUNNING
2019-09-16 06:29:44,546 INFO org.apache.hadoop.yarn.server.resourcemanager.rmcontainer.RMContainerImpl: container_1568623076950_0003_01_000022 Container Transitioned from ACQUIRED to RUNNING
2019-09-16 06:29:44,547 INFO org.apache.hadoop.yarn.server.resourcemanager.rmcontainer.RMContainerImpl: container_1568623076950_0003_01_000016 Container Transitioned from RUNNING to COMPLETED
2019-09-16 06:29:44,547 INFO org.apache.hadoop.yarn.server.resourcemanager.scheduler.common.fica.FiCaSchedulerApp: Completed container: container_1568623076950_0003_01_000016 in state: COMPLETED event:FINISHED
2019-09-16 06:29:44,547 INFO org.apache.hadoop.yarn.server.resourcemanager.RMAuditLogger: USER=root	OPERATION=AM Released Container	TARGET=SchedulerApp	RESULT=SUCCESS	APPID=application_1568623076950_0003	CONTAINERID=container_1568623076950_0003_01_000016
2019-09-16 06:29:44,548 INFO org.apache.hadoop.yarn.server.resourcemanager.scheduler.SchedulerNode: Released container container_1568623076950_0003_01_000016 of capacity <memory:1024, vCores:1> on host e9a6a0455f0d:38503, which currently has 6 containers, <memory:7168, vCores:6> used and <memory:1024, vCores:2> available, release resources=true
2019-09-16 06:29:44,548 INFO org.apache.hadoop.yarn.server.resourcemanager.scheduler.capacity.LeafQueue: default used=<memory:7168, vCores:6> numContainers=6 user=root user-resources=<memory:7168, vCores:6>
2019-09-16 06:29:44,554 INFO org.apache.hadoop.yarn.server.resourcemanager.scheduler.capacity.LeafQueue: completedContainer container=Container: [ContainerId: container_1568623076950_0003_01_000016, NodeId: e9a6a0455f0d:38503, NodeHttpAddress: e9a6a0455f0d:8042, Resource: <memory:1024, vCores:1>, Priority: 20, Token: Token { kind: ContainerToken, service: 172.24.0.2:38503 }, ] queue=default: capacity=1.0, absoluteCapacity=1.0, usedResources=<memory:7168, vCores:6>, usedCapacity=0.875, absoluteUsedCapacity=0.875, numApps=1, numContainers=6 cluster=<memory:8192, vCores:8>
2019-09-16 06:29:44,555 INFO org.apache.hadoop.yarn.server.resourcemanager.scheduler.capacity.ParentQueue: completedContainer queue=root usedCapacity=0.875 absoluteUsedCapacity=0.875 used=<memory:7168, vCores:6> cluster=<memory:8192, vCores:8>
2019-09-16 06:29:44,555 INFO org.apache.hadoop.yarn.server.resourcemanager.scheduler.capacity.ParentQueue: Re-sorting completed queue: root.default stats: default: capacity=1.0, absoluteCapacity=1.0, usedResources=<memory:7168, vCores:6>, usedCapacity=0.875, absoluteUsedCapacity=0.875, numApps=1, numContainers=6
2019-09-16 06:29:44,555 INFO org.apache.hadoop.yarn.server.resourcemanager.scheduler.capacity.CapacityScheduler: Application attempt appattempt_1568623076950_0003_000001 released container container_1568623076950_0003_01_000016 on node: host: e9a6a0455f0d:38503 #containers=6 available=<memory:1024, vCores:2> used=<memory:7168, vCores:6> with event: FINISHED
2019-09-16 06:29:44,556 INFO org.apache.hadoop.yarn.server.resourcemanager.rmcontainer.RMContainerImpl: container_1568623076950_0003_01_000023 Container Transitioned from NEW to ALLOCATED
2019-09-16 06:29:44,557 INFO org.apache.hadoop.yarn.server.resourcemanager.RMAuditLogger: USER=root	OPERATION=AM Allocated Container	TARGET=SchedulerApp	RESULT=SUCCESS	APPID=application_1568623076950_0003	CONTAINERID=container_1568623076950_0003_01_000023
2019-09-16 06:29:44,557 INFO org.apache.hadoop.yarn.server.resourcemanager.scheduler.SchedulerNode: Assigned container container_1568623076950_0003_01_000023 of capacity <memory:1024, vCores:1> on host e9a6a0455f0d:38503, which has 7 containers, <memory:8192, vCores:7> used and <memory:0, vCores:1> available after allocation
2019-09-16 06:29:44,558 INFO org.apache.hadoop.yarn.server.resourcemanager.scheduler.capacity.LeafQueue: assignedContainer application attempt=appattempt_1568623076950_0003_000001 container=Container: [ContainerId: container_1568623076950_0003_01_000023, NodeId: e9a6a0455f0d:38503, NodeHttpAddress: e9a6a0455f0d:8042, Resource: <memory:1024, vCores:1>, Priority: 20, Token: null, ] queue=default: capacity=1.0, absoluteCapacity=1.0, usedResources=<memory:7168, vCores:6>, usedCapacity=0.875, absoluteUsedCapacity=0.875, numApps=1, numContainers=6 clusterResource=<memory:8192, vCores:8>
2019-09-16 06:29:44,558 INFO org.apache.hadoop.yarn.server.resourcemanager.scheduler.capacity.ParentQueue: Re-sorting assigned queue: root.default stats: default: capacity=1.0, absoluteCapacity=1.0, usedResources=<memory:8192, vCores:7>, usedCapacity=1.0, absoluteUsedCapacity=1.0, numApps=1, numContainers=7
2019-09-16 06:29:44,559 INFO org.apache.hadoop.yarn.server.resourcemanager.scheduler.capacity.ParentQueue: assignedContainer queue=root usedCapacity=1.0 absoluteUsedCapacity=1.0 used=<memory:8192, vCores:7> cluster=<memory:8192, vCores:8>
2019-09-16 06:29:44,770 INFO org.apache.hadoop.yarn.server.resourcemanager.rmcontainer.RMContainerImpl: container_1568623076950_0003_01_000023 Container Transitioned from ALLOCATED to ACQUIRED
2019-09-16 06:29:45,549 INFO org.apache.hadoop.yarn.server.resourcemanager.rmcontainer.RMContainerImpl: container_1568623076950_0003_01_000023 Container Transitioned from ACQUIRED to RUNNING
2019-09-16 06:29:52,039 INFO org.apache.hadoop.yarn.server.resourcemanager.rmcontainer.RMContainerImpl: container_1568623076950_0003_01_000019 Container Transitioned from RUNNING to COMPLETED
2019-09-16 06:29:52,039 INFO org.apache.hadoop.yarn.server.resourcemanager.scheduler.common.fica.FiCaSchedulerApp: Completed container: container_1568623076950_0003_01_000019 in state: COMPLETED event:FINISHED
2019-09-16 06:29:52,039 INFO org.apache.hadoop.yarn.server.resourcemanager.RMAuditLogger: USER=root	OPERATION=AM Released Container	TARGET=SchedulerApp	RESULT=SUCCESS	APPID=application_1568623076950_0003	CONTAINERID=container_1568623076950_0003_01_000019
2019-09-16 06:29:52,040 INFO org.apache.hadoop.yarn.server.resourcemanager.scheduler.SchedulerNode: Released container container_1568623076950_0003_01_000019 of capacity <memory:1024, vCores:1> on host e9a6a0455f0d:38503, which currently has 6 containers, <memory:7168, vCores:6> used and <memory:1024, vCores:2> available, release resources=true
2019-09-16 06:29:52,040 INFO org.apache.hadoop.yarn.server.resourcemanager.scheduler.capacity.LeafQueue: default used=<memory:7168, vCores:6> numContainers=6 user=root user-resources=<memory:7168, vCores:6>
2019-09-16 06:29:52,042 INFO org.apache.hadoop.yarn.server.resourcemanager.scheduler.capacity.LeafQueue: completedContainer container=Container: [ContainerId: container_1568623076950_0003_01_000019, NodeId: e9a6a0455f0d:38503, NodeHttpAddress: e9a6a0455f0d:8042, Resource: <memory:1024, vCores:1>, Priority: 20, Token: Token { kind: ContainerToken, service: 172.24.0.2:38503 }, ] queue=default: capacity=1.0, absoluteCapacity=1.0, usedResources=<memory:7168, vCores:6>, usedCapacity=0.875, absoluteUsedCapacity=0.875, numApps=1, numContainers=6 cluster=<memory:8192, vCores:8>
2019-09-16 06:29:52,042 INFO org.apache.hadoop.yarn.server.resourcemanager.scheduler.capacity.ParentQueue: completedContainer queue=root usedCapacity=0.875 absoluteUsedCapacity=0.875 used=<memory:7168, vCores:6> cluster=<memory:8192, vCores:8>
2019-09-16 06:29:52,043 INFO org.apache.hadoop.yarn.server.resourcemanager.scheduler.capacity.ParentQueue: Re-sorting completed queue: root.default stats: default: capacity=1.0, absoluteCapacity=1.0, usedResources=<memory:7168, vCores:6>, usedCapacity=0.875, absoluteUsedCapacity=0.875, numApps=1, numContainers=6
2019-09-16 06:29:52,043 INFO org.apache.hadoop.yarn.server.resourcemanager.scheduler.capacity.CapacityScheduler: Application attempt appattempt_1568623076950_0003_000001 released container container_1568623076950_0003_01_000019 on node: host: e9a6a0455f0d:38503 #containers=6 available=<memory:1024, vCores:2> used=<memory:7168, vCores:6> with event: FINISHED
2019-09-16 06:29:52,046 INFO org.apache.hadoop.yarn.server.resourcemanager.rmcontainer.RMContainerImpl: container_1568623076950_0003_01_000024 Container Transitioned from NEW to ALLOCATED
2019-09-16 06:29:52,046 INFO org.apache.hadoop.yarn.server.resourcemanager.RMAuditLogger: USER=root	OPERATION=AM Allocated Container	TARGET=SchedulerApp	RESULT=SUCCESS	APPID=application_1568623076950_0003	CONTAINERID=container_1568623076950_0003_01_000024
2019-09-16 06:29:52,046 INFO org.apache.hadoop.yarn.server.resourcemanager.scheduler.SchedulerNode: Assigned container container_1568623076950_0003_01_000024 of capacity <memory:1024, vCores:1> on host e9a6a0455f0d:38503, which has 7 containers, <memory:8192, vCores:7> used and <memory:0, vCores:1> available after allocation
2019-09-16 06:29:52,046 INFO org.apache.hadoop.yarn.server.resourcemanager.scheduler.capacity.LeafQueue: assignedContainer application attempt=appattempt_1568623076950_0003_000001 container=Container: [ContainerId: container_1568623076950_0003_01_000024, NodeId: e9a6a0455f0d:38503, NodeHttpAddress: e9a6a0455f0d:8042, Resource: <memory:1024, vCores:1>, Priority: 20, Token: null, ] queue=default: capacity=1.0, absoluteCapacity=1.0, usedResources=<memory:7168, vCores:6>, usedCapacity=0.875, absoluteUsedCapacity=0.875, numApps=1, numContainers=6 clusterResource=<memory:8192, vCores:8>
2019-09-16 06:29:52,046 INFO org.apache.hadoop.yarn.server.resourcemanager.scheduler.capacity.ParentQueue: Re-sorting assigned queue: root.default stats: default: capacity=1.0, absoluteCapacity=1.0, usedResources=<memory:8192, vCores:7>, usedCapacity=1.0, absoluteUsedCapacity=1.0, numApps=1, numContainers=7
2019-09-16 06:29:52,046 INFO org.apache.hadoop.yarn.server.resourcemanager.scheduler.capacity.ParentQueue: assignedContainer queue=root usedCapacity=1.0 absoluteUsedCapacity=1.0 used=<memory:8192, vCores:7> cluster=<memory:8192, vCores:8>
2019-09-16 06:29:52,284 INFO org.apache.hadoop.yarn.server.resourcemanager.rmcontainer.RMContainerImpl: container_1568623076950_0003_01_000022 Container Transitioned from RUNNING to COMPLETED
2019-09-16 06:29:52,285 INFO org.apache.hadoop.yarn.server.resourcemanager.scheduler.common.fica.FiCaSchedulerApp: Completed container: container_1568623076950_0003_01_000022 in state: COMPLETED event:FINISHED
2019-09-16 06:29:52,285 INFO org.apache.hadoop.yarn.server.resourcemanager.RMAuditLogger: USER=root	OPERATION=AM Released Container	TARGET=SchedulerApp	RESULT=SUCCESS	APPID=application_1568623076950_0003	CONTAINERID=container_1568623076950_0003_01_000022
2019-09-16 06:29:52,285 INFO org.apache.hadoop.yarn.server.resourcemanager.scheduler.SchedulerNode: Released container container_1568623076950_0003_01_000022 of capacity <memory:1024, vCores:1> on host e9a6a0455f0d:38503, which currently has 6 containers, <memory:7168, vCores:6> used and <memory:1024, vCores:2> available, release resources=true
2019-09-16 06:29:52,285 INFO org.apache.hadoop.yarn.server.resourcemanager.scheduler.capacity.LeafQueue: default used=<memory:7168, vCores:6> numContainers=6 user=root user-resources=<memory:7168, vCores:6>
2019-09-16 06:29:52,285 INFO org.apache.hadoop.yarn.server.resourcemanager.scheduler.capacity.LeafQueue: completedContainer container=Container: [ContainerId: container_1568623076950_0003_01_000022, NodeId: e9a6a0455f0d:38503, NodeHttpAddress: e9a6a0455f0d:8042, Resource: <memory:1024, vCores:1>, Priority: 20, Token: Token { kind: ContainerToken, service: 172.24.0.2:38503 }, ] queue=default: capacity=1.0, absoluteCapacity=1.0, usedResources=<memory:7168, vCores:6>, usedCapacity=0.875, absoluteUsedCapacity=0.875, numApps=1, numContainers=6 cluster=<memory:8192, vCores:8>
2019-09-16 06:29:52,286 INFO org.apache.hadoop.yarn.server.resourcemanager.scheduler.capacity.ParentQueue: completedContainer queue=root usedCapacity=0.875 absoluteUsedCapacity=0.875 used=<memory:7168, vCores:6> cluster=<memory:8192, vCores:8>
2019-09-16 06:29:52,286 INFO org.apache.hadoop.yarn.server.resourcemanager.scheduler.capacity.ParentQueue: Re-sorting completed queue: root.default stats: default: capacity=1.0, absoluteCapacity=1.0, usedResources=<memory:7168, vCores:6>, usedCapacity=0.875, absoluteUsedCapacity=0.875, numApps=1, numContainers=6
2019-09-16 06:29:52,286 INFO org.apache.hadoop.yarn.server.resourcemanager.scheduler.capacity.CapacityScheduler: Application attempt appattempt_1568623076950_0003_000001 released container container_1568623076950_0003_01_000022 on node: host: e9a6a0455f0d:38503 #containers=6 available=<memory:1024, vCores:2> used=<memory:7168, vCores:6> with event: FINISHED
2019-09-16 06:29:52,286 INFO org.apache.hadoop.yarn.server.resourcemanager.rmcontainer.RMContainerImpl: container_1568623076950_0003_01_000025 Container Transitioned from NEW to ALLOCATED
2019-09-16 06:29:52,286 INFO org.apache.hadoop.yarn.server.resourcemanager.RMAuditLogger: USER=root	OPERATION=AM Allocated Container	TARGET=SchedulerApp	RESULT=SUCCESS	APPID=application_1568623076950_0003	CONTAINERID=container_1568623076950_0003_01_000025
2019-09-16 06:29:52,286 INFO org.apache.hadoop.yarn.server.resourcemanager.scheduler.SchedulerNode: Assigned container container_1568623076950_0003_01_000025 of capacity <memory:1024, vCores:1> on host e9a6a0455f0d:38503, which has 7 containers, <memory:8192, vCores:7> used and <memory:0, vCores:1> available after allocation
2019-09-16 06:29:52,287 INFO org.apache.hadoop.yarn.server.resourcemanager.scheduler.capacity.LeafQueue: assignedContainer application attempt=appattempt_1568623076950_0003_000001 container=Container: [ContainerId: container_1568623076950_0003_01_000025, NodeId: e9a6a0455f0d:38503, NodeHttpAddress: e9a6a0455f0d:8042, Resource: <memory:1024, vCores:1>, Priority: 20, Token: null, ] queue=default: capacity=1.0, absoluteCapacity=1.0, usedResources=<memory:7168, vCores:6>, usedCapacity=0.875, absoluteUsedCapacity=0.875, numApps=1, numContainers=6 clusterResource=<memory:8192, vCores:8>
2019-09-16 06:29:52,287 INFO org.apache.hadoop.yarn.server.resourcemanager.scheduler.capacity.ParentQueue: Re-sorting assigned queue: root.default stats: default: capacity=1.0, absoluteCapacity=1.0, usedResources=<memory:8192, vCores:7>, usedCapacity=1.0, absoluteUsedCapacity=1.0, numApps=1, numContainers=7
2019-09-16 06:29:52,287 INFO org.apache.hadoop.yarn.server.resourcemanager.scheduler.capacity.ParentQueue: assignedContainer queue=root usedCapacity=1.0 absoluteUsedCapacity=1.0 used=<memory:8192, vCores:7> cluster=<memory:8192, vCores:8>
2019-09-16 06:29:52,822 INFO org.apache.hadoop.yarn.server.resourcemanager.rmcontainer.RMContainerImpl: container_1568623076950_0003_01_000024 Container Transitioned from ALLOCATED to ACQUIRED
2019-09-16 06:29:52,826 INFO org.apache.hadoop.yarn.server.resourcemanager.rmcontainer.RMContainerImpl: container_1568623076950_0003_01_000025 Container Transitioned from ALLOCATED to ACQUIRED
2019-09-16 06:29:52,827 INFO org.apache.hadoop.yarn.server.resourcemanager.rmcontainer.RMContainerImpl: container_1568623076950_0003_01_000020 Container Transitioned from RUNNING to COMPLETED
2019-09-16 06:29:52,827 INFO org.apache.hadoop.yarn.server.resourcemanager.scheduler.common.fica.FiCaSchedulerApp: Completed container: container_1568623076950_0003_01_000020 in state: COMPLETED event:FINISHED
2019-09-16 06:29:52,827 INFO org.apache.hadoop.yarn.server.resourcemanager.RMAuditLogger: USER=root	OPERATION=AM Released Container	TARGET=SchedulerApp	RESULT=SUCCESS	APPID=application_1568623076950_0003	CONTAINERID=container_1568623076950_0003_01_000020
2019-09-16 06:29:52,827 INFO org.apache.hadoop.yarn.server.resourcemanager.scheduler.SchedulerNode: Released container container_1568623076950_0003_01_000020 of capacity <memory:1024, vCores:1> on host e9a6a0455f0d:38503, which currently has 6 containers, <memory:7168, vCores:6> used and <memory:1024, vCores:2> available, release resources=true
2019-09-16 06:29:52,827 INFO org.apache.hadoop.yarn.server.resourcemanager.scheduler.capacity.LeafQueue: default used=<memory:7168, vCores:6> numContainers=6 user=root user-resources=<memory:7168, vCores:6>
2019-09-16 06:29:52,827 INFO org.apache.hadoop.yarn.server.resourcemanager.scheduler.capacity.LeafQueue: completedContainer container=Container: [ContainerId: container_1568623076950_0003_01_000020, NodeId: e9a6a0455f0d:38503, NodeHttpAddress: e9a6a0455f0d:8042, Resource: <memory:1024, vCores:1>, Priority: 20, Token: Token { kind: ContainerToken, service: 172.24.0.2:38503 }, ] queue=default: capacity=1.0, absoluteCapacity=1.0, usedResources=<memory:7168, vCores:6>, usedCapacity=0.875, absoluteUsedCapacity=0.875, numApps=1, numContainers=6 cluster=<memory:8192, vCores:8>
2019-09-16 06:29:52,827 INFO org.apache.hadoop.yarn.server.resourcemanager.scheduler.capacity.ParentQueue: completedContainer queue=root usedCapacity=0.875 absoluteUsedCapacity=0.875 used=<memory:7168, vCores:6> cluster=<memory:8192, vCores:8>
2019-09-16 06:29:52,827 INFO org.apache.hadoop.yarn.server.resourcemanager.scheduler.capacity.ParentQueue: Re-sorting completed queue: root.default stats: default: capacity=1.0, absoluteCapacity=1.0, usedResources=<memory:7168, vCores:6>, usedCapacity=0.875, absoluteUsedCapacity=0.875, numApps=1, numContainers=6
2019-09-16 06:29:52,827 INFO org.apache.hadoop.yarn.server.resourcemanager.scheduler.capacity.CapacityScheduler: Application attempt appattempt_1568623076950_0003_000001 released container container_1568623076950_0003_01_000020 on node: host: e9a6a0455f0d:38503 #containers=6 available=<memory:1024, vCores:2> used=<memory:7168, vCores:6> with event: FINISHED
2019-09-16 06:29:52,827 INFO org.apache.hadoop.yarn.server.resourcemanager.rmcontainer.RMContainerImpl: container_1568623076950_0003_01_000021 Container Transitioned from RUNNING to COMPLETED
2019-09-16 06:29:52,828 INFO org.apache.hadoop.yarn.server.resourcemanager.scheduler.common.fica.FiCaSchedulerApp: Completed container: container_1568623076950_0003_01_000021 in state: COMPLETED event:FINISHED
2019-09-16 06:29:52,828 INFO org.apache.hadoop.yarn.server.resourcemanager.RMAuditLogger: USER=root	OPERATION=AM Released Container	TARGET=SchedulerApp	RESULT=SUCCESS	APPID=application_1568623076950_0003	CONTAINERID=container_1568623076950_0003_01_000021
2019-09-16 06:29:52,828 INFO org.apache.hadoop.yarn.server.resourcemanager.scheduler.SchedulerNode: Released container container_1568623076950_0003_01_000021 of capacity <memory:1024, vCores:1> on host e9a6a0455f0d:38503, which currently has 5 containers, <memory:6144, vCores:5> used and <memory:2048, vCores:3> available, release resources=true
2019-09-16 06:29:52,828 INFO org.apache.hadoop.yarn.server.resourcemanager.scheduler.capacity.LeafQueue: default used=<memory:6144, vCores:5> numContainers=5 user=root user-resources=<memory:6144, vCores:5>
2019-09-16 06:29:52,828 INFO org.apache.hadoop.yarn.server.resourcemanager.scheduler.capacity.LeafQueue: completedContainer container=Container: [ContainerId: container_1568623076950_0003_01_000021, NodeId: e9a6a0455f0d:38503, NodeHttpAddress: e9a6a0455f0d:8042, Resource: <memory:1024, vCores:1>, Priority: 20, Token: Token { kind: ContainerToken, service: 172.24.0.2:38503 }, ] queue=default: capacity=1.0, absoluteCapacity=1.0, usedResources=<memory:6144, vCores:5>, usedCapacity=0.75, absoluteUsedCapacity=0.75, numApps=1, numContainers=5 cluster=<memory:8192, vCores:8>
2019-09-16 06:29:52,828 INFO org.apache.hadoop.yarn.server.resourcemanager.scheduler.capacity.ParentQueue: completedContainer queue=root usedCapacity=0.75 absoluteUsedCapacity=0.75 used=<memory:6144, vCores:5> cluster=<memory:8192, vCores:8>
2019-09-16 06:29:52,828 INFO org.apache.hadoop.yarn.server.resourcemanager.scheduler.capacity.ParentQueue: Re-sorting completed queue: root.default stats: default: capacity=1.0, absoluteCapacity=1.0, usedResources=<memory:6144, vCores:5>, usedCapacity=0.75, absoluteUsedCapacity=0.75, numApps=1, numContainers=5
2019-09-16 06:29:52,828 INFO org.apache.hadoop.yarn.server.resourcemanager.scheduler.capacity.CapacityScheduler: Application attempt appattempt_1568623076950_0003_000001 released container container_1568623076950_0003_01_000021 on node: host: e9a6a0455f0d:38503 #containers=5 available=<memory:2048, vCores:3> used=<memory:6144, vCores:5> with event: FINISHED
2019-09-16 06:29:52,829 INFO org.apache.hadoop.yarn.server.resourcemanager.rmcontainer.RMContainerImpl: container_1568623076950_0003_01_000026 Container Transitioned from NEW to ALLOCATED
2019-09-16 06:29:52,829 INFO org.apache.hadoop.yarn.server.resourcemanager.RMAuditLogger: USER=root	OPERATION=AM Allocated Container	TARGET=SchedulerApp	RESULT=SUCCESS	APPID=application_1568623076950_0003	CONTAINERID=container_1568623076950_0003_01_000026
2019-09-16 06:29:52,829 INFO org.apache.hadoop.yarn.server.resourcemanager.scheduler.SchedulerNode: Assigned container container_1568623076950_0003_01_000026 of capacity <memory:1024, vCores:1> on host e9a6a0455f0d:38503, which has 6 containers, <memory:7168, vCores:6> used and <memory:1024, vCores:2> available after allocation
2019-09-16 06:29:52,829 INFO org.apache.hadoop.yarn.server.resourcemanager.scheduler.capacity.LeafQueue: assignedContainer application attempt=appattempt_1568623076950_0003_000001 container=Container: [ContainerId: container_1568623076950_0003_01_000026, NodeId: e9a6a0455f0d:38503, NodeHttpAddress: e9a6a0455f0d:8042, Resource: <memory:1024, vCores:1>, Priority: 20, Token: null, ] queue=default: capacity=1.0, absoluteCapacity=1.0, usedResources=<memory:6144, vCores:5>, usedCapacity=0.75, absoluteUsedCapacity=0.75, numApps=1, numContainers=5 clusterResource=<memory:8192, vCores:8>
2019-09-16 06:29:52,829 INFO org.apache.hadoop.yarn.server.resourcemanager.scheduler.capacity.ParentQueue: Re-sorting assigned queue: root.default stats: default: capacity=1.0, absoluteCapacity=1.0, usedResources=<memory:7168, vCores:6>, usedCapacity=0.875, absoluteUsedCapacity=0.875, numApps=1, numContainers=6
2019-09-16 06:29:52,829 INFO org.apache.hadoop.yarn.server.resourcemanager.scheduler.capacity.ParentQueue: assignedContainer queue=root usedCapacity=0.875 absoluteUsedCapacity=0.875 used=<memory:7168, vCores:6> cluster=<memory:8192, vCores:8>
2019-09-16 06:29:52,829 INFO org.apache.hadoop.yarn.server.resourcemanager.rmcontainer.RMContainerImpl: container_1568623076950_0003_01_000027 Container Transitioned from NEW to ALLOCATED
2019-09-16 06:29:52,829 INFO org.apache.hadoop.yarn.server.resourcemanager.RMAuditLogger: USER=root	OPERATION=AM Allocated Container	TARGET=SchedulerApp	RESULT=SUCCESS	APPID=application_1568623076950_0003	CONTAINERID=container_1568623076950_0003_01_000027
2019-09-16 06:29:52,829 INFO org.apache.hadoop.yarn.server.resourcemanager.scheduler.SchedulerNode: Assigned container container_1568623076950_0003_01_000027 of capacity <memory:1024, vCores:1> on host e9a6a0455f0d:38503, which has 7 containers, <memory:8192, vCores:7> used and <memory:0, vCores:1> available after allocation
2019-09-16 06:29:52,830 INFO org.apache.hadoop.yarn.server.resourcemanager.scheduler.capacity.LeafQueue: assignedContainer application attempt=appattempt_1568623076950_0003_000001 container=Container: [ContainerId: container_1568623076950_0003_01_000027, NodeId: e9a6a0455f0d:38503, NodeHttpAddress: e9a6a0455f0d:8042, Resource: <memory:1024, vCores:1>, Priority: 20, Token: null, ] queue=default: capacity=1.0, absoluteCapacity=1.0, usedResources=<memory:7168, vCores:6>, usedCapacity=0.875, absoluteUsedCapacity=0.875, numApps=1, numContainers=6 clusterResource=<memory:8192, vCores:8>
2019-09-16 06:29:52,830 INFO org.apache.hadoop.yarn.server.resourcemanager.scheduler.capacity.ParentQueue: Re-sorting assigned queue: root.default stats: default: capacity=1.0, absoluteCapacity=1.0, usedResources=<memory:8192, vCores:7>, usedCapacity=1.0, absoluteUsedCapacity=1.0, numApps=1, numContainers=7
2019-09-16 06:29:52,830 INFO org.apache.hadoop.yarn.server.resourcemanager.scheduler.capacity.ParentQueue: assignedContainer queue=root usedCapacity=1.0 absoluteUsedCapacity=1.0 used=<memory:8192, vCores:7> cluster=<memory:8192, vCores:8>
2019-09-16 06:29:53,827 INFO org.apache.hadoop.yarn.server.resourcemanager.rmcontainer.RMContainerImpl: container_1568623076950_0003_01_000024 Container Transitioned from ACQUIRED to RUNNING
2019-09-16 06:29:53,828 INFO org.apache.hadoop.yarn.server.resourcemanager.rmcontainer.RMContainerImpl: container_1568623076950_0003_01_000025 Container Transitioned from ACQUIRED to RUNNING
2019-09-16 06:29:53,828 INFO org.apache.hadoop.yarn.server.resourcemanager.rmcontainer.RMContainerImpl: container_1568623076950_0003_01_000023 Container Transitioned from RUNNING to COMPLETED
2019-09-16 06:29:53,828 INFO org.apache.hadoop.yarn.server.resourcemanager.scheduler.common.fica.FiCaSchedulerApp: Completed container: container_1568623076950_0003_01_000023 in state: COMPLETED event:FINISHED
2019-09-16 06:29:53,828 INFO org.apache.hadoop.yarn.server.resourcemanager.RMAuditLogger: USER=root	OPERATION=AM Released Container	TARGET=SchedulerApp	RESULT=SUCCESS	APPID=application_1568623076950_0003	CONTAINERID=container_1568623076950_0003_01_000023
2019-09-16 06:29:53,828 INFO org.apache.hadoop.yarn.server.resourcemanager.scheduler.SchedulerNode: Released container container_1568623076950_0003_01_000023 of capacity <memory:1024, vCores:1> on host e9a6a0455f0d:38503, which currently has 6 containers, <memory:7168, vCores:6> used and <memory:1024, vCores:2> available, release resources=true
2019-09-16 06:29:53,828 INFO org.apache.hadoop.yarn.server.resourcemanager.scheduler.capacity.LeafQueue: default used=<memory:7168, vCores:6> numContainers=6 user=root user-resources=<memory:7168, vCores:6>
2019-09-16 06:29:53,831 INFO org.apache.hadoop.yarn.server.resourcemanager.scheduler.capacity.LeafQueue: completedContainer container=Container: [ContainerId: container_1568623076950_0003_01_000023, NodeId: e9a6a0455f0d:38503, NodeHttpAddress: e9a6a0455f0d:8042, Resource: <memory:1024, vCores:1>, Priority: 20, Token: Token { kind: ContainerToken, service: 172.24.0.2:38503 }, ] queue=default: capacity=1.0, absoluteCapacity=1.0, usedResources=<memory:7168, vCores:6>, usedCapacity=0.875, absoluteUsedCapacity=0.875, numApps=1, numContainers=6 cluster=<memory:8192, vCores:8>
2019-09-16 06:29:53,831 INFO org.apache.hadoop.yarn.server.resourcemanager.scheduler.capacity.ParentQueue: completedContainer queue=root usedCapacity=0.875 absoluteUsedCapacity=0.875 used=<memory:7168, vCores:6> cluster=<memory:8192, vCores:8>
2019-09-16 06:29:53,831 INFO org.apache.hadoop.yarn.server.resourcemanager.scheduler.capacity.ParentQueue: Re-sorting completed queue: root.default stats: default: capacity=1.0, absoluteCapacity=1.0, usedResources=<memory:7168, vCores:6>, usedCapacity=0.875, absoluteUsedCapacity=0.875, numApps=1, numContainers=6
2019-09-16 06:29:53,831 INFO org.apache.hadoop.yarn.server.resourcemanager.scheduler.capacity.CapacityScheduler: Application attempt appattempt_1568623076950_0003_000001 released container container_1568623076950_0003_01_000023 on node: host: e9a6a0455f0d:38503 #containers=6 available=<memory:1024, vCores:2> used=<memory:7168, vCores:6> with event: FINISHED
2019-09-16 06:29:53,832 INFO org.apache.hadoop.yarn.server.resourcemanager.rmcontainer.RMContainerImpl: container_1568623076950_0003_01_000028 Container Transitioned from NEW to ALLOCATED
2019-09-16 06:29:53,832 INFO org.apache.hadoop.yarn.server.resourcemanager.RMAuditLogger: USER=root	OPERATION=AM Allocated Container	TARGET=SchedulerApp	RESULT=SUCCESS	APPID=application_1568623076950_0003	CONTAINERID=container_1568623076950_0003_01_000028
2019-09-16 06:29:53,832 INFO org.apache.hadoop.yarn.server.resourcemanager.scheduler.SchedulerNode: Assigned container container_1568623076950_0003_01_000028 of capacity <memory:1024, vCores:1> on host e9a6a0455f0d:38503, which has 7 containers, <memory:8192, vCores:7> used and <memory:0, vCores:1> available after allocation
2019-09-16 06:29:53,832 INFO org.apache.hadoop.yarn.server.resourcemanager.scheduler.capacity.LeafQueue: assignedContainer application attempt=appattempt_1568623076950_0003_000001 container=Container: [ContainerId: container_1568623076950_0003_01_000028, NodeId: e9a6a0455f0d:38503, NodeHttpAddress: e9a6a0455f0d:8042, Resource: <memory:1024, vCores:1>, Priority: 20, Token: null, ] queue=default: capacity=1.0, absoluteCapacity=1.0, usedResources=<memory:7168, vCores:6>, usedCapacity=0.875, absoluteUsedCapacity=0.875, numApps=1, numContainers=6 clusterResource=<memory:8192, vCores:8>
2019-09-16 06:29:53,833 INFO org.apache.hadoop.yarn.server.resourcemanager.scheduler.capacity.ParentQueue: Re-sorting assigned queue: root.default stats: default: capacity=1.0, absoluteCapacity=1.0, usedResources=<memory:8192, vCores:7>, usedCapacity=1.0, absoluteUsedCapacity=1.0, numApps=1, numContainers=7
2019-09-16 06:29:53,833 INFO org.apache.hadoop.yarn.server.resourcemanager.scheduler.capacity.ParentQueue: assignedContainer queue=root usedCapacity=1.0 absoluteUsedCapacity=1.0 used=<memory:8192, vCores:7> cluster=<memory:8192, vCores:8>
2019-09-16 06:29:53,840 INFO org.apache.hadoop.yarn.server.resourcemanager.rmcontainer.RMContainerImpl: container_1568623076950_0003_01_000026 Container Transitioned from ALLOCATED to ACQUIRED
2019-09-16 06:29:53,842 INFO org.apache.hadoop.yarn.server.resourcemanager.rmcontainer.RMContainerImpl: container_1568623076950_0003_01_000027 Container Transitioned from ALLOCATED to ACQUIRED
2019-09-16 06:29:53,845 INFO org.apache.hadoop.yarn.server.resourcemanager.rmcontainer.RMContainerImpl: container_1568623076950_0003_01_000028 Container Transitioned from ALLOCATED to ACQUIRED
2019-09-16 06:29:54,832 INFO org.apache.hadoop.yarn.server.resourcemanager.rmcontainer.RMContainerImpl: container_1568623076950_0003_01_000026 Container Transitioned from ACQUIRED to RUNNING
2019-09-16 06:29:54,832 INFO org.apache.hadoop.yarn.server.resourcemanager.rmcontainer.RMContainerImpl: container_1568623076950_0003_01_000027 Container Transitioned from ACQUIRED to RUNNING
2019-09-16 06:29:54,833 INFO org.apache.hadoop.yarn.server.resourcemanager.rmcontainer.RMContainerImpl: container_1568623076950_0003_01_000028 Container Transitioned from ACQUIRED to RUNNING
2019-09-16 06:30:00,438 INFO org.apache.hadoop.yarn.server.resourcemanager.rmcontainer.RMContainerImpl: container_1568623076950_0003_01_000024 Container Transitioned from RUNNING to COMPLETED
2019-09-16 06:30:00,438 INFO org.apache.hadoop.yarn.server.resourcemanager.scheduler.common.fica.FiCaSchedulerApp: Completed container: container_1568623076950_0003_01_000024 in state: COMPLETED event:FINISHED
2019-09-16 06:30:00,439 INFO org.apache.hadoop.yarn.server.resourcemanager.RMAuditLogger: USER=root	OPERATION=AM Released Container	TARGET=SchedulerApp	RESULT=SUCCESS	APPID=application_1568623076950_0003	CONTAINERID=container_1568623076950_0003_01_000024
2019-09-16 06:30:00,439 INFO org.apache.hadoop.yarn.server.resourcemanager.scheduler.SchedulerNode: Released container container_1568623076950_0003_01_000024 of capacity <memory:1024, vCores:1> on host e9a6a0455f0d:38503, which currently has 6 containers, <memory:7168, vCores:6> used and <memory:1024, vCores:2> available, release resources=true
2019-09-16 06:30:00,439 INFO org.apache.hadoop.yarn.server.resourcemanager.scheduler.capacity.LeafQueue: default used=<memory:7168, vCores:6> numContainers=6 user=root user-resources=<memory:7168, vCores:6>
2019-09-16 06:30:00,443 INFO org.apache.hadoop.yarn.server.resourcemanager.scheduler.capacity.LeafQueue: completedContainer container=Container: [ContainerId: container_1568623076950_0003_01_000024, NodeId: e9a6a0455f0d:38503, NodeHttpAddress: e9a6a0455f0d:8042, Resource: <memory:1024, vCores:1>, Priority: 20, Token: Token { kind: ContainerToken, service: 172.24.0.2:38503 }, ] queue=default: capacity=1.0, absoluteCapacity=1.0, usedResources=<memory:7168, vCores:6>, usedCapacity=0.875, absoluteUsedCapacity=0.875, numApps=1, numContainers=6 cluster=<memory:8192, vCores:8>
2019-09-16 06:30:00,443 INFO org.apache.hadoop.yarn.server.resourcemanager.scheduler.capacity.ParentQueue: completedContainer queue=root usedCapacity=0.875 absoluteUsedCapacity=0.875 used=<memory:7168, vCores:6> cluster=<memory:8192, vCores:8>
2019-09-16 06:30:00,443 INFO org.apache.hadoop.yarn.server.resourcemanager.scheduler.capacity.ParentQueue: Re-sorting completed queue: root.default stats: default: capacity=1.0, absoluteCapacity=1.0, usedResources=<memory:7168, vCores:6>, usedCapacity=0.875, absoluteUsedCapacity=0.875, numApps=1, numContainers=6
2019-09-16 06:30:00,443 INFO org.apache.hadoop.yarn.server.resourcemanager.scheduler.capacity.CapacityScheduler: Application attempt appattempt_1568623076950_0003_000001 released container container_1568623076950_0003_01_000024 on node: host: e9a6a0455f0d:38503 #containers=6 available=<memory:1024, vCores:2> used=<memory:7168, vCores:6> with event: FINISHED
2019-09-16 06:30:00,444 INFO org.apache.hadoop.yarn.server.resourcemanager.rmcontainer.RMContainerImpl: container_1568623076950_0003_01_000029 Container Transitioned from NEW to ALLOCATED
2019-09-16 06:30:00,444 INFO org.apache.hadoop.yarn.server.resourcemanager.RMAuditLogger: USER=root	OPERATION=AM Allocated Container	TARGET=SchedulerApp	RESULT=SUCCESS	APPID=application_1568623076950_0003	CONTAINERID=container_1568623076950_0003_01_000029
2019-09-16 06:30:00,444 INFO org.apache.hadoop.yarn.server.resourcemanager.scheduler.SchedulerNode: Assigned container container_1568623076950_0003_01_000029 of capacity <memory:1024, vCores:1> on host e9a6a0455f0d:38503, which has 7 containers, <memory:8192, vCores:7> used and <memory:0, vCores:1> available after allocation
2019-09-16 06:30:00,444 INFO org.apache.hadoop.yarn.server.resourcemanager.scheduler.capacity.LeafQueue: assignedContainer application attempt=appattempt_1568623076950_0003_000001 container=Container: [ContainerId: container_1568623076950_0003_01_000029, NodeId: e9a6a0455f0d:38503, NodeHttpAddress: e9a6a0455f0d:8042, Resource: <memory:1024, vCores:1>, Priority: 20, Token: null, ] queue=default: capacity=1.0, absoluteCapacity=1.0, usedResources=<memory:7168, vCores:6>, usedCapacity=0.875, absoluteUsedCapacity=0.875, numApps=1, numContainers=6 clusterResource=<memory:8192, vCores:8>
2019-09-16 06:30:00,444 INFO org.apache.hadoop.yarn.server.resourcemanager.scheduler.capacity.ParentQueue: Re-sorting assigned queue: root.default stats: default: capacity=1.0, absoluteCapacity=1.0, usedResources=<memory:8192, vCores:7>, usedCapacity=1.0, absoluteUsedCapacity=1.0, numApps=1, numContainers=7
2019-09-16 06:30:00,445 INFO org.apache.hadoop.yarn.server.resourcemanager.scheduler.capacity.ParentQueue: assignedContainer queue=root usedCapacity=1.0 absoluteUsedCapacity=1.0 used=<memory:8192, vCores:7> cluster=<memory:8192, vCores:8>
2019-09-16 06:30:00,921 INFO org.apache.hadoop.yarn.server.resourcemanager.rmcontainer.RMContainerImpl: container_1568623076950_0003_01_000029 Container Transitioned from ALLOCATED to ACQUIRED
2019-09-16 06:30:01,449 INFO org.apache.hadoop.yarn.server.resourcemanager.rmcontainer.RMContainerImpl: container_1568623076950_0003_01_000029 Container Transitioned from ACQUIRED to RUNNING
2019-09-16 06:30:01,450 INFO org.apache.hadoop.yarn.server.resourcemanager.rmcontainer.RMContainerImpl: container_1568623076950_0003_01_000025 Container Transitioned from RUNNING to COMPLETED
2019-09-16 06:30:01,450 INFO org.apache.hadoop.yarn.server.resourcemanager.scheduler.common.fica.FiCaSchedulerApp: Completed container: container_1568623076950_0003_01_000025 in state: COMPLETED event:FINISHED
2019-09-16 06:30:01,450 INFO org.apache.hadoop.yarn.server.resourcemanager.RMAuditLogger: USER=root	OPERATION=AM Released Container	TARGET=SchedulerApp	RESULT=SUCCESS	APPID=application_1568623076950_0003	CONTAINERID=container_1568623076950_0003_01_000025
2019-09-16 06:30:01,451 INFO org.apache.hadoop.yarn.server.resourcemanager.scheduler.SchedulerNode: Released container container_1568623076950_0003_01_000025 of capacity <memory:1024, vCores:1> on host e9a6a0455f0d:38503, which currently has 6 containers, <memory:7168, vCores:6> used and <memory:1024, vCores:2> available, release resources=true
2019-09-16 06:30:01,451 INFO org.apache.hadoop.yarn.server.resourcemanager.scheduler.capacity.LeafQueue: default used=<memory:7168, vCores:6> numContainers=6 user=root user-resources=<memory:7168, vCores:6>
2019-09-16 06:30:01,456 INFO org.apache.hadoop.yarn.server.resourcemanager.scheduler.capacity.LeafQueue: completedContainer container=Container: [ContainerId: container_1568623076950_0003_01_000025, NodeId: e9a6a0455f0d:38503, NodeHttpAddress: e9a6a0455f0d:8042, Resource: <memory:1024, vCores:1>, Priority: 20, Token: Token { kind: ContainerToken, service: 172.24.0.2:38503 }, ] queue=default: capacity=1.0, absoluteCapacity=1.0, usedResources=<memory:7168, vCores:6>, usedCapacity=0.875, absoluteUsedCapacity=0.875, numApps=1, numContainers=6 cluster=<memory:8192, vCores:8>
2019-09-16 06:30:01,456 INFO org.apache.hadoop.yarn.server.resourcemanager.scheduler.capacity.ParentQueue: completedContainer queue=root usedCapacity=0.875 absoluteUsedCapacity=0.875 used=<memory:7168, vCores:6> cluster=<memory:8192, vCores:8>
2019-09-16 06:30:01,457 INFO org.apache.hadoop.yarn.server.resourcemanager.scheduler.capacity.ParentQueue: Re-sorting completed queue: root.default stats: default: capacity=1.0, absoluteCapacity=1.0, usedResources=<memory:7168, vCores:6>, usedCapacity=0.875, absoluteUsedCapacity=0.875, numApps=1, numContainers=6
2019-09-16 06:30:01,457 INFO org.apache.hadoop.yarn.server.resourcemanager.scheduler.capacity.CapacityScheduler: Application attempt appattempt_1568623076950_0003_000001 released container container_1568623076950_0003_01_000025 on node: host: e9a6a0455f0d:38503 #containers=6 available=<memory:1024, vCores:2> used=<memory:7168, vCores:6> with event: FINISHED
2019-09-16 06:30:01,458 INFO org.apache.hadoop.yarn.server.resourcemanager.rmcontainer.RMContainerImpl: container_1568623076950_0003_01_000030 Container Transitioned from NEW to ALLOCATED
2019-09-16 06:30:01,459 INFO org.apache.hadoop.yarn.server.resourcemanager.RMAuditLogger: USER=root	OPERATION=AM Allocated Container	TARGET=SchedulerApp	RESULT=SUCCESS	APPID=application_1568623076950_0003	CONTAINERID=container_1568623076950_0003_01_000030
2019-09-16 06:30:01,459 INFO org.apache.hadoop.yarn.server.resourcemanager.scheduler.SchedulerNode: Assigned container container_1568623076950_0003_01_000030 of capacity <memory:1024, vCores:1> on host e9a6a0455f0d:38503, which has 7 containers, <memory:8192, vCores:7> used and <memory:0, vCores:1> available after allocation
2019-09-16 06:30:01,460 INFO org.apache.hadoop.yarn.server.resourcemanager.scheduler.capacity.LeafQueue: assignedContainer application attempt=appattempt_1568623076950_0003_000001 container=Container: [ContainerId: container_1568623076950_0003_01_000030, NodeId: e9a6a0455f0d:38503, NodeHttpAddress: e9a6a0455f0d:8042, Resource: <memory:1024, vCores:1>, Priority: 20, Token: null, ] queue=default: capacity=1.0, absoluteCapacity=1.0, usedResources=<memory:7168, vCores:6>, usedCapacity=0.875, absoluteUsedCapacity=0.875, numApps=1, numContainers=6 clusterResource=<memory:8192, vCores:8>
2019-09-16 06:30:01,460 INFO org.apache.hadoop.yarn.server.resourcemanager.scheduler.capacity.ParentQueue: Re-sorting assigned queue: root.default stats: default: capacity=1.0, absoluteCapacity=1.0, usedResources=<memory:8192, vCores:7>, usedCapacity=1.0, absoluteUsedCapacity=1.0, numApps=1, numContainers=7
2019-09-16 06:30:01,461 INFO org.apache.hadoop.yarn.server.resourcemanager.scheduler.capacity.ParentQueue: assignedContainer queue=root usedCapacity=1.0 absoluteUsedCapacity=1.0 used=<memory:8192, vCores:7> cluster=<memory:8192, vCores:8>
2019-09-16 06:30:01,935 INFO org.apache.hadoop.yarn.server.resourcemanager.rmcontainer.RMContainerImpl: container_1568623076950_0003_01_000030 Container Transitioned from ALLOCATED to ACQUIRED
2019-09-16 06:30:02,454 INFO org.apache.hadoop.yarn.server.resourcemanager.rmcontainer.RMContainerImpl: container_1568623076950_0003_01_000030 Container Transitioned from ACQUIRED to RUNNING
2019-09-16 06:30:03,976 INFO org.apache.hadoop.yarn.server.resourcemanager.rmcontainer.RMContainerImpl: container_1568623076950_0003_01_000027 Container Transitioned from RUNNING to COMPLETED
2019-09-16 06:30:03,976 INFO org.apache.hadoop.yarn.server.resourcemanager.scheduler.common.fica.FiCaSchedulerApp: Completed container: container_1568623076950_0003_01_000027 in state: COMPLETED event:FINISHED
2019-09-16 06:30:03,976 INFO org.apache.hadoop.yarn.server.resourcemanager.RMAuditLogger: USER=root	OPERATION=AM Released Container	TARGET=SchedulerApp	RESULT=SUCCESS	APPID=application_1568623076950_0003	CONTAINERID=container_1568623076950_0003_01_000027
2019-09-16 06:30:03,976 INFO org.apache.hadoop.yarn.server.resourcemanager.scheduler.SchedulerNode: Released container container_1568623076950_0003_01_000027 of capacity <memory:1024, vCores:1> on host e9a6a0455f0d:38503, which currently has 6 containers, <memory:7168, vCores:6> used and <memory:1024, vCores:2> available, release resources=true
2019-09-16 06:30:03,976 INFO org.apache.hadoop.yarn.server.resourcemanager.scheduler.capacity.LeafQueue: default used=<memory:7168, vCores:6> numContainers=6 user=root user-resources=<memory:7168, vCores:6>
2019-09-16 06:30:03,979 INFO org.apache.hadoop.yarn.server.resourcemanager.scheduler.capacity.LeafQueue: completedContainer container=Container: [ContainerId: container_1568623076950_0003_01_000027, NodeId: e9a6a0455f0d:38503, NodeHttpAddress: e9a6a0455f0d:8042, Resource: <memory:1024, vCores:1>, Priority: 20, Token: Token { kind: ContainerToken, service: 172.24.0.2:38503 }, ] queue=default: capacity=1.0, absoluteCapacity=1.0, usedResources=<memory:7168, vCores:6>, usedCapacity=0.875, absoluteUsedCapacity=0.875, numApps=1, numContainers=6 cluster=<memory:8192, vCores:8>
2019-09-16 06:30:03,979 INFO org.apache.hadoop.yarn.server.resourcemanager.scheduler.capacity.ParentQueue: completedContainer queue=root usedCapacity=0.875 absoluteUsedCapacity=0.875 used=<memory:7168, vCores:6> cluster=<memory:8192, vCores:8>
2019-09-16 06:30:03,979 INFO org.apache.hadoop.yarn.server.resourcemanager.scheduler.capacity.ParentQueue: Re-sorting completed queue: root.default stats: default: capacity=1.0, absoluteCapacity=1.0, usedResources=<memory:7168, vCores:6>, usedCapacity=0.875, absoluteUsedCapacity=0.875, numApps=1, numContainers=6
2019-09-16 06:30:03,979 INFO org.apache.hadoop.yarn.server.resourcemanager.scheduler.capacity.CapacityScheduler: Application attempt appattempt_1568623076950_0003_000001 released container container_1568623076950_0003_01_000027 on node: host: e9a6a0455f0d:38503 #containers=6 available=<memory:1024, vCores:2> used=<memory:7168, vCores:6> with event: FINISHED
2019-09-16 06:30:03,979 INFO org.apache.hadoop.yarn.server.resourcemanager.rmcontainer.RMContainerImpl: container_1568623076950_0003_01_000028 Container Transitioned from RUNNING to COMPLETED
2019-09-16 06:30:03,979 INFO org.apache.hadoop.yarn.server.resourcemanager.scheduler.common.fica.FiCaSchedulerApp: Completed container: container_1568623076950_0003_01_000028 in state: COMPLETED event:FINISHED
2019-09-16 06:30:03,979 INFO org.apache.hadoop.yarn.server.resourcemanager.RMAuditLogger: USER=root	OPERATION=AM Released Container	TARGET=SchedulerApp	RESULT=SUCCESS	APPID=application_1568623076950_0003	CONTAINERID=container_1568623076950_0003_01_000028
2019-09-16 06:30:03,979 INFO org.apache.hadoop.yarn.server.resourcemanager.scheduler.SchedulerNode: Released container container_1568623076950_0003_01_000028 of capacity <memory:1024, vCores:1> on host e9a6a0455f0d:38503, which currently has 5 containers, <memory:6144, vCores:5> used and <memory:2048, vCores:3> available, release resources=true
2019-09-16 06:30:03,980 INFO org.apache.hadoop.yarn.server.resourcemanager.scheduler.capacity.LeafQueue: default used=<memory:6144, vCores:5> numContainers=5 user=root user-resources=<memory:6144, vCores:5>
2019-09-16 06:30:03,980 INFO org.apache.hadoop.yarn.server.resourcemanager.scheduler.capacity.LeafQueue: completedContainer container=Container: [ContainerId: container_1568623076950_0003_01_000028, NodeId: e9a6a0455f0d:38503, NodeHttpAddress: e9a6a0455f0d:8042, Resource: <memory:1024, vCores:1>, Priority: 20, Token: Token { kind: ContainerToken, service: 172.24.0.2:38503 }, ] queue=default: capacity=1.0, absoluteCapacity=1.0, usedResources=<memory:6144, vCores:5>, usedCapacity=0.75, absoluteUsedCapacity=0.75, numApps=1, numContainers=5 cluster=<memory:8192, vCores:8>
2019-09-16 06:30:03,980 INFO org.apache.hadoop.yarn.server.resourcemanager.scheduler.capacity.ParentQueue: completedContainer queue=root usedCapacity=0.75 absoluteUsedCapacity=0.75 used=<memory:6144, vCores:5> cluster=<memory:8192, vCores:8>
2019-09-16 06:30:03,980 INFO org.apache.hadoop.yarn.server.resourcemanager.scheduler.capacity.ParentQueue: Re-sorting completed queue: root.default stats: default: capacity=1.0, absoluteCapacity=1.0, usedResources=<memory:6144, vCores:5>, usedCapacity=0.75, absoluteUsedCapacity=0.75, numApps=1, numContainers=5
2019-09-16 06:30:03,980 INFO org.apache.hadoop.yarn.server.resourcemanager.scheduler.capacity.CapacityScheduler: Application attempt appattempt_1568623076950_0003_000001 released container container_1568623076950_0003_01_000028 on node: host: e9a6a0455f0d:38503 #containers=5 available=<memory:2048, vCores:3> used=<memory:6144, vCores:5> with event: FINISHED
2019-09-16 06:30:03,980 INFO org.apache.hadoop.yarn.server.resourcemanager.rmcontainer.RMContainerImpl: container_1568623076950_0003_01_000026 Container Transitioned from RUNNING to COMPLETED
2019-09-16 06:30:03,980 INFO org.apache.hadoop.yarn.server.resourcemanager.scheduler.common.fica.FiCaSchedulerApp: Completed container: container_1568623076950_0003_01_000026 in state: COMPLETED event:FINISHED
2019-09-16 06:30:03,980 INFO org.apache.hadoop.yarn.server.resourcemanager.RMAuditLogger: USER=root	OPERATION=AM Released Container	TARGET=SchedulerApp	RESULT=SUCCESS	APPID=application_1568623076950_0003	CONTAINERID=container_1568623076950_0003_01_000026
2019-09-16 06:30:03,980 INFO org.apache.hadoop.yarn.server.resourcemanager.scheduler.SchedulerNode: Released container container_1568623076950_0003_01_000026 of capacity <memory:1024, vCores:1> on host e9a6a0455f0d:38503, which currently has 4 containers, <memory:5120, vCores:4> used and <memory:3072, vCores:4> available, release resources=true
2019-09-16 06:30:03,981 INFO org.apache.hadoop.yarn.server.resourcemanager.scheduler.capacity.LeafQueue: default used=<memory:5120, vCores:4> numContainers=4 user=root user-resources=<memory:5120, vCores:4>
2019-09-16 06:30:03,981 INFO org.apache.hadoop.yarn.server.resourcemanager.scheduler.capacity.LeafQueue: completedContainer container=Container: [ContainerId: container_1568623076950_0003_01_000026, NodeId: e9a6a0455f0d:38503, NodeHttpAddress: e9a6a0455f0d:8042, Resource: <memory:1024, vCores:1>, Priority: 20, Token: Token { kind: ContainerToken, service: 172.24.0.2:38503 }, ] queue=default: capacity=1.0, absoluteCapacity=1.0, usedResources=<memory:5120, vCores:4>, usedCapacity=0.625, absoluteUsedCapacity=0.625, numApps=1, numContainers=4 cluster=<memory:8192, vCores:8>
2019-09-16 06:30:03,981 INFO org.apache.hadoop.yarn.server.resourcemanager.scheduler.capacity.ParentQueue: completedContainer queue=root usedCapacity=0.625 absoluteUsedCapacity=0.625 used=<memory:5120, vCores:4> cluster=<memory:8192, vCores:8>
2019-09-16 06:30:03,981 INFO org.apache.hadoop.yarn.server.resourcemanager.scheduler.capacity.ParentQueue: Re-sorting completed queue: root.default stats: default: capacity=1.0, absoluteCapacity=1.0, usedResources=<memory:5120, vCores:4>, usedCapacity=0.625, absoluteUsedCapacity=0.625, numApps=1, numContainers=4
2019-09-16 06:30:03,981 INFO org.apache.hadoop.yarn.server.resourcemanager.scheduler.capacity.CapacityScheduler: Application attempt appattempt_1568623076950_0003_000001 released container container_1568623076950_0003_01_000026 on node: host: e9a6a0455f0d:38503 #containers=4 available=<memory:3072, vCores:4> used=<memory:5120, vCores:4> with event: FINISHED
2019-09-16 06:30:03,982 INFO org.apache.hadoop.yarn.server.resourcemanager.rmcontainer.RMContainerImpl: container_1568623076950_0003_01_000031 Container Transitioned from NEW to ALLOCATED
2019-09-16 06:30:03,982 INFO org.apache.hadoop.yarn.server.resourcemanager.RMAuditLogger: USER=root	OPERATION=AM Allocated Container	TARGET=SchedulerApp	RESULT=SUCCESS	APPID=application_1568623076950_0003	CONTAINERID=container_1568623076950_0003_01_000031
2019-09-16 06:30:03,982 INFO org.apache.hadoop.yarn.server.resourcemanager.scheduler.SchedulerNode: Assigned container container_1568623076950_0003_01_000031 of capacity <memory:1024, vCores:1> on host e9a6a0455f0d:38503, which has 5 containers, <memory:6144, vCores:5> used and <memory:2048, vCores:3> available after allocation
2019-09-16 06:30:03,982 INFO org.apache.hadoop.yarn.server.resourcemanager.scheduler.capacity.LeafQueue: assignedContainer application attempt=appattempt_1568623076950_0003_000001 container=Container: [ContainerId: container_1568623076950_0003_01_000031, NodeId: e9a6a0455f0d:38503, NodeHttpAddress: e9a6a0455f0d:8042, Resource: <memory:1024, vCores:1>, Priority: 20, Token: null, ] queue=default: capacity=1.0, absoluteCapacity=1.0, usedResources=<memory:5120, vCores:4>, usedCapacity=0.625, absoluteUsedCapacity=0.625, numApps=1, numContainers=4 clusterResource=<memory:8192, vCores:8>
2019-09-16 06:30:03,982 INFO org.apache.hadoop.yarn.server.resourcemanager.scheduler.capacity.ParentQueue: Re-sorting assigned queue: root.default stats: default: capacity=1.0, absoluteCapacity=1.0, usedResources=<memory:6144, vCores:5>, usedCapacity=0.75, absoluteUsedCapacity=0.75, numApps=1, numContainers=5
2019-09-16 06:30:03,983 INFO org.apache.hadoop.yarn.server.resourcemanager.scheduler.capacity.ParentQueue: assignedContainer queue=root usedCapacity=0.75 absoluteUsedCapacity=0.75 used=<memory:6144, vCores:5> cluster=<memory:8192, vCores:8>
2019-09-16 06:30:03,983 INFO org.apache.hadoop.yarn.server.resourcemanager.rmcontainer.RMContainerImpl: container_1568623076950_0003_01_000032 Container Transitioned from NEW to ALLOCATED
2019-09-16 06:30:03,983 INFO org.apache.hadoop.yarn.server.resourcemanager.RMAuditLogger: USER=root	OPERATION=AM Allocated Container	TARGET=SchedulerApp	RESULT=SUCCESS	APPID=application_1568623076950_0003	CONTAINERID=container_1568623076950_0003_01_000032
2019-09-16 06:30:03,983 INFO org.apache.hadoop.yarn.server.resourcemanager.scheduler.SchedulerNode: Assigned container container_1568623076950_0003_01_000032 of capacity <memory:1024, vCores:1> on host e9a6a0455f0d:38503, which has 6 containers, <memory:7168, vCores:6> used and <memory:1024, vCores:2> available after allocation
2019-09-16 06:30:03,983 INFO org.apache.hadoop.yarn.server.resourcemanager.scheduler.capacity.LeafQueue: assignedContainer application attempt=appattempt_1568623076950_0003_000001 container=Container: [ContainerId: container_1568623076950_0003_01_000032, NodeId: e9a6a0455f0d:38503, NodeHttpAddress: e9a6a0455f0d:8042, Resource: <memory:1024, vCores:1>, Priority: 20, Token: null, ] queue=default: capacity=1.0, absoluteCapacity=1.0, usedResources=<memory:6144, vCores:5>, usedCapacity=0.75, absoluteUsedCapacity=0.75, numApps=1, numContainers=5 clusterResource=<memory:8192, vCores:8>
2019-09-16 06:30:03,983 INFO org.apache.hadoop.yarn.server.resourcemanager.scheduler.capacity.ParentQueue: Re-sorting assigned queue: root.default stats: default: capacity=1.0, absoluteCapacity=1.0, usedResources=<memory:7168, vCores:6>, usedCapacity=0.875, absoluteUsedCapacity=0.875, numApps=1, numContainers=6
2019-09-16 06:30:03,987 INFO org.apache.hadoop.yarn.server.resourcemanager.scheduler.capacity.ParentQueue: assignedContainer queue=root usedCapacity=0.875 absoluteUsedCapacity=0.875 used=<memory:7168, vCores:6> cluster=<memory:8192, vCores:8>
2019-09-16 06:30:03,988 INFO org.apache.hadoop.yarn.server.resourcemanager.rmcontainer.RMContainerImpl: container_1568623076950_0003_01_000033 Container Transitioned from NEW to ALLOCATED
2019-09-16 06:30:03,989 INFO org.apache.hadoop.yarn.server.resourcemanager.RMAuditLogger: USER=root	OPERATION=AM Allocated Container	TARGET=SchedulerApp	RESULT=SUCCESS	APPID=application_1568623076950_0003	CONTAINERID=container_1568623076950_0003_01_000033
2019-09-16 06:30:03,989 INFO org.apache.hadoop.yarn.server.resourcemanager.scheduler.SchedulerNode: Assigned container container_1568623076950_0003_01_000033 of capacity <memory:1024, vCores:1> on host e9a6a0455f0d:38503, which has 7 containers, <memory:8192, vCores:7> used and <memory:0, vCores:1> available after allocation
2019-09-16 06:30:03,989 INFO org.apache.hadoop.yarn.server.resourcemanager.scheduler.capacity.LeafQueue: assignedContainer application attempt=appattempt_1568623076950_0003_000001 container=Container: [ContainerId: container_1568623076950_0003_01_000033, NodeId: e9a6a0455f0d:38503, NodeHttpAddress: e9a6a0455f0d:8042, Resource: <memory:1024, vCores:1>, Priority: 20, Token: null, ] queue=default: capacity=1.0, absoluteCapacity=1.0, usedResources=<memory:7168, vCores:6>, usedCapacity=0.875, absoluteUsedCapacity=0.875, numApps=1, numContainers=6 clusterResource=<memory:8192, vCores:8>
2019-09-16 06:30:03,989 INFO org.apache.hadoop.yarn.server.resourcemanager.scheduler.capacity.ParentQueue: Re-sorting assigned queue: root.default stats: default: capacity=1.0, absoluteCapacity=1.0, usedResources=<memory:8192, vCores:7>, usedCapacity=1.0, absoluteUsedCapacity=1.0, numApps=1, numContainers=7
2019-09-16 06:30:03,990 INFO org.apache.hadoop.yarn.server.resourcemanager.scheduler.capacity.ParentQueue: assignedContainer queue=root usedCapacity=1.0 absoluteUsedCapacity=1.0 used=<memory:8192, vCores:7> cluster=<memory:8192, vCores:8>
2019-09-16 06:30:04,954 INFO org.apache.hadoop.yarn.server.resourcemanager.rmcontainer.RMContainerImpl: container_1568623076950_0003_01_000031 Container Transitioned from ALLOCATED to ACQUIRED
2019-09-16 06:30:04,956 INFO org.apache.hadoop.yarn.server.resourcemanager.rmcontainer.RMContainerImpl: container_1568623076950_0003_01_000032 Container Transitioned from ALLOCATED to ACQUIRED
2019-09-16 06:30:04,962 INFO org.apache.hadoop.yarn.server.resourcemanager.rmcontainer.RMContainerImpl: container_1568623076950_0003_01_000033 Container Transitioned from ALLOCATED to ACQUIRED
2019-09-16 06:30:05,968 INFO org.apache.hadoop.yarn.server.resourcemanager.scheduler.AppSchedulingInfo: checking for deactivate of application :application_1568623076950_0003
2019-09-16 06:30:05,983 INFO org.apache.hadoop.yarn.server.resourcemanager.rmcontainer.RMContainerImpl: container_1568623076950_0003_01_000031 Container Transitioned from ACQUIRED to RUNNING
2019-09-16 06:30:05,983 INFO org.apache.hadoop.yarn.server.resourcemanager.rmcontainer.RMContainerImpl: container_1568623076950_0003_01_000032 Container Transitioned from ACQUIRED to RUNNING
2019-09-16 06:30:05,983 INFO org.apache.hadoop.yarn.server.resourcemanager.rmcontainer.RMContainerImpl: container_1568623076950_0003_01_000033 Container Transitioned from ACQUIRED to RUNNING
2019-09-16 06:30:07,727 INFO org.apache.hadoop.yarn.server.resourcemanager.rmcontainer.RMContainerImpl: container_1568623076950_0003_01_000029 Container Transitioned from RUNNING to COMPLETED
